[Mon Mar 12 15:57:17.094265 2018] [wsgi:error] [pid 14272] [remote 85.26.235.40:60056] [2018-03-12 15:57:17,082] ERROR in app: Exception on /work/wait_confirm [GET]
[Mon Mar 12 15:57:17.094480 2018] [wsgi:error] [pid 14272] [remote 85.26.235.40:60056] Traceback (most recent call last):
[Mon Mar 12 15:57:17.094495 2018] [wsgi:error] [pid 14272] [remote 85.26.235.40:60056]   File "/usr/lib/python3.6/site-packages/flask/app.py", line 1982, in wsgi_app
[Mon Mar 12 15:57:17.094506 2018] [wsgi:error] [pid 14272] [remote 85.26.235.40:60056]     response = self.full_dispatch_request()
[Mon Mar 12 15:57:17.094515 2018] [wsgi:error] [pid 14272] [remote 85.26.235.40:60056]   File "/usr/lib/python3.6/site-packages/flask/app.py", line 1614, in full_dispatch_request
[Mon Mar 12 15:57:17.094524 2018] [wsgi:error] [pid 14272] [remote 85.26.235.40:60056]     rv = self.handle_user_exception(e)
[Mon Mar 12 15:57:17.094533 2018] [wsgi:error] [pid 14272] [remote 85.26.235.40:60056]   File "/usr/lib/python3.6/site-packages/flask/app.py", line 1517, in handle_user_exception
[Mon Mar 12 15:57:17.094542 2018] [wsgi:error] [pid 14272] [remote 85.26.235.40:60056]     reraise(exc_type, exc_value, tb)
[Mon Mar 12 15:57:17.094551 2018] [wsgi:error] [pid 14272] [remote 85.26.235.40:60056]   File "/usr/lib/python3.6/site-packages/flask/_compat.py", line 33, in reraise
[Mon Mar 12 15:57:17.094559 2018] [wsgi:error] [pid 14272] [remote 85.26.235.40:60056]     raise value
[Mon Mar 12 15:57:17.094568 2018] [wsgi:error] [pid 14272] [remote 85.26.235.40:60056]   File "/usr/lib/python3.6/site-packages/flask/app.py", line 1612, in full_dispatch_request
[Mon Mar 12 15:57:17.094577 2018] [wsgi:error] [pid 14272] [remote 85.26.235.40:60056]     rv = self.dispatch_request()
[Mon Mar 12 15:57:17.094585 2018] [wsgi:error] [pid 14272] [remote 85.26.235.40:60056]   File "/usr/lib/python3.6/site-packages/flask/app.py", line 1598, in dispatch_request
[Mon Mar 12 15:57:17.094595 2018] [wsgi:error] [pid 14272] [remote 85.26.235.40:60056]     return self.view_functions[rule.endpoint](**req.view_args)
[Mon Mar 12 15:57:17.094603 2018] [wsgi:error] [pid 14272] [remote 85.26.235.40:60056]   File "/srv/http/virtlabs.tk/5koleso.tk/worker.py", line 91, in wait_confirm
[Mon Mar 12 15:57:17.094612 2018] [wsgi:error] [pid 14272] [remote 85.26.235.40:60056]     select(p for p in Taxi_order if p.phone == context['phone']).delete()
[Mon Mar 12 15:57:17.094621 2018] [wsgi:error] [pid 14272] [remote 85.26.235.40:60056]   File "<string>", line 2, in delete
[Mon Mar 12 15:57:17.094630 2018] [wsgi:error] [pid 14272] [remote 85.26.235.40:60056]   File "/usr/lib/python3.6/site-packages/pony/utils/utils.py", line 58, in cut_traceback
[Mon Mar 12 15:57:17.094639 2018] [wsgi:error] [pid 14272] [remote 85.26.235.40:60056]     return func(*args, **kwargs)
[Mon Mar 12 15:57:17.094648 2018] [wsgi:error] [pid 14272] [remote 85.26.235.40:60056]   File "/usr/lib/python3.6/site-packages/pony/orm/core.py", line 5483, in delete
[Mon Mar 12 15:57:17.094656 2018] [wsgi:error] [pid 14272] [remote 85.26.235.40:60056]     objects = query._fetch()
[Mon Mar 12 15:57:17.094665 2018] [wsgi:error] [pid 14272] [remote 85.26.235.40:60056]   File "/usr/lib/python3.6/site-packages/pony/orm/core.py", line 5336, in _fetch
[Mon Mar 12 15:57:17.094674 2018] [wsgi:error] [pid 14272] [remote 85.26.235.40:60056]     sql, arguments, attr_offsets, query_key = query._construct_sql_and_arguments(range)
[Mon Mar 12 15:57:17.094690 2018] [wsgi:error] [pid 14272] [remote 85.26.235.40:60056]   File "/usr/lib/python3.6/site-packages/pony/orm/core.py", line 5316, in _construct_sql_and_arguments
[Mon Mar 12 15:57:17.094700 2018] [wsgi:error] [pid 14272] [remote 85.26.235.40:60056]     cache = database._get_cache()
[Mon Mar 12 15:57:17.094709 2018] [wsgi:error] [pid 14272] [remote 85.26.235.40:60056]   File "/usr/lib/python3.6/site-packages/pony/orm/core.py", line 726, in _get_cache
[Mon Mar 12 15:57:17.094718 2018] [wsgi:error] [pid 14272] [remote 85.26.235.40:60056]     ): throw(TransactionError, 'db_session is required when working with the database')
[Mon Mar 12 15:57:17.094761 2018] [wsgi:error] [pid 14272] [remote 85.26.235.40:60056]   File "/usr/lib/python3.6/site-packages/pony/utils/utils.py", line 98, in throw
[Mon Mar 12 15:57:17.094773 2018] [wsgi:error] [pid 14272] [remote 85.26.235.40:60056]     raise exc
[Mon Mar 12 15:57:17.094790 2018] [wsgi:error] [pid 14272] [remote 85.26.235.40:60056] pony.orm.core.TransactionError: db_session is required when working with the database
[Mon Mar 12 15:57:17.094859 2018] [wsgi:error] [pid 14272] [remote 85.26.235.40:60056] 
[Mon Mar 12 15:57:41.573022 2018] [wsgi:error] [pid 14272] [remote 85.26.235.40:34774] [2018-03-12 15:57:41,571] ERROR in app: Exception on /work/wait_confirm [GET]
[Mon Mar 12 15:57:41.573136 2018] [wsgi:error] [pid 14272] [remote 85.26.235.40:34774] Traceback (most recent call last):
[Mon Mar 12 15:57:41.573149 2018] [wsgi:error] [pid 14272] [remote 85.26.235.40:34774]   File "/usr/lib/python3.6/site-packages/flask/app.py", line 1982, in wsgi_app
[Mon Mar 12 15:57:41.573160 2018] [wsgi:error] [pid 14272] [remote 85.26.235.40:34774]     response = self.full_dispatch_request()
[Mon Mar 12 15:57:41.573169 2018] [wsgi:error] [pid 14272] [remote 85.26.235.40:34774]   File "/usr/lib/python3.6/site-packages/flask/app.py", line 1614, in full_dispatch_request
[Mon Mar 12 15:57:41.573179 2018] [wsgi:error] [pid 14272] [remote 85.26.235.40:34774]     rv = self.handle_user_exception(e)
[Mon Mar 12 15:57:41.573188 2018] [wsgi:error] [pid 14272] [remote 85.26.235.40:34774]   File "/usr/lib/python3.6/site-packages/flask/app.py", line 1517, in handle_user_exception
[Mon Mar 12 15:57:41.573197 2018] [wsgi:error] [pid 14272] [remote 85.26.235.40:34774]     reraise(exc_type, exc_value, tb)
[Mon Mar 12 15:57:41.573206 2018] [wsgi:error] [pid 14272] [remote 85.26.235.40:34774]   File "/usr/lib/python3.6/site-packages/flask/_compat.py", line 33, in reraise
[Mon Mar 12 15:57:41.573215 2018] [wsgi:error] [pid 14272] [remote 85.26.235.40:34774]     raise value
[Mon Mar 12 15:57:41.573223 2018] [wsgi:error] [pid 14272] [remote 85.26.235.40:34774]   File "/usr/lib/python3.6/site-packages/flask/app.py", line 1612, in full_dispatch_request
[Mon Mar 12 15:57:41.573232 2018] [wsgi:error] [pid 14272] [remote 85.26.235.40:34774]     rv = self.dispatch_request()
[Mon Mar 12 15:57:41.573241 2018] [wsgi:error] [pid 14272] [remote 85.26.235.40:34774]   File "/usr/lib/python3.6/site-packages/flask/app.py", line 1598, in dispatch_request
[Mon Mar 12 15:57:41.573251 2018] [wsgi:error] [pid 14272] [remote 85.26.235.40:34774]     return self.view_functions[rule.endpoint](**req.view_args)
[Mon Mar 12 15:57:41.573260 2018] [wsgi:error] [pid 14272] [remote 85.26.235.40:34774]   File "/srv/http/virtlabs.tk/5koleso.tk/worker.py", line 91, in wait_confirm
[Mon Mar 12 15:57:41.573408 2018] [wsgi:error] [pid 14272] [remote 85.26.235.40:34774]     select(p for p in Taxi_order if p.phone == context['phone']).delete()
[Mon Mar 12 15:57:41.573425 2018] [wsgi:error] [pid 14272] [remote 85.26.235.40:34774]   File "<string>", line 2, in delete
[Mon Mar 12 15:57:41.573435 2018] [wsgi:error] [pid 14272] [remote 85.26.235.40:34774]   File "/usr/lib/python3.6/site-packages/pony/utils/utils.py", line 58, in cut_traceback
[Mon Mar 12 15:57:41.573444 2018] [wsgi:error] [pid 14272] [remote 85.26.235.40:34774]     return func(*args, **kwargs)
[Mon Mar 12 15:57:41.573453 2018] [wsgi:error] [pid 14272] [remote 85.26.235.40:34774]   File "/usr/lib/python3.6/site-packages/pony/orm/core.py", line 5483, in delete
[Mon Mar 12 15:57:41.573462 2018] [wsgi:error] [pid 14272] [remote 85.26.235.40:34774]     objects = query._fetch()
[Mon Mar 12 15:57:41.573471 2018] [wsgi:error] [pid 14272] [remote 85.26.235.40:34774]   File "/usr/lib/python3.6/site-packages/pony/orm/core.py", line 5336, in _fetch
[Mon Mar 12 15:57:41.573480 2018] [wsgi:error] [pid 14272] [remote 85.26.235.40:34774]     sql, arguments, attr_offsets, query_key = query._construct_sql_and_arguments(range)
[Mon Mar 12 15:57:41.573490 2018] [wsgi:error] [pid 14272] [remote 85.26.235.40:34774]   File "/usr/lib/python3.6/site-packages/pony/orm/core.py", line 5316, in _construct_sql_and_arguments
[Mon Mar 12 15:57:41.573583 2018] [wsgi:error] [pid 14272] [remote 85.26.235.40:34774]     cache = database._get_cache()
[Mon Mar 12 15:57:41.573594 2018] [wsgi:error] [pid 14272] [remote 85.26.235.40:34774]   File "/usr/lib/python3.6/site-packages/pony/orm/core.py", line 726, in _get_cache
[Mon Mar 12 15:57:41.573604 2018] [wsgi:error] [pid 14272] [remote 85.26.235.40:34774]     ): throw(TransactionError, 'db_session is required when working with the database')
[Mon Mar 12 15:57:41.573614 2018] [wsgi:error] [pid 14272] [remote 85.26.235.40:34774]   File "/usr/lib/python3.6/site-packages/pony/utils/utils.py", line 98, in throw
[Mon Mar 12 15:57:41.573623 2018] [wsgi:error] [pid 14272] [remote 85.26.235.40:34774]     raise exc
[Mon Mar 12 15:57:41.573639 2018] [wsgi:error] [pid 14272] [remote 85.26.235.40:34774] pony.orm.core.TransactionError: db_session is required when working with the database
[Mon Mar 12 15:57:41.573722 2018] [wsgi:error] [pid 14272] [remote 85.26.235.40:34774] 
[Mon Mar 12 15:59:01.907586 2018] [wsgi:error] [pid 14272] [remote 85.26.235.40:50323] [2018-03-12 15:59:01,905] ERROR in app: Exception on /work/wait_confirm [GET]
[Mon Mar 12 15:59:01.907710 2018] [wsgi:error] [pid 14272] [remote 85.26.235.40:50323] Traceback (most recent call last):
[Mon Mar 12 15:59:01.907723 2018] [wsgi:error] [pid 14272] [remote 85.26.235.40:50323]   File "/usr/lib/python3.6/site-packages/flask/app.py", line 1982, in wsgi_app
[Mon Mar 12 15:59:01.907734 2018] [wsgi:error] [pid 14272] [remote 85.26.235.40:50323]     response = self.full_dispatch_request()
[Mon Mar 12 15:59:01.907743 2018] [wsgi:error] [pid 14272] [remote 85.26.235.40:50323]   File "/usr/lib/python3.6/site-packages/flask/app.py", line 1614, in full_dispatch_request
[Mon Mar 12 15:59:01.907752 2018] [wsgi:error] [pid 14272] [remote 85.26.235.40:50323]     rv = self.handle_user_exception(e)
[Mon Mar 12 15:59:01.907762 2018] [wsgi:error] [pid 14272] [remote 85.26.235.40:50323]   File "/usr/lib/python3.6/site-packages/flask/app.py", line 1517, in handle_user_exception
[Mon Mar 12 15:59:01.907771 2018] [wsgi:error] [pid 14272] [remote 85.26.235.40:50323]     reraise(exc_type, exc_value, tb)
[Mon Mar 12 15:59:01.907779 2018] [wsgi:error] [pid 14272] [remote 85.26.235.40:50323]   File "/usr/lib/python3.6/site-packages/flask/_compat.py", line 33, in reraise
[Mon Mar 12 15:59:01.907789 2018] [wsgi:error] [pid 14272] [remote 85.26.235.40:50323]     raise value
[Mon Mar 12 15:59:01.907797 2018] [wsgi:error] [pid 14272] [remote 85.26.235.40:50323]   File "/usr/lib/python3.6/site-packages/flask/app.py", line 1612, in full_dispatch_request
[Mon Mar 12 15:59:01.907806 2018] [wsgi:error] [pid 14272] [remote 85.26.235.40:50323]     rv = self.dispatch_request()
[Mon Mar 12 15:59:01.907815 2018] [wsgi:error] [pid 14272] [remote 85.26.235.40:50323]   File "/usr/lib/python3.6/site-packages/flask/app.py", line 1598, in dispatch_request
[Mon Mar 12 15:59:01.907825 2018] [wsgi:error] [pid 14272] [remote 85.26.235.40:50323]     return self.view_functions[rule.endpoint](**req.view_args)
[Mon Mar 12 15:59:01.907834 2018] [wsgi:error] [pid 14272] [remote 85.26.235.40:50323]   File "/srv/http/virtlabs.tk/5koleso.tk/worker.py", line 91, in wait_confirm
[Mon Mar 12 15:59:01.907843 2018] [wsgi:error] [pid 14272] [remote 85.26.235.40:50323]     with db_session:
[Mon Mar 12 15:59:01.907851 2018] [wsgi:error] [pid 14272] [remote 85.26.235.40:50323]   File "<string>", line 2, in delete
[Mon Mar 12 15:59:01.907860 2018] [wsgi:error] [pid 14272] [remote 85.26.235.40:50323]   File "/usr/lib/python3.6/site-packages/pony/utils/utils.py", line 58, in cut_traceback
[Mon Mar 12 15:59:01.907869 2018] [wsgi:error] [pid 14272] [remote 85.26.235.40:50323]     return func(*args, **kwargs)
[Mon Mar 12 15:59:01.907878 2018] [wsgi:error] [pid 14272] [remote 85.26.235.40:50323]   File "/usr/lib/python3.6/site-packages/pony/orm/core.py", line 5483, in delete
[Mon Mar 12 15:59:01.907887 2018] [wsgi:error] [pid 14272] [remote 85.26.235.40:50323]     objects = query._fetch()
[Mon Mar 12 15:59:01.907970 2018] [wsgi:error] [pid 14272] [remote 85.26.235.40:50323]   File "/usr/lib/python3.6/site-packages/pony/orm/core.py", line 5336, in _fetch
[Mon Mar 12 15:59:01.907982 2018] [wsgi:error] [pid 14272] [remote 85.26.235.40:50323]     sql, arguments, attr_offsets, query_key = query._construct_sql_and_arguments(range)
[Mon Mar 12 15:59:01.907992 2018] [wsgi:error] [pid 14272] [remote 85.26.235.40:50323]   File "/usr/lib/python3.6/site-packages/pony/orm/core.py", line 5316, in _construct_sql_and_arguments
[Mon Mar 12 15:59:01.908001 2018] [wsgi:error] [pid 14272] [remote 85.26.235.40:50323]     cache = database._get_cache()
[Mon Mar 12 15:59:01.908010 2018] [wsgi:error] [pid 14272] [remote 85.26.235.40:50323]   File "/usr/lib/python3.6/site-packages/pony/orm/core.py", line 726, in _get_cache
[Mon Mar 12 15:59:01.908019 2018] [wsgi:error] [pid 14272] [remote 85.26.235.40:50323]     ): throw(TransactionError, 'db_session is required when working with the database')
[Mon Mar 12 15:59:01.908028 2018] [wsgi:error] [pid 14272] [remote 85.26.235.40:50323]   File "/usr/lib/python3.6/site-packages/pony/utils/utils.py", line 98, in throw
[Mon Mar 12 15:59:01.908037 2018] [wsgi:error] [pid 14272] [remote 85.26.235.40:50323]     raise exc
[Mon Mar 12 15:59:01.908051 2018] [wsgi:error] [pid 14272] [remote 85.26.235.40:50323] pony.orm.core.TransactionError: db_session is required when working with the database
[Mon Mar 12 15:59:01.908105 2018] [wsgi:error] [pid 14272] [remote 85.26.235.40:50323] 
[Mon Mar 12 15:59:43.534706 2018] [wsgi:error] [pid 14326] [remote 85.26.235.40:50656] [2018-03-12 15:59:43,525] ERROR in app: Exception on /work/wait_confirm [GET]
[Mon Mar 12 15:59:43.534860 2018] [wsgi:error] [pid 14326] [remote 85.26.235.40:50656] Traceback (most recent call last):
[Mon Mar 12 15:59:43.534872 2018] [wsgi:error] [pid 14326] [remote 85.26.235.40:50656]   File "/usr/lib/python3.6/site-packages/flask/app.py", line 1982, in wsgi_app
[Mon Mar 12 15:59:43.534883 2018] [wsgi:error] [pid 14326] [remote 85.26.235.40:50656]     response = self.full_dispatch_request()
[Mon Mar 12 15:59:43.534893 2018] [wsgi:error] [pid 14326] [remote 85.26.235.40:50656]   File "/usr/lib/python3.6/site-packages/flask/app.py", line 1614, in full_dispatch_request
[Mon Mar 12 15:59:43.534903 2018] [wsgi:error] [pid 14326] [remote 85.26.235.40:50656]     rv = self.handle_user_exception(e)
[Mon Mar 12 15:59:43.534911 2018] [wsgi:error] [pid 14326] [remote 85.26.235.40:50656]   File "/usr/lib/python3.6/site-packages/flask/app.py", line 1517, in handle_user_exception
[Mon Mar 12 15:59:43.534921 2018] [wsgi:error] [pid 14326] [remote 85.26.235.40:50656]     reraise(exc_type, exc_value, tb)
[Mon Mar 12 15:59:43.534930 2018] [wsgi:error] [pid 14326] [remote 85.26.235.40:50656]   File "/usr/lib/python3.6/site-packages/flask/_compat.py", line 33, in reraise
[Mon Mar 12 15:59:43.534939 2018] [wsgi:error] [pid 14326] [remote 85.26.235.40:50656]     raise value
[Mon Mar 12 15:59:43.534948 2018] [wsgi:error] [pid 14326] [remote 85.26.235.40:50656]   File "/usr/lib/python3.6/site-packages/flask/app.py", line 1612, in full_dispatch_request
[Mon Mar 12 15:59:43.534957 2018] [wsgi:error] [pid 14326] [remote 85.26.235.40:50656]     rv = self.dispatch_request()
[Mon Mar 12 15:59:43.534966 2018] [wsgi:error] [pid 14326] [remote 85.26.235.40:50656]   File "/usr/lib/python3.6/site-packages/flask/app.py", line 1598, in dispatch_request
[Mon Mar 12 15:59:43.534976 2018] [wsgi:error] [pid 14326] [remote 85.26.235.40:50656]     return self.view_functions[rule.endpoint](**req.view_args)
[Mon Mar 12 15:59:43.534985 2018] [wsgi:error] [pid 14326] [remote 85.26.235.40:50656]   File "/srv/http/virtlabs.tk/5koleso.tk/worker.py", line 93, in wait_confirm
[Mon Mar 12 15:59:43.534994 2018] [wsgi:error] [pid 14326] [remote 85.26.235.40:50656]     return render_template('work/wait_confirm.html', **context)
[Mon Mar 12 15:59:43.535003 2018] [wsgi:error] [pid 14326] [remote 85.26.235.40:50656]   File "/usr/lib/python3.6/site-packages/flask/templating.py", line 134, in render_template
[Mon Mar 12 15:59:43.535088 2018] [wsgi:error] [pid 14326] [remote 85.26.235.40:50656]     context, ctx.app)
[Mon Mar 12 15:59:43.535099 2018] [wsgi:error] [pid 14326] [remote 85.26.235.40:50656]   File "/usr/lib/python3.6/site-packages/flask/templating.py", line 116, in _render
[Mon Mar 12 15:59:43.535108 2018] [wsgi:error] [pid 14326] [remote 85.26.235.40:50656]     rv = template.render(context)
[Mon Mar 12 15:59:43.535117 2018] [wsgi:error] [pid 14326] [remote 85.26.235.40:50656]   File "/usr/lib/python3.6/site-packages/jinja2/asyncsupport.py", line 76, in render
[Mon Mar 12 15:59:43.535127 2018] [wsgi:error] [pid 14326] [remote 85.26.235.40:50656]     return original_render(self, *args, **kwargs)
[Mon Mar 12 15:59:43.535135 2018] [wsgi:error] [pid 14326] [remote 85.26.235.40:50656]   File "/usr/lib/python3.6/site-packages/jinja2/environment.py", line 1008, in render
[Mon Mar 12 15:59:43.535144 2018] [wsgi:error] [pid 14326] [remote 85.26.235.40:50656]     return self.environment.handle_exception(exc_info, True)
[Mon Mar 12 15:59:43.535153 2018] [wsgi:error] [pid 14326] [remote 85.26.235.40:50656]   File "/usr/lib/python3.6/site-packages/jinja2/environment.py", line 780, in handle_exception
[Mon Mar 12 15:59:43.535163 2018] [wsgi:error] [pid 14326] [remote 85.26.235.40:50656]     reraise(exc_type, exc_value, tb)
[Mon Mar 12 15:59:43.535171 2018] [wsgi:error] [pid 14326] [remote 85.26.235.40:50656]   File "/usr/lib/python3.6/site-packages/jinja2/_compat.py", line 37, in reraise
[Mon Mar 12 15:59:43.535180 2018] [wsgi:error] [pid 14326] [remote 85.26.235.40:50656]     raise value.with_traceback(tb)
[Mon Mar 12 15:59:43.535189 2018] [wsgi:error] [pid 14326] [remote 85.26.235.40:50656]   File "/srv/http/virtlabs.tk/5koleso.tk/templates/work/wait_confirm.html", line 1, in top-level template code
[Mon Mar 12 15:59:43.535199 2018] [wsgi:error] [pid 14326] [remote 85.26.235.40:50656]     {% extends "index.html" %}
[Mon Mar 12 15:59:43.535208 2018] [wsgi:error] [pid 14326] [remote 85.26.235.40:50656]   File "/srv/http/virtlabs.tk/5koleso.tk/templates/index.html", line 42, in top-level template code
[Mon Mar 12 15:59:43.535217 2018] [wsgi:error] [pid 14326] [remote 85.26.235.40:50656]     {% block body %}
[Mon Mar 12 15:59:43.535225 2018] [wsgi:error] [pid 14326] [remote 85.26.235.40:50656]   File "/srv/http/virtlabs.tk/5koleso.tk/templates/work/wait_confirm.html", line 5, in block "body"
[Mon Mar 12 15:59:43.535235 2018] [wsgi:error] [pid 14326] [remote 85.26.235.40:50656]     <a href="/work/confirm?id={{ order.id }}&phone={{ order.phone }}&address_from={{ order.address_from }}&address_to={{ order.address_to }}&comment={{ order.comment }}" style="float:left">
[Mon Mar 12 15:59:43.535246 2018] [wsgi:error] [pid 14326] [remote 85.26.235.40:50656]   File "/usr/lib/python3.6/site-packages/jinja2/environment.py", line 430, in getattr
[Mon Mar 12 15:59:43.535255 2018] [wsgi:error] [pid 14326] [remote 85.26.235.40:50656]     return getattr(obj, attribute)
[Mon Mar 12 15:59:43.535269 2018] [wsgi:error] [pid 14326] [remote 85.26.235.40:50656] jinja2.exceptions.UndefinedError: 'order' is undefined
[Mon Mar 12 15:59:43.535335 2018] [wsgi:error] [pid 14326] [remote 85.26.235.40:50656] 
[Mon Mar 12 16:09:09.134107 2018] [wsgi:error] [pid 14499] [remote 85.26.235.40:31010] [2018-03-12 16:09:09,122] ERROR in app: Exception on /wait [GET]
[Mon Mar 12 16:09:09.134282 2018] [wsgi:error] [pid 14499] [remote 85.26.235.40:31010] Traceback (most recent call last):
[Mon Mar 12 16:09:09.134298 2018] [wsgi:error] [pid 14499] [remote 85.26.235.40:31010]   File "/usr/lib/python3.6/site-packages/flask/app.py", line 1982, in wsgi_app
[Mon Mar 12 16:09:09.134309 2018] [wsgi:error] [pid 14499] [remote 85.26.235.40:31010]     response = self.full_dispatch_request()
[Mon Mar 12 16:09:09.134319 2018] [wsgi:error] [pid 14499] [remote 85.26.235.40:31010]   File "/usr/lib/python3.6/site-packages/flask/app.py", line 1614, in full_dispatch_request
[Mon Mar 12 16:09:09.134328 2018] [wsgi:error] [pid 14499] [remote 85.26.235.40:31010]     rv = self.handle_user_exception(e)
[Mon Mar 12 16:09:09.134410 2018] [wsgi:error] [pid 14499] [remote 85.26.235.40:31010]   File "/usr/lib/python3.6/site-packages/flask/app.py", line 1517, in handle_user_exception
[Mon Mar 12 16:09:09.134422 2018] [wsgi:error] [pid 14499] [remote 85.26.235.40:31010]     reraise(exc_type, exc_value, tb)
[Mon Mar 12 16:09:09.134431 2018] [wsgi:error] [pid 14499] [remote 85.26.235.40:31010]   File "/usr/lib/python3.6/site-packages/flask/_compat.py", line 33, in reraise
[Mon Mar 12 16:09:09.134440 2018] [wsgi:error] [pid 14499] [remote 85.26.235.40:31010]     raise value
[Mon Mar 12 16:09:09.134449 2018] [wsgi:error] [pid 14499] [remote 85.26.235.40:31010]   File "/usr/lib/python3.6/site-packages/flask/app.py", line 1612, in full_dispatch_request
[Mon Mar 12 16:09:09.134458 2018] [wsgi:error] [pid 14499] [remote 85.26.235.40:31010]     rv = self.dispatch_request()
[Mon Mar 12 16:09:09.134467 2018] [wsgi:error] [pid 14499] [remote 85.26.235.40:31010]   File "/usr/lib/python3.6/site-packages/flask/app.py", line 1598, in dispatch_request
[Mon Mar 12 16:09:09.134477 2018] [wsgi:error] [pid 14499] [remote 85.26.235.40:31010]     return self.view_functions[rule.endpoint](**req.view_args)
[Mon Mar 12 16:09:09.134486 2018] [wsgi:error] [pid 14499] [remote 85.26.235.40:31010]   File "/srv/http/virtlabs.tk/5koleso.tk/passenger.py", line 61, in wait
[Mon Mar 12 16:09:09.134495 2018] [wsgi:error] [pid 14499] [remote 85.26.235.40:31010]     order = Taxi_order.get(phone=request.cookies.get('user_phone'))
[Mon Mar 12 16:09:09.134504 2018] [wsgi:error] [pid 14499] [remote 85.26.235.40:31010]   File "<string>", line 2, in get
[Mon Mar 12 16:09:09.134513 2018] [wsgi:error] [pid 14499] [remote 85.26.235.40:31010]   File "/usr/lib/python3.6/site-packages/pony/utils/utils.py", line 58, in cut_traceback
[Mon Mar 12 16:09:09.134522 2018] [wsgi:error] [pid 14499] [remote 85.26.235.40:31010]     return func(*args, **kwargs)
[Mon Mar 12 16:09:09.134530 2018] [wsgi:error] [pid 14499] [remote 85.26.235.40:31010]   File "/usr/lib/python3.6/site-packages/pony/orm/core.py", line 3702, in get
[Mon Mar 12 16:09:09.134540 2018] [wsgi:error] [pid 14499] [remote 85.26.235.40:31010]     try: return entity._find_one_(kwargs)  # can throw MultipleObjectsFoundError
[Mon Mar 12 16:09:09.134549 2018] [wsgi:error] [pid 14499] [remote 85.26.235.40:31010]   File "/usr/lib/python3.6/site-packages/pony/orm/core.py", line 3792, in _find_one_
[Mon Mar 12 16:09:09.134558 2018] [wsgi:error] [pid 14499] [remote 85.26.235.40:31010]     avdict[attr] = attr.validate(val, None, entity, from_db=False)
[Mon Mar 12 16:09:09.134567 2018] [wsgi:error] [pid 14499] [remote 85.26.235.40:31010]   File "/usr/lib/python3.6/site-packages/pony/orm/core.py", line 2356, in validate
[Mon Mar 12 16:09:09.134576 2018] [wsgi:error] [pid 14499] [remote 85.26.235.40:31010]     attr if obj is None or obj._status_ is None else '%r.%s' % (obj, attr.name)))
[Mon Mar 12 16:09:09.134585 2018] [wsgi:error] [pid 14499] [remote 85.26.235.40:31010]   File "/usr/lib/python3.6/site-packages/pony/utils/utils.py", line 98, in throw
[Mon Mar 12 16:09:09.134594 2018] [wsgi:error] [pid 14499] [remote 85.26.235.40:31010]     raise exc
[Mon Mar 12 16:09:09.134611 2018] [wsgi:error] [pid 14499] [remote 85.26.235.40:31010] ValueError: Attribute Taxi_order.phone is required
[Mon Mar 12 16:09:09.134679 2018] [wsgi:error] [pid 14499] [remote 85.26.235.40:31010] 
[Mon Mar 12 16:17:34.428634 2018] [wsgi:error] [pid 14574] [remote 85.26.235.40:39598] [2018-03-12 16:17:34,424] ERROR in app: Exception on /work/lets_go [GET]
[Mon Mar 12 16:17:34.428808 2018] [wsgi:error] [pid 14574] [remote 85.26.235.40:39598] Traceback (most recent call last):
[Mon Mar 12 16:17:34.428822 2018] [wsgi:error] [pid 14574] [remote 85.26.235.40:39598]   File "/usr/lib/python3.6/site-packages/flask/app.py", line 1982, in wsgi_app
[Mon Mar 12 16:17:34.428833 2018] [wsgi:error] [pid 14574] [remote 85.26.235.40:39598]     response = self.full_dispatch_request()
[Mon Mar 12 16:17:34.428843 2018] [wsgi:error] [pid 14574] [remote 85.26.235.40:39598]   File "/usr/lib/python3.6/site-packages/flask/app.py", line 1614, in full_dispatch_request
[Mon Mar 12 16:17:34.428921 2018] [wsgi:error] [pid 14574] [remote 85.26.235.40:39598]     rv = self.handle_user_exception(e)
[Mon Mar 12 16:17:34.428933 2018] [wsgi:error] [pid 14574] [remote 85.26.235.40:39598]   File "/usr/lib/python3.6/site-packages/flask/app.py", line 1517, in handle_user_exception
[Mon Mar 12 16:17:34.428943 2018] [wsgi:error] [pid 14574] [remote 85.26.235.40:39598]     reraise(exc_type, exc_value, tb)
[Mon Mar 12 16:17:34.428952 2018] [wsgi:error] [pid 14574] [remote 85.26.235.40:39598]   File "/usr/lib/python3.6/site-packages/flask/_compat.py", line 33, in reraise
[Mon Mar 12 16:17:34.428961 2018] [wsgi:error] [pid 14574] [remote 85.26.235.40:39598]     raise value
[Mon Mar 12 16:17:34.428970 2018] [wsgi:error] [pid 14574] [remote 85.26.235.40:39598]   File "/usr/lib/python3.6/site-packages/flask/app.py", line 1612, in full_dispatch_request
[Mon Mar 12 16:17:34.428979 2018] [wsgi:error] [pid 14574] [remote 85.26.235.40:39598]     rv = self.dispatch_request()
[Mon Mar 12 16:17:34.428988 2018] [wsgi:error] [pid 14574] [remote 85.26.235.40:39598]   File "/usr/lib/python3.6/site-packages/flask/app.py", line 1598, in dispatch_request
[Mon Mar 12 16:17:34.428997 2018] [wsgi:error] [pid 14574] [remote 85.26.235.40:39598]     return self.view_functions[rule.endpoint](**req.view_args)
[Mon Mar 12 16:17:34.429006 2018] [wsgi:error] [pid 14574] [remote 85.26.235.40:39598]   File "/srv/http/virtlabs.tk/5koleso.tk/worker.py", line 103, in lets_go
[Mon Mar 12 16:17:34.429015 2018] [wsgi:error] [pid 14574] [remote 85.26.235.40:39598]     'time': request.args.get['time']
[Mon Mar 12 16:17:34.429032 2018] [wsgi:error] [pid 14574] [remote 85.26.235.40:39598] TypeError: 'method' object is not subscriptable
[Mon Mar 12 16:17:34.429096 2018] [wsgi:error] [pid 14574] [remote 85.26.235.40:39598] 
[Mon Mar 12 16:22:17.220536 2018] [wsgi:error] [pid 14649] [remote 85.26.235.40:47177] mod_wsgi (pid=14649): Target WSGI script '/srv/http/virtlabs.tk/5koleso.tk/api.wsgi' cannot be loaded as Python module.
[Mon Mar 12 16:22:17.220844 2018] [wsgi:error] [pid 14649] [remote 85.26.235.40:47177] mod_wsgi (pid=14649): Exception occurred processing WSGI script '/srv/http/virtlabs.tk/5koleso.tk/api.wsgi'.
[Mon Mar 12 16:22:17.221952 2018] [wsgi:error] [pid 14649] [remote 85.26.235.40:47177] Traceback (most recent call last):
[Mon Mar 12 16:22:17.222082 2018] [wsgi:error] [pid 14649] [remote 85.26.235.40:47177]   File "/srv/http/virtlabs.tk/5koleso.tk/api.wsgi", line 1, in <module>
[Mon Mar 12 16:22:17.222100 2018] [wsgi:error] [pid 14649] [remote 85.26.235.40:47177]     from api import app as application
[Mon Mar 12 16:22:17.222128 2018] [wsgi:error] [pid 14649] [remote 85.26.235.40:47177]   File "/srv/http/virtlabs.tk/5koleso.tk/api.py", line 28, in <module>
[Mon Mar 12 16:22:17.222142 2018] [wsgi:error] [pid 14649] [remote 85.26.235.40:47177]     from worker import *
[Mon Mar 12 16:22:17.222201 2018] [wsgi:error] [pid 14649] [remote 85.26.235.40:47177]   File "/srv/http/virtlabs.tk/5koleso.tk/worker.py", line 108
[Mon Mar 12 16:22:17.222237 2018] [wsgi:error] [pid 14649] [remote 85.26.235.40:47177]     def lets_go():
[Mon Mar 12 16:22:17.222303 2018] [wsgi:error] [pid 14649] [remote 85.26.235.40:47177]       ^
[Mon Mar 12 16:22:17.222337 2018] [wsgi:error] [pid 14649] [remote 85.26.235.40:47177] SyntaxError: invalid syntax
[Mon Mar 12 16:24:57.068715 2018] [wsgi:error] [pid 14649] [remote 85.26.235.40:58041] [2018-03-12 16:24:57,057] ERROR in app: Exception on /wait [GET]
[Mon Mar 12 16:24:57.068846 2018] [wsgi:error] [pid 14649] [remote 85.26.235.40:58041] Traceback (most recent call last):
[Mon Mar 12 16:24:57.068859 2018] [wsgi:error] [pid 14649] [remote 85.26.235.40:58041]   File "/usr/lib/python3.6/site-packages/flask/app.py", line 1982, in wsgi_app
[Mon Mar 12 16:24:57.068870 2018] [wsgi:error] [pid 14649] [remote 85.26.235.40:58041]     response = self.full_dispatch_request()
[Mon Mar 12 16:24:57.068960 2018] [wsgi:error] [pid 14649] [remote 85.26.235.40:58041]   File "/usr/lib/python3.6/site-packages/flask/app.py", line 1614, in full_dispatch_request
[Mon Mar 12 16:24:57.068971 2018] [wsgi:error] [pid 14649] [remote 85.26.235.40:58041]     rv = self.handle_user_exception(e)
[Mon Mar 12 16:24:57.068980 2018] [wsgi:error] [pid 14649] [remote 85.26.235.40:58041]   File "/usr/lib/python3.6/site-packages/flask/app.py", line 1517, in handle_user_exception
[Mon Mar 12 16:24:57.068990 2018] [wsgi:error] [pid 14649] [remote 85.26.235.40:58041]     reraise(exc_type, exc_value, tb)
[Mon Mar 12 16:24:57.068999 2018] [wsgi:error] [pid 14649] [remote 85.26.235.40:58041]   File "/usr/lib/python3.6/site-packages/flask/_compat.py", line 33, in reraise
[Mon Mar 12 16:24:57.069007 2018] [wsgi:error] [pid 14649] [remote 85.26.235.40:58041]     raise value
[Mon Mar 12 16:24:57.069016 2018] [wsgi:error] [pid 14649] [remote 85.26.235.40:58041]   File "/usr/lib/python3.6/site-packages/flask/app.py", line 1612, in full_dispatch_request
[Mon Mar 12 16:24:57.069025 2018] [wsgi:error] [pid 14649] [remote 85.26.235.40:58041]     rv = self.dispatch_request()
[Mon Mar 12 16:24:57.069033 2018] [wsgi:error] [pid 14649] [remote 85.26.235.40:58041]   File "/usr/lib/python3.6/site-packages/flask/app.py", line 1598, in dispatch_request
[Mon Mar 12 16:24:57.069042 2018] [wsgi:error] [pid 14649] [remote 85.26.235.40:58041]     return self.view_functions[rule.endpoint](**req.view_args)
[Mon Mar 12 16:24:57.069051 2018] [wsgi:error] [pid 14649] [remote 85.26.235.40:58041]   File "/srv/http/virtlabs.tk/5koleso.tk/passenger.py", line 61, in wait
[Mon Mar 12 16:24:57.069060 2018] [wsgi:error] [pid 14649] [remote 85.26.235.40:58041]     order = Taxi_order.get(phone=request.cookies.get('user_phone'))
[Mon Mar 12 16:24:57.069069 2018] [wsgi:error] [pid 14649] [remote 85.26.235.40:58041]   File "<string>", line 2, in get
[Mon Mar 12 16:24:57.069077 2018] [wsgi:error] [pid 14649] [remote 85.26.235.40:58041]   File "/usr/lib/python3.6/site-packages/pony/utils/utils.py", line 58, in cut_traceback
[Mon Mar 12 16:24:57.069086 2018] [wsgi:error] [pid 14649] [remote 85.26.235.40:58041]     return func(*args, **kwargs)
[Mon Mar 12 16:24:57.069095 2018] [wsgi:error] [pid 14649] [remote 85.26.235.40:58041]   File "/usr/lib/python3.6/site-packages/pony/orm/core.py", line 3702, in get
[Mon Mar 12 16:24:57.069104 2018] [wsgi:error] [pid 14649] [remote 85.26.235.40:58041]     try: return entity._find_one_(kwargs)  # can throw MultipleObjectsFoundError
[Mon Mar 12 16:24:57.069113 2018] [wsgi:error] [pid 14649] [remote 85.26.235.40:58041]   File "/usr/lib/python3.6/site-packages/pony/orm/core.py", line 3792, in _find_one_
[Mon Mar 12 16:24:57.069122 2018] [wsgi:error] [pid 14649] [remote 85.26.235.40:58041]     avdict[attr] = attr.validate(val, None, entity, from_db=False)
[Mon Mar 12 16:24:57.069130 2018] [wsgi:error] [pid 14649] [remote 85.26.235.40:58041]   File "/usr/lib/python3.6/site-packages/pony/orm/core.py", line 2356, in validate
[Mon Mar 12 16:24:57.069139 2018] [wsgi:error] [pid 14649] [remote 85.26.235.40:58041]     attr if obj is None or obj._status_ is None else '%r.%s' % (obj, attr.name)))
[Mon Mar 12 16:24:57.069148 2018] [wsgi:error] [pid 14649] [remote 85.26.235.40:58041]   File "/usr/lib/python3.6/site-packages/pony/utils/utils.py", line 98, in throw
[Mon Mar 12 16:24:57.069157 2018] [wsgi:error] [pid 14649] [remote 85.26.235.40:58041]     raise exc
[Mon Mar 12 16:24:57.069172 2018] [wsgi:error] [pid 14649] [remote 85.26.235.40:58041] ValueError: Attribute Taxi_order.phone is required
[Mon Mar 12 16:24:57.069226 2018] [wsgi:error] [pid 14649] [remote 85.26.235.40:58041] 
[Mon Mar 12 16:25:19.168941 2018] [wsgi:error] [pid 14649] [remote 85.26.235.40:18416] [2018-03-12 16:25:19,167] ERROR in app: Exception on /work/confirm [GET]
[Mon Mar 12 16:25:19.169064 2018] [wsgi:error] [pid 14649] [remote 85.26.235.40:18416] Traceback (most recent call last):
[Mon Mar 12 16:25:19.169077 2018] [wsgi:error] [pid 14649] [remote 85.26.235.40:18416]   File "/usr/lib/python3.6/site-packages/flask/app.py", line 1982, in wsgi_app
[Mon Mar 12 16:25:19.169176 2018] [wsgi:error] [pid 14649] [remote 85.26.235.40:18416]     response = self.full_dispatch_request()
[Mon Mar 12 16:25:19.169188 2018] [wsgi:error] [pid 14649] [remote 85.26.235.40:18416]   File "/usr/lib/python3.6/site-packages/flask/app.py", line 1614, in full_dispatch_request
[Mon Mar 12 16:25:19.169198 2018] [wsgi:error] [pid 14649] [remote 85.26.235.40:18416]     rv = self.handle_user_exception(e)
[Mon Mar 12 16:25:19.169207 2018] [wsgi:error] [pid 14649] [remote 85.26.235.40:18416]   File "/usr/lib/python3.6/site-packages/flask/app.py", line 1517, in handle_user_exception
[Mon Mar 12 16:25:19.169216 2018] [wsgi:error] [pid 14649] [remote 85.26.235.40:18416]     reraise(exc_type, exc_value, tb)
[Mon Mar 12 16:25:19.169225 2018] [wsgi:error] [pid 14649] [remote 85.26.235.40:18416]   File "/usr/lib/python3.6/site-packages/flask/_compat.py", line 33, in reraise
[Mon Mar 12 16:25:19.169234 2018] [wsgi:error] [pid 14649] [remote 85.26.235.40:18416]     raise value
[Mon Mar 12 16:25:19.169242 2018] [wsgi:error] [pid 14649] [remote 85.26.235.40:18416]   File "/usr/lib/python3.6/site-packages/flask/app.py", line 1612, in full_dispatch_request
[Mon Mar 12 16:25:19.169251 2018] [wsgi:error] [pid 14649] [remote 85.26.235.40:18416]     rv = self.dispatch_request()
[Mon Mar 12 16:25:19.169260 2018] [wsgi:error] [pid 14649] [remote 85.26.235.40:18416]   File "/usr/lib/python3.6/site-packages/flask/app.py", line 1598, in dispatch_request
[Mon Mar 12 16:25:19.169269 2018] [wsgi:error] [pid 14649] [remote 85.26.235.40:18416]     return self.view_functions[rule.endpoint](**req.view_args)
[Mon Mar 12 16:25:19.169278 2018] [wsgi:error] [pid 14649] [remote 85.26.235.40:18416]   File "/srv/http/virtlabs.tk/5koleso.tk/worker.py", line 103, in confirm
[Mon Mar 12 16:25:19.169287 2018] [wsgi:error] [pid 14649] [remote 85.26.235.40:18416]     'time': request.args.get['time']
[Mon Mar 12 16:25:19.169301 2018] [wsgi:error] [pid 14649] [remote 85.26.235.40:18416] TypeError: 'method' object is not subscriptable
[Mon Mar 12 16:25:19.169354 2018] [wsgi:error] [pid 14649] [remote 85.26.235.40:18416] 
[Mon Mar 12 16:27:03.288894 2018] [wsgi:error] [pid 14649] [remote 85.26.235.40:46552] [2018-03-12 16:27:03,287] ERROR in app: Exception on /work/confirm [GET]
[Mon Mar 12 16:27:03.289060 2018] [wsgi:error] [pid 14649] [remote 85.26.235.40:46552] Traceback (most recent call last):
[Mon Mar 12 16:27:03.289074 2018] [wsgi:error] [pid 14649] [remote 85.26.235.40:46552]   File "/usr/lib/python3.6/site-packages/flask/app.py", line 1982, in wsgi_app
[Mon Mar 12 16:27:03.289085 2018] [wsgi:error] [pid 14649] [remote 85.26.235.40:46552]     response = self.full_dispatch_request()
[Mon Mar 12 16:27:03.289094 2018] [wsgi:error] [pid 14649] [remote 85.26.235.40:46552]   File "/usr/lib/python3.6/site-packages/flask/app.py", line 1614, in full_dispatch_request
[Mon Mar 12 16:27:03.289104 2018] [wsgi:error] [pid 14649] [remote 85.26.235.40:46552]     rv = self.handle_user_exception(e)
[Mon Mar 12 16:27:03.289113 2018] [wsgi:error] [pid 14649] [remote 85.26.235.40:46552]   File "/usr/lib/python3.6/site-packages/flask/app.py", line 1517, in handle_user_exception
[Mon Mar 12 16:27:03.289122 2018] [wsgi:error] [pid 14649] [remote 85.26.235.40:46552]     reraise(exc_type, exc_value, tb)
[Mon Mar 12 16:27:03.289131 2018] [wsgi:error] [pid 14649] [remote 85.26.235.40:46552]   File "/usr/lib/python3.6/site-packages/flask/_compat.py", line 33, in reraise
[Mon Mar 12 16:27:03.289140 2018] [wsgi:error] [pid 14649] [remote 85.26.235.40:46552]     raise value
[Mon Mar 12 16:27:03.289148 2018] [wsgi:error] [pid 14649] [remote 85.26.235.40:46552]   File "/usr/lib/python3.6/site-packages/flask/app.py", line 1612, in full_dispatch_request
[Mon Mar 12 16:27:03.289157 2018] [wsgi:error] [pid 14649] [remote 85.26.235.40:46552]     rv = self.dispatch_request()
[Mon Mar 12 16:27:03.289166 2018] [wsgi:error] [pid 14649] [remote 85.26.235.40:46552]   File "/usr/lib/python3.6/site-packages/flask/app.py", line 1598, in dispatch_request
[Mon Mar 12 16:27:03.289247 2018] [wsgi:error] [pid 14649] [remote 85.26.235.40:46552]     return self.view_functions[rule.endpoint](**req.view_args)
[Mon Mar 12 16:27:03.289258 2018] [wsgi:error] [pid 14649] [remote 85.26.235.40:46552]   File "/srv/http/virtlabs.tk/5koleso.tk/worker.py", line 103, in confirm
[Mon Mar 12 16:27:03.289267 2018] [wsgi:error] [pid 14649] [remote 85.26.235.40:46552]     'time': request.args.get('time')
[Mon Mar 12 16:27:03.289283 2018] [wsgi:error] [pid 14649] [remote 85.26.235.40:46552] TypeError: 'method' object is not subscriptable
[Mon Mar 12 16:27:03.289341 2018] [wsgi:error] [pid 14649] [remote 85.26.235.40:46552] 
[Mon Mar 12 16:28:24.778067 2018] [wsgi:error] [pid 14704] [remote 85.26.235.40:55675] [2018-03-12 16:28:24,762] ERROR in app: Exception on /work/confirm [GET]
[Mon Mar 12 16:28:24.778234 2018] [wsgi:error] [pid 14704] [remote 85.26.235.40:55675] Traceback (most recent call last):
[Mon Mar 12 16:28:24.778247 2018] [wsgi:error] [pid 14704] [remote 85.26.235.40:55675]   File "/usr/lib/python3.6/site-packages/flask/app.py", line 1982, in wsgi_app
[Mon Mar 12 16:28:24.778259 2018] [wsgi:error] [pid 14704] [remote 85.26.235.40:55675]     response = self.full_dispatch_request()
[Mon Mar 12 16:28:24.778268 2018] [wsgi:error] [pid 14704] [remote 85.26.235.40:55675]   File "/usr/lib/python3.6/site-packages/flask/app.py", line 1614, in full_dispatch_request
[Mon Mar 12 16:28:24.778277 2018] [wsgi:error] [pid 14704] [remote 85.26.235.40:55675]     rv = self.handle_user_exception(e)
[Mon Mar 12 16:28:24.778286 2018] [wsgi:error] [pid 14704] [remote 85.26.235.40:55675]   File "/usr/lib/python3.6/site-packages/flask/app.py", line 1517, in handle_user_exception
[Mon Mar 12 16:28:24.778295 2018] [wsgi:error] [pid 14704] [remote 85.26.235.40:55675]     reraise(exc_type, exc_value, tb)
[Mon Mar 12 16:28:24.778304 2018] [wsgi:error] [pid 14704] [remote 85.26.235.40:55675]   File "/usr/lib/python3.6/site-packages/flask/_compat.py", line 33, in reraise
[Mon Mar 12 16:28:24.778313 2018] [wsgi:error] [pid 14704] [remote 85.26.235.40:55675]     raise value
[Mon Mar 12 16:28:24.778321 2018] [wsgi:error] [pid 14704] [remote 85.26.235.40:55675]   File "/usr/lib/python3.6/site-packages/flask/app.py", line 1612, in full_dispatch_request
[Mon Mar 12 16:28:24.778331 2018] [wsgi:error] [pid 14704] [remote 85.26.235.40:55675]     rv = self.dispatch_request()
[Mon Mar 12 16:28:24.778339 2018] [wsgi:error] [pid 14704] [remote 85.26.235.40:55675]   File "/usr/lib/python3.6/site-packages/flask/app.py", line 1598, in dispatch_request
[Mon Mar 12 16:28:24.778349 2018] [wsgi:error] [pid 14704] [remote 85.26.235.40:55675]     return self.view_functions[rule.endpoint](**req.view_args)
[Mon Mar 12 16:28:24.778357 2018] [wsgi:error] [pid 14704] [remote 85.26.235.40:55675]   File "/srv/http/virtlabs.tk/5koleso.tk/worker.py", line 105, in confirm
[Mon Mar 12 16:28:24.778367 2018] [wsgi:error] [pid 14704] [remote 85.26.235.40:55675]     return render_template('work/confirm', **context)
[Mon Mar 12 16:28:24.778376 2018] [wsgi:error] [pid 14704] [remote 85.26.235.40:55675]   File "/usr/lib/python3.6/site-packages/flask/templating.py", line 133, in render_template
[Mon Mar 12 16:28:24.778385 2018] [wsgi:error] [pid 14704] [remote 85.26.235.40:55675]     return _render(ctx.app.jinja_env.get_or_select_template(template_name_or_list),
[Mon Mar 12 16:28:24.778395 2018] [wsgi:error] [pid 14704] [remote 85.26.235.40:55675]   File "/usr/lib/python3.6/site-packages/jinja2/environment.py", line 869, in get_or_select_template
[Mon Mar 12 16:28:24.778404 2018] [wsgi:error] [pid 14704] [remote 85.26.235.40:55675]     return self.get_template(template_name_or_list, parent, globals)
[Mon Mar 12 16:28:24.778413 2018] [wsgi:error] [pid 14704] [remote 85.26.235.40:55675]   File "/usr/lib/python3.6/site-packages/jinja2/environment.py", line 830, in get_template
[Mon Mar 12 16:28:24.778423 2018] [wsgi:error] [pid 14704] [remote 85.26.235.40:55675]     return self._load_template(name, self.make_globals(globals))
[Mon Mar 12 16:28:24.778514 2018] [wsgi:error] [pid 14704] [remote 85.26.235.40:55675]   File "/usr/lib/python3.6/site-packages/jinja2/environment.py", line 804, in _load_template
[Mon Mar 12 16:28:24.778526 2018] [wsgi:error] [pid 14704] [remote 85.26.235.40:55675]     template = self.loader.load(self, name, globals)
[Mon Mar 12 16:28:24.778535 2018] [wsgi:error] [pid 14704] [remote 85.26.235.40:55675]   File "/usr/lib/python3.6/site-packages/jinja2/loaders.py", line 113, in load
[Mon Mar 12 16:28:24.778544 2018] [wsgi:error] [pid 14704] [remote 85.26.235.40:55675]     source, filename, uptodate = self.get_source(environment, name)
[Mon Mar 12 16:28:24.778553 2018] [wsgi:error] [pid 14704] [remote 85.26.235.40:55675]   File "/usr/lib/python3.6/site-packages/flask/templating.py", line 57, in get_source
[Mon Mar 12 16:28:24.778562 2018] [wsgi:error] [pid 14704] [remote 85.26.235.40:55675]     return self._get_source_fast(environment, template)
[Mon Mar 12 16:28:24.778571 2018] [wsgi:error] [pid 14704] [remote 85.26.235.40:55675]   File "/usr/lib/python3.6/site-packages/flask/templating.py", line 85, in _get_source_fast
[Mon Mar 12 16:28:24.778580 2018] [wsgi:error] [pid 14704] [remote 85.26.235.40:55675]     raise TemplateNotFound(template)
[Mon Mar 12 16:28:24.778596 2018] [wsgi:error] [pid 14704] [remote 85.26.235.40:55675] jinja2.exceptions.TemplateNotFound: work/confirm
[Mon Mar 12 16:28:24.778661 2018] [wsgi:error] [pid 14704] [remote 85.26.235.40:55675] 
[Mon Mar 12 16:29:10.022007 2018] [wsgi:error] [pid 14704] [remote 85.26.235.40:39209] [2018-03-12 16:29:10,019] ERROR in app: Exception on /work/confirm [GET]
[Mon Mar 12 16:29:10.022145 2018] [wsgi:error] [pid 14704] [remote 85.26.235.40:39209] Traceback (most recent call last):
[Mon Mar 12 16:29:10.022158 2018] [wsgi:error] [pid 14704] [remote 85.26.235.40:39209]   File "/usr/lib/python3.6/site-packages/flask/app.py", line 1982, in wsgi_app
[Mon Mar 12 16:29:10.022169 2018] [wsgi:error] [pid 14704] [remote 85.26.235.40:39209]     response = self.full_dispatch_request()
[Mon Mar 12 16:29:10.022179 2018] [wsgi:error] [pid 14704] [remote 85.26.235.40:39209]   File "/usr/lib/python3.6/site-packages/flask/app.py", line 1614, in full_dispatch_request
[Mon Mar 12 16:29:10.022189 2018] [wsgi:error] [pid 14704] [remote 85.26.235.40:39209]     rv = self.handle_user_exception(e)
[Mon Mar 12 16:29:10.022198 2018] [wsgi:error] [pid 14704] [remote 85.26.235.40:39209]   File "/usr/lib/python3.6/site-packages/flask/app.py", line 1517, in handle_user_exception
[Mon Mar 12 16:29:10.022207 2018] [wsgi:error] [pid 14704] [remote 85.26.235.40:39209]     reraise(exc_type, exc_value, tb)
[Mon Mar 12 16:29:10.022216 2018] [wsgi:error] [pid 14704] [remote 85.26.235.40:39209]   File "/usr/lib/python3.6/site-packages/flask/_compat.py", line 33, in reraise
[Mon Mar 12 16:29:10.022225 2018] [wsgi:error] [pid 14704] [remote 85.26.235.40:39209]     raise value
[Mon Mar 12 16:29:10.022234 2018] [wsgi:error] [pid 14704] [remote 85.26.235.40:39209]   File "/usr/lib/python3.6/site-packages/flask/app.py", line 1612, in full_dispatch_request
[Mon Mar 12 16:29:10.022243 2018] [wsgi:error] [pid 14704] [remote 85.26.235.40:39209]     rv = self.dispatch_request()
[Mon Mar 12 16:29:10.022252 2018] [wsgi:error] [pid 14704] [remote 85.26.235.40:39209]   File "/usr/lib/python3.6/site-packages/flask/app.py", line 1598, in dispatch_request
[Mon Mar 12 16:29:10.022261 2018] [wsgi:error] [pid 14704] [remote 85.26.235.40:39209]     return self.view_functions[rule.endpoint](**req.view_args)
[Mon Mar 12 16:29:10.022270 2018] [wsgi:error] [pid 14704] [remote 85.26.235.40:39209]   File "/srv/http/virtlabs.tk/5koleso.tk/worker.py", line 105, in confirm
[Mon Mar 12 16:29:10.022280 2018] [wsgi:error] [pid 14704] [remote 85.26.235.40:39209]     return render_template('work/confirm.html', **context)
[Mon Mar 12 16:29:10.022289 2018] [wsgi:error] [pid 14704] [remote 85.26.235.40:39209]   File "/usr/lib/python3.6/site-packages/flask/templating.py", line 133, in render_template
[Mon Mar 12 16:29:10.022298 2018] [wsgi:error] [pid 14704] [remote 85.26.235.40:39209]     return _render(ctx.app.jinja_env.get_or_select_template(template_name_or_list),
[Mon Mar 12 16:29:10.022384 2018] [wsgi:error] [pid 14704] [remote 85.26.235.40:39209]   File "/usr/lib/python3.6/site-packages/jinja2/environment.py", line 869, in get_or_select_template
[Mon Mar 12 16:29:10.022396 2018] [wsgi:error] [pid 14704] [remote 85.26.235.40:39209]     return self.get_template(template_name_or_list, parent, globals)
[Mon Mar 12 16:29:10.022406 2018] [wsgi:error] [pid 14704] [remote 85.26.235.40:39209]   File "/usr/lib/python3.6/site-packages/jinja2/environment.py", line 830, in get_template
[Mon Mar 12 16:29:10.022415 2018] [wsgi:error] [pid 14704] [remote 85.26.235.40:39209]     return self._load_template(name, self.make_globals(globals))
[Mon Mar 12 16:29:10.022424 2018] [wsgi:error] [pid 14704] [remote 85.26.235.40:39209]   File "/usr/lib/python3.6/site-packages/jinja2/environment.py", line 804, in _load_template
[Mon Mar 12 16:29:10.022433 2018] [wsgi:error] [pid 14704] [remote 85.26.235.40:39209]     template = self.loader.load(self, name, globals)
[Mon Mar 12 16:29:10.022442 2018] [wsgi:error] [pid 14704] [remote 85.26.235.40:39209]   File "/usr/lib/python3.6/site-packages/jinja2/loaders.py", line 113, in load
[Mon Mar 12 16:29:10.022451 2018] [wsgi:error] [pid 14704] [remote 85.26.235.40:39209]     source, filename, uptodate = self.get_source(environment, name)
[Mon Mar 12 16:29:10.022460 2018] [wsgi:error] [pid 14704] [remote 85.26.235.40:39209]   File "/usr/lib/python3.6/site-packages/flask/templating.py", line 57, in get_source
[Mon Mar 12 16:29:10.022469 2018] [wsgi:error] [pid 14704] [remote 85.26.235.40:39209]     return self._get_source_fast(environment, template)
[Mon Mar 12 16:29:10.022478 2018] [wsgi:error] [pid 14704] [remote 85.26.235.40:39209]   File "/usr/lib/python3.6/site-packages/flask/templating.py", line 85, in _get_source_fast
[Mon Mar 12 16:29:10.022487 2018] [wsgi:error] [pid 14704] [remote 85.26.235.40:39209]     raise TemplateNotFound(template)
[Mon Mar 12 16:29:10.022502 2018] [wsgi:error] [pid 14704] [remote 85.26.235.40:39209] jinja2.exceptions.TemplateNotFound: work/confirm
[Mon Mar 12 16:29:10.022557 2018] [wsgi:error] [pid 14704] [remote 85.26.235.40:39209] 
[Mon Mar 12 16:29:55.671606 2018] [wsgi:error] [pid 14704] [remote 85.26.235.40:47701] [2018-03-12 16:29:55,669] ERROR in app: Exception on /work/confirm [GET]
[Mon Mar 12 16:29:55.671780 2018] [wsgi:error] [pid 14704] [remote 85.26.235.40:47701] Traceback (most recent call last):
[Mon Mar 12 16:29:55.671794 2018] [wsgi:error] [pid 14704] [remote 85.26.235.40:47701]   File "/usr/lib/python3.6/site-packages/flask/app.py", line 1982, in wsgi_app
[Mon Mar 12 16:29:55.671806 2018] [wsgi:error] [pid 14704] [remote 85.26.235.40:47701]     response = self.full_dispatch_request()
[Mon Mar 12 16:29:55.671816 2018] [wsgi:error] [pid 14704] [remote 85.26.235.40:47701]   File "/usr/lib/python3.6/site-packages/flask/app.py", line 1614, in full_dispatch_request
[Mon Mar 12 16:29:55.671825 2018] [wsgi:error] [pid 14704] [remote 85.26.235.40:47701]     rv = self.handle_user_exception(e)
[Mon Mar 12 16:29:55.671834 2018] [wsgi:error] [pid 14704] [remote 85.26.235.40:47701]   File "/usr/lib/python3.6/site-packages/flask/app.py", line 1517, in handle_user_exception
[Mon Mar 12 16:29:55.671843 2018] [wsgi:error] [pid 14704] [remote 85.26.235.40:47701]     reraise(exc_type, exc_value, tb)
[Mon Mar 12 16:29:55.671852 2018] [wsgi:error] [pid 14704] [remote 85.26.235.40:47701]   File "/usr/lib/python3.6/site-packages/flask/_compat.py", line 33, in reraise
[Mon Mar 12 16:29:55.671861 2018] [wsgi:error] [pid 14704] [remote 85.26.235.40:47701]     raise value
[Mon Mar 12 16:29:55.671869 2018] [wsgi:error] [pid 14704] [remote 85.26.235.40:47701]   File "/usr/lib/python3.6/site-packages/flask/app.py", line 1612, in full_dispatch_request
[Mon Mar 12 16:29:55.671879 2018] [wsgi:error] [pid 14704] [remote 85.26.235.40:47701]     rv = self.dispatch_request()
[Mon Mar 12 16:29:55.671887 2018] [wsgi:error] [pid 14704] [remote 85.26.235.40:47701]   File "/usr/lib/python3.6/site-packages/flask/app.py", line 1598, in dispatch_request
[Mon Mar 12 16:29:55.671999 2018] [wsgi:error] [pid 14704] [remote 85.26.235.40:47701]     return self.view_functions[rule.endpoint](**req.view_args)
[Mon Mar 12 16:29:55.672011 2018] [wsgi:error] [pid 14704] [remote 85.26.235.40:47701]   File "/srv/http/virtlabs.tk/5koleso.tk/worker.py", line 105, in confirm
[Mon Mar 12 16:29:55.672021 2018] [wsgi:error] [pid 14704] [remote 85.26.235.40:47701]     return render_template('work/confirm.html', **context)
[Mon Mar 12 16:29:55.672030 2018] [wsgi:error] [pid 14704] [remote 85.26.235.40:47701]   File "/usr/lib/python3.6/site-packages/flask/templating.py", line 133, in render_template
[Mon Mar 12 16:29:55.672039 2018] [wsgi:error] [pid 14704] [remote 85.26.235.40:47701]     return _render(ctx.app.jinja_env.get_or_select_template(template_name_or_list),
[Mon Mar 12 16:29:55.672048 2018] [wsgi:error] [pid 14704] [remote 85.26.235.40:47701]   File "/usr/lib/python3.6/site-packages/jinja2/environment.py", line 869, in get_or_select_template
[Mon Mar 12 16:29:55.672057 2018] [wsgi:error] [pid 14704] [remote 85.26.235.40:47701]     return self.get_template(template_name_or_list, parent, globals)
[Mon Mar 12 16:29:55.672066 2018] [wsgi:error] [pid 14704] [remote 85.26.235.40:47701]   File "/usr/lib/python3.6/site-packages/jinja2/environment.py", line 830, in get_template
[Mon Mar 12 16:29:55.672075 2018] [wsgi:error] [pid 14704] [remote 85.26.235.40:47701]     return self._load_template(name, self.make_globals(globals))
[Mon Mar 12 16:29:55.672084 2018] [wsgi:error] [pid 14704] [remote 85.26.235.40:47701]   File "/usr/lib/python3.6/site-packages/jinja2/environment.py", line 804, in _load_template
[Mon Mar 12 16:29:55.672093 2018] [wsgi:error] [pid 14704] [remote 85.26.235.40:47701]     template = self.loader.load(self, name, globals)
[Mon Mar 12 16:29:55.672101 2018] [wsgi:error] [pid 14704] [remote 85.26.235.40:47701]   File "/usr/lib/python3.6/site-packages/jinja2/loaders.py", line 113, in load
[Mon Mar 12 16:29:55.672110 2018] [wsgi:error] [pid 14704] [remote 85.26.235.40:47701]     source, filename, uptodate = self.get_source(environment, name)
[Mon Mar 12 16:29:55.672119 2018] [wsgi:error] [pid 14704] [remote 85.26.235.40:47701]   File "/usr/lib/python3.6/site-packages/flask/templating.py", line 57, in get_source
[Mon Mar 12 16:29:55.672128 2018] [wsgi:error] [pid 14704] [remote 85.26.235.40:47701]     return self._get_source_fast(environment, template)
[Mon Mar 12 16:29:55.672136 2018] [wsgi:error] [pid 14704] [remote 85.26.235.40:47701]   File "/usr/lib/python3.6/site-packages/flask/templating.py", line 85, in _get_source_fast
[Mon Mar 12 16:29:55.672145 2018] [wsgi:error] [pid 14704] [remote 85.26.235.40:47701]     raise TemplateNotFound(template)
[Mon Mar 12 16:29:55.672160 2018] [wsgi:error] [pid 14704] [remote 85.26.235.40:47701] jinja2.exceptions.TemplateNotFound: work/confirm
[Mon Mar 12 16:29:55.672221 2018] [wsgi:error] [pid 14704] [remote 85.26.235.40:47701] 
[Mon Mar 12 16:30:51.131803 2018] [wsgi:error] [pid 14750] [remote 85.26.235.40:33094] [2018-03-12 16:30:51,123] ERROR in app: Exception on /work/lets_go [GET]
[Mon Mar 12 16:30:51.131943 2018] [wsgi:error] [pid 14750] [remote 85.26.235.40:33094] Traceback (most recent call last):
[Mon Mar 12 16:30:51.131955 2018] [wsgi:error] [pid 14750] [remote 85.26.235.40:33094]   File "/usr/lib/python3.6/site-packages/flask/app.py", line 1982, in wsgi_app
[Mon Mar 12 16:30:51.131966 2018] [wsgi:error] [pid 14750] [remote 85.26.235.40:33094]     response = self.full_dispatch_request()
[Mon Mar 12 16:30:51.131975 2018] [wsgi:error] [pid 14750] [remote 85.26.235.40:33094]   File "/usr/lib/python3.6/site-packages/flask/app.py", line 1614, in full_dispatch_request
[Mon Mar 12 16:30:51.131985 2018] [wsgi:error] [pid 14750] [remote 85.26.235.40:33094]     rv = self.handle_user_exception(e)
[Mon Mar 12 16:30:51.131994 2018] [wsgi:error] [pid 14750] [remote 85.26.235.40:33094]   File "/usr/lib/python3.6/site-packages/flask/app.py", line 1517, in handle_user_exception
[Mon Mar 12 16:30:51.132085 2018] [wsgi:error] [pid 14750] [remote 85.26.235.40:33094]     reraise(exc_type, exc_value, tb)
[Mon Mar 12 16:30:51.132096 2018] [wsgi:error] [pid 14750] [remote 85.26.235.40:33094]   File "/usr/lib/python3.6/site-packages/flask/_compat.py", line 33, in reraise
[Mon Mar 12 16:30:51.132106 2018] [wsgi:error] [pid 14750] [remote 85.26.235.40:33094]     raise value
[Mon Mar 12 16:30:51.132115 2018] [wsgi:error] [pid 14750] [remote 85.26.235.40:33094]   File "/usr/lib/python3.6/site-packages/flask/app.py", line 1612, in full_dispatch_request
[Mon Mar 12 16:30:51.132124 2018] [wsgi:error] [pid 14750] [remote 85.26.235.40:33094]     rv = self.dispatch_request()
[Mon Mar 12 16:30:51.132133 2018] [wsgi:error] [pid 14750] [remote 85.26.235.40:33094]   File "/usr/lib/python3.6/site-packages/flask/app.py", line 1598, in dispatch_request
[Mon Mar 12 16:30:51.132142 2018] [wsgi:error] [pid 14750] [remote 85.26.235.40:33094]     return self.view_functions[rule.endpoint](**req.view_args)
[Mon Mar 12 16:30:51.132151 2018] [wsgi:error] [pid 14750] [remote 85.26.235.40:33094]   File "/srv/http/virtlabs.tk/5koleso.tk/worker.py", line 117, in lets_go
[Mon Mar 12 16:30:51.132161 2018] [wsgi:error] [pid 14750] [remote 85.26.235.40:33094]     return render_template('/work/lets_go.html', **context)
[Mon Mar 12 16:30:51.132169 2018] [wsgi:error] [pid 14750] [remote 85.26.235.40:33094]   File "/usr/lib/python3.6/site-packages/flask/templating.py", line 134, in render_template
[Mon Mar 12 16:30:51.132179 2018] [wsgi:error] [pid 14750] [remote 85.26.235.40:33094]     context, ctx.app)
[Mon Mar 12 16:30:51.132187 2018] [wsgi:error] [pid 14750] [remote 85.26.235.40:33094]   File "/usr/lib/python3.6/site-packages/flask/templating.py", line 116, in _render
[Mon Mar 12 16:30:51.132196 2018] [wsgi:error] [pid 14750] [remote 85.26.235.40:33094]     rv = template.render(context)
[Mon Mar 12 16:30:51.132205 2018] [wsgi:error] [pid 14750] [remote 85.26.235.40:33094]   File "/usr/lib/python3.6/site-packages/jinja2/asyncsupport.py", line 76, in render
[Mon Mar 12 16:30:51.132214 2018] [wsgi:error] [pid 14750] [remote 85.26.235.40:33094]     return original_render(self, *args, **kwargs)
[Mon Mar 12 16:30:51.132223 2018] [wsgi:error] [pid 14750] [remote 85.26.235.40:33094]   File "/usr/lib/python3.6/site-packages/jinja2/environment.py", line 1008, in render
[Mon Mar 12 16:30:51.132232 2018] [wsgi:error] [pid 14750] [remote 85.26.235.40:33094]     return self.environment.handle_exception(exc_info, True)
[Mon Mar 12 16:30:51.132241 2018] [wsgi:error] [pid 14750] [remote 85.26.235.40:33094]   File "/usr/lib/python3.6/site-packages/jinja2/environment.py", line 780, in handle_exception
[Mon Mar 12 16:30:51.132251 2018] [wsgi:error] [pid 14750] [remote 85.26.235.40:33094]     reraise(exc_type, exc_value, tb)
[Mon Mar 12 16:30:51.132259 2018] [wsgi:error] [pid 14750] [remote 85.26.235.40:33094]   File "/usr/lib/python3.6/site-packages/jinja2/_compat.py", line 37, in reraise
[Mon Mar 12 16:30:51.132268 2018] [wsgi:error] [pid 14750] [remote 85.26.235.40:33094]     raise value.with_traceback(tb)
[Mon Mar 12 16:30:51.132277 2018] [wsgi:error] [pid 14750] [remote 85.26.235.40:33094]   File "/srv/http/virtlabs.tk/5koleso.tk/templates/work/lets_go.html", line 1, in top-level template code
[Mon Mar 12 16:30:51.132287 2018] [wsgi:error] [pid 14750] [remote 85.26.235.40:33094]     {% extends "index.html" %}
[Mon Mar 12 16:30:51.132295 2018] [wsgi:error] [pid 14750] [remote 85.26.235.40:33094]   File "/srv/http/virtlabs.tk/5koleso.tk/templates/index.html", line 42, in top-level template code
[Mon Mar 12 16:30:51.132304 2018] [wsgi:error] [pid 14750] [remote 85.26.235.40:33094]     {% block body %}
[Mon Mar 12 16:30:51.132313 2018] [wsgi:error] [pid 14750] [remote 85.26.235.40:33094]   File "/srv/http/virtlabs.tk/5koleso.tk/templates/work/lets_go.html", line 6, in block "body"
[Mon Mar 12 16:30:51.132322 2018] [wsgi:error] [pid 14750] [remote 85.26.235.40:33094]     <a href="/work/end_order?id={{ order.id }}">
[Mon Mar 12 16:30:51.132352 2018] [wsgi:error] [pid 14750] [remote 85.26.235.40:33094]   File "/usr/lib/python3.6/site-packages/jinja2/environment.py", line 430, in getattr
[Mon Mar 12 16:30:51.132363 2018] [wsgi:error] [pid 14750] [remote 85.26.235.40:33094]     return getattr(obj, attribute)
[Mon Mar 12 16:30:51.132378 2018] [wsgi:error] [pid 14750] [remote 85.26.235.40:33094] jinja2.exceptions.UndefinedError: 'order' is undefined
[Mon Mar 12 16:30:51.132443 2018] [wsgi:error] [pid 14750] [remote 85.26.235.40:33094] 
[Mon Mar 12 17:41:12.037096 2018] [wsgi:error] [pid 15125] [remote 94.181.164.38:49743] [2018-03-12 17:41:12,025] ERROR in app: Exception on /work/end_order [GET]
[Mon Mar 12 17:41:12.037255 2018] [wsgi:error] [pid 15125] [remote 94.181.164.38:49743] Traceback (most recent call last):
[Mon Mar 12 17:41:12.037269 2018] [wsgi:error] [pid 15125] [remote 94.181.164.38:49743]   File "/usr/lib/python3.6/site-packages/flask/app.py", line 1982, in wsgi_app
[Mon Mar 12 17:41:12.037280 2018] [wsgi:error] [pid 15125] [remote 94.181.164.38:49743]     response = self.full_dispatch_request()
[Mon Mar 12 17:41:12.037290 2018] [wsgi:error] [pid 15125] [remote 94.181.164.38:49743]   File "/usr/lib/python3.6/site-packages/flask/app.py", line 1614, in full_dispatch_request
[Mon Mar 12 17:41:12.037300 2018] [wsgi:error] [pid 15125] [remote 94.181.164.38:49743]     rv = self.handle_user_exception(e)
[Mon Mar 12 17:41:12.037308 2018] [wsgi:error] [pid 15125] [remote 94.181.164.38:49743]   File "/usr/lib/python3.6/site-packages/flask/app.py", line 1517, in handle_user_exception
[Mon Mar 12 17:41:12.037318 2018] [wsgi:error] [pid 15125] [remote 94.181.164.38:49743]     reraise(exc_type, exc_value, tb)
[Mon Mar 12 17:41:12.037327 2018] [wsgi:error] [pid 15125] [remote 94.181.164.38:49743]   File "/usr/lib/python3.6/site-packages/flask/_compat.py", line 33, in reraise
[Mon Mar 12 17:41:12.037336 2018] [wsgi:error] [pid 15125] [remote 94.181.164.38:49743]     raise value
[Mon Mar 12 17:41:12.037345 2018] [wsgi:error] [pid 15125] [remote 94.181.164.38:49743]   File "/usr/lib/python3.6/site-packages/flask/app.py", line 1612, in full_dispatch_request
[Mon Mar 12 17:41:12.037354 2018] [wsgi:error] [pid 15125] [remote 94.181.164.38:49743]     rv = self.dispatch_request()
[Mon Mar 12 17:41:12.037363 2018] [wsgi:error] [pid 15125] [remote 94.181.164.38:49743]   File "/usr/lib/python3.6/site-packages/flask/app.py", line 1598, in dispatch_request
[Mon Mar 12 17:41:12.037372 2018] [wsgi:error] [pid 15125] [remote 94.181.164.38:49743]     return self.view_functions[rule.endpoint](**req.view_args)
[Mon Mar 12 17:41:12.037381 2018] [wsgi:error] [pid 15125] [remote 94.181.164.38:49743]   File "/srv/http/virtlabs.tk/5koleso.tk/worker.py", line 125, in end_order
[Mon Mar 12 17:41:12.037390 2018] [wsgi:error] [pid 15125] [remote 94.181.164.38:49743]     select(p for p in Taxi_order if p.id == request.args.get('id')).delete()
[Mon Mar 12 17:41:12.037399 2018] [wsgi:error] [pid 15125] [remote 94.181.164.38:49743]   File "<string>", line 2, in delete
[Mon Mar 12 17:41:12.037408 2018] [wsgi:error] [pid 15125] [remote 94.181.164.38:49743]   File "/usr/lib/python3.6/site-packages/pony/utils/utils.py", line 58, in cut_traceback
[Mon Mar 12 17:41:12.037417 2018] [wsgi:error] [pid 15125] [remote 94.181.164.38:49743]     return func(*args, **kwargs)
[Mon Mar 12 17:41:12.037426 2018] [wsgi:error] [pid 15125] [remote 94.181.164.38:49743]   File "/usr/lib/python3.6/site-packages/pony/orm/core.py", line 5483, in delete
[Mon Mar 12 17:41:12.037435 2018] [wsgi:error] [pid 15125] [remote 94.181.164.38:49743]     objects = query._fetch()
[Mon Mar 12 17:41:12.037444 2018] [wsgi:error] [pid 15125] [remote 94.181.164.38:49743]   File "/usr/lib/python3.6/site-packages/pony/orm/core.py", line 5336, in _fetch
[Mon Mar 12 17:41:12.037453 2018] [wsgi:error] [pid 15125] [remote 94.181.164.38:49743]     sql, arguments, attr_offsets, query_key = query._construct_sql_and_arguments(range)
[Mon Mar 12 17:41:12.037463 2018] [wsgi:error] [pid 15125] [remote 94.181.164.38:49743]   File "/usr/lib/python3.6/site-packages/pony/orm/core.py", line 5316, in _construct_sql_and_arguments
[Mon Mar 12 17:41:12.037557 2018] [wsgi:error] [pid 15125] [remote 94.181.164.38:49743]     cache = database._get_cache()
[Mon Mar 12 17:41:12.037569 2018] [wsgi:error] [pid 15125] [remote 94.181.164.38:49743]   File "/usr/lib/python3.6/site-packages/pony/orm/core.py", line 726, in _get_cache
[Mon Mar 12 17:41:12.037579 2018] [wsgi:error] [pid 15125] [remote 94.181.164.38:49743]     ): throw(TransactionError, 'db_session is required when working with the database')
[Mon Mar 12 17:41:12.037589 2018] [wsgi:error] [pid 15125] [remote 94.181.164.38:49743]   File "/usr/lib/python3.6/site-packages/pony/utils/utils.py", line 98, in throw
[Mon Mar 12 17:41:12.037598 2018] [wsgi:error] [pid 15125] [remote 94.181.164.38:49743]     raise exc
[Mon Mar 12 17:41:12.037614 2018] [wsgi:error] [pid 15125] [remote 94.181.164.38:49743] pony.orm.core.TransactionError: db_session is required when working with the database
[Mon Mar 12 17:41:12.037679 2018] [wsgi:error] [pid 15125] [remote 94.181.164.38:49743] 
[Mon Mar 12 20:11:29.886267 2018] [wsgi:error] [pid 15125] [remote 217.118.90.249:61946] [2018-03-12 20:11:29,884] ERROR in app: Exception on /work/end_order [GET]
[Mon Mar 12 20:11:29.886382 2018] [wsgi:error] [pid 15125] [remote 217.118.90.249:61946] Traceback (most recent call last):
[Mon Mar 12 20:11:29.886395 2018] [wsgi:error] [pid 15125] [remote 217.118.90.249:61946]   File "/usr/lib/python3.6/site-packages/flask/app.py", line 1982, in wsgi_app
[Mon Mar 12 20:11:29.886406 2018] [wsgi:error] [pid 15125] [remote 217.118.90.249:61946]     response = self.full_dispatch_request()
[Mon Mar 12 20:11:29.886415 2018] [wsgi:error] [pid 15125] [remote 217.118.90.249:61946]   File "/usr/lib/python3.6/site-packages/flask/app.py", line 1614, in full_dispatch_request
[Mon Mar 12 20:11:29.886425 2018] [wsgi:error] [pid 15125] [remote 217.118.90.249:61946]     rv = self.handle_user_exception(e)
[Mon Mar 12 20:11:29.886434 2018] [wsgi:error] [pid 15125] [remote 217.118.90.249:61946]   File "/usr/lib/python3.6/site-packages/flask/app.py", line 1517, in handle_user_exception
[Mon Mar 12 20:11:29.886443 2018] [wsgi:error] [pid 15125] [remote 217.118.90.249:61946]     reraise(exc_type, exc_value, tb)
[Mon Mar 12 20:11:29.886452 2018] [wsgi:error] [pid 15125] [remote 217.118.90.249:61946]   File "/usr/lib/python3.6/site-packages/flask/_compat.py", line 33, in reraise
[Mon Mar 12 20:11:29.886462 2018] [wsgi:error] [pid 15125] [remote 217.118.90.249:61946]     raise value
[Mon Mar 12 20:11:29.886471 2018] [wsgi:error] [pid 15125] [remote 217.118.90.249:61946]   File "/usr/lib/python3.6/site-packages/flask/app.py", line 1612, in full_dispatch_request
[Mon Mar 12 20:11:29.886480 2018] [wsgi:error] [pid 15125] [remote 217.118.90.249:61946]     rv = self.dispatch_request()
[Mon Mar 12 20:11:29.886489 2018] [wsgi:error] [pid 15125] [remote 217.118.90.249:61946]   File "/usr/lib/python3.6/site-packages/flask/app.py", line 1598, in dispatch_request
[Mon Mar 12 20:11:29.886499 2018] [wsgi:error] [pid 15125] [remote 217.118.90.249:61946]     return self.view_functions[rule.endpoint](**req.view_args)
[Mon Mar 12 20:11:29.886508 2018] [wsgi:error] [pid 15125] [remote 217.118.90.249:61946]   File "/srv/http/virtlabs.tk/5koleso.tk/worker.py", line 125, in end_order
[Mon Mar 12 20:11:29.886517 2018] [wsgi:error] [pid 15125] [remote 217.118.90.249:61946]     select(p for p in Taxi_order if p.id == request.args.get('id')).delete()
[Mon Mar 12 20:11:29.886526 2018] [wsgi:error] [pid 15125] [remote 217.118.90.249:61946]   File "<string>", line 2, in delete
[Mon Mar 12 20:11:29.886535 2018] [wsgi:error] [pid 15125] [remote 217.118.90.249:61946]   File "/usr/lib/python3.6/site-packages/pony/utils/utils.py", line 58, in cut_traceback
[Mon Mar 12 20:11:29.886545 2018] [wsgi:error] [pid 15125] [remote 217.118.90.249:61946]     return func(*args, **kwargs)
[Mon Mar 12 20:11:29.886553 2018] [wsgi:error] [pid 15125] [remote 217.118.90.249:61946]   File "/usr/lib/python3.6/site-packages/pony/orm/core.py", line 5483, in delete
[Mon Mar 12 20:11:29.886664 2018] [wsgi:error] [pid 15125] [remote 217.118.90.249:61946]     objects = query._fetch()
[Mon Mar 12 20:11:29.886676 2018] [wsgi:error] [pid 15125] [remote 217.118.90.249:61946]   File "/usr/lib/python3.6/site-packages/pony/orm/core.py", line 5336, in _fetch
[Mon Mar 12 20:11:29.886686 2018] [wsgi:error] [pid 15125] [remote 217.118.90.249:61946]     sql, arguments, attr_offsets, query_key = query._construct_sql_and_arguments(range)
[Mon Mar 12 20:11:29.886696 2018] [wsgi:error] [pid 15125] [remote 217.118.90.249:61946]   File "/usr/lib/python3.6/site-packages/pony/orm/core.py", line 5316, in _construct_sql_and_arguments
[Mon Mar 12 20:11:29.886706 2018] [wsgi:error] [pid 15125] [remote 217.118.90.249:61946]     cache = database._get_cache()
[Mon Mar 12 20:11:29.886715 2018] [wsgi:error] [pid 15125] [remote 217.118.90.249:61946]   File "/usr/lib/python3.6/site-packages/pony/orm/core.py", line 726, in _get_cache
[Mon Mar 12 20:11:29.886724 2018] [wsgi:error] [pid 15125] [remote 217.118.90.249:61946]     ): throw(TransactionError, 'db_session is required when working with the database')
[Mon Mar 12 20:11:29.886734 2018] [wsgi:error] [pid 15125] [remote 217.118.90.249:61946]   File "/usr/lib/python3.6/site-packages/pony/utils/utils.py", line 98, in throw
[Mon Mar 12 20:11:29.886743 2018] [wsgi:error] [pid 15125] [remote 217.118.90.249:61946]     raise exc
[Mon Mar 12 20:11:29.886756 2018] [wsgi:error] [pid 15125] [remote 217.118.90.249:61946] pony.orm.core.TransactionError: db_session is required when working with the database
[Mon Mar 12 20:11:29.886813 2018] [wsgi:error] [pid 15125] [remote 217.118.90.249:61946] 
[Tue Mar 13 05:40:50.743854 2018] [wsgi:error] [pid 15125] [remote 31.173.83.108:64321] mod_wsgi (pid=15125): Exception occurred processing WSGI script '/srv/http/virtlabs.tk/5koleso.tk/api.wsgi'.
[Tue Mar 13 05:40:50.744254 2018] [wsgi:error] [pid 15125] [remote 31.173.83.108:64321] OSError: Apache/mod_wsgi failed to write response data: Broken pipe.
[Tue Mar 13 05:41:30.056874 2018] [wsgi:error] [pid 15128] (70007)The timeout specified has expired: [client 31.173.81.175:49860] mod_wsgi (pid=15128): Failed to proxy response to client., referer: http://5koleso.tk/application
[Tue Mar 13 05:41:30.058420 2018] [wsgi:error] [pid 15125] [remote 31.173.81.175:49860] mod_wsgi (pid=15125): Exception occurred processing WSGI script '/srv/http/virtlabs.tk/5koleso.tk/api.wsgi'.
[Tue Mar 13 05:41:30.058797 2018] [wsgi:error] [pid 15125] [remote 31.173.81.175:49860] OSError: Apache/mod_wsgi failed to write response data: Broken pipe.
[Tue Mar 13 09:28:16.329767 2018] [wsgi:error] [pid 15125] [remote 31.173.81.175:64349] mod_wsgi (pid=15125): Exception occurred processing WSGI script '/srv/http/virtlabs.tk/5koleso.tk/api.wsgi'.
[Tue Mar 13 09:28:16.330125 2018] [wsgi:error] [pid 15125] [remote 31.173.81.175:64349] OSError: Apache/mod_wsgi failed to write response data: Broken pipe.
