[Wed Aug 22 09:45:32.634772 2018] [wsgi:error] [pid 29569] [remote 83.149.21.22:40996] [2018-08-22 09:45:32,629] ERROR in app: Exception on /work/part [GET]
[Wed Aug 22 09:45:32.635038 2018] [wsgi:error] [pid 29569] [remote 83.149.21.22:40996] Traceback (most recent call last):
[Wed Aug 22 09:45:32.635055 2018] [wsgi:error] [pid 29569] [remote 83.149.21.22:40996]   File "/usr/lib/python3.6/site-packages/flask/app.py", line 1982, in wsgi_app
[Wed Aug 22 09:45:32.635067 2018] [wsgi:error] [pid 29569] [remote 83.149.21.22:40996]     response = self.full_dispatch_request()
[Wed Aug 22 09:45:32.635077 2018] [wsgi:error] [pid 29569] [remote 83.149.21.22:40996]   File "/usr/lib/python3.6/site-packages/flask/app.py", line 1614, in full_dispatch_request
[Wed Aug 22 09:45:32.635088 2018] [wsgi:error] [pid 29569] [remote 83.149.21.22:40996]     rv = self.handle_user_exception(e)
[Wed Aug 22 09:45:32.635097 2018] [wsgi:error] [pid 29569] [remote 83.149.21.22:40996]   File "/usr/lib/python3.6/site-packages/flask/app.py", line 1517, in handle_user_exception
[Wed Aug 22 09:45:32.635107 2018] [wsgi:error] [pid 29569] [remote 83.149.21.22:40996]     reraise(exc_type, exc_value, tb)
[Wed Aug 22 09:45:32.635117 2018] [wsgi:error] [pid 29569] [remote 83.149.21.22:40996]   File "/usr/lib/python3.6/site-packages/flask/_compat.py", line 33, in reraise
[Wed Aug 22 09:45:32.635127 2018] [wsgi:error] [pid 29569] [remote 83.149.21.22:40996]     raise value
[Wed Aug 22 09:45:32.635136 2018] [wsgi:error] [pid 29569] [remote 83.149.21.22:40996]   File "/usr/lib/python3.6/site-packages/flask/app.py", line 1612, in full_dispatch_request
[Wed Aug 22 09:45:32.635147 2018] [wsgi:error] [pid 29569] [remote 83.149.21.22:40996]     rv = self.dispatch_request()
[Wed Aug 22 09:45:32.635156 2018] [wsgi:error] [pid 29569] [remote 83.149.21.22:40996]   File "/usr/lib/python3.6/site-packages/flask/app.py", line 1598, in dispatch_request
[Wed Aug 22 09:45:32.635166 2018] [wsgi:error] [pid 29569] [remote 83.149.21.22:40996]     return self.view_functions[rule.endpoint](**req.view_args)
[Wed Aug 22 09:45:32.635176 2018] [wsgi:error] [pid 29569] [remote 83.149.21.22:40996]   File "/srv/http/virtlabs.tk/5koleso.tk/worker.py", line 73, in work_part
[Wed Aug 22 09:45:32.635186 2018] [wsgi:error] [pid 29569] [remote 83.149.21.22:40996]     worker_queue.append(worker.worker_id)
[Wed Aug 22 09:45:32.635204 2018] [wsgi:error] [pid 29569] [remote 83.149.21.22:40996] AttributeError: 'NoneType' object has no attribute 'worker_id'
[Wed Aug 22 09:45:32.635269 2018] [wsgi:error] [pid 29569] [remote 83.149.21.22:40996] 
[Wed Aug 22 09:45:32.729762 2018] [wsgi:error] [pid 29569] [remote 83.149.21.22:40996] --- Logging error ---
[Wed Aug 22 09:45:32.734928 2018] [wsgi:error] [pid 29569] [remote 83.149.21.22:40996] Traceback (most recent call last):
[Wed Aug 22 09:45:32.735181 2018] [wsgi:error] [pid 29569] [remote 83.149.21.22:40996]   File "/usr/lib/python3.6/site-packages/flask/app.py", line 1982, in wsgi_app
[Wed Aug 22 09:45:32.735200 2018] [wsgi:error] [pid 29569] [remote 83.149.21.22:40996]     response = self.full_dispatch_request()
[Wed Aug 22 09:45:32.735232 2018] [wsgi:error] [pid 29569] [remote 83.149.21.22:40996]   File "/usr/lib/python3.6/site-packages/flask/app.py", line 1614, in full_dispatch_request
[Wed Aug 22 09:45:32.735247 2018] [wsgi:error] [pid 29569] [remote 83.149.21.22:40996]     rv = self.handle_user_exception(e)
[Wed Aug 22 09:45:32.735275 2018] [wsgi:error] [pid 29569] [remote 83.149.21.22:40996]   File "/usr/lib/python3.6/site-packages/flask/app.py", line 1517, in handle_user_exception
[Wed Aug 22 09:45:32.735289 2018] [wsgi:error] [pid 29569] [remote 83.149.21.22:40996]     reraise(exc_type, exc_value, tb)
[Wed Aug 22 09:45:32.735316 2018] [wsgi:error] [pid 29569] [remote 83.149.21.22:40996]   File "/usr/lib/python3.6/site-packages/flask/_compat.py", line 33, in reraise
[Wed Aug 22 09:45:32.735329 2018] [wsgi:error] [pid 29569] [remote 83.149.21.22:40996]     raise value
[Wed Aug 22 09:45:32.735355 2018] [wsgi:error] [pid 29569] [remote 83.149.21.22:40996]   File "/usr/lib/python3.6/site-packages/flask/app.py", line 1612, in full_dispatch_request
[Wed Aug 22 09:45:32.736755 2018] [wsgi:error] [pid 29569] [remote 83.149.21.22:40996]     rv = self.dispatch_request()
[Wed Aug 22 09:45:32.736953 2018] [wsgi:error] [pid 29569] [remote 83.149.21.22:40996]   File "/usr/lib/python3.6/site-packages/flask/app.py", line 1598, in dispatch_request
[Wed Aug 22 09:45:32.736974 2018] [wsgi:error] [pid 29569] [remote 83.149.21.22:40996]     return self.view_functions[rule.endpoint](**req.view_args)
[Wed Aug 22 09:45:32.737007 2018] [wsgi:error] [pid 29569] [remote 83.149.21.22:40996]   File "/srv/http/virtlabs.tk/5koleso.tk/worker.py", line 73, in work_part
[Wed Aug 22 09:45:32.737022 2018] [wsgi:error] [pid 29569] [remote 83.149.21.22:40996]     worker_queue.append(worker.worker_id)
[Wed Aug 22 09:45:32.737121 2018] [wsgi:error] [pid 29569] [remote 83.149.21.22:40996] AttributeError: 'NoneType' object has no attribute 'worker_id'
[Wed Aug 22 09:45:32.737187 2018] [wsgi:error] [pid 29569] [remote 83.149.21.22:40996] 
[Wed Aug 22 09:45:32.737201 2018] [wsgi:error] [pid 29569] [remote 83.149.21.22:40996] During handling of the above exception, another exception occurred:
[Wed Aug 22 09:45:32.737212 2018] [wsgi:error] [pid 29569] [remote 83.149.21.22:40996] 
[Wed Aug 22 09:45:32.737240 2018] [wsgi:error] [pid 29569] [remote 83.149.21.22:40996] Traceback (most recent call last):
[Wed Aug 22 09:45:32.737391 2018] [wsgi:error] [pid 29569] [remote 83.149.21.22:40996]   File "/usr/lib/python3.6/logging/handlers.py", line 1010, in emit
[Wed Aug 22 09:45:32.737407 2018] [wsgi:error] [pid 29569] [remote 83.149.21.22:40996]     smtp = smtplib.SMTP(self.mailhost, port, timeout=self.timeout)
[Wed Aug 22 09:45:32.737435 2018] [wsgi:error] [pid 29569] [remote 83.149.21.22:40996]   File "/usr/lib/python3.6/smtplib.py", line 251, in __init__
[Wed Aug 22 09:45:32.737448 2018] [wsgi:error] [pid 29569] [remote 83.149.21.22:40996]     (code, msg) = self.connect(host, port)
[Wed Aug 22 09:45:32.737474 2018] [wsgi:error] [pid 29569] [remote 83.149.21.22:40996]   File "/usr/lib/python3.6/smtplib.py", line 336, in connect
[Wed Aug 22 09:45:32.737488 2018] [wsgi:error] [pid 29569] [remote 83.149.21.22:40996]     self.sock = self._get_socket(host, port, self.timeout)
[Wed Aug 22 09:45:32.737514 2018] [wsgi:error] [pid 29569] [remote 83.149.21.22:40996]   File "/usr/lib/python3.6/smtplib.py", line 307, in _get_socket
[Wed Aug 22 09:45:32.737528 2018] [wsgi:error] [pid 29569] [remote 83.149.21.22:40996]     self.source_address)
[Wed Aug 22 09:45:32.737554 2018] [wsgi:error] [pid 29569] [remote 83.149.21.22:40996]   File "/usr/lib/python3.6/socket.py", line 704, in create_connection
[Wed Aug 22 09:45:32.737567 2018] [wsgi:error] [pid 29569] [remote 83.149.21.22:40996]     for res in getaddrinfo(host, port, 0, SOCK_STREAM):
[Wed Aug 22 09:45:32.737594 2018] [wsgi:error] [pid 29569] [remote 83.149.21.22:40996]   File "/usr/lib/python3.6/socket.py", line 745, in getaddrinfo
[Wed Aug 22 09:45:32.737607 2018] [wsgi:error] [pid 29569] [remote 83.149.21.22:40996]     for res in _socket.getaddrinfo(host, port, family, type, proto, flags):
[Wed Aug 22 09:45:32.737657 2018] [wsgi:error] [pid 29569] [remote 83.149.21.22:40996] socket.gaierror: [Errno -2] Name or service not known
[Wed Aug 22 09:45:32.737714 2018] [wsgi:error] [pid 29569] [remote 83.149.21.22:40996] Call stack:
[Wed Aug 22 09:45:32.738194 2018] [wsgi:error] [pid 29569] [remote 83.149.21.22:40996]   File "/usr/lib/python3.6/site-packages/flask/app.py", line 1997, in __call__
[Wed Aug 22 09:45:32.738221 2018] [wsgi:error] [pid 29569] [remote 83.149.21.22:40996]     return self.wsgi_app(environ, start_response)
[Wed Aug 22 09:45:32.738252 2018] [wsgi:error] [pid 29569] [remote 83.149.21.22:40996]   File "/usr/lib/python3.6/site-packages/flask/app.py", line 1985, in wsgi_app
[Wed Aug 22 09:45:32.738266 2018] [wsgi:error] [pid 29569] [remote 83.149.21.22:40996]     response = self.handle_exception(e)
[Wed Aug 22 09:45:32.738293 2018] [wsgi:error] [pid 29569] [remote 83.149.21.22:40996]   File "/usr/lib/python3.6/site-packages/flask/app.py", line 1544, in handle_exception
[Wed Aug 22 09:45:32.738391 2018] [wsgi:error] [pid 29569] [remote 83.149.21.22:40996]     self.log_exception((exc_type, exc_value, tb))
[Wed Aug 22 09:45:32.738423 2018] [wsgi:error] [pid 29569] [remote 83.149.21.22:40996]   File "/usr/lib/python3.6/site-packages/flask/app.py", line 1560, in log_exception
[Wed Aug 22 09:45:32.738437 2018] [wsgi:error] [pid 29569] [remote 83.149.21.22:40996]     ), exc_info=exc_info)
[Wed Aug 22 09:45:32.738499 2018] [wsgi:error] [pid 29569] [remote 83.149.21.22:40996] Message: 'Exception on /work/part [GET]'
[Wed Aug 22 09:45:32.738514 2018] [wsgi:error] [pid 29569] [remote 83.149.21.22:40996] Arguments: ()
[Wed Aug 22 09:49:29.062404 2018] [wsgi:error] [pid 29660] [remote 176.59.104.106:62038] [2018-08-22 09:49:29,058] ERROR in app: Exception on /work/logout [GET]
[Wed Aug 22 09:49:29.062645 2018] [wsgi:error] [pid 29660] [remote 176.59.104.106:62038] Traceback (most recent call last):
[Wed Aug 22 09:49:29.062661 2018] [wsgi:error] [pid 29660] [remote 176.59.104.106:62038]   File "/usr/lib/python3.6/site-packages/flask/app.py", line 1982, in wsgi_app
[Wed Aug 22 09:49:29.062673 2018] [wsgi:error] [pid 29660] [remote 176.59.104.106:62038]     response = self.full_dispatch_request()
[Wed Aug 22 09:49:29.062683 2018] [wsgi:error] [pid 29660] [remote 176.59.104.106:62038]   File "/usr/lib/python3.6/site-packages/flask/app.py", line 1615, in full_dispatch_request
[Wed Aug 22 09:49:29.062693 2018] [wsgi:error] [pid 29660] [remote 176.59.104.106:62038]     return self.finalize_request(rv)
[Wed Aug 22 09:49:29.062703 2018] [wsgi:error] [pid 29660] [remote 176.59.104.106:62038]   File "/usr/lib/python3.6/site-packages/flask/app.py", line 1630, in finalize_request
[Wed Aug 22 09:49:29.062713 2018] [wsgi:error] [pid 29660] [remote 176.59.104.106:62038]     response = self.make_response(rv)
[Wed Aug 22 09:49:29.062723 2018] [wsgi:error] [pid 29660] [remote 176.59.104.106:62038]   File "/usr/lib/python3.6/site-packages/flask/app.py", line 1725, in make_response
[Wed Aug 22 09:49:29.062733 2018] [wsgi:error] [pid 29660] [remote 176.59.104.106:62038]     raise ValueError('View function did not return a response')
[Wed Aug 22 09:49:29.062751 2018] [wsgi:error] [pid 29660] [remote 176.59.104.106:62038] ValueError: View function did not return a response
[Wed Aug 22 09:49:29.062810 2018] [wsgi:error] [pid 29660] [remote 176.59.104.106:62038] 
[Wed Aug 22 09:49:29.107356 2018] [wsgi:error] [pid 29660] [remote 176.59.104.106:62038] --- Logging error ---
[Wed Aug 22 09:49:29.114209 2018] [wsgi:error] [pid 29660] [remote 176.59.104.106:62038] Traceback (most recent call last):
[Wed Aug 22 09:49:29.114427 2018] [wsgi:error] [pid 29660] [remote 176.59.104.106:62038]   File "/usr/lib/python3.6/site-packages/flask/app.py", line 1982, in wsgi_app
[Wed Aug 22 09:49:29.114446 2018] [wsgi:error] [pid 29660] [remote 176.59.104.106:62038]     response = self.full_dispatch_request()
[Wed Aug 22 09:49:29.114478 2018] [wsgi:error] [pid 29660] [remote 176.59.104.106:62038]   File "/usr/lib/python3.6/site-packages/flask/app.py", line 1615, in full_dispatch_request
[Wed Aug 22 09:49:29.114493 2018] [wsgi:error] [pid 29660] [remote 176.59.104.106:62038]     return self.finalize_request(rv)
[Wed Aug 22 09:49:29.114520 2018] [wsgi:error] [pid 29660] [remote 176.59.104.106:62038]   File "/usr/lib/python3.6/site-packages/flask/app.py", line 1630, in finalize_request
[Wed Aug 22 09:49:29.114534 2018] [wsgi:error] [pid 29660] [remote 176.59.104.106:62038]     response = self.make_response(rv)
[Wed Aug 22 09:49:29.114561 2018] [wsgi:error] [pid 29660] [remote 176.59.104.106:62038]   File "/usr/lib/python3.6/site-packages/flask/app.py", line 1725, in make_response
[Wed Aug 22 09:49:29.114574 2018] [wsgi:error] [pid 29660] [remote 176.59.104.106:62038]     raise ValueError('View function did not return a response')
[Wed Aug 22 09:49:29.114636 2018] [wsgi:error] [pid 29660] [remote 176.59.104.106:62038] ValueError: View function did not return a response
[Wed Aug 22 09:49:29.114790 2018] [wsgi:error] [pid 29660] [remote 176.59.104.106:62038] 
[Wed Aug 22 09:49:29.114805 2018] [wsgi:error] [pid 29660] [remote 176.59.104.106:62038] During handling of the above exception, another exception occurred:
[Wed Aug 22 09:49:29.114816 2018] [wsgi:error] [pid 29660] [remote 176.59.104.106:62038] 
[Wed Aug 22 09:49:29.114842 2018] [wsgi:error] [pid 29660] [remote 176.59.104.106:62038] Traceback (most recent call last):
[Wed Aug 22 09:49:29.114950 2018] [wsgi:error] [pid 29660] [remote 176.59.104.106:62038]   File "/usr/lib/python3.6/logging/handlers.py", line 1010, in emit
[Wed Aug 22 09:49:29.114965 2018] [wsgi:error] [pid 29660] [remote 176.59.104.106:62038]     smtp = smtplib.SMTP(self.mailhost, port, timeout=self.timeout)
[Wed Aug 22 09:49:29.114992 2018] [wsgi:error] [pid 29660] [remote 176.59.104.106:62038]   File "/usr/lib/python3.6/smtplib.py", line 251, in __init__
[Wed Aug 22 09:49:29.115005 2018] [wsgi:error] [pid 29660] [remote 176.59.104.106:62038]     (code, msg) = self.connect(host, port)
[Wed Aug 22 09:49:29.115030 2018] [wsgi:error] [pid 29660] [remote 176.59.104.106:62038]   File "/usr/lib/python3.6/smtplib.py", line 336, in connect
[Wed Aug 22 09:49:29.115043 2018] [wsgi:error] [pid 29660] [remote 176.59.104.106:62038]     self.sock = self._get_socket(host, port, self.timeout)
[Wed Aug 22 09:49:29.115069 2018] [wsgi:error] [pid 29660] [remote 176.59.104.106:62038]   File "/usr/lib/python3.6/smtplib.py", line 307, in _get_socket
[Wed Aug 22 09:49:29.115082 2018] [wsgi:error] [pid 29660] [remote 176.59.104.106:62038]     self.source_address)
[Wed Aug 22 09:49:29.115107 2018] [wsgi:error] [pid 29660] [remote 176.59.104.106:62038]   File "/usr/lib/python3.6/socket.py", line 704, in create_connection
[Wed Aug 22 09:49:29.115120 2018] [wsgi:error] [pid 29660] [remote 176.59.104.106:62038]     for res in getaddrinfo(host, port, 0, SOCK_STREAM):
[Wed Aug 22 09:49:29.115145 2018] [wsgi:error] [pid 29660] [remote 176.59.104.106:62038]   File "/usr/lib/python3.6/socket.py", line 745, in getaddrinfo
[Wed Aug 22 09:49:29.115158 2018] [wsgi:error] [pid 29660] [remote 176.59.104.106:62038]     for res in _socket.getaddrinfo(host, port, family, type, proto, flags):
[Wed Aug 22 09:49:29.115204 2018] [wsgi:error] [pid 29660] [remote 176.59.104.106:62038] socket.gaierror: [Errno -2] Name or service not known
[Wed Aug 22 09:49:29.115251 2018] [wsgi:error] [pid 29660] [remote 176.59.104.106:62038] Call stack:
[Wed Aug 22 09:49:29.115913 2018] [wsgi:error] [pid 29660] [remote 176.59.104.106:62038]   File "/usr/lib/python3.6/site-packages/flask/app.py", line 1997, in __call__
[Wed Aug 22 09:49:29.115973 2018] [wsgi:error] [pid 29660] [remote 176.59.104.106:62038]     return self.wsgi_app(environ, start_response)
[Wed Aug 22 09:49:29.116008 2018] [wsgi:error] [pid 29660] [remote 176.59.104.106:62038]   File "/usr/lib/python3.6/site-packages/flask/app.py", line 1985, in wsgi_app
[Wed Aug 22 09:49:29.116025 2018] [wsgi:error] [pid 29660] [remote 176.59.104.106:62038]     response = self.handle_exception(e)
[Wed Aug 22 09:49:29.116052 2018] [wsgi:error] [pid 29660] [remote 176.59.104.106:62038]   File "/usr/lib/python3.6/site-packages/flask/app.py", line 1544, in handle_exception
[Wed Aug 22 09:49:29.116065 2018] [wsgi:error] [pid 29660] [remote 176.59.104.106:62038]     self.log_exception((exc_type, exc_value, tb))
[Wed Aug 22 09:49:29.116091 2018] [wsgi:error] [pid 29660] [remote 176.59.104.106:62038]   File "/usr/lib/python3.6/site-packages/flask/app.py", line 1560, in log_exception
[Wed Aug 22 09:49:29.116105 2018] [wsgi:error] [pid 29660] [remote 176.59.104.106:62038]     ), exc_info=exc_info)
[Wed Aug 22 09:49:29.116163 2018] [wsgi:error] [pid 29660] [remote 176.59.104.106:62038] Message: 'Exception on /work/logout [GET]'
[Wed Aug 22 09:49:29.116179 2018] [wsgi:error] [pid 29660] [remote 176.59.104.106:62038] Arguments: ()
[Wed Aug 22 10:00:17.405097 2018] [wsgi:error] [pid 29737] [remote 83.149.21.22:20193] mod_wsgi (pid=29737): Target WSGI script '/srv/http/virtlabs.tk/5koleso.tk/api.wsgi' cannot be loaded as Python module.
[Wed Aug 22 10:00:17.405620 2018] [wsgi:error] [pid 29737] [remote 83.149.21.22:20193] mod_wsgi (pid=29737): Exception occurred processing WSGI script '/srv/http/virtlabs.tk/5koleso.tk/api.wsgi'.
[Wed Aug 22 10:00:17.506486 2018] [wsgi:error] [pid 29737] [remote 83.149.21.22:20193] Traceback (most recent call last):
[Wed Aug 22 10:00:17.506724 2018] [wsgi:error] [pid 29737] [remote 83.149.21.22:20193]   File "/usr/lib/python3.6/site-packages/pony/orm/dbapiprovider.py", line 50, in wrap_dbapi_exceptions
[Wed Aug 22 10:00:17.506744 2018] [wsgi:error] [pid 29737] [remote 83.149.21.22:20193]     return func(provider, *args, **kwargs)
[Wed Aug 22 10:00:17.506773 2018] [wsgi:error] [pid 29737] [remote 83.149.21.22:20193]   File "/usr/lib/python3.6/site-packages/pony/orm/dbproviders/postgres.py", line 215, in execute
[Wed Aug 22 10:00:17.506788 2018] [wsgi:error] [pid 29737] [remote 83.149.21.22:20193]     if arguments is None: cursor.execute(sql)
[Wed Aug 22 10:00:17.506816 2018] [wsgi:error] [pid 29737] [remote 83.149.21.22:20193]   File "/usr/lib/python3.6/site-packages/psycopg2cffi/_impl/cursor.py", line 30, in check_closed_
[Wed Aug 22 10:00:17.506829 2018] [wsgi:error] [pid 29737] [remote 83.149.21.22:20193]     return func(self, *args, **kwargs)
[Wed Aug 22 10:00:17.506856 2018] [wsgi:error] [pid 29737] [remote 83.149.21.22:20193]   File "/usr/lib/python3.6/site-packages/psycopg2cffi/_impl/cursor.py", line 263, in execute
[Wed Aug 22 10:00:17.506869 2018] [wsgi:error] [pid 29737] [remote 83.149.21.22:20193]     self._pq_execute(self._query, conn._async)
[Wed Aug 22 10:00:17.506896 2018] [wsgi:error] [pid 29737] [remote 83.149.21.22:20193]   File "/usr/lib/python3.6/site-packages/psycopg2cffi/_impl/cursor.py", line 696, in _pq_execute
[Wed Aug 22 10:00:17.506909 2018] [wsgi:error] [pid 29737] [remote 83.149.21.22:20193]     self._pq_fetch()
[Wed Aug 22 10:00:17.506935 2018] [wsgi:error] [pid 29737] [remote 83.149.21.22:20193]   File "/usr/lib/python3.6/site-packages/psycopg2cffi/_impl/cursor.py", line 757, in _pq_fetch
[Wed Aug 22 10:00:17.506949 2018] [wsgi:error] [pid 29737] [remote 83.149.21.22:20193]     raise self._conn._create_exception(cursor=self)
[Wed Aug 22 10:00:17.507073 2018] [wsgi:error] [pid 29737] [remote 83.149.21.22:20193] psycopg2cffi._impl.exceptions.ProgrammingError: \xd0\x9e\xd0\xa8\xd0\x98\xd0\x91\xd0\x9a\xd0\x90:  \xd1\x81\xd1\x82\xd0\xbe\xd0\xbb\xd0\xb1\xd0\xb5\xd1\x86 online.queue_number \xd0\xbd\xd0\xb5 \xd1\x81\xd1\x83\xd1\x89\xd0\xb5\xd1\x81\xd1\x82\xd0\xb2\xd1\x83\xd0\xb5\xd1\x82
[Wed Aug 22 10:00:17.507091 2018] [wsgi:error] [pid 29737] [remote 83.149.21.22:20193] LINE 1: SELECT "online"."id", "online"."worker_id", "online"."queue_...
[Wed Aug 22 10:00:17.507104 2018] [wsgi:error] [pid 29737] [remote 83.149.21.22:20193]                                                     ^
[Wed Aug 22 10:00:17.507115 2018] [wsgi:error] [pid 29737] [remote 83.149.21.22:20193] 
[Wed Aug 22 10:00:17.507153 2018] [wsgi:error] [pid 29737] [remote 83.149.21.22:20193] 
[Wed Aug 22 10:00:17.507166 2018] [wsgi:error] [pid 29737] [remote 83.149.21.22:20193] During handling of the above exception, another exception occurred:
[Wed Aug 22 10:00:17.507178 2018] [wsgi:error] [pid 29737] [remote 83.149.21.22:20193] 
[Wed Aug 22 10:00:17.507203 2018] [wsgi:error] [pid 29737] [remote 83.149.21.22:20193] Traceback (most recent call last):
[Wed Aug 22 10:00:17.507390 2018] [wsgi:error] [pid 29737] [remote 83.149.21.22:20193]   File "/srv/http/virtlabs.tk/5koleso.tk/api.wsgi", line 1, in <module>
[Wed Aug 22 10:00:17.507406 2018] [wsgi:error] [pid 29737] [remote 83.149.21.22:20193]     from api import app as application
[Wed Aug 22 10:00:17.507433 2018] [wsgi:error] [pid 29737] [remote 83.149.21.22:20193]   File "/srv/http/virtlabs.tk/5koleso.tk/api.py", line 16, in <module>
[Wed Aug 22 10:00:17.507446 2018] [wsgi:error] [pid 29737] [remote 83.149.21.22:20193]     from initdb import Worker, Auth, Online, Taxi_order
[Wed Aug 22 10:00:17.507472 2018] [wsgi:error] [pid 29737] [remote 83.149.21.22:20193]   File "/srv/http/virtlabs.tk/5koleso.tk/initdb.py", line 40, in <module>
[Wed Aug 22 10:00:17.507572 2018] [wsgi:error] [pid 29737] [remote 83.149.21.22:20193]     _PostgresDb.generate_mapping(check_tables = True, create_tables = False)
[Wed Aug 22 10:00:17.507603 2018] [wsgi:error] [pid 29737] [remote 83.149.21.22:20193]   File "<string>", line 2, in generate_mapping
[Wed Aug 22 10:00:17.507632 2018] [wsgi:error] [pid 29737] [remote 83.149.21.22:20193]   File "/usr/lib/python3.6/site-packages/pony/utils/utils.py", line 58, in cut_traceback
[Wed Aug 22 10:00:17.507645 2018] [wsgi:error] [pid 29737] [remote 83.149.21.22:20193]     return func(*args, **kwargs)
[Wed Aug 22 10:00:17.507671 2018] [wsgi:error] [pid 29737] [remote 83.149.21.22:20193]   File "/usr/lib/python3.6/site-packages/pony/orm/core.py", line 996, in generate_mapping
[Wed Aug 22 10:00:17.507685 2018] [wsgi:error] [pid 29737] [remote 83.149.21.22:20193]     elif check_tables: database.check_tables()
[Wed Aug 22 10:00:17.507710 2018] [wsgi:error] [pid 29737] [remote 83.149.21.22:20193]   File "<string>", line 2, in check_tables
[Wed Aug 22 10:00:17.507737 2018] [wsgi:error] [pid 29737] [remote 83.149.21.22:20193]   File "/usr/lib/python3.6/site-packages/pony/utils/utils.py", line 58, in cut_traceback
[Wed Aug 22 10:00:17.507750 2018] [wsgi:error] [pid 29737] [remote 83.149.21.22:20193]     return func(*args, **kwargs)
[Wed Aug 22 10:00:17.507775 2018] [wsgi:error] [pid 29737] [remote 83.149.21.22:20193]   File "<string>", line 2, in check_tables
[Wed Aug 22 10:00:17.507803 2018] [wsgi:error] [pid 29737] [remote 83.149.21.22:20193]   File "/usr/lib/python3.6/site-packages/pony/orm/core.py", line 460, in new_func
[Wed Aug 22 10:00:17.507816 2018] [wsgi:error] [pid 29737] [remote 83.149.21.22:20193]     try: return func(*args, **kwargs)
[Wed Aug 22 10:00:17.507840 2018] [wsgi:error] [pid 29737] [remote 83.149.21.22:20193]   File "/usr/lib/python3.6/site-packages/pony/orm/core.py", line 1061, in check_tables
[Wed Aug 22 10:00:17.507854 2018] [wsgi:error] [pid 29737] [remote 83.149.21.22:20193]     database.schema.check_tables(database.provider, connection)
[Wed Aug 22 10:00:17.507879 2018] [wsgi:error] [pid 29737] [remote 83.149.21.22:20193]   File "/usr/lib/python3.6/site-packages/pony/orm/dbschema.py", line 77, in check_tables
[Wed Aug 22 10:00:17.507892 2018] [wsgi:error] [pid 29737] [remote 83.149.21.22:20193]     provider.execute(cursor, sql)
[Wed Aug 22 10:00:17.507916 2018] [wsgi:error] [pid 29737] [remote 83.149.21.22:20193]   File "<string>", line 2, in execute
[Wed Aug 22 10:00:17.507945 2018] [wsgi:error] [pid 29737] [remote 83.149.21.22:20193]   File "/usr/lib/python3.6/site-packages/pony/orm/dbapiprovider.py", line 56, in wrap_dbapi_exceptions
[Wed Aug 22 10:00:17.507958 2018] [wsgi:error] [pid 29737] [remote 83.149.21.22:20193]     except dbapi_module.ProgrammingError as e: raise ProgrammingError(e)
[Wed Aug 22 10:00:17.508018 2018] [wsgi:error] [pid 29737] [remote 83.149.21.22:20193] pony.orm.dbapiprovider.ProgrammingError: \xd0\x9e\xd0\xa8\xd0\x98\xd0\x91\xd0\x9a\xd0\x90:  \xd1\x81\xd1\x82\xd0\xbe\xd0\xbb\xd0\xb1\xd0\xb5\xd1\x86 online.queue_number \xd0\xbd\xd0\xb5 \xd1\x81\xd1\x83\xd1\x89\xd0\xb5\xd1\x81\xd1\x82\xd0\xb2\xd1\x83\xd0\xb5\xd1\x82
[Wed Aug 22 10:00:17.508035 2018] [wsgi:error] [pid 29737] [remote 83.149.21.22:20193] LINE 1: SELECT "online"."id", "online"."worker_id", "online"."queue_...
[Wed Aug 22 10:00:17.508047 2018] [wsgi:error] [pid 29737] [remote 83.149.21.22:20193]                                                     ^
[Wed Aug 22 10:00:17.508056 2018] [wsgi:error] [pid 29737] [remote 83.149.21.22:20193] 
[Wed Aug 22 10:00:25.104770 2018] [wsgi:error] [pid 29737] [remote 83.149.21.22:17692] mod_wsgi (pid=29737): Target WSGI script '/srv/http/virtlabs.tk/5koleso.tk/api.wsgi' cannot be loaded as Python module.
[Wed Aug 22 10:00:25.105057 2018] [wsgi:error] [pid 29737] [remote 83.149.21.22:17692] mod_wsgi (pid=29737): Exception occurred processing WSGI script '/srv/http/virtlabs.tk/5koleso.tk/api.wsgi'.
[Wed Aug 22 10:00:25.106247 2018] [wsgi:error] [pid 29737] [remote 83.149.21.22:17692] Traceback (most recent call last):
[Wed Aug 22 10:00:25.106444 2018] [wsgi:error] [pid 29737] [remote 83.149.21.22:17692]   File "/usr/lib/python3.6/site-packages/pony/orm/dbapiprovider.py", line 50, in wrap_dbapi_exceptions
[Wed Aug 22 10:00:25.106465 2018] [wsgi:error] [pid 29737] [remote 83.149.21.22:17692]     return func(provider, *args, **kwargs)
[Wed Aug 22 10:00:25.106495 2018] [wsgi:error] [pid 29737] [remote 83.149.21.22:17692]   File "/usr/lib/python3.6/site-packages/pony/orm/dbproviders/postgres.py", line 215, in execute
[Wed Aug 22 10:00:25.106512 2018] [wsgi:error] [pid 29737] [remote 83.149.21.22:17692]     if arguments is None: cursor.execute(sql)
[Wed Aug 22 10:00:25.106539 2018] [wsgi:error] [pid 29737] [remote 83.149.21.22:17692]   File "/usr/lib/python3.6/site-packages/psycopg2cffi/_impl/cursor.py", line 30, in check_closed_
[Wed Aug 22 10:00:25.106553 2018] [wsgi:error] [pid 29737] [remote 83.149.21.22:17692]     return func(self, *args, **kwargs)
[Wed Aug 22 10:00:25.106579 2018] [wsgi:error] [pid 29737] [remote 83.149.21.22:17692]   File "/usr/lib/python3.6/site-packages/psycopg2cffi/_impl/cursor.py", line 263, in execute
[Wed Aug 22 10:00:25.106592 2018] [wsgi:error] [pid 29737] [remote 83.149.21.22:17692]     self._pq_execute(self._query, conn._async)
[Wed Aug 22 10:00:25.106618 2018] [wsgi:error] [pid 29737] [remote 83.149.21.22:17692]   File "/usr/lib/python3.6/site-packages/psycopg2cffi/_impl/cursor.py", line 696, in _pq_execute
[Wed Aug 22 10:00:25.106631 2018] [wsgi:error] [pid 29737] [remote 83.149.21.22:17692]     self._pq_fetch()
[Wed Aug 22 10:00:25.106656 2018] [wsgi:error] [pid 29737] [remote 83.149.21.22:17692]   File "/usr/lib/python3.6/site-packages/psycopg2cffi/_impl/cursor.py", line 757, in _pq_fetch
[Wed Aug 22 10:00:25.106670 2018] [wsgi:error] [pid 29737] [remote 83.149.21.22:17692]     raise self._conn._create_exception(cursor=self)
[Wed Aug 22 10:00:25.106750 2018] [wsgi:error] [pid 29737] [remote 83.149.21.22:17692] psycopg2cffi._impl.exceptions.ProgrammingError: \xd0\x9e\xd0\xa8\xd0\x98\xd0\x91\xd0\x9a\xd0\x90:  \xd1\x81\xd1\x82\xd0\xbe\xd0\xbb\xd0\xb1\xd0\xb5\xd1\x86 online.queue_number \xd0\xbd\xd0\xb5 \xd1\x81\xd1\x83\xd1\x89\xd0\xb5\xd1\x81\xd1\x82\xd0\xb2\xd1\x83\xd0\xb5\xd1\x82
[Wed Aug 22 10:00:25.106768 2018] [wsgi:error] [pid 29737] [remote 83.149.21.22:17692] LINE 1: SELECT "online"."id", "online"."worker_id", "online"."queue_...
[Wed Aug 22 10:00:25.106779 2018] [wsgi:error] [pid 29737] [remote 83.149.21.22:17692]                                                     ^
[Wed Aug 22 10:00:25.106790 2018] [wsgi:error] [pid 29737] [remote 83.149.21.22:17692] 
[Wed Aug 22 10:00:25.106820 2018] [wsgi:error] [pid 29737] [remote 83.149.21.22:17692] 
[Wed Aug 22 10:00:25.106833 2018] [wsgi:error] [pid 29737] [remote 83.149.21.22:17692] During handling of the above exception, another exception occurred:
[Wed Aug 22 10:00:25.106843 2018] [wsgi:error] [pid 29737] [remote 83.149.21.22:17692] 
[Wed Aug 22 10:00:25.106867 2018] [wsgi:error] [pid 29737] [remote 83.149.21.22:17692] Traceback (most recent call last):
[Wed Aug 22 10:00:25.107041 2018] [wsgi:error] [pid 29737] [remote 83.149.21.22:17692]   File "/srv/http/virtlabs.tk/5koleso.tk/api.wsgi", line 1, in <module>
[Wed Aug 22 10:00:25.107056 2018] [wsgi:error] [pid 29737] [remote 83.149.21.22:17692]     from api import app as application
[Wed Aug 22 10:00:25.107083 2018] [wsgi:error] [pid 29737] [remote 83.149.21.22:17692]   File "/srv/http/virtlabs.tk/5koleso.tk/api.py", line 16, in <module>
[Wed Aug 22 10:00:25.107096 2018] [wsgi:error] [pid 29737] [remote 83.149.21.22:17692]     from initdb import Worker, Auth, Online, Taxi_order
[Wed Aug 22 10:00:25.107122 2018] [wsgi:error] [pid 29737] [remote 83.149.21.22:17692]   File "/srv/http/virtlabs.tk/5koleso.tk/initdb.py", line 40, in <module>
[Wed Aug 22 10:00:25.107137 2018] [wsgi:error] [pid 29737] [remote 83.149.21.22:17692]     _PostgresDb.generate_mapping(check_tables = True, create_tables = False)
[Wed Aug 22 10:00:25.107253 2018] [wsgi:error] [pid 29737] [remote 83.149.21.22:17692]   File "<string>", line 2, in generate_mapping
[Wed Aug 22 10:00:25.107283 2018] [wsgi:error] [pid 29737] [remote 83.149.21.22:17692]   File "/usr/lib/python3.6/site-packages/pony/utils/utils.py", line 58, in cut_traceback
[Wed Aug 22 10:00:25.107296 2018] [wsgi:error] [pid 29737] [remote 83.149.21.22:17692]     return func(*args, **kwargs)
[Wed Aug 22 10:00:25.107321 2018] [wsgi:error] [pid 29737] [remote 83.149.21.22:17692]   File "/usr/lib/python3.6/site-packages/pony/orm/core.py", line 996, in generate_mapping
[Wed Aug 22 10:00:25.107334 2018] [wsgi:error] [pid 29737] [remote 83.149.21.22:17692]     elif check_tables: database.check_tables()
[Wed Aug 22 10:00:25.107359 2018] [wsgi:error] [pid 29737] [remote 83.149.21.22:17692]   File "<string>", line 2, in check_tables
[Wed Aug 22 10:00:25.107386 2018] [wsgi:error] [pid 29737] [remote 83.149.21.22:17692]   File "/usr/lib/python3.6/site-packages/pony/utils/utils.py", line 58, in cut_traceback
[Wed Aug 22 10:00:25.107399 2018] [wsgi:error] [pid 29737] [remote 83.149.21.22:17692]     return func(*args, **kwargs)
[Wed Aug 22 10:00:25.107424 2018] [wsgi:error] [pid 29737] [remote 83.149.21.22:17692]   File "<string>", line 2, in check_tables
[Wed Aug 22 10:00:25.107451 2018] [wsgi:error] [pid 29737] [remote 83.149.21.22:17692]   File "/usr/lib/python3.6/site-packages/pony/orm/core.py", line 460, in new_func
[Wed Aug 22 10:00:25.107464 2018] [wsgi:error] [pid 29737] [remote 83.149.21.22:17692]     try: return func(*args, **kwargs)
[Wed Aug 22 10:00:25.107489 2018] [wsgi:error] [pid 29737] [remote 83.149.21.22:17692]   File "/usr/lib/python3.6/site-packages/pony/orm/core.py", line 1061, in check_tables
[Wed Aug 22 10:00:25.107502 2018] [wsgi:error] [pid 29737] [remote 83.149.21.22:17692]     database.schema.check_tables(database.provider, connection)
[Wed Aug 22 10:00:25.107527 2018] [wsgi:error] [pid 29737] [remote 83.149.21.22:17692]   File "/usr/lib/python3.6/site-packages/pony/orm/dbschema.py", line 77, in check_tables
[Wed Aug 22 10:00:25.107540 2018] [wsgi:error] [pid 29737] [remote 83.149.21.22:17692]     provider.execute(cursor, sql)
[Wed Aug 22 10:00:25.107564 2018] [wsgi:error] [pid 29737] [remote 83.149.21.22:17692]   File "<string>", line 2, in execute
[Wed Aug 22 10:00:25.107592 2018] [wsgi:error] [pid 29737] [remote 83.149.21.22:17692]   File "/usr/lib/python3.6/site-packages/pony/orm/dbapiprovider.py", line 56, in wrap_dbapi_exceptions
[Wed Aug 22 10:00:25.107605 2018] [wsgi:error] [pid 29737] [remote 83.149.21.22:17692]     except dbapi_module.ProgrammingError as e: raise ProgrammingError(e)
[Wed Aug 22 10:00:25.107660 2018] [wsgi:error] [pid 29737] [remote 83.149.21.22:17692] pony.orm.dbapiprovider.ProgrammingError: \xd0\x9e\xd0\xa8\xd0\x98\xd0\x91\xd0\x9a\xd0\x90:  \xd1\x81\xd1\x82\xd0\xbe\xd0\xbb\xd0\xb1\xd0\xb5\xd1\x86 online.queue_number \xd0\xbd\xd0\xb5 \xd1\x81\xd1\x83\xd1\x89\xd0\xb5\xd1\x81\xd1\x82\xd0\xb2\xd1\x83\xd0\xb5\xd1\x82
[Wed Aug 22 10:00:25.107676 2018] [wsgi:error] [pid 29737] [remote 83.149.21.22:17692] LINE 1: SELECT "online"."id", "online"."worker_id", "online"."queue_...
[Wed Aug 22 10:00:25.107687 2018] [wsgi:error] [pid 29737] [remote 83.149.21.22:17692]                                                     ^
[Wed Aug 22 10:00:25.107696 2018] [wsgi:error] [pid 29737] [remote 83.149.21.22:17692] 
[Wed Aug 22 10:00:25.495168 2018] [wsgi:error] [pid 29737] [remote 83.149.21.22:30778] mod_wsgi (pid=29737): Target WSGI script '/srv/http/virtlabs.tk/5koleso.tk/api.wsgi' cannot be loaded as Python module.
[Wed Aug 22 10:00:25.495530 2018] [wsgi:error] [pid 29737] [remote 83.149.21.22:30778] mod_wsgi (pid=29737): Exception occurred processing WSGI script '/srv/http/virtlabs.tk/5koleso.tk/api.wsgi'.
[Wed Aug 22 10:00:25.496488 2018] [wsgi:error] [pid 29737] [remote 83.149.21.22:30778] Traceback (most recent call last):
[Wed Aug 22 10:00:25.496650 2018] [wsgi:error] [pid 29737] [remote 83.149.21.22:30778]   File "/usr/lib/python3.6/site-packages/pony/orm/dbapiprovider.py", line 50, in wrap_dbapi_exceptions
[Wed Aug 22 10:00:25.496767 2018] [wsgi:error] [pid 29737] [remote 83.149.21.22:30778]     return func(provider, *args, **kwargs)
[Wed Aug 22 10:00:25.496802 2018] [wsgi:error] [pid 29737] [remote 83.149.21.22:30778]   File "/usr/lib/python3.6/site-packages/pony/orm/dbproviders/postgres.py", line 215, in execute
[Wed Aug 22 10:00:25.496817 2018] [wsgi:error] [pid 29737] [remote 83.149.21.22:30778]     if arguments is None: cursor.execute(sql)
[Wed Aug 22 10:00:25.496846 2018] [wsgi:error] [pid 29737] [remote 83.149.21.22:30778]   File "/usr/lib/python3.6/site-packages/psycopg2cffi/_impl/cursor.py", line 30, in check_closed_
[Wed Aug 22 10:00:25.496859 2018] [wsgi:error] [pid 29737] [remote 83.149.21.22:30778]     return func(self, *args, **kwargs)
[Wed Aug 22 10:00:25.496886 2018] [wsgi:error] [pid 29737] [remote 83.149.21.22:30778]   File "/usr/lib/python3.6/site-packages/psycopg2cffi/_impl/cursor.py", line 263, in execute
[Wed Aug 22 10:00:25.496899 2018] [wsgi:error] [pid 29737] [remote 83.149.21.22:30778]     self._pq_execute(self._query, conn._async)
[Wed Aug 22 10:00:25.496926 2018] [wsgi:error] [pid 29737] [remote 83.149.21.22:30778]   File "/usr/lib/python3.6/site-packages/psycopg2cffi/_impl/cursor.py", line 696, in _pq_execute
[Wed Aug 22 10:00:25.496939 2018] [wsgi:error] [pid 29737] [remote 83.149.21.22:30778]     self._pq_fetch()
[Wed Aug 22 10:00:25.496965 2018] [wsgi:error] [pid 29737] [remote 83.149.21.22:30778]   File "/usr/lib/python3.6/site-packages/psycopg2cffi/_impl/cursor.py", line 757, in _pq_fetch
[Wed Aug 22 10:00:25.496978 2018] [wsgi:error] [pid 29737] [remote 83.149.21.22:30778]     raise self._conn._create_exception(cursor=self)
[Wed Aug 22 10:00:25.497062 2018] [wsgi:error] [pid 29737] [remote 83.149.21.22:30778] psycopg2cffi._impl.exceptions.ProgrammingError: \xd0\x9e\xd0\xa8\xd0\x98\xd0\x91\xd0\x9a\xd0\x90:  \xd1\x81\xd1\x82\xd0\xbe\xd0\xbb\xd0\xb1\xd0\xb5\xd1\x86 online.queue_number \xd0\xbd\xd0\xb5 \xd1\x81\xd1\x83\xd1\x89\xd0\xb5\xd1\x81\xd1\x82\xd0\xb2\xd1\x83\xd0\xb5\xd1\x82
[Wed Aug 22 10:00:25.497080 2018] [wsgi:error] [pid 29737] [remote 83.149.21.22:30778] LINE 1: SELECT "online"."id", "online"."worker_id", "online"."queue_...
[Wed Aug 22 10:00:25.497091 2018] [wsgi:error] [pid 29737] [remote 83.149.21.22:30778]                                                     ^
[Wed Aug 22 10:00:25.497102 2018] [wsgi:error] [pid 29737] [remote 83.149.21.22:30778] 
[Wed Aug 22 10:00:25.497135 2018] [wsgi:error] [pid 29737] [remote 83.149.21.22:30778] 
[Wed Aug 22 10:00:25.497147 2018] [wsgi:error] [pid 29737] [remote 83.149.21.22:30778] During handling of the above exception, another exception occurred:
[Wed Aug 22 10:00:25.497157 2018] [wsgi:error] [pid 29737] [remote 83.149.21.22:30778] 
[Wed Aug 22 10:00:25.497184 2018] [wsgi:error] [pid 29737] [remote 83.149.21.22:30778] Traceback (most recent call last):
[Wed Aug 22 10:00:25.497363 2018] [wsgi:error] [pid 29737] [remote 83.149.21.22:30778]   File "/srv/http/virtlabs.tk/5koleso.tk/api.wsgi", line 1, in <module>
[Wed Aug 22 10:00:25.497378 2018] [wsgi:error] [pid 29737] [remote 83.149.21.22:30778]     from api import app as application
[Wed Aug 22 10:00:25.497405 2018] [wsgi:error] [pid 29737] [remote 83.149.21.22:30778]   File "/srv/http/virtlabs.tk/5koleso.tk/api.py", line 16, in <module>
[Wed Aug 22 10:00:25.497418 2018] [wsgi:error] [pid 29737] [remote 83.149.21.22:30778]     from initdb import Worker, Auth, Online, Taxi_order
[Wed Aug 22 10:00:25.497444 2018] [wsgi:error] [pid 29737] [remote 83.149.21.22:30778]   File "/srv/http/virtlabs.tk/5koleso.tk/initdb.py", line 40, in <module>
[Wed Aug 22 10:00:25.497458 2018] [wsgi:error] [pid 29737] [remote 83.149.21.22:30778]     _PostgresDb.generate_mapping(check_tables = True, create_tables = False)
[Wed Aug 22 10:00:25.497484 2018] [wsgi:error] [pid 29737] [remote 83.149.21.22:30778]   File "<string>", line 2, in generate_mapping
[Wed Aug 22 10:00:25.497512 2018] [wsgi:error] [pid 29737] [remote 83.149.21.22:30778]   File "/usr/lib/python3.6/site-packages/pony/utils/utils.py", line 58, in cut_traceback
[Wed Aug 22 10:00:25.497556 2018] [wsgi:error] [pid 29737] [remote 83.149.21.22:30778]     return func(*args, **kwargs)
[Wed Aug 22 10:00:25.497586 2018] [wsgi:error] [pid 29737] [remote 83.149.21.22:30778]   File "/usr/lib/python3.6/site-packages/pony/orm/core.py", line 996, in generate_mapping
[Wed Aug 22 10:00:25.497599 2018] [wsgi:error] [pid 29737] [remote 83.149.21.22:30778]     elif check_tables: database.check_tables()
[Wed Aug 22 10:00:25.497625 2018] [wsgi:error] [pid 29737] [remote 83.149.21.22:30778]   File "<string>", line 2, in check_tables
[Wed Aug 22 10:00:25.497654 2018] [wsgi:error] [pid 29737] [remote 83.149.21.22:30778]   File "/usr/lib/python3.6/site-packages/pony/utils/utils.py", line 58, in cut_traceback
[Wed Aug 22 10:00:25.497667 2018] [wsgi:error] [pid 29737] [remote 83.149.21.22:30778]     return func(*args, **kwargs)
[Wed Aug 22 10:00:25.497692 2018] [wsgi:error] [pid 29737] [remote 83.149.21.22:30778]   File "<string>", line 2, in check_tables
[Wed Aug 22 10:00:25.497720 2018] [wsgi:error] [pid 29737] [remote 83.149.21.22:30778]   File "/usr/lib/python3.6/site-packages/pony/orm/core.py", line 460, in new_func
[Wed Aug 22 10:00:25.497733 2018] [wsgi:error] [pid 29737] [remote 83.149.21.22:30778]     try: return func(*args, **kwargs)
[Wed Aug 22 10:00:25.497759 2018] [wsgi:error] [pid 29737] [remote 83.149.21.22:30778]   File "/usr/lib/python3.6/site-packages/pony/orm/core.py", line 1061, in check_tables
[Wed Aug 22 10:00:25.497772 2018] [wsgi:error] [pid 29737] [remote 83.149.21.22:30778]     database.schema.check_tables(database.provider, connection)
[Wed Aug 22 10:00:25.497798 2018] [wsgi:error] [pid 29737] [remote 83.149.21.22:30778]   File "/usr/lib/python3.6/site-packages/pony/orm/dbschema.py", line 77, in check_tables
[Wed Aug 22 10:00:25.497811 2018] [wsgi:error] [pid 29737] [remote 83.149.21.22:30778]     provider.execute(cursor, sql)
[Wed Aug 22 10:00:25.497836 2018] [wsgi:error] [pid 29737] [remote 83.149.21.22:30778]   File "<string>", line 2, in execute
[Wed Aug 22 10:00:25.497864 2018] [wsgi:error] [pid 29737] [remote 83.149.21.22:30778]   File "/usr/lib/python3.6/site-packages/pony/orm/dbapiprovider.py", line 56, in wrap_dbapi_exceptions
[Wed Aug 22 10:00:25.497878 2018] [wsgi:error] [pid 29737] [remote 83.149.21.22:30778]     except dbapi_module.ProgrammingError as e: raise ProgrammingError(e)
[Wed Aug 22 10:00:25.497931 2018] [wsgi:error] [pid 29737] [remote 83.149.21.22:30778] pony.orm.dbapiprovider.ProgrammingError: \xd0\x9e\xd0\xa8\xd0\x98\xd0\x91\xd0\x9a\xd0\x90:  \xd1\x81\xd1\x82\xd0\xbe\xd0\xbb\xd0\xb1\xd0\xb5\xd1\x86 online.queue_number \xd0\xbd\xd0\xb5 \xd1\x81\xd1\x83\xd1\x89\xd0\xb5\xd1\x81\xd1\x82\xd0\xb2\xd1\x83\xd0\xb5\xd1\x82
[Wed Aug 22 10:00:25.497947 2018] [wsgi:error] [pid 29737] [remote 83.149.21.22:30778] LINE 1: SELECT "online"."id", "online"."worker_id", "online"."queue_...
[Wed Aug 22 10:00:25.497958 2018] [wsgi:error] [pid 29737] [remote 83.149.21.22:30778]                                                     ^
[Wed Aug 22 10:00:25.497968 2018] [wsgi:error] [pid 29737] [remote 83.149.21.22:30778] 
[Wed Aug 22 10:01:10.547584 2018] [wsgi:error] [pid 29779] [remote 83.149.21.22:30723] mod_wsgi (pid=29779): Target WSGI script '/srv/http/virtlabs.tk/5koleso.tk/api.wsgi' cannot be loaded as Python module.
[Wed Aug 22 10:01:10.547917 2018] [wsgi:error] [pid 29779] [remote 83.149.21.22:30723] mod_wsgi (pid=29779): Exception occurred processing WSGI script '/srv/http/virtlabs.tk/5koleso.tk/api.wsgi'.
[Wed Aug 22 10:01:10.561079 2018] [wsgi:error] [pid 29779] [remote 83.149.21.22:30723] Traceback (most recent call last):
[Wed Aug 22 10:01:10.561326 2018] [wsgi:error] [pid 29779] [remote 83.149.21.22:30723]   File "/usr/lib/python3.6/site-packages/pony/orm/dbapiprovider.py", line 50, in wrap_dbapi_exceptions
[Wed Aug 22 10:01:10.561348 2018] [wsgi:error] [pid 29779] [remote 83.149.21.22:30723]     return func(provider, *args, **kwargs)
[Wed Aug 22 10:01:10.561378 2018] [wsgi:error] [pid 29779] [remote 83.149.21.22:30723]   File "/usr/lib/python3.6/site-packages/pony/orm/dbproviders/postgres.py", line 215, in execute
[Wed Aug 22 10:01:10.561494 2018] [wsgi:error] [pid 29779] [remote 83.149.21.22:30723]     if arguments is None: cursor.execute(sql)
[Wed Aug 22 10:01:10.561527 2018] [wsgi:error] [pid 29779] [remote 83.149.21.22:30723]   File "/usr/lib/python3.6/site-packages/psycopg2cffi/_impl/cursor.py", line 30, in check_closed_
[Wed Aug 22 10:01:10.561541 2018] [wsgi:error] [pid 29779] [remote 83.149.21.22:30723]     return func(self, *args, **kwargs)
[Wed Aug 22 10:01:10.561567 2018] [wsgi:error] [pid 29779] [remote 83.149.21.22:30723]   File "/usr/lib/python3.6/site-packages/psycopg2cffi/_impl/cursor.py", line 263, in execute
[Wed Aug 22 10:01:10.561580 2018] [wsgi:error] [pid 29779] [remote 83.149.21.22:30723]     self._pq_execute(self._query, conn._async)
[Wed Aug 22 10:01:10.561606 2018] [wsgi:error] [pid 29779] [remote 83.149.21.22:30723]   File "/usr/lib/python3.6/site-packages/psycopg2cffi/_impl/cursor.py", line 696, in _pq_execute
[Wed Aug 22 10:01:10.561620 2018] [wsgi:error] [pid 29779] [remote 83.149.21.22:30723]     self._pq_fetch()
[Wed Aug 22 10:01:10.561645 2018] [wsgi:error] [pid 29779] [remote 83.149.21.22:30723]   File "/usr/lib/python3.6/site-packages/psycopg2cffi/_impl/cursor.py", line 757, in _pq_fetch
[Wed Aug 22 10:01:10.561658 2018] [wsgi:error] [pid 29779] [remote 83.149.21.22:30723]     raise self._conn._create_exception(cursor=self)
[Wed Aug 22 10:01:10.561781 2018] [wsgi:error] [pid 29779] [remote 83.149.21.22:30723] psycopg2cffi._impl.exceptions.ProgrammingError: \xd0\x9e\xd0\xa8\xd0\x98\xd0\x91\xd0\x9a\xd0\x90:  \xd1\x81\xd1\x82\xd0\xbe\xd0\xbb\xd0\xb1\xd0\xb5\xd1\x86 online.queue_number \xd0\xbd\xd0\xb5 \xd1\x81\xd1\x83\xd1\x89\xd0\xb5\xd1\x81\xd1\x82\xd0\xb2\xd1\x83\xd0\xb5\xd1\x82
[Wed Aug 22 10:01:10.561799 2018] [wsgi:error] [pid 29779] [remote 83.149.21.22:30723] LINE 1: SELECT "online"."id", "online"."worker_id", "online"."queue_...
[Wed Aug 22 10:01:10.561810 2018] [wsgi:error] [pid 29779] [remote 83.149.21.22:30723]                                                     ^
[Wed Aug 22 10:01:10.561821 2018] [wsgi:error] [pid 29779] [remote 83.149.21.22:30723] 
[Wed Aug 22 10:01:10.561858 2018] [wsgi:error] [pid 29779] [remote 83.149.21.22:30723] 
[Wed Aug 22 10:01:10.561871 2018] [wsgi:error] [pid 29779] [remote 83.149.21.22:30723] During handling of the above exception, another exception occurred:
[Wed Aug 22 10:01:10.561881 2018] [wsgi:error] [pid 29779] [remote 83.149.21.22:30723] 
[Wed Aug 22 10:01:10.561906 2018] [wsgi:error] [pid 29779] [remote 83.149.21.22:30723] Traceback (most recent call last):
[Wed Aug 22 10:01:10.562245 2018] [wsgi:error] [pid 29779] [remote 83.149.21.22:30723]   File "/srv/http/virtlabs.tk/5koleso.tk/api.wsgi", line 1, in <module>
[Wed Aug 22 10:01:10.562268 2018] [wsgi:error] [pid 29779] [remote 83.149.21.22:30723]     from api import app as application
[Wed Aug 22 10:01:10.562296 2018] [wsgi:error] [pid 29779] [remote 83.149.21.22:30723]   File "/srv/http/virtlabs.tk/5koleso.tk/api.py", line 16, in <module>
[Wed Aug 22 10:01:10.562311 2018] [wsgi:error] [pid 29779] [remote 83.149.21.22:30723]     from initdb import Worker, Auth, Online, Taxi_order
[Wed Aug 22 10:01:10.562337 2018] [wsgi:error] [pid 29779] [remote 83.149.21.22:30723]   File "/srv/http/virtlabs.tk/5koleso.tk/initdb.py", line 40, in <module>
[Wed Aug 22 10:01:10.562350 2018] [wsgi:error] [pid 29779] [remote 83.149.21.22:30723]     _PostgresDb.generate_mapping(check_tables = True, create_tables = False)
[Wed Aug 22 10:01:10.562376 2018] [wsgi:error] [pid 29779] [remote 83.149.21.22:30723]   File "<string>", line 2, in generate_mapping
[Wed Aug 22 10:01:10.562404 2018] [wsgi:error] [pid 29779] [remote 83.149.21.22:30723]   File "/usr/lib/python3.6/site-packages/pony/utils/utils.py", line 58, in cut_traceback
[Wed Aug 22 10:01:10.562417 2018] [wsgi:error] [pid 29779] [remote 83.149.21.22:30723]     return func(*args, **kwargs)
[Wed Aug 22 10:01:10.562443 2018] [wsgi:error] [pid 29779] [remote 83.149.21.22:30723]   File "/usr/lib/python3.6/site-packages/pony/orm/core.py", line 996, in generate_mapping
[Wed Aug 22 10:01:10.562511 2018] [wsgi:error] [pid 29779] [remote 83.149.21.22:30723]     elif check_tables: database.check_tables()
[Wed Aug 22 10:01:10.562541 2018] [wsgi:error] [pid 29779] [remote 83.149.21.22:30723]   File "<string>", line 2, in check_tables
[Wed Aug 22 10:01:10.562570 2018] [wsgi:error] [pid 29779] [remote 83.149.21.22:30723]   File "/usr/lib/python3.6/site-packages/pony/utils/utils.py", line 58, in cut_traceback
[Wed Aug 22 10:01:10.562583 2018] [wsgi:error] [pid 29779] [remote 83.149.21.22:30723]     return func(*args, **kwargs)
[Wed Aug 22 10:01:10.562608 2018] [wsgi:error] [pid 29779] [remote 83.149.21.22:30723]   File "<string>", line 2, in check_tables
[Wed Aug 22 10:01:10.562636 2018] [wsgi:error] [pid 29779] [remote 83.149.21.22:30723]   File "/usr/lib/python3.6/site-packages/pony/orm/core.py", line 460, in new_func
[Wed Aug 22 10:01:10.562649 2018] [wsgi:error] [pid 29779] [remote 83.149.21.22:30723]     try: return func(*args, **kwargs)
[Wed Aug 22 10:01:10.562674 2018] [wsgi:error] [pid 29779] [remote 83.149.21.22:30723]   File "/usr/lib/python3.6/site-packages/pony/orm/core.py", line 1061, in check_tables
[Wed Aug 22 10:01:10.562687 2018] [wsgi:error] [pid 29779] [remote 83.149.21.22:30723]     database.schema.check_tables(database.provider, connection)
[Wed Aug 22 10:01:10.562712 2018] [wsgi:error] [pid 29779] [remote 83.149.21.22:30723]   File "/usr/lib/python3.6/site-packages/pony/orm/dbschema.py", line 77, in check_tables
[Wed Aug 22 10:01:10.562725 2018] [wsgi:error] [pid 29779] [remote 83.149.21.22:30723]     provider.execute(cursor, sql)
[Wed Aug 22 10:01:10.562749 2018] [wsgi:error] [pid 29779] [remote 83.149.21.22:30723]   File "<string>", line 2, in execute
[Wed Aug 22 10:01:10.562777 2018] [wsgi:error] [pid 29779] [remote 83.149.21.22:30723]   File "/usr/lib/python3.6/site-packages/pony/orm/dbapiprovider.py", line 56, in wrap_dbapi_exceptions
[Wed Aug 22 10:01:10.562791 2018] [wsgi:error] [pid 29779] [remote 83.149.21.22:30723]     except dbapi_module.ProgrammingError as e: raise ProgrammingError(e)
[Wed Aug 22 10:01:10.562867 2018] [wsgi:error] [pid 29779] [remote 83.149.21.22:30723] pony.orm.dbapiprovider.ProgrammingError: \xd0\x9e\xd0\xa8\xd0\x98\xd0\x91\xd0\x9a\xd0\x90:  \xd1\x81\xd1\x82\xd0\xbe\xd0\xbb\xd0\xb1\xd0\xb5\xd1\x86 online.queue_number \xd0\xbd\xd0\xb5 \xd1\x81\xd1\x83\xd1\x89\xd0\xb5\xd1\x81\xd1\x82\xd0\xb2\xd1\x83\xd0\xb5\xd1\x82
[Wed Aug 22 10:01:10.562885 2018] [wsgi:error] [pid 29779] [remote 83.149.21.22:30723] LINE 1: SELECT "online"."id", "online"."worker_id", "online"."queue_...
[Wed Aug 22 10:01:10.562895 2018] [wsgi:error] [pid 29779] [remote 83.149.21.22:30723]                                                     ^
[Wed Aug 22 10:01:10.562905 2018] [wsgi:error] [pid 29779] [remote 83.149.21.22:30723] 
[Wed Aug 22 11:20:18.181405 2018] [wsgi:error] [pid 29829] [remote 176.59.104.106:29391] [2018-08-22 11:20:18,176] ERROR in app: Exception on /work/check_worker [POST]
[Wed Aug 22 11:20:18.182324 2018] [wsgi:error] [pid 29829] [remote 176.59.104.106:29391] Traceback (most recent call last):
[Wed Aug 22 11:20:18.182351 2018] [wsgi:error] [pid 29829] [remote 176.59.104.106:29391]   File "/usr/lib/python3.6/site-packages/flask/app.py", line 1982, in wsgi_app
[Wed Aug 22 11:20:18.182366 2018] [wsgi:error] [pid 29829] [remote 176.59.104.106:29391]     response = self.full_dispatch_request()
[Wed Aug 22 11:20:18.182376 2018] [wsgi:error] [pid 29829] [remote 176.59.104.106:29391]   File "/usr/lib/python3.6/site-packages/flask/app.py", line 1614, in full_dispatch_request
[Wed Aug 22 11:20:18.182387 2018] [wsgi:error] [pid 29829] [remote 176.59.104.106:29391]     rv = self.handle_user_exception(e)
[Wed Aug 22 11:20:18.182397 2018] [wsgi:error] [pid 29829] [remote 176.59.104.106:29391]   File "/usr/lib/python3.6/site-packages/flask/app.py", line 1517, in handle_user_exception
[Wed Aug 22 11:20:18.182408 2018] [wsgi:error] [pid 29829] [remote 176.59.104.106:29391]     reraise(exc_type, exc_value, tb)
[Wed Aug 22 11:20:18.182527 2018] [wsgi:error] [pid 29829] [remote 176.59.104.106:29391]   File "/usr/lib/python3.6/site-packages/flask/_compat.py", line 33, in reraise
[Wed Aug 22 11:20:18.182542 2018] [wsgi:error] [pid 29829] [remote 176.59.104.106:29391]     raise value
[Wed Aug 22 11:20:18.182553 2018] [wsgi:error] [pid 29829] [remote 176.59.104.106:29391]   File "/usr/lib/python3.6/site-packages/flask/app.py", line 1612, in full_dispatch_request
[Wed Aug 22 11:20:18.182563 2018] [wsgi:error] [pid 29829] [remote 176.59.104.106:29391]     rv = self.dispatch_request()
[Wed Aug 22 11:20:18.182573 2018] [wsgi:error] [pid 29829] [remote 176.59.104.106:29391]   File "/usr/lib/python3.6/site-packages/flask/app.py", line 1598, in dispatch_request
[Wed Aug 22 11:20:18.182588 2018] [wsgi:error] [pid 29829] [remote 176.59.104.106:29391]     return self.view_functions[rule.endpoint](**req.view_args)
[Wed Aug 22 11:20:18.182599 2018] [wsgi:error] [pid 29829] [remote 176.59.104.106:29391]   File "/srv/http/virtlabs.tk/5koleso.tk/worker.py", line 53, in check_worker
[Wed Aug 22 11:20:18.182610 2018] [wsgi:error] [pid 29829] [remote 176.59.104.106:29391]     commit()
[Wed Aug 22 11:20:18.182638 2018] [wsgi:error] [pid 29829] [remote 176.59.104.106:29391] NameError: name 'commit' is not defined
[Wed Aug 22 11:20:18.182818 2018] [wsgi:error] [pid 29829] [remote 176.59.104.106:29391] 
[Wed Aug 22 11:20:18.219033 2018] [wsgi:error] [pid 29829] [remote 176.59.104.106:29391] --- Logging error ---
[Wed Aug 22 11:20:18.224091 2018] [wsgi:error] [pid 29829] [remote 176.59.104.106:29391] Traceback (most recent call last):
[Wed Aug 22 11:20:18.224352 2018] [wsgi:error] [pid 29829] [remote 176.59.104.106:29391]   File "/usr/lib/python3.6/site-packages/flask/app.py", line 1982, in wsgi_app
[Wed Aug 22 11:20:18.224371 2018] [wsgi:error] [pid 29829] [remote 176.59.104.106:29391]     response = self.full_dispatch_request()
[Wed Aug 22 11:20:18.224401 2018] [wsgi:error] [pid 29829] [remote 176.59.104.106:29391]   File "/usr/lib/python3.6/site-packages/flask/app.py", line 1614, in full_dispatch_request
[Wed Aug 22 11:20:18.224417 2018] [wsgi:error] [pid 29829] [remote 176.59.104.106:29391]     rv = self.handle_user_exception(e)
[Wed Aug 22 11:20:18.224445 2018] [wsgi:error] [pid 29829] [remote 176.59.104.106:29391]   File "/usr/lib/python3.6/site-packages/flask/app.py", line 1517, in handle_user_exception
[Wed Aug 22 11:20:18.224458 2018] [wsgi:error] [pid 29829] [remote 176.59.104.106:29391]     reraise(exc_type, exc_value, tb)
[Wed Aug 22 11:20:18.224485 2018] [wsgi:error] [pid 29829] [remote 176.59.104.106:29391]   File "/usr/lib/python3.6/site-packages/flask/_compat.py", line 33, in reraise
[Wed Aug 22 11:20:18.224498 2018] [wsgi:error] [pid 29829] [remote 176.59.104.106:29391]     raise value
[Wed Aug 22 11:20:18.224525 2018] [wsgi:error] [pid 29829] [remote 176.59.104.106:29391]   File "/usr/lib/python3.6/site-packages/flask/app.py", line 1612, in full_dispatch_request
[Wed Aug 22 11:20:18.224538 2018] [wsgi:error] [pid 29829] [remote 176.59.104.106:29391]     rv = self.dispatch_request()
[Wed Aug 22 11:20:18.224565 2018] [wsgi:error] [pid 29829] [remote 176.59.104.106:29391]   File "/usr/lib/python3.6/site-packages/flask/app.py", line 1598, in dispatch_request
[Wed Aug 22 11:20:18.224579 2018] [wsgi:error] [pid 29829] [remote 176.59.104.106:29391]     return self.view_functions[rule.endpoint](**req.view_args)
[Wed Aug 22 11:20:18.224605 2018] [wsgi:error] [pid 29829] [remote 176.59.104.106:29391]   File "/srv/http/virtlabs.tk/5koleso.tk/worker.py", line 53, in check_worker
[Wed Aug 22 11:20:18.224619 2018] [wsgi:error] [pid 29829] [remote 176.59.104.106:29391]     commit()
[Wed Aug 22 11:20:18.224680 2018] [wsgi:error] [pid 29829] [remote 176.59.104.106:29391] NameError: name 'commit' is not defined
[Wed Aug 22 11:20:18.224730 2018] [wsgi:error] [pid 29829] [remote 176.59.104.106:29391] 
[Wed Aug 22 11:20:18.224743 2018] [wsgi:error] [pid 29829] [remote 176.59.104.106:29391] During handling of the above exception, another exception occurred:
[Wed Aug 22 11:20:18.226134 2018] [wsgi:error] [pid 29829] [remote 176.59.104.106:29391] 
[Wed Aug 22 11:20:18.226331 2018] [wsgi:error] [pid 29829] [remote 176.59.104.106:29391] Traceback (most recent call last):
[Wed Aug 22 11:20:18.226509 2018] [wsgi:error] [pid 29829] [remote 176.59.104.106:29391]   File "/usr/lib/python3.6/logging/handlers.py", line 1010, in emit
[Wed Aug 22 11:20:18.226527 2018] [wsgi:error] [pid 29829] [remote 176.59.104.106:29391]     smtp = smtplib.SMTP(self.mailhost, port, timeout=self.timeout)
[Wed Aug 22 11:20:18.226559 2018] [wsgi:error] [pid 29829] [remote 176.59.104.106:29391]   File "/usr/lib/python3.6/smtplib.py", line 251, in __init__
[Wed Aug 22 11:20:18.226572 2018] [wsgi:error] [pid 29829] [remote 176.59.104.106:29391]     (code, msg) = self.connect(host, port)
[Wed Aug 22 11:20:18.226600 2018] [wsgi:error] [pid 29829] [remote 176.59.104.106:29391]   File "/usr/lib/python3.6/smtplib.py", line 336, in connect
[Wed Aug 22 11:20:18.226614 2018] [wsgi:error] [pid 29829] [remote 176.59.104.106:29391]     self.sock = self._get_socket(host, port, self.timeout)
[Wed Aug 22 11:20:18.226641 2018] [wsgi:error] [pid 29829] [remote 176.59.104.106:29391]   File "/usr/lib/python3.6/smtplib.py", line 307, in _get_socket
[Wed Aug 22 11:20:18.226655 2018] [wsgi:error] [pid 29829] [remote 176.59.104.106:29391]     self.source_address)
[Wed Aug 22 11:20:18.226682 2018] [wsgi:error] [pid 29829] [remote 176.59.104.106:29391]   File "/usr/lib/python3.6/socket.py", line 704, in create_connection
[Wed Aug 22 11:20:18.226695 2018] [wsgi:error] [pid 29829] [remote 176.59.104.106:29391]     for res in getaddrinfo(host, port, 0, SOCK_STREAM):
[Wed Aug 22 11:20:18.226722 2018] [wsgi:error] [pid 29829] [remote 176.59.104.106:29391]   File "/usr/lib/python3.6/socket.py", line 745, in getaddrinfo
[Wed Aug 22 11:20:18.226735 2018] [wsgi:error] [pid 29829] [remote 176.59.104.106:29391]     for res in _socket.getaddrinfo(host, port, family, type, proto, flags):
[Wed Aug 22 11:20:18.226818 2018] [wsgi:error] [pid 29829] [remote 176.59.104.106:29391] socket.gaierror: [Errno -2] Name or service not known
[Wed Aug 22 11:20:18.226887 2018] [wsgi:error] [pid 29829] [remote 176.59.104.106:29391] Call stack:
[Wed Aug 22 11:20:18.227552 2018] [wsgi:error] [pid 29829] [remote 176.59.104.106:29391]   File "/usr/lib/python3.6/site-packages/flask/app.py", line 1997, in __call__
[Wed Aug 22 11:20:18.227599 2018] [wsgi:error] [pid 29829] [remote 176.59.104.106:29391]     return self.wsgi_app(environ, start_response)
[Wed Aug 22 11:20:18.227632 2018] [wsgi:error] [pid 29829] [remote 176.59.104.106:29391]   File "/usr/lib/python3.6/site-packages/flask/app.py", line 1985, in wsgi_app
[Wed Aug 22 11:20:18.227647 2018] [wsgi:error] [pid 29829] [remote 176.59.104.106:29391]     response = self.handle_exception(e)
[Wed Aug 22 11:20:18.227687 2018] [wsgi:error] [pid 29829] [remote 176.59.104.106:29391]   File "/usr/lib/python3.6/site-packages/flask/app.py", line 1544, in handle_exception
[Wed Aug 22 11:20:18.227703 2018] [wsgi:error] [pid 29829] [remote 176.59.104.106:29391]     self.log_exception((exc_type, exc_value, tb))
[Wed Aug 22 11:20:18.227743 2018] [wsgi:error] [pid 29829] [remote 176.59.104.106:29391]   File "/usr/lib/python3.6/site-packages/flask/app.py", line 1560, in log_exception
[Wed Aug 22 11:20:18.227759 2018] [wsgi:error] [pid 29829] [remote 176.59.104.106:29391]     ), exc_info=exc_info)
[Wed Aug 22 11:20:18.227818 2018] [wsgi:error] [pid 29829] [remote 176.59.104.106:29391] Message: 'Exception on /work/check_worker [POST]'
[Wed Aug 22 11:20:18.227833 2018] [wsgi:error] [pid 29829] [remote 176.59.104.106:29391] Arguments: ()
[Mon Sep 24 15:58:04.601737 2018] [wsgi:error] [pid 15401] [remote 176.59.98.114:59025] mod_wsgi (pid=15401): Target WSGI script '/srv/http/virtlabs.tk/5koleso.tk/api.wsgi' cannot be loaded as Python module.
[Mon Sep 24 15:58:04.602094 2018] [wsgi:error] [pid 15401] [remote 176.59.98.114:59025] mod_wsgi (pid=15401): Exception occurred processing WSGI script '/srv/http/virtlabs.tk/5koleso.tk/api.wsgi'.
[Mon Sep 24 15:58:04.621062 2018] [wsgi:error] [pid 15401] [remote 176.59.98.114:59025] Traceback (most recent call last):
[Mon Sep 24 15:58:04.621227 2018] [wsgi:error] [pid 15401] [remote 176.59.98.114:59025]   File "/srv/http/virtlabs.tk/5koleso.tk/api.wsgi", line 1, in <module>
[Mon Sep 24 15:58:04.621248 2018] [wsgi:error] [pid 15401] [remote 176.59.98.114:59025]     from api import app as application
[Mon Sep 24 15:58:04.621278 2018] [wsgi:error] [pid 15401] [remote 176.59.98.114:59025]   File "/srv/http/virtlabs.tk/5koleso.tk/api.py", line 54, in <module>
[Mon Sep 24 15:58:04.621291 2018] [wsgi:error] [pid 15401] [remote 176.59.98.114:59025]     from worker import *
[Mon Sep 24 15:58:04.621357 2018] [wsgi:error] [pid 15401] [remote 176.59.98.114:59025]   File "/srv/http/virtlabs.tk/5koleso.tk/worker.py", line 205
[Mon Sep 24 15:58:04.621633 2018] [wsgi:error] [pid 15401] [remote 176.59.98.114:59025]     f = os.path.join(app.root_path, 'static', 'sound', 'free.mp3')
[Mon Sep 24 15:58:04.621730 2018] [wsgi:error] [pid 15401] [remote 176.59.98.114:59025]     ^
[Mon Sep 24 15:58:04.621767 2018] [wsgi:error] [pid 15401] [remote 176.59.98.114:59025] IndentationError: unexpected indent
[Mon Sep 24 16:04:49.292276 2018] [wsgi:error] [pid 15401] [remote 176.59.98.114:27835] mod_wsgi (pid=15401): Target WSGI script '/srv/http/virtlabs.tk/5koleso.tk/api.wsgi' cannot be loaded as Python module.
[Mon Sep 24 16:04:49.292599 2018] [wsgi:error] [pid 15401] [remote 176.59.98.114:27835] mod_wsgi (pid=15401): Exception occurred processing WSGI script '/srv/http/virtlabs.tk/5koleso.tk/api.wsgi'.
[Mon Sep 24 16:04:49.293026 2018] [wsgi:error] [pid 15401] [remote 176.59.98.114:27835] Traceback (most recent call last):
[Mon Sep 24 16:04:49.293138 2018] [wsgi:error] [pid 15401] [remote 176.59.98.114:27835]   File "/srv/http/virtlabs.tk/5koleso.tk/api.wsgi", line 1, in <module>
[Mon Sep 24 16:04:49.293156 2018] [wsgi:error] [pid 15401] [remote 176.59.98.114:27835]     from api import app as application
[Mon Sep 24 16:04:49.293186 2018] [wsgi:error] [pid 15401] [remote 176.59.98.114:27835]   File "/srv/http/virtlabs.tk/5koleso.tk/api.py", line 54, in <module>
[Mon Sep 24 16:04:49.293200 2018] [wsgi:error] [pid 15401] [remote 176.59.98.114:27835]     from worker import *
[Mon Sep 24 16:04:49.293252 2018] [wsgi:error] [pid 15401] [remote 176.59.98.114:27835]   File "/srv/http/virtlabs.tk/5koleso.tk/worker.py", line 205
[Mon Sep 24 16:04:49.293289 2018] [wsgi:error] [pid 15401] [remote 176.59.98.114:27835]     f = os.path.join(app.root_path, 'static', 'sound', 'free.mp3')
[Mon Sep 24 16:04:49.293373 2018] [wsgi:error] [pid 15401] [remote 176.59.98.114:27835]     ^
[Mon Sep 24 16:04:49.293407 2018] [wsgi:error] [pid 15401] [remote 176.59.98.114:27835] IndentationError: unexpected indent
[Mon Sep 24 16:04:49.522681 2018] [wsgi:error] [pid 15401] [remote 176.59.98.114:2960] mod_wsgi (pid=15401): Target WSGI script '/srv/http/virtlabs.tk/5koleso.tk/api.wsgi' cannot be loaded as Python module.
[Mon Sep 24 16:04:49.522939 2018] [wsgi:error] [pid 15401] [remote 176.59.98.114:2960] mod_wsgi (pid=15401): Exception occurred processing WSGI script '/srv/http/virtlabs.tk/5koleso.tk/api.wsgi'.
[Mon Sep 24 16:04:49.523364 2018] [wsgi:error] [pid 15401] [remote 176.59.98.114:2960] Traceback (most recent call last):
[Mon Sep 24 16:04:49.523468 2018] [wsgi:error] [pid 15401] [remote 176.59.98.114:2960]   File "/srv/http/virtlabs.tk/5koleso.tk/api.wsgi", line 1, in <module>
[Mon Sep 24 16:04:49.523486 2018] [wsgi:error] [pid 15401] [remote 176.59.98.114:2960]     from api import app as application
[Mon Sep 24 16:04:49.523516 2018] [wsgi:error] [pid 15401] [remote 176.59.98.114:2960]   File "/srv/http/virtlabs.tk/5koleso.tk/api.py", line 54, in <module>
[Mon Sep 24 16:04:49.523529 2018] [wsgi:error] [pid 15401] [remote 176.59.98.114:2960]     from worker import *
[Mon Sep 24 16:04:49.523581 2018] [wsgi:error] [pid 15401] [remote 176.59.98.114:2960]   File "/srv/http/virtlabs.tk/5koleso.tk/worker.py", line 205
[Mon Sep 24 16:04:49.523734 2018] [wsgi:error] [pid 15401] [remote 176.59.98.114:2960]     f = os.path.join(app.root_path, 'static', 'sound', 'free.mp3')
[Mon Sep 24 16:04:49.523810 2018] [wsgi:error] [pid 15401] [remote 176.59.98.114:2960]     ^
[Mon Sep 24 16:04:49.523844 2018] [wsgi:error] [pid 15401] [remote 176.59.98.114:2960] IndentationError: unexpected indent
[Mon Sep 24 16:04:52.792830 2018] [wsgi:error] [pid 15401] [remote 176.59.98.114:39282] mod_wsgi (pid=15401): Target WSGI script '/srv/http/virtlabs.tk/5koleso.tk/api.wsgi' cannot be loaded as Python module.
[Mon Sep 24 16:04:52.793107 2018] [wsgi:error] [pid 15401] [remote 176.59.98.114:39282] mod_wsgi (pid=15401): Exception occurred processing WSGI script '/srv/http/virtlabs.tk/5koleso.tk/api.wsgi'.
[Mon Sep 24 16:04:52.793512 2018] [wsgi:error] [pid 15401] [remote 176.59.98.114:39282] Traceback (most recent call last):
[Mon Sep 24 16:04:52.793610 2018] [wsgi:error] [pid 15401] [remote 176.59.98.114:39282]   File "/srv/http/virtlabs.tk/5koleso.tk/api.wsgi", line 1, in <module>
[Mon Sep 24 16:04:52.793629 2018] [wsgi:error] [pid 15401] [remote 176.59.98.114:39282]     from api import app as application
[Mon Sep 24 16:04:52.793658 2018] [wsgi:error] [pid 15401] [remote 176.59.98.114:39282]   File "/srv/http/virtlabs.tk/5koleso.tk/api.py", line 54, in <module>
[Mon Sep 24 16:04:52.793672 2018] [wsgi:error] [pid 15401] [remote 176.59.98.114:39282]     from worker import *
[Mon Sep 24 16:04:52.793723 2018] [wsgi:error] [pid 15401] [remote 176.59.98.114:39282]   File "/srv/http/virtlabs.tk/5koleso.tk/worker.py", line 205
[Mon Sep 24 16:04:52.793760 2018] [wsgi:error] [pid 15401] [remote 176.59.98.114:39282]     f = os.path.join(app.root_path, 'static', 'sound', 'free.mp3')
[Mon Sep 24 16:04:52.793827 2018] [wsgi:error] [pid 15401] [remote 176.59.98.114:39282]     ^
[Mon Sep 24 16:04:52.793860 2018] [wsgi:error] [pid 15401] [remote 176.59.98.114:39282] IndentationError: unexpected indent
[Mon Sep 24 16:04:56.032234 2018] [wsgi:error] [pid 15401] [remote 176.59.98.114:64023] mod_wsgi (pid=15401): Target WSGI script '/srv/http/virtlabs.tk/5koleso.tk/api.wsgi' cannot be loaded as Python module.
[Mon Sep 24 16:04:56.032551 2018] [wsgi:error] [pid 15401] [remote 176.59.98.114:64023] mod_wsgi (pid=15401): Exception occurred processing WSGI script '/srv/http/virtlabs.tk/5koleso.tk/api.wsgi'.
[Mon Sep 24 16:04:56.032978 2018] [wsgi:error] [pid 15401] [remote 176.59.98.114:64023] Traceback (most recent call last):
[Mon Sep 24 16:04:56.033081 2018] [wsgi:error] [pid 15401] [remote 176.59.98.114:64023]   File "/srv/http/virtlabs.tk/5koleso.tk/api.wsgi", line 1, in <module>
[Mon Sep 24 16:04:56.033100 2018] [wsgi:error] [pid 15401] [remote 176.59.98.114:64023]     from api import app as application
[Mon Sep 24 16:04:56.033129 2018] [wsgi:error] [pid 15401] [remote 176.59.98.114:64023]   File "/srv/http/virtlabs.tk/5koleso.tk/api.py", line 54, in <module>
[Mon Sep 24 16:04:56.033143 2018] [wsgi:error] [pid 15401] [remote 176.59.98.114:64023]     from worker import *
[Mon Sep 24 16:04:56.033196 2018] [wsgi:error] [pid 15401] [remote 176.59.98.114:64023]   File "/srv/http/virtlabs.tk/5koleso.tk/worker.py", line 205
[Mon Sep 24 16:04:56.033233 2018] [wsgi:error] [pid 15401] [remote 176.59.98.114:64023]     f = os.path.join(app.root_path, 'static', 'sound', 'free.mp3')
[Mon Sep 24 16:04:56.033305 2018] [wsgi:error] [pid 15401] [remote 176.59.98.114:64023]     ^
[Mon Sep 24 16:04:56.033340 2018] [wsgi:error] [pid 15401] [remote 176.59.98.114:64023] IndentationError: unexpected indent
[Mon Sep 24 16:04:59.275097 2018] [wsgi:error] [pid 15401] [remote 176.59.98.114:57603] mod_wsgi (pid=15401): Target WSGI script '/srv/http/virtlabs.tk/5koleso.tk/api.wsgi' cannot be loaded as Python module.
[Mon Sep 24 16:04:59.275389 2018] [wsgi:error] [pid 15401] [remote 176.59.98.114:57603] mod_wsgi (pid=15401): Exception occurred processing WSGI script '/srv/http/virtlabs.tk/5koleso.tk/api.wsgi'.
[Mon Sep 24 16:04:59.275815 2018] [wsgi:error] [pid 15401] [remote 176.59.98.114:57603] Traceback (most recent call last):
[Mon Sep 24 16:04:59.276064 2018] [wsgi:error] [pid 15401] [remote 176.59.98.114:57603]   File "/srv/http/virtlabs.tk/5koleso.tk/api.wsgi", line 1, in <module>
[Mon Sep 24 16:04:59.276084 2018] [wsgi:error] [pid 15401] [remote 176.59.98.114:57603]     from api import app as application
[Mon Sep 24 16:04:59.276115 2018] [wsgi:error] [pid 15401] [remote 176.59.98.114:57603]   File "/srv/http/virtlabs.tk/5koleso.tk/api.py", line 54, in <module>
[Mon Sep 24 16:04:59.276129 2018] [wsgi:error] [pid 15401] [remote 176.59.98.114:57603]     from worker import *
[Mon Sep 24 16:04:59.276185 2018] [wsgi:error] [pid 15401] [remote 176.59.98.114:57603]   File "/srv/http/virtlabs.tk/5koleso.tk/worker.py", line 205
[Mon Sep 24 16:04:59.276222 2018] [wsgi:error] [pid 15401] [remote 176.59.98.114:57603]     f = os.path.join(app.root_path, 'static', 'sound', 'free.mp3')
[Mon Sep 24 16:04:59.276295 2018] [wsgi:error] [pid 15401] [remote 176.59.98.114:57603]     ^
[Mon Sep 24 16:04:59.276329 2018] [wsgi:error] [pid 15401] [remote 176.59.98.114:57603] IndentationError: unexpected indent
[Mon Sep 24 16:05:02.502817 2018] [wsgi:error] [pid 15401] [remote 176.59.98.114:38858] mod_wsgi (pid=15401): Target WSGI script '/srv/http/virtlabs.tk/5koleso.tk/api.wsgi' cannot be loaded as Python module.
[Mon Sep 24 16:05:02.503139 2018] [wsgi:error] [pid 15401] [remote 176.59.98.114:38858] mod_wsgi (pid=15401): Exception occurred processing WSGI script '/srv/http/virtlabs.tk/5koleso.tk/api.wsgi'.
[Mon Sep 24 16:05:02.503566 2018] [wsgi:error] [pid 15401] [remote 176.59.98.114:38858] Traceback (most recent call last):
[Mon Sep 24 16:05:02.503669 2018] [wsgi:error] [pid 15401] [remote 176.59.98.114:38858]   File "/srv/http/virtlabs.tk/5koleso.tk/api.wsgi", line 1, in <module>
[Mon Sep 24 16:05:02.503687 2018] [wsgi:error] [pid 15401] [remote 176.59.98.114:38858]     from api import app as application
[Mon Sep 24 16:05:02.503717 2018] [wsgi:error] [pid 15401] [remote 176.59.98.114:38858]   File "/srv/http/virtlabs.tk/5koleso.tk/api.py", line 54, in <module>
[Mon Sep 24 16:05:02.503730 2018] [wsgi:error] [pid 15401] [remote 176.59.98.114:38858]     from worker import *
[Mon Sep 24 16:05:02.503785 2018] [wsgi:error] [pid 15401] [remote 176.59.98.114:38858]   File "/srv/http/virtlabs.tk/5koleso.tk/worker.py", line 205
[Mon Sep 24 16:05:02.503821 2018] [wsgi:error] [pid 15401] [remote 176.59.98.114:38858]     f = os.path.join(app.root_path, 'static', 'sound', 'free.mp3')
[Mon Sep 24 16:05:02.503894 2018] [wsgi:error] [pid 15401] [remote 176.59.98.114:38858]     ^
[Mon Sep 24 16:05:02.503927 2018] [wsgi:error] [pid 15401] [remote 176.59.98.114:38858] IndentationError: unexpected indent
[Mon Sep 24 16:05:05.731716 2018] [wsgi:error] [pid 15401] [remote 176.59.98.114:50666] mod_wsgi (pid=15401): Target WSGI script '/srv/http/virtlabs.tk/5koleso.tk/api.wsgi' cannot be loaded as Python module.
[Mon Sep 24 16:05:05.732004 2018] [wsgi:error] [pid 15401] [remote 176.59.98.114:50666] mod_wsgi (pid=15401): Exception occurred processing WSGI script '/srv/http/virtlabs.tk/5koleso.tk/api.wsgi'.
[Mon Sep 24 16:05:05.732422 2018] [wsgi:error] [pid 15401] [remote 176.59.98.114:50666] Traceback (most recent call last):
[Mon Sep 24 16:05:05.732524 2018] [wsgi:error] [pid 15401] [remote 176.59.98.114:50666]   File "/srv/http/virtlabs.tk/5koleso.tk/api.wsgi", line 1, in <module>
[Mon Sep 24 16:05:05.732542 2018] [wsgi:error] [pid 15401] [remote 176.59.98.114:50666]     from api import app as application
[Mon Sep 24 16:05:05.732573 2018] [wsgi:error] [pid 15401] [remote 176.59.98.114:50666]   File "/srv/http/virtlabs.tk/5koleso.tk/api.py", line 54, in <module>
[Mon Sep 24 16:05:05.732587 2018] [wsgi:error] [pid 15401] [remote 176.59.98.114:50666]     from worker import *
[Mon Sep 24 16:05:05.732639 2018] [wsgi:error] [pid 15401] [remote 176.59.98.114:50666]   File "/srv/http/virtlabs.tk/5koleso.tk/worker.py", line 205
[Mon Sep 24 16:05:05.732677 2018] [wsgi:error] [pid 15401] [remote 176.59.98.114:50666]     f = os.path.join(app.root_path, 'static', 'sound', 'free.mp3')
[Mon Sep 24 16:05:05.732861 2018] [wsgi:error] [pid 15401] [remote 176.59.98.114:50666]     ^
[Mon Sep 24 16:05:05.732898 2018] [wsgi:error] [pid 15401] [remote 176.59.98.114:50666] IndentationError: unexpected indent
[Mon Sep 24 16:05:08.975133 2018] [wsgi:error] [pid 15401] [remote 176.59.98.114:59973] mod_wsgi (pid=15401): Target WSGI script '/srv/http/virtlabs.tk/5koleso.tk/api.wsgi' cannot be loaded as Python module.
[Mon Sep 24 16:05:08.975440 2018] [wsgi:error] [pid 15401] [remote 176.59.98.114:59973] mod_wsgi (pid=15401): Exception occurred processing WSGI script '/srv/http/virtlabs.tk/5koleso.tk/api.wsgi'.
[Mon Sep 24 16:05:08.975861 2018] [wsgi:error] [pid 15401] [remote 176.59.98.114:59973] Traceback (most recent call last):
[Mon Sep 24 16:05:08.975964 2018] [wsgi:error] [pid 15401] [remote 176.59.98.114:59973]   File "/srv/http/virtlabs.tk/5koleso.tk/api.wsgi", line 1, in <module>
[Mon Sep 24 16:05:08.975982 2018] [wsgi:error] [pid 15401] [remote 176.59.98.114:59973]     from api import app as application
[Mon Sep 24 16:05:08.976013 2018] [wsgi:error] [pid 15401] [remote 176.59.98.114:59973]   File "/srv/http/virtlabs.tk/5koleso.tk/api.py", line 54, in <module>
[Mon Sep 24 16:05:08.976026 2018] [wsgi:error] [pid 15401] [remote 176.59.98.114:59973]     from worker import *
[Mon Sep 24 16:05:08.976078 2018] [wsgi:error] [pid 15401] [remote 176.59.98.114:59973]   File "/srv/http/virtlabs.tk/5koleso.tk/worker.py", line 205
[Mon Sep 24 16:05:08.976114 2018] [wsgi:error] [pid 15401] [remote 176.59.98.114:59973]     f = os.path.join(app.root_path, 'static', 'sound', 'free.mp3')
[Mon Sep 24 16:05:08.976185 2018] [wsgi:error] [pid 15401] [remote 176.59.98.114:59973]     ^
[Mon Sep 24 16:05:08.976219 2018] [wsgi:error] [pid 15401] [remote 176.59.98.114:59973] IndentationError: unexpected indent
[Mon Sep 24 16:05:12.222703 2018] [wsgi:error] [pid 15401] [remote 176.59.98.114:47059] mod_wsgi (pid=15401): Target WSGI script '/srv/http/virtlabs.tk/5koleso.tk/api.wsgi' cannot be loaded as Python module.
[Mon Sep 24 16:05:12.222998 2018] [wsgi:error] [pid 15401] [remote 176.59.98.114:47059] mod_wsgi (pid=15401): Exception occurred processing WSGI script '/srv/http/virtlabs.tk/5koleso.tk/api.wsgi'.
[Mon Sep 24 16:05:12.223426 2018] [wsgi:error] [pid 15401] [remote 176.59.98.114:47059] Traceback (most recent call last):
[Mon Sep 24 16:05:12.223527 2018] [wsgi:error] [pid 15401] [remote 176.59.98.114:47059]   File "/srv/http/virtlabs.tk/5koleso.tk/api.wsgi", line 1, in <module>
[Mon Sep 24 16:05:12.223544 2018] [wsgi:error] [pid 15401] [remote 176.59.98.114:47059]     from api import app as application
[Mon Sep 24 16:05:12.223574 2018] [wsgi:error] [pid 15401] [remote 176.59.98.114:47059]   File "/srv/http/virtlabs.tk/5koleso.tk/api.py", line 54, in <module>
[Mon Sep 24 16:05:12.223589 2018] [wsgi:error] [pid 15401] [remote 176.59.98.114:47059]     from worker import *
[Mon Sep 24 16:05:12.223641 2018] [wsgi:error] [pid 15401] [remote 176.59.98.114:47059]   File "/srv/http/virtlabs.tk/5koleso.tk/worker.py", line 205
[Mon Sep 24 16:05:12.223677 2018] [wsgi:error] [pid 15401] [remote 176.59.98.114:47059]     f = os.path.join(app.root_path, 'static', 'sound', 'free.mp3')
[Mon Sep 24 16:05:12.223748 2018] [wsgi:error] [pid 15401] [remote 176.59.98.114:47059]     ^
[Mon Sep 24 16:05:12.223782 2018] [wsgi:error] [pid 15401] [remote 176.59.98.114:47059] IndentationError: unexpected indent
[Mon Sep 24 16:05:15.451916 2018] [wsgi:error] [pid 15401] [remote 176.59.98.114:34097] mod_wsgi (pid=15401): Target WSGI script '/srv/http/virtlabs.tk/5koleso.tk/api.wsgi' cannot be loaded as Python module.
[Mon Sep 24 16:05:15.452217 2018] [wsgi:error] [pid 15401] [remote 176.59.98.114:34097] mod_wsgi (pid=15401): Exception occurred processing WSGI script '/srv/http/virtlabs.tk/5koleso.tk/api.wsgi'.
[Mon Sep 24 16:05:15.452642 2018] [wsgi:error] [pid 15401] [remote 176.59.98.114:34097] Traceback (most recent call last):
[Mon Sep 24 16:05:15.452748 2018] [wsgi:error] [pid 15401] [remote 176.59.98.114:34097]   File "/srv/http/virtlabs.tk/5koleso.tk/api.wsgi", line 1, in <module>
[Mon Sep 24 16:05:15.452870 2018] [wsgi:error] [pid 15401] [remote 176.59.98.114:34097]     from api import app as application
[Mon Sep 24 16:05:15.452905 2018] [wsgi:error] [pid 15401] [remote 176.59.98.114:34097]   File "/srv/http/virtlabs.tk/5koleso.tk/api.py", line 54, in <module>
[Mon Sep 24 16:05:15.452919 2018] [wsgi:error] [pid 15401] [remote 176.59.98.114:34097]     from worker import *
[Mon Sep 24 16:05:15.452975 2018] [wsgi:error] [pid 15401] [remote 176.59.98.114:34097]   File "/srv/http/virtlabs.tk/5koleso.tk/worker.py", line 205
[Mon Sep 24 16:05:15.453013 2018] [wsgi:error] [pid 15401] [remote 176.59.98.114:34097]     f = os.path.join(app.root_path, 'static', 'sound', 'free.mp3')
[Mon Sep 24 16:05:15.453086 2018] [wsgi:error] [pid 15401] [remote 176.59.98.114:34097]     ^
[Mon Sep 24 16:05:15.453120 2018] [wsgi:error] [pid 15401] [remote 176.59.98.114:34097] IndentationError: unexpected indent
[Mon Sep 24 16:05:18.691824 2018] [wsgi:error] [pid 15401] [remote 176.59.98.114:60888] mod_wsgi (pid=15401): Target WSGI script '/srv/http/virtlabs.tk/5koleso.tk/api.wsgi' cannot be loaded as Python module.
[Mon Sep 24 16:05:18.692112 2018] [wsgi:error] [pid 15401] [remote 176.59.98.114:60888] mod_wsgi (pid=15401): Exception occurred processing WSGI script '/srv/http/virtlabs.tk/5koleso.tk/api.wsgi'.
[Mon Sep 24 16:05:18.692531 2018] [wsgi:error] [pid 15401] [remote 176.59.98.114:60888] Traceback (most recent call last):
[Mon Sep 24 16:05:18.692631 2018] [wsgi:error] [pid 15401] [remote 176.59.98.114:60888]   File "/srv/http/virtlabs.tk/5koleso.tk/api.wsgi", line 1, in <module>
[Mon Sep 24 16:05:18.692650 2018] [wsgi:error] [pid 15401] [remote 176.59.98.114:60888]     from api import app as application
[Mon Sep 24 16:05:18.692680 2018] [wsgi:error] [pid 15401] [remote 176.59.98.114:60888]   File "/srv/http/virtlabs.tk/5koleso.tk/api.py", line 54, in <module>
[Mon Sep 24 16:05:18.692694 2018] [wsgi:error] [pid 15401] [remote 176.59.98.114:60888]     from worker import *
[Mon Sep 24 16:05:18.692747 2018] [wsgi:error] [pid 15401] [remote 176.59.98.114:60888]   File "/srv/http/virtlabs.tk/5koleso.tk/worker.py", line 205
[Mon Sep 24 16:05:18.692783 2018] [wsgi:error] [pid 15401] [remote 176.59.98.114:60888]     f = os.path.join(app.root_path, 'static', 'sound', 'free.mp3')
[Mon Sep 24 16:05:18.692853 2018] [wsgi:error] [pid 15401] [remote 176.59.98.114:60888]     ^
[Mon Sep 24 16:05:18.692887 2018] [wsgi:error] [pid 15401] [remote 176.59.98.114:60888] IndentationError: unexpected indent
[Mon Sep 24 16:05:21.932537 2018] [wsgi:error] [pid 15401] [remote 176.59.98.114:60147] mod_wsgi (pid=15401): Target WSGI script '/srv/http/virtlabs.tk/5koleso.tk/api.wsgi' cannot be loaded as Python module.
[Mon Sep 24 16:05:21.932858 2018] [wsgi:error] [pid 15401] [remote 176.59.98.114:60147] mod_wsgi (pid=15401): Exception occurred processing WSGI script '/srv/http/virtlabs.tk/5koleso.tk/api.wsgi'.
[Mon Sep 24 16:05:21.933283 2018] [wsgi:error] [pid 15401] [remote 176.59.98.114:60147] Traceback (most recent call last):
[Mon Sep 24 16:05:21.933387 2018] [wsgi:error] [pid 15401] [remote 176.59.98.114:60147]   File "/srv/http/virtlabs.tk/5koleso.tk/api.wsgi", line 1, in <module>
[Mon Sep 24 16:05:21.933405 2018] [wsgi:error] [pid 15401] [remote 176.59.98.114:60147]     from api import app as application
[Mon Sep 24 16:05:21.933434 2018] [wsgi:error] [pid 15401] [remote 176.59.98.114:60147]   File "/srv/http/virtlabs.tk/5koleso.tk/api.py", line 54, in <module>
[Mon Sep 24 16:05:21.933448 2018] [wsgi:error] [pid 15401] [remote 176.59.98.114:60147]     from worker import *
[Mon Sep 24 16:05:21.933500 2018] [wsgi:error] [pid 15401] [remote 176.59.98.114:60147]   File "/srv/http/virtlabs.tk/5koleso.tk/worker.py", line 205
[Mon Sep 24 16:05:21.933536 2018] [wsgi:error] [pid 15401] [remote 176.59.98.114:60147]     f = os.path.join(app.root_path, 'static', 'sound', 'free.mp3')
[Mon Sep 24 16:05:21.933607 2018] [wsgi:error] [pid 15401] [remote 176.59.98.114:60147]     ^
[Mon Sep 24 16:05:21.933641 2018] [wsgi:error] [pid 15401] [remote 176.59.98.114:60147] IndentationError: unexpected indent
[Mon Sep 24 16:05:22.151579 2018] [wsgi:error] [pid 15401] [remote 176.59.98.114:26342] mod_wsgi (pid=15401): Target WSGI script '/srv/http/virtlabs.tk/5koleso.tk/api.wsgi' cannot be loaded as Python module.
[Mon Sep 24 16:05:22.151867 2018] [wsgi:error] [pid 15401] [remote 176.59.98.114:26342] mod_wsgi (pid=15401): Exception occurred processing WSGI script '/srv/http/virtlabs.tk/5koleso.tk/api.wsgi'.
[Mon Sep 24 16:05:22.152292 2018] [wsgi:error] [pid 15401] [remote 176.59.98.114:26342] Traceback (most recent call last):
[Mon Sep 24 16:05:22.152395 2018] [wsgi:error] [pid 15401] [remote 176.59.98.114:26342]   File "/srv/http/virtlabs.tk/5koleso.tk/api.wsgi", line 1, in <module>
[Mon Sep 24 16:05:22.152413 2018] [wsgi:error] [pid 15401] [remote 176.59.98.114:26342]     from api import app as application
[Mon Sep 24 16:05:22.152443 2018] [wsgi:error] [pid 15401] [remote 176.59.98.114:26342]   File "/srv/http/virtlabs.tk/5koleso.tk/api.py", line 54, in <module>
[Mon Sep 24 16:05:22.152458 2018] [wsgi:error] [pid 15401] [remote 176.59.98.114:26342]     from worker import *
[Mon Sep 24 16:05:22.152510 2018] [wsgi:error] [pid 15401] [remote 176.59.98.114:26342]   File "/srv/http/virtlabs.tk/5koleso.tk/worker.py", line 205
[Mon Sep 24 16:05:22.152546 2018] [wsgi:error] [pid 15401] [remote 176.59.98.114:26342]     f = os.path.join(app.root_path, 'static', 'sound', 'free.mp3')
[Mon Sep 24 16:05:22.152617 2018] [wsgi:error] [pid 15401] [remote 176.59.98.114:26342]     ^
[Mon Sep 24 16:05:22.152651 2018] [wsgi:error] [pid 15401] [remote 176.59.98.114:26342] IndentationError: unexpected indent
[Mon Sep 24 16:23:21.493259 2018] [wsgi:error] [pid 15401] [remote 176.59.98.114:17140] mod_wsgi (pid=15401): Target WSGI script '/srv/http/virtlabs.tk/5koleso.tk/api.wsgi' cannot be loaded as Python module.
[Mon Sep 24 16:23:21.493581 2018] [wsgi:error] [pid 15401] [remote 176.59.98.114:17140] mod_wsgi (pid=15401): Exception occurred processing WSGI script '/srv/http/virtlabs.tk/5koleso.tk/api.wsgi'.
[Mon Sep 24 16:23:21.494012 2018] [wsgi:error] [pid 15401] [remote 176.59.98.114:17140] Traceback (most recent call last):
[Mon Sep 24 16:23:21.494121 2018] [wsgi:error] [pid 15401] [remote 176.59.98.114:17140]   File "/srv/http/virtlabs.tk/5koleso.tk/api.wsgi", line 1, in <module>
[Mon Sep 24 16:23:21.494140 2018] [wsgi:error] [pid 15401] [remote 176.59.98.114:17140]     from api import app as application
[Mon Sep 24 16:23:21.494168 2018] [wsgi:error] [pid 15401] [remote 176.59.98.114:17140]   File "/srv/http/virtlabs.tk/5koleso.tk/api.py", line 54, in <module>
[Mon Sep 24 16:23:21.494182 2018] [wsgi:error] [pid 15401] [remote 176.59.98.114:17140]     from worker import *
[Mon Sep 24 16:23:21.494234 2018] [wsgi:error] [pid 15401] [remote 176.59.98.114:17140]   File "/srv/http/virtlabs.tk/5koleso.tk/worker.py", line 205
[Mon Sep 24 16:23:21.494271 2018] [wsgi:error] [pid 15401] [remote 176.59.98.114:17140]     f = os.path.join(app.root_path, 'static', 'sound', 'free.mp3')
[Mon Sep 24 16:23:21.494343 2018] [wsgi:error] [pid 15401] [remote 176.59.98.114:17140]     ^
[Mon Sep 24 16:23:21.494377 2018] [wsgi:error] [pid 15401] [remote 176.59.98.114:17140] IndentationError: unexpected indent
[Mon Sep 24 16:25:02.074719 2018] [wsgi:error] [pid 15577] [remote 176.59.98.114:29617] mod_wsgi (pid=15577): Target WSGI script '/srv/http/virtlabs.tk/5koleso.tk/api.wsgi' cannot be loaded as Python module.
[Mon Sep 24 16:25:02.075118 2018] [wsgi:error] [pid 15577] [remote 176.59.98.114:29617] mod_wsgi (pid=15577): Exception occurred processing WSGI script '/srv/http/virtlabs.tk/5koleso.tk/api.wsgi'.
[Mon Sep 24 16:25:02.076369 2018] [wsgi:error] [pid 15577] [remote 176.59.98.114:29617] Traceback (most recent call last):
[Mon Sep 24 16:25:02.076532 2018] [wsgi:error] [pid 15577] [remote 176.59.98.114:29617]   File "/srv/http/virtlabs.tk/5koleso.tk/api.wsgi", line 1, in <module>
[Mon Sep 24 16:25:02.076552 2018] [wsgi:error] [pid 15577] [remote 176.59.98.114:29617]     from api import app as application
[Mon Sep 24 16:25:02.076690 2018] [wsgi:error] [pid 15577] [remote 176.59.98.114:29617]   File "/srv/http/virtlabs.tk/5koleso.tk/api.py", line 54, in <module>
[Mon Sep 24 16:25:02.076706 2018] [wsgi:error] [pid 15577] [remote 176.59.98.114:29617]     from worker import *
[Mon Sep 24 16:25:02.076773 2018] [wsgi:error] [pid 15577] [remote 176.59.98.114:29617]   File "/srv/http/virtlabs.tk/5koleso.tk/worker.py", line 205
[Mon Sep 24 16:25:02.077077 2018] [wsgi:error] [pid 15577] [remote 176.59.98.114:29617]     f = os.path.join(app.root_path, 'static', 'sound', 'free.mp3')
[Mon Sep 24 16:25:02.077208 2018] [wsgi:error] [pid 15577] [remote 176.59.98.114:29617]     ^
[Mon Sep 24 16:25:02.077247 2018] [wsgi:error] [pid 15577] [remote 176.59.98.114:29617] IndentationError: unexpected indent
