[Mon Apr 23 15:11:48.326410 2018] [wsgi:error] [pid 31971] [remote 85.26.233.229:18447] [2018-04-23 15:11:48,303] ERROR in app: Exception on /work/wait_confirm [GET]
[Mon Apr 23 15:11:48.326657 2018] [wsgi:error] [pid 31971] [remote 85.26.233.229:18447] Traceback (most recent call last):
[Mon Apr 23 15:11:48.326672 2018] [wsgi:error] [pid 31971] [remote 85.26.233.229:18447]   File "/usr/lib/python3.6/site-packages/flask/app.py", line 1982, in wsgi_app
[Mon Apr 23 15:11:48.326683 2018] [wsgi:error] [pid 31971] [remote 85.26.233.229:18447]     response = self.full_dispatch_request()
[Mon Apr 23 15:11:48.326693 2018] [wsgi:error] [pid 31971] [remote 85.26.233.229:18447]   File "/usr/lib/python3.6/site-packages/flask/app.py", line 1614, in full_dispatch_request
[Mon Apr 23 15:11:48.326703 2018] [wsgi:error] [pid 31971] [remote 85.26.233.229:18447]     rv = self.handle_user_exception(e)
[Mon Apr 23 15:11:48.326712 2018] [wsgi:error] [pid 31971] [remote 85.26.233.229:18447]   File "/usr/lib/python3.6/site-packages/flask/app.py", line 1517, in handle_user_exception
[Mon Apr 23 15:11:48.326721 2018] [wsgi:error] [pid 31971] [remote 85.26.233.229:18447]     reraise(exc_type, exc_value, tb)
[Mon Apr 23 15:11:48.326731 2018] [wsgi:error] [pid 31971] [remote 85.26.233.229:18447]   File "/usr/lib/python3.6/site-packages/flask/_compat.py", line 33, in reraise
[Mon Apr 23 15:11:48.326740 2018] [wsgi:error] [pid 31971] [remote 85.26.233.229:18447]     raise value
[Mon Apr 23 15:11:48.326749 2018] [wsgi:error] [pid 31971] [remote 85.26.233.229:18447]   File "/usr/lib/python3.6/site-packages/flask/app.py", line 1612, in full_dispatch_request
[Mon Apr 23 15:11:48.326759 2018] [wsgi:error] [pid 31971] [remote 85.26.233.229:18447]     rv = self.dispatch_request()
[Mon Apr 23 15:11:48.326768 2018] [wsgi:error] [pid 31971] [remote 85.26.233.229:18447]   File "/usr/lib/python3.6/site-packages/flask/app.py", line 1598, in dispatch_request
[Mon Apr 23 15:11:48.326778 2018] [wsgi:error] [pid 31971] [remote 85.26.233.229:18447]     return self.view_functions[rule.endpoint](**req.view_args)
[Mon Apr 23 15:11:48.326788 2018] [wsgi:error] [pid 31971] [remote 85.26.233.229:18447]   File "/srv/http/virtlabs.tk/5koleso.tk/worker.py", line 106, in wait_confirm
[Mon Apr 23 15:11:48.326797 2018] [wsgi:error] [pid 31971] [remote 85.26.233.229:18447]     o.time = time
[Mon Apr 23 15:11:48.326806 2018] [wsgi:error] [pid 31971] [remote 85.26.233.229:18447]   File "<string>", line 2, in __set__
[Mon Apr 23 15:11:48.326815 2018] [wsgi:error] [pid 31971] [remote 85.26.233.229:18447]   File "/usr/lib/python3.6/site-packages/pony/utils/utils.py", line 58, in cut_traceback
[Mon Apr 23 15:11:48.326825 2018] [wsgi:error] [pid 31971] [remote 85.26.233.229:18447]     return func(*args, **kwargs)
[Mon Apr 23 15:11:48.326834 2018] [wsgi:error] [pid 31971] [remote 85.26.233.229:18447]   File "/usr/lib/python3.6/site-packages/pony/orm/core.py", line 2120, in __set__
[Mon Apr 23 15:11:48.326844 2018] [wsgi:error] [pid 31971] [remote 85.26.233.229:18447]     new_val = attr.validate(new_val, obj, from_db=False)
[Mon Apr 23 15:11:48.326853 2018] [wsgi:error] [pid 31971] [remote 85.26.233.229:18447]   File "/usr/lib/python3.6/site-packages/pony/orm/core.py", line 2027, in validate
[Mon Apr 23 15:11:48.326863 2018] [wsgi:error] [pid 31971] [remote 85.26.233.229:18447]     val = converter.validate(val, obj)
[Mon Apr 23 15:11:48.326872 2018] [wsgi:error] [pid 31971] [remote 85.26.233.229:18447]   File "/usr/lib/python3.6/site-packages/pony/orm/dbapiprovider.py", line 508, in validate
[Mon Apr 23 15:11:48.326882 2018] [wsgi:error] [pid 31971] [remote 85.26.233.229:18447]     else: throw(TypeError, 'Value type for attribute %s must be int. Got: %r' % (converter.attr, type(val)))
[Mon Apr 23 15:11:48.326892 2018] [wsgi:error] [pid 31971] [remote 85.26.233.229:18447]   File "/usr/lib/python3.6/site-packages/pony/utils/utils.py", line 98, in throw
[Mon Apr 23 15:11:48.326901 2018] [wsgi:error] [pid 31971] [remote 85.26.233.229:18447]     raise exc
[Mon Apr 23 15:11:48.326916 2018] [wsgi:error] [pid 31971] [remote 85.26.233.229:18447] TypeError: Value type for attribute Taxi_order.time must be int. Got: <class 'module'>
[Mon Apr 23 15:11:48.327010 2018] [wsgi:error] [pid 31971] [remote 85.26.233.229:18447] 
[Mon Apr 23 15:11:48.411369 2018] [wsgi:error] [pid 31971] [remote 85.26.233.229:18447] --- Logging error ---
[Mon Apr 23 15:11:48.416847 2018] [wsgi:error] [pid 31971] [remote 85.26.233.229:18447] Traceback (most recent call last):
[Mon Apr 23 15:11:48.417125 2018] [wsgi:error] [pid 31971] [remote 85.26.233.229:18447]   File "/usr/lib/python3.6/site-packages/flask/app.py", line 1982, in wsgi_app
[Mon Apr 23 15:11:48.417144 2018] [wsgi:error] [pid 31971] [remote 85.26.233.229:18447]     response = self.full_dispatch_request()
[Mon Apr 23 15:11:48.417175 2018] [wsgi:error] [pid 31971] [remote 85.26.233.229:18447]   File "/usr/lib/python3.6/site-packages/flask/app.py", line 1614, in full_dispatch_request
[Mon Apr 23 15:11:48.417189 2018] [wsgi:error] [pid 31971] [remote 85.26.233.229:18447]     rv = self.handle_user_exception(e)
[Mon Apr 23 15:11:48.417216 2018] [wsgi:error] [pid 31971] [remote 85.26.233.229:18447]   File "/usr/lib/python3.6/site-packages/flask/app.py", line 1517, in handle_user_exception
[Mon Apr 23 15:11:48.417230 2018] [wsgi:error] [pid 31971] [remote 85.26.233.229:18447]     reraise(exc_type, exc_value, tb)
[Mon Apr 23 15:11:48.417256 2018] [wsgi:error] [pid 31971] [remote 85.26.233.229:18447]   File "/usr/lib/python3.6/site-packages/flask/_compat.py", line 33, in reraise
[Mon Apr 23 15:11:48.417270 2018] [wsgi:error] [pid 31971] [remote 85.26.233.229:18447]     raise value
[Mon Apr 23 15:11:48.417296 2018] [wsgi:error] [pid 31971] [remote 85.26.233.229:18447]   File "/usr/lib/python3.6/site-packages/flask/app.py", line 1612, in full_dispatch_request
[Mon Apr 23 15:11:48.417309 2018] [wsgi:error] [pid 31971] [remote 85.26.233.229:18447]     rv = self.dispatch_request()
[Mon Apr 23 15:11:48.417335 2018] [wsgi:error] [pid 31971] [remote 85.26.233.229:18447]   File "/usr/lib/python3.6/site-packages/flask/app.py", line 1598, in dispatch_request
[Mon Apr 23 15:11:48.417349 2018] [wsgi:error] [pid 31971] [remote 85.26.233.229:18447]     return self.view_functions[rule.endpoint](**req.view_args)
[Mon Apr 23 15:11:48.417376 2018] [wsgi:error] [pid 31971] [remote 85.26.233.229:18447]   File "/srv/http/virtlabs.tk/5koleso.tk/worker.py", line 106, in wait_confirm
[Mon Apr 23 15:11:48.417389 2018] [wsgi:error] [pid 31971] [remote 85.26.233.229:18447]     o.time = time
[Mon Apr 23 15:11:48.417414 2018] [wsgi:error] [pid 31971] [remote 85.26.233.229:18447]   File "<string>", line 2, in __set__
[Mon Apr 23 15:11:48.417443 2018] [wsgi:error] [pid 31971] [remote 85.26.233.229:18447]   File "/usr/lib/python3.6/site-packages/pony/utils/utils.py", line 58, in cut_traceback
[Mon Apr 23 15:11:48.417456 2018] [wsgi:error] [pid 31971] [remote 85.26.233.229:18447]     return func(*args, **kwargs)
[Mon Apr 23 15:11:48.417482 2018] [wsgi:error] [pid 31971] [remote 85.26.233.229:18447]   File "/usr/lib/python3.6/site-packages/pony/orm/core.py", line 2120, in __set__
[Mon Apr 23 15:11:48.417496 2018] [wsgi:error] [pid 31971] [remote 85.26.233.229:18447]     new_val = attr.validate(new_val, obj, from_db=False)
[Mon Apr 23 15:11:48.417522 2018] [wsgi:error] [pid 31971] [remote 85.26.233.229:18447]   File "/usr/lib/python3.6/site-packages/pony/orm/core.py", line 2027, in validate
[Mon Apr 23 15:11:48.417535 2018] [wsgi:error] [pid 31971] [remote 85.26.233.229:18447]     val = converter.validate(val, obj)
[Mon Apr 23 15:11:48.417702 2018] [wsgi:error] [pid 31971] [remote 85.26.233.229:18447]   File "/usr/lib/python3.6/site-packages/pony/orm/dbapiprovider.py", line 508, in validate
[Mon Apr 23 15:11:48.417718 2018] [wsgi:error] [pid 31971] [remote 85.26.233.229:18447]     else: throw(TypeError, 'Value type for attribute %s must be int. Got: %r' % (converter.attr, type(val)))
[Mon Apr 23 15:11:48.417746 2018] [wsgi:error] [pid 31971] [remote 85.26.233.229:18447]   File "/usr/lib/python3.6/site-packages/pony/utils/utils.py", line 98, in throw
[Mon Apr 23 15:11:48.417834 2018] [wsgi:error] [pid 31971] [remote 85.26.233.229:18447]     raise exc
[Mon Apr 23 15:11:48.417907 2018] [wsgi:error] [pid 31971] [remote 85.26.233.229:18447] TypeError: Value type for attribute Taxi_order.time must be int. Got: <class 'module'>
[Mon Apr 23 15:11:48.417964 2018] [wsgi:error] [pid 31971] [remote 85.26.233.229:18447] 
[Mon Apr 23 15:11:48.417977 2018] [wsgi:error] [pid 31971] [remote 85.26.233.229:18447] During handling of the above exception, another exception occurred:
[Mon Apr 23 15:11:48.417987 2018] [wsgi:error] [pid 31971] [remote 85.26.233.229:18447] 
[Mon Apr 23 15:11:48.418013 2018] [wsgi:error] [pid 31971] [remote 85.26.233.229:18447] Traceback (most recent call last):
[Mon Apr 23 15:11:48.418132 2018] [wsgi:error] [pid 31971] [remote 85.26.233.229:18447]   File "/usr/lib/python3.6/logging/handlers.py", line 1010, in emit
[Mon Apr 23 15:11:48.418146 2018] [wsgi:error] [pid 31971] [remote 85.26.233.229:18447]     smtp = smtplib.SMTP(self.mailhost, port, timeout=self.timeout)
[Mon Apr 23 15:11:48.418173 2018] [wsgi:error] [pid 31971] [remote 85.26.233.229:18447]   File "/usr/lib/python3.6/smtplib.py", line 251, in __init__
[Mon Apr 23 15:11:48.418187 2018] [wsgi:error] [pid 31971] [remote 85.26.233.229:18447]     (code, msg) = self.connect(host, port)
[Mon Apr 23 15:11:48.418212 2018] [wsgi:error] [pid 31971] [remote 85.26.233.229:18447]   File "/usr/lib/python3.6/smtplib.py", line 336, in connect
[Mon Apr 23 15:11:48.418226 2018] [wsgi:error] [pid 31971] [remote 85.26.233.229:18447]     self.sock = self._get_socket(host, port, self.timeout)
[Mon Apr 23 15:11:48.418252 2018] [wsgi:error] [pid 31971] [remote 85.26.233.229:18447]   File "/usr/lib/python3.6/smtplib.py", line 307, in _get_socket
[Mon Apr 23 15:11:48.418265 2018] [wsgi:error] [pid 31971] [remote 85.26.233.229:18447]     self.source_address)
[Mon Apr 23 15:11:48.418290 2018] [wsgi:error] [pid 31971] [remote 85.26.233.229:18447]   File "/usr/lib/python3.6/socket.py", line 704, in create_connection
[Mon Apr 23 15:11:48.418303 2018] [wsgi:error] [pid 31971] [remote 85.26.233.229:18447]     for res in getaddrinfo(host, port, 0, SOCK_STREAM):
[Mon Apr 23 15:11:48.418328 2018] [wsgi:error] [pid 31971] [remote 85.26.233.229:18447]   File "/usr/lib/python3.6/socket.py", line 745, in getaddrinfo
[Mon Apr 23 15:11:48.418341 2018] [wsgi:error] [pid 31971] [remote 85.26.233.229:18447]     for res in _socket.getaddrinfo(host, port, family, type, proto, flags):
[Mon Apr 23 15:11:48.418386 2018] [wsgi:error] [pid 31971] [remote 85.26.233.229:18447] socket.gaierror: [Errno -2] Name or service not known
[Mon Apr 23 15:11:48.418439 2018] [wsgi:error] [pid 31971] [remote 85.26.233.229:18447] Call stack:
[Mon Apr 23 15:11:48.418877 2018] [wsgi:error] [pid 31971] [remote 85.26.233.229:18447]   File "/usr/lib/python3.6/site-packages/flask/app.py", line 1997, in __call__
[Mon Apr 23 15:11:48.418903 2018] [wsgi:error] [pid 31971] [remote 85.26.233.229:18447]     return self.wsgi_app(environ, start_response)
[Mon Apr 23 15:11:48.418932 2018] [wsgi:error] [pid 31971] [remote 85.26.233.229:18447]   File "/usr/lib/python3.6/site-packages/flask/app.py", line 1985, in wsgi_app
[Mon Apr 23 15:11:48.418945 2018] [wsgi:error] [pid 31971] [remote 85.26.233.229:18447]     response = self.handle_exception(e)
[Mon Apr 23 15:11:48.418971 2018] [wsgi:error] [pid 31971] [remote 85.26.233.229:18447]   File "/usr/lib/python3.6/site-packages/flask/app.py", line 1544, in handle_exception
[Mon Apr 23 15:11:48.418985 2018] [wsgi:error] [pid 31971] [remote 85.26.233.229:18447]     self.log_exception((exc_type, exc_value, tb))
[Mon Apr 23 15:11:48.419010 2018] [wsgi:error] [pid 31971] [remote 85.26.233.229:18447]   File "/usr/lib/python3.6/site-packages/flask/app.py", line 1560, in log_exception
[Mon Apr 23 15:11:48.419023 2018] [wsgi:error] [pid 31971] [remote 85.26.233.229:18447]     ), exc_info=exc_info)
[Mon Apr 23 15:11:48.419075 2018] [wsgi:error] [pid 31971] [remote 85.26.233.229:18447] Message: 'Exception on /work/wait_confirm [GET]'
[Mon Apr 23 15:11:48.419149 2018] [wsgi:error] [pid 31971] [remote 85.26.233.229:18447] Arguments: ()
[Mon Apr 23 15:14:08.912316 2018] [wsgi:error] [pid 32041] [remote 85.26.233.229:34211] [2018-04-23 15:14:08,907] ERROR in app: Exception on /work/wait_confirm [GET]
[Mon Apr 23 15:14:08.912497 2018] [wsgi:error] [pid 32041] [remote 85.26.233.229:34211] Traceback (most recent call last):
[Mon Apr 23 15:14:08.912511 2018] [wsgi:error] [pid 32041] [remote 85.26.233.229:34211]   File "/usr/lib/python3.6/site-packages/flask/app.py", line 1982, in wsgi_app
[Mon Apr 23 15:14:08.912522 2018] [wsgi:error] [pid 32041] [remote 85.26.233.229:34211]     response = self.full_dispatch_request()
[Mon Apr 23 15:14:08.912532 2018] [wsgi:error] [pid 32041] [remote 85.26.233.229:34211]   File "/usr/lib/python3.6/site-packages/flask/app.py", line 1614, in full_dispatch_request
[Mon Apr 23 15:14:08.912542 2018] [wsgi:error] [pid 32041] [remote 85.26.233.229:34211]     rv = self.handle_user_exception(e)
[Mon Apr 23 15:14:08.912552 2018] [wsgi:error] [pid 32041] [remote 85.26.233.229:34211]   File "/usr/lib/python3.6/site-packages/flask/app.py", line 1517, in handle_user_exception
[Mon Apr 23 15:14:08.912561 2018] [wsgi:error] [pid 32041] [remote 85.26.233.229:34211]     reraise(exc_type, exc_value, tb)
[Mon Apr 23 15:14:08.912571 2018] [wsgi:error] [pid 32041] [remote 85.26.233.229:34211]   File "/usr/lib/python3.6/site-packages/flask/_compat.py", line 33, in reraise
[Mon Apr 23 15:14:08.912580 2018] [wsgi:error] [pid 32041] [remote 85.26.233.229:34211]     raise value
[Mon Apr 23 15:14:08.912589 2018] [wsgi:error] [pid 32041] [remote 85.26.233.229:34211]   File "/usr/lib/python3.6/site-packages/flask/app.py", line 1612, in full_dispatch_request
[Mon Apr 23 15:14:08.912599 2018] [wsgi:error] [pid 32041] [remote 85.26.233.229:34211]     rv = self.dispatch_request()
[Mon Apr 23 15:14:08.912608 2018] [wsgi:error] [pid 32041] [remote 85.26.233.229:34211]   File "/usr/lib/python3.6/site-packages/flask/app.py", line 1598, in dispatch_request
[Mon Apr 23 15:14:08.912619 2018] [wsgi:error] [pid 32041] [remote 85.26.233.229:34211]     return self.view_functions[rule.endpoint](**req.view_args)
[Mon Apr 23 15:14:08.912628 2018] [wsgi:error] [pid 32041] [remote 85.26.233.229:34211]   File "/srv/http/virtlabs.tk/5koleso.tk/worker.py", line 105, in wait_confirm
[Mon Apr 23 15:14:08.912638 2018] [wsgi:error] [pid 32041] [remote 85.26.233.229:34211]     o.time = time
[Mon Apr 23 15:14:08.912651 2018] [wsgi:error] [pid 32041] [remote 85.26.233.229:34211] NameError: name 'time' is not defined
[Mon Apr 23 15:14:08.912705 2018] [wsgi:error] [pid 32041] [remote 85.26.233.229:34211] 
[Mon Apr 23 15:14:09.002768 2018] [wsgi:error] [pid 32041] [remote 85.26.233.229:34211] --- Logging error ---
[Mon Apr 23 15:14:09.007418 2018] [wsgi:error] [pid 32041] [remote 85.26.233.229:34211] Traceback (most recent call last):
[Mon Apr 23 15:14:09.007758 2018] [wsgi:error] [pid 32041] [remote 85.26.233.229:34211]   File "/usr/lib/python3.6/site-packages/flask/app.py", line 1982, in wsgi_app
[Mon Apr 23 15:14:09.007780 2018] [wsgi:error] [pid 32041] [remote 85.26.233.229:34211]     response = self.full_dispatch_request()
[Mon Apr 23 15:14:09.007812 2018] [wsgi:error] [pid 32041] [remote 85.26.233.229:34211]   File "/usr/lib/python3.6/site-packages/flask/app.py", line 1614, in full_dispatch_request
[Mon Apr 23 15:14:09.007827 2018] [wsgi:error] [pid 32041] [remote 85.26.233.229:34211]     rv = self.handle_user_exception(e)
[Mon Apr 23 15:14:09.007855 2018] [wsgi:error] [pid 32041] [remote 85.26.233.229:34211]   File "/usr/lib/python3.6/site-packages/flask/app.py", line 1517, in handle_user_exception
[Mon Apr 23 15:14:09.007869 2018] [wsgi:error] [pid 32041] [remote 85.26.233.229:34211]     reraise(exc_type, exc_value, tb)
[Mon Apr 23 15:14:09.007895 2018] [wsgi:error] [pid 32041] [remote 85.26.233.229:34211]   File "/usr/lib/python3.6/site-packages/flask/_compat.py", line 33, in reraise
[Mon Apr 23 15:14:09.007908 2018] [wsgi:error] [pid 32041] [remote 85.26.233.229:34211]     raise value
[Mon Apr 23 15:14:09.008004 2018] [wsgi:error] [pid 32041] [remote 85.26.233.229:34211]   File "/usr/lib/python3.6/site-packages/flask/app.py", line 1612, in full_dispatch_request
[Mon Apr 23 15:14:09.008018 2018] [wsgi:error] [pid 32041] [remote 85.26.233.229:34211]     rv = self.dispatch_request()
[Mon Apr 23 15:14:09.008045 2018] [wsgi:error] [pid 32041] [remote 85.26.233.229:34211]   File "/usr/lib/python3.6/site-packages/flask/app.py", line 1598, in dispatch_request
[Mon Apr 23 15:14:09.008059 2018] [wsgi:error] [pid 32041] [remote 85.26.233.229:34211]     return self.view_functions[rule.endpoint](**req.view_args)
[Mon Apr 23 15:14:09.008085 2018] [wsgi:error] [pid 32041] [remote 85.26.233.229:34211]   File "/srv/http/virtlabs.tk/5koleso.tk/worker.py", line 105, in wait_confirm
[Mon Apr 23 15:14:09.008098 2018] [wsgi:error] [pid 32041] [remote 85.26.233.229:34211]     o.time = time
[Mon Apr 23 15:14:09.008162 2018] [wsgi:error] [pid 32041] [remote 85.26.233.229:34211] NameError: name 'time' is not defined
[Mon Apr 23 15:14:09.008219 2018] [wsgi:error] [pid 32041] [remote 85.26.233.229:34211] 
[Mon Apr 23 15:14:09.008232 2018] [wsgi:error] [pid 32041] [remote 85.26.233.229:34211] During handling of the above exception, another exception occurred:
[Mon Apr 23 15:14:09.008242 2018] [wsgi:error] [pid 32041] [remote 85.26.233.229:34211] 
[Mon Apr 23 15:14:09.008268 2018] [wsgi:error] [pid 32041] [remote 85.26.233.229:34211] Traceback (most recent call last):
[Mon Apr 23 15:14:09.008377 2018] [wsgi:error] [pid 32041] [remote 85.26.233.229:34211]   File "/usr/lib/python3.6/logging/handlers.py", line 1010, in emit
[Mon Apr 23 15:14:09.008391 2018] [wsgi:error] [pid 32041] [remote 85.26.233.229:34211]     smtp = smtplib.SMTP(self.mailhost, port, timeout=self.timeout)
[Mon Apr 23 15:14:09.008418 2018] [wsgi:error] [pid 32041] [remote 85.26.233.229:34211]   File "/usr/lib/python3.6/smtplib.py", line 251, in __init__
[Mon Apr 23 15:14:09.008431 2018] [wsgi:error] [pid 32041] [remote 85.26.233.229:34211]     (code, msg) = self.connect(host, port)
[Mon Apr 23 15:14:09.008457 2018] [wsgi:error] [pid 32041] [remote 85.26.233.229:34211]   File "/usr/lib/python3.6/smtplib.py", line 336, in connect
[Mon Apr 23 15:14:09.008470 2018] [wsgi:error] [pid 32041] [remote 85.26.233.229:34211]     self.sock = self._get_socket(host, port, self.timeout)
[Mon Apr 23 15:14:09.008496 2018] [wsgi:error] [pid 32041] [remote 85.26.233.229:34211]   File "/usr/lib/python3.6/smtplib.py", line 307, in _get_socket
[Mon Apr 23 15:14:09.008508 2018] [wsgi:error] [pid 32041] [remote 85.26.233.229:34211]     self.source_address)
[Mon Apr 23 15:14:09.008534 2018] [wsgi:error] [pid 32041] [remote 85.26.233.229:34211]   File "/usr/lib/python3.6/socket.py", line 704, in create_connection
[Mon Apr 23 15:14:09.008546 2018] [wsgi:error] [pid 32041] [remote 85.26.233.229:34211]     for res in getaddrinfo(host, port, 0, SOCK_STREAM):
[Mon Apr 23 15:14:09.008572 2018] [wsgi:error] [pid 32041] [remote 85.26.233.229:34211]   File "/usr/lib/python3.6/socket.py", line 745, in getaddrinfo
[Mon Apr 23 15:14:09.008585 2018] [wsgi:error] [pid 32041] [remote 85.26.233.229:34211]     for res in _socket.getaddrinfo(host, port, family, type, proto, flags):
[Mon Apr 23 15:14:09.008630 2018] [wsgi:error] [pid 32041] [remote 85.26.233.229:34211] socket.gaierror: [Errno -2] Name or service not known
[Mon Apr 23 15:14:09.008678 2018] [wsgi:error] [pid 32041] [remote 85.26.233.229:34211] Call stack:
[Mon Apr 23 15:14:09.009108 2018] [wsgi:error] [pid 32041] [remote 85.26.233.229:34211]   File "/usr/lib/python3.6/site-packages/flask/app.py", line 1997, in __call__
[Mon Apr 23 15:14:09.009133 2018] [wsgi:error] [pid 32041] [remote 85.26.233.229:34211]     return self.wsgi_app(environ, start_response)
[Mon Apr 23 15:14:09.009164 2018] [wsgi:error] [pid 32041] [remote 85.26.233.229:34211]   File "/usr/lib/python3.6/site-packages/flask/app.py", line 1985, in wsgi_app
[Mon Apr 23 15:14:09.009179 2018] [wsgi:error] [pid 32041] [remote 85.26.233.229:34211]     response = self.handle_exception(e)
[Mon Apr 23 15:14:09.009267 2018] [wsgi:error] [pid 32041] [remote 85.26.233.229:34211]   File "/usr/lib/python3.6/site-packages/flask/app.py", line 1544, in handle_exception
[Mon Apr 23 15:14:09.009282 2018] [wsgi:error] [pid 32041] [remote 85.26.233.229:34211]     self.log_exception((exc_type, exc_value, tb))
[Mon Apr 23 15:14:09.009309 2018] [wsgi:error] [pid 32041] [remote 85.26.233.229:34211]   File "/usr/lib/python3.6/site-packages/flask/app.py", line 1560, in log_exception
[Mon Apr 23 15:14:09.009322 2018] [wsgi:error] [pid 32041] [remote 85.26.233.229:34211]     ), exc_info=exc_info)
[Mon Apr 23 15:14:09.009373 2018] [wsgi:error] [pid 32041] [remote 85.26.233.229:34211] Message: 'Exception on /work/wait_confirm [GET]'
[Mon Apr 23 15:14:09.009388 2018] [wsgi:error] [pid 32041] [remote 85.26.233.229:34211] Arguments: ()
[Mon Apr 23 15:15:14.207600 2018] [wsgi:error] [pid 32046] (2)No such file or directory: [client 176.59.110.90:37347] mod_wsgi (pid=32046): Unable to connect to WSGI daemon process 'api' on '/run/httpd/wsgi.32180.21.1.sock' as user with uid=1002.
[Mon Apr 23 15:17:25.517374 2018] [wsgi:error] [pid 32110] (2)No such file or directory: [client 176.59.110.90:8637] mod_wsgi (pid=32110): Unable to connect to WSGI daemon process 'api' on '/run/httpd/wsgi.32180.22.1.sock' as user with uid=1002.
[Mon Apr 23 15:33:29.615861 2018] [wsgi:error] [pid 32357] [remote 85.26.233.229:18483] [2018-04-23 15:33:29,611] ERROR in app: Exception on /work/wait_confirm [GET]
[Mon Apr 23 15:33:29.616021 2018] [wsgi:error] [pid 32357] [remote 85.26.233.229:18483] Traceback (most recent call last):
[Mon Apr 23 15:33:29.616036 2018] [wsgi:error] [pid 32357] [remote 85.26.233.229:18483]   File "/usr/lib/python3.6/site-packages/flask/app.py", line 1982, in wsgi_app
[Mon Apr 23 15:33:29.616047 2018] [wsgi:error] [pid 32357] [remote 85.26.233.229:18483]     response = self.full_dispatch_request()
[Mon Apr 23 15:33:29.616057 2018] [wsgi:error] [pid 32357] [remote 85.26.233.229:18483]   File "/usr/lib/python3.6/site-packages/flask/app.py", line 1614, in full_dispatch_request
[Mon Apr 23 15:33:29.616067 2018] [wsgi:error] [pid 32357] [remote 85.26.233.229:18483]     rv = self.handle_user_exception(e)
[Mon Apr 23 15:33:29.616076 2018] [wsgi:error] [pid 32357] [remote 85.26.233.229:18483]   File "/usr/lib/python3.6/site-packages/flask/app.py", line 1517, in handle_user_exception
[Mon Apr 23 15:33:29.616086 2018] [wsgi:error] [pid 32357] [remote 85.26.233.229:18483]     reraise(exc_type, exc_value, tb)
[Mon Apr 23 15:33:29.616095 2018] [wsgi:error] [pid 32357] [remote 85.26.233.229:18483]   File "/usr/lib/python3.6/site-packages/flask/_compat.py", line 33, in reraise
[Mon Apr 23 15:33:29.616105 2018] [wsgi:error] [pid 32357] [remote 85.26.233.229:18483]     raise value
[Mon Apr 23 15:33:29.616114 2018] [wsgi:error] [pid 32357] [remote 85.26.233.229:18483]   File "/usr/lib/python3.6/site-packages/flask/app.py", line 1612, in full_dispatch_request
[Mon Apr 23 15:33:29.616124 2018] [wsgi:error] [pid 32357] [remote 85.26.233.229:18483]     rv = self.dispatch_request()
[Mon Apr 23 15:33:29.616133 2018] [wsgi:error] [pid 32357] [remote 85.26.233.229:18483]   File "/usr/lib/python3.6/site-packages/flask/app.py", line 1598, in dispatch_request
[Mon Apr 23 15:33:29.616143 2018] [wsgi:error] [pid 32357] [remote 85.26.233.229:18483]     return self.view_functions[rule.endpoint](**req.view_args)
[Mon Apr 23 15:33:29.616152 2018] [wsgi:error] [pid 32357] [remote 85.26.233.229:18483]   File "/srv/http/virtlabs.tk/5koleso.tk/worker.py", line 103, in wait_confirm
[Mon Apr 23 15:33:29.616162 2018] [wsgi:error] [pid 32357] [remote 85.26.233.229:18483]     timer[request.cookies.get('id')] = time.time() + context['time']*60
[Mon Apr 23 15:33:29.616177 2018] [wsgi:error] [pid 32357] [remote 85.26.233.229:18483] TypeError: unsupported operand type(s) for +: 'float' and 'str'
[Mon Apr 23 15:33:29.616230 2018] [wsgi:error] [pid 32357] [remote 85.26.233.229:18483] 
[Mon Apr 23 15:33:29.704417 2018] [wsgi:error] [pid 32357] [remote 85.26.233.229:18483] --- Logging error ---
[Mon Apr 23 15:33:29.709172 2018] [wsgi:error] [pid 32357] [remote 85.26.233.229:18483] Traceback (most recent call last):
[Mon Apr 23 15:33:29.709388 2018] [wsgi:error] [pid 32357] [remote 85.26.233.229:18483]   File "/usr/lib/python3.6/site-packages/flask/app.py", line 1982, in wsgi_app
[Mon Apr 23 15:33:29.709406 2018] [wsgi:error] [pid 32357] [remote 85.26.233.229:18483]     response = self.full_dispatch_request()
[Mon Apr 23 15:33:29.709436 2018] [wsgi:error] [pid 32357] [remote 85.26.233.229:18483]   File "/usr/lib/python3.6/site-packages/flask/app.py", line 1614, in full_dispatch_request
[Mon Apr 23 15:33:29.709451 2018] [wsgi:error] [pid 32357] [remote 85.26.233.229:18483]     rv = self.handle_user_exception(e)
[Mon Apr 23 15:33:29.709478 2018] [wsgi:error] [pid 32357] [remote 85.26.233.229:18483]   File "/usr/lib/python3.6/site-packages/flask/app.py", line 1517, in handle_user_exception
[Mon Apr 23 15:33:29.709491 2018] [wsgi:error] [pid 32357] [remote 85.26.233.229:18483]     reraise(exc_type, exc_value, tb)
[Mon Apr 23 15:33:29.709517 2018] [wsgi:error] [pid 32357] [remote 85.26.233.229:18483]   File "/usr/lib/python3.6/site-packages/flask/_compat.py", line 33, in reraise
[Mon Apr 23 15:33:29.709530 2018] [wsgi:error] [pid 32357] [remote 85.26.233.229:18483]     raise value
[Mon Apr 23 15:33:29.709557 2018] [wsgi:error] [pid 32357] [remote 85.26.233.229:18483]   File "/usr/lib/python3.6/site-packages/flask/app.py", line 1612, in full_dispatch_request
[Mon Apr 23 15:33:29.709570 2018] [wsgi:error] [pid 32357] [remote 85.26.233.229:18483]     rv = self.dispatch_request()
[Mon Apr 23 15:33:29.709596 2018] [wsgi:error] [pid 32357] [remote 85.26.233.229:18483]   File "/usr/lib/python3.6/site-packages/flask/app.py", line 1598, in dispatch_request
[Mon Apr 23 15:33:29.709610 2018] [wsgi:error] [pid 32357] [remote 85.26.233.229:18483]     return self.view_functions[rule.endpoint](**req.view_args)
[Mon Apr 23 15:33:29.709635 2018] [wsgi:error] [pid 32357] [remote 85.26.233.229:18483]   File "/srv/http/virtlabs.tk/5koleso.tk/worker.py", line 103, in wait_confirm
[Mon Apr 23 15:33:29.709648 2018] [wsgi:error] [pid 32357] [remote 85.26.233.229:18483]     timer[request.cookies.get('id')] = time.time() + context['time']*60
[Mon Apr 23 15:33:29.709705 2018] [wsgi:error] [pid 32357] [remote 85.26.233.229:18483] TypeError: unsupported operand type(s) for +: 'float' and 'str'
[Mon Apr 23 15:33:29.709757 2018] [wsgi:error] [pid 32357] [remote 85.26.233.229:18483] 
[Mon Apr 23 15:33:29.709770 2018] [wsgi:error] [pid 32357] [remote 85.26.233.229:18483] During handling of the above exception, another exception occurred:
[Mon Apr 23 15:33:29.709781 2018] [wsgi:error] [pid 32357] [remote 85.26.233.229:18483] 
[Mon Apr 23 15:33:29.709807 2018] [wsgi:error] [pid 32357] [remote 85.26.233.229:18483] Traceback (most recent call last):
[Mon Apr 23 15:33:29.709911 2018] [wsgi:error] [pid 32357] [remote 85.26.233.229:18483]   File "/usr/lib/python3.6/logging/handlers.py", line 1010, in emit
[Mon Apr 23 15:33:29.709925 2018] [wsgi:error] [pid 32357] [remote 85.26.233.229:18483]     smtp = smtplib.SMTP(self.mailhost, port, timeout=self.timeout)
[Mon Apr 23 15:33:29.709952 2018] [wsgi:error] [pid 32357] [remote 85.26.233.229:18483]   File "/usr/lib/python3.6/smtplib.py", line 251, in __init__
[Mon Apr 23 15:33:29.709965 2018] [wsgi:error] [pid 32357] [remote 85.26.233.229:18483]     (code, msg) = self.connect(host, port)
[Mon Apr 23 15:33:29.709991 2018] [wsgi:error] [pid 32357] [remote 85.26.233.229:18483]   File "/usr/lib/python3.6/smtplib.py", line 336, in connect
[Mon Apr 23 15:33:29.710004 2018] [wsgi:error] [pid 32357] [remote 85.26.233.229:18483]     self.sock = self._get_socket(host, port, self.timeout)
[Mon Apr 23 15:33:29.710031 2018] [wsgi:error] [pid 32357] [remote 85.26.233.229:18483]   File "/usr/lib/python3.6/smtplib.py", line 307, in _get_socket
[Mon Apr 23 15:33:29.710044 2018] [wsgi:error] [pid 32357] [remote 85.26.233.229:18483]     self.source_address)
[Mon Apr 23 15:33:29.710070 2018] [wsgi:error] [pid 32357] [remote 85.26.233.229:18483]   File "/usr/lib/python3.6/socket.py", line 704, in create_connection
[Mon Apr 23 15:33:29.710156 2018] [wsgi:error] [pid 32357] [remote 85.26.233.229:18483]     for res in getaddrinfo(host, port, 0, SOCK_STREAM):
[Mon Apr 23 15:33:29.710187 2018] [wsgi:error] [pid 32357] [remote 85.26.233.229:18483]   File "/usr/lib/python3.6/socket.py", line 745, in getaddrinfo
[Mon Apr 23 15:33:29.710200 2018] [wsgi:error] [pid 32357] [remote 85.26.233.229:18483]     for res in _socket.getaddrinfo(host, port, family, type, proto, flags):
[Mon Apr 23 15:33:29.710247 2018] [wsgi:error] [pid 32357] [remote 85.26.233.229:18483] socket.gaierror: [Errno -2] Name or service not known
[Mon Apr 23 15:33:29.710294 2018] [wsgi:error] [pid 32357] [remote 85.26.233.229:18483] Call stack:
[Mon Apr 23 15:33:29.710725 2018] [wsgi:error] [pid 32357] [remote 85.26.233.229:18483]   File "/usr/lib/python3.6/site-packages/flask/app.py", line 1997, in __call__
[Mon Apr 23 15:33:29.710884 2018] [wsgi:error] [pid 32357] [remote 85.26.233.229:18483]     return self.wsgi_app(environ, start_response)
[Mon Apr 23 15:33:29.710927 2018] [wsgi:error] [pid 32357] [remote 85.26.233.229:18483]   File "/usr/lib/python3.6/site-packages/flask/app.py", line 1985, in wsgi_app
[Mon Apr 23 15:33:29.710942 2018] [wsgi:error] [pid 32357] [remote 85.26.233.229:18483]     response = self.handle_exception(e)
[Mon Apr 23 15:33:29.710970 2018] [wsgi:error] [pid 32357] [remote 85.26.233.229:18483]   File "/usr/lib/python3.6/site-packages/flask/app.py", line 1544, in handle_exception
[Mon Apr 23 15:33:29.710983 2018] [wsgi:error] [pid 32357] [remote 85.26.233.229:18483]     self.log_exception((exc_type, exc_value, tb))
[Mon Apr 23 15:33:29.711009 2018] [wsgi:error] [pid 32357] [remote 85.26.233.229:18483]   File "/usr/lib/python3.6/site-packages/flask/app.py", line 1560, in log_exception
[Mon Apr 23 15:33:29.711022 2018] [wsgi:error] [pid 32357] [remote 85.26.233.229:18483]     ), exc_info=exc_info)
[Mon Apr 23 15:33:29.711084 2018] [wsgi:error] [pid 32357] [remote 85.26.233.229:18483] Message: 'Exception on /work/wait_confirm [GET]'
[Mon Apr 23 15:33:29.711100 2018] [wsgi:error] [pid 32357] [remote 85.26.233.229:18483] Arguments: ()
[Mon Apr 23 15:37:18.529589 2018] [wsgi:error] [pid 32365] (2)No such file or directory: [client 176.59.110.90:8351] mod_wsgi (pid=32365): Unable to connect to WSGI daemon process 'api' on '/run/httpd/wsgi.32180.25.1.sock' as user with uid=1002.
[Mon Apr 23 15:53:56.569295 2018] [wsgi:error] [pid 32654] [remote 85.26.233.229:32712] [2018-04-23 15:53:56,561] ERROR in app: Exception on /work/confirm [GET]
[Mon Apr 23 15:53:56.569477 2018] [wsgi:error] [pid 32654] [remote 85.26.233.229:32712] Traceback (most recent call last):
[Mon Apr 23 15:53:56.569493 2018] [wsgi:error] [pid 32654] [remote 85.26.233.229:32712]   File "/usr/lib/python3.6/site-packages/flask/app.py", line 1982, in wsgi_app
[Mon Apr 23 15:53:56.569504 2018] [wsgi:error] [pid 32654] [remote 85.26.233.229:32712]     response = self.full_dispatch_request()
[Mon Apr 23 15:53:56.569514 2018] [wsgi:error] [pid 32654] [remote 85.26.233.229:32712]   File "/usr/lib/python3.6/site-packages/flask/app.py", line 1614, in full_dispatch_request
[Mon Apr 23 15:53:56.569524 2018] [wsgi:error] [pid 32654] [remote 85.26.233.229:32712]     rv = self.handle_user_exception(e)
[Mon Apr 23 15:53:56.569534 2018] [wsgi:error] [pid 32654] [remote 85.26.233.229:32712]   File "/usr/lib/python3.6/site-packages/flask/app.py", line 1517, in handle_user_exception
[Mon Apr 23 15:53:56.569543 2018] [wsgi:error] [pid 32654] [remote 85.26.233.229:32712]     reraise(exc_type, exc_value, tb)
[Mon Apr 23 15:53:56.569552 2018] [wsgi:error] [pid 32654] [remote 85.26.233.229:32712]   File "/usr/lib/python3.6/site-packages/flask/_compat.py", line 33, in reraise
[Mon Apr 23 15:53:56.569562 2018] [wsgi:error] [pid 32654] [remote 85.26.233.229:32712]     raise value
[Mon Apr 23 15:53:56.569571 2018] [wsgi:error] [pid 32654] [remote 85.26.233.229:32712]   File "/usr/lib/python3.6/site-packages/flask/app.py", line 1612, in full_dispatch_request
[Mon Apr 23 15:53:56.569638 2018] [wsgi:error] [pid 32654] [remote 85.26.233.229:32712]     rv = self.dispatch_request()
[Mon Apr 23 15:53:56.569651 2018] [wsgi:error] [pid 32654] [remote 85.26.233.229:32712]   File "/usr/lib/python3.6/site-packages/flask/app.py", line 1598, in dispatch_request
[Mon Apr 23 15:53:56.569661 2018] [wsgi:error] [pid 32654] [remote 85.26.233.229:32712]     return self.view_functions[rule.endpoint](**req.view_args)
[Mon Apr 23 15:53:56.569670 2018] [wsgi:error] [pid 32654] [remote 85.26.233.229:32712]   File "/srv/http/virtlabs.tk/5koleso.tk/worker.py", line 132, in confirm
[Mon Apr 23 15:53:56.569680 2018] [wsgi:error] [pid 32654] [remote 85.26.233.229:32712]     return render_template('work/confirm.html', **context)
[Mon Apr 23 15:53:56.569690 2018] [wsgi:error] [pid 32654] [remote 85.26.233.229:32712]   File "/usr/lib/python3.6/site-packages/flask/templating.py", line 134, in render_template
[Mon Apr 23 15:53:56.569699 2018] [wsgi:error] [pid 32654] [remote 85.26.233.229:32712]     context, ctx.app)
[Mon Apr 23 15:53:56.569709 2018] [wsgi:error] [pid 32654] [remote 85.26.233.229:32712]   File "/usr/lib/python3.6/site-packages/flask/templating.py", line 116, in _render
[Mon Apr 23 15:53:56.569718 2018] [wsgi:error] [pid 32654] [remote 85.26.233.229:32712]     rv = template.render(context)
[Mon Apr 23 15:53:56.569727 2018] [wsgi:error] [pid 32654] [remote 85.26.233.229:32712]   File "/usr/lib/python3.6/site-packages/jinja2/asyncsupport.py", line 76, in render
[Mon Apr 23 15:53:56.569737 2018] [wsgi:error] [pid 32654] [remote 85.26.233.229:32712]     return original_render(self, *args, **kwargs)
[Mon Apr 23 15:53:56.569746 2018] [wsgi:error] [pid 32654] [remote 85.26.233.229:32712]   File "/usr/lib/python3.6/site-packages/jinja2/environment.py", line 1008, in render
[Mon Apr 23 15:53:56.569756 2018] [wsgi:error] [pid 32654] [remote 85.26.233.229:32712]     return self.environment.handle_exception(exc_info, True)
[Mon Apr 23 15:53:56.569768 2018] [wsgi:error] [pid 32654] [remote 85.26.233.229:32712]   File "/usr/lib/python3.6/site-packages/jinja2/environment.py", line 780, in handle_exception
[Mon Apr 23 15:53:56.569778 2018] [wsgi:error] [pid 32654] [remote 85.26.233.229:32712]     reraise(exc_type, exc_value, tb)
[Mon Apr 23 15:53:56.569787 2018] [wsgi:error] [pid 32654] [remote 85.26.233.229:32712]   File "/usr/lib/python3.6/site-packages/jinja2/_compat.py", line 37, in reraise
[Mon Apr 23 15:53:56.569797 2018] [wsgi:error] [pid 32654] [remote 85.26.233.229:32712]     raise value.with_traceback(tb)
[Mon Apr 23 15:53:56.569806 2018] [wsgi:error] [pid 32654] [remote 85.26.233.229:32712]   File "/srv/http/virtlabs.tk/5koleso.tk/templates/work/confirm.html", line 1, in top-level template code
[Mon Apr 23 15:53:56.569816 2018] [wsgi:error] [pid 32654] [remote 85.26.233.229:32712]     {% extends "index.html" %}
[Mon Apr 23 15:53:56.569825 2018] [wsgi:error] [pid 32654] [remote 85.26.233.229:32712]   File "/srv/http/virtlabs.tk/5koleso.tk/templates/index.html", line 53, in top-level template code
[Mon Apr 23 15:53:56.569835 2018] [wsgi:error] [pid 32654] [remote 85.26.233.229:32712]     {% block body %}
[Mon Apr 23 15:53:56.569844 2018] [wsgi:error] [pid 32654] [remote 85.26.233.229:32712]   File "/srv/http/virtlabs.tk/5koleso.tk/templates/work/confirm.html", line 4, in block "body"
[Mon Apr 23 15:53:56.569853 2018] [wsgi:error] [pid 32654] [remote 85.26.233.229:32712]     <p id="timer">{{ time // 60 }}:{{ (time % 60).format('02.0f') }}</p>
[Mon Apr 23 15:53:56.569870 2018] [wsgi:error] [pid 32654] [remote 85.26.233.229:32712] jinja2.exceptions.UndefinedError: 'float object' has no attribute 'format'
[Mon Apr 23 15:53:56.569935 2018] [wsgi:error] [pid 32654] [remote 85.26.233.229:32712] 
[Mon Apr 23 15:53:56.606076 2018] [wsgi:error] [pid 32654] [remote 85.26.233.229:32712] --- Logging error ---
[Mon Apr 23 15:53:56.611349 2018] [wsgi:error] [pid 32654] [remote 85.26.233.229:32712] Traceback (most recent call last):
[Mon Apr 23 15:53:56.611662 2018] [wsgi:error] [pid 32654] [remote 85.26.233.229:32712]   File "/usr/lib/python3.6/site-packages/flask/app.py", line 1982, in wsgi_app
[Mon Apr 23 15:53:56.611752 2018] [wsgi:error] [pid 32654] [remote 85.26.233.229:32712]     response = self.full_dispatch_request()
[Mon Apr 23 15:53:56.611785 2018] [wsgi:error] [pid 32654] [remote 85.26.233.229:32712]   File "/usr/lib/python3.6/site-packages/flask/app.py", line 1614, in full_dispatch_request
[Mon Apr 23 15:53:56.611800 2018] [wsgi:error] [pid 32654] [remote 85.26.233.229:32712]     rv = self.handle_user_exception(e)
[Mon Apr 23 15:53:56.611827 2018] [wsgi:error] [pid 32654] [remote 85.26.233.229:32712]   File "/usr/lib/python3.6/site-packages/flask/app.py", line 1517, in handle_user_exception
[Mon Apr 23 15:53:56.611840 2018] [wsgi:error] [pid 32654] [remote 85.26.233.229:32712]     reraise(exc_type, exc_value, tb)
[Mon Apr 23 15:53:56.611867 2018] [wsgi:error] [pid 32654] [remote 85.26.233.229:32712]   File "/usr/lib/python3.6/site-packages/flask/_compat.py", line 33, in reraise
[Mon Apr 23 15:53:56.611880 2018] [wsgi:error] [pid 32654] [remote 85.26.233.229:32712]     raise value
[Mon Apr 23 15:53:56.611906 2018] [wsgi:error] [pid 32654] [remote 85.26.233.229:32712]   File "/usr/lib/python3.6/site-packages/flask/app.py", line 1612, in full_dispatch_request
[Mon Apr 23 15:53:56.611919 2018] [wsgi:error] [pid 32654] [remote 85.26.233.229:32712]     rv = self.dispatch_request()
[Mon Apr 23 15:53:56.611945 2018] [wsgi:error] [pid 32654] [remote 85.26.233.229:32712]   File "/usr/lib/python3.6/site-packages/flask/app.py", line 1598, in dispatch_request
[Mon Apr 23 15:53:56.611959 2018] [wsgi:error] [pid 32654] [remote 85.26.233.229:32712]     return self.view_functions[rule.endpoint](**req.view_args)
[Mon Apr 23 15:53:56.611985 2018] [wsgi:error] [pid 32654] [remote 85.26.233.229:32712]   File "/srv/http/virtlabs.tk/5koleso.tk/worker.py", line 132, in confirm
[Mon Apr 23 15:53:56.611999 2018] [wsgi:error] [pid 32654] [remote 85.26.233.229:32712]     return render_template('work/confirm.html', **context)
[Mon Apr 23 15:53:56.612025 2018] [wsgi:error] [pid 32654] [remote 85.26.233.229:32712]   File "/usr/lib/python3.6/site-packages/flask/templating.py", line 134, in render_template
[Mon Apr 23 15:53:56.612038 2018] [wsgi:error] [pid 32654] [remote 85.26.233.229:32712]     context, ctx.app)
[Mon Apr 23 15:53:56.612063 2018] [wsgi:error] [pid 32654] [remote 85.26.233.229:32712]   File "/usr/lib/python3.6/site-packages/flask/templating.py", line 116, in _render
[Mon Apr 23 15:53:56.612076 2018] [wsgi:error] [pid 32654] [remote 85.26.233.229:32712]     rv = template.render(context)
[Mon Apr 23 15:53:56.612102 2018] [wsgi:error] [pid 32654] [remote 85.26.233.229:32712]   File "/usr/lib/python3.6/site-packages/jinja2/asyncsupport.py", line 76, in render
[Mon Apr 23 15:53:56.612116 2018] [wsgi:error] [pid 32654] [remote 85.26.233.229:32712]     return original_render(self, *args, **kwargs)
[Mon Apr 23 15:53:56.612142 2018] [wsgi:error] [pid 32654] [remote 85.26.233.229:32712]   File "/usr/lib/python3.6/site-packages/jinja2/environment.py", line 1008, in render
[Mon Apr 23 15:53:56.612155 2018] [wsgi:error] [pid 32654] [remote 85.26.233.229:32712]     return self.environment.handle_exception(exc_info, True)
[Mon Apr 23 15:53:56.612181 2018] [wsgi:error] [pid 32654] [remote 85.26.233.229:32712]   File "/usr/lib/python3.6/site-packages/jinja2/environment.py", line 780, in handle_exception
[Mon Apr 23 15:53:56.612195 2018] [wsgi:error] [pid 32654] [remote 85.26.233.229:32712]     reraise(exc_type, exc_value, tb)
[Mon Apr 23 15:53:56.612221 2018] [wsgi:error] [pid 32654] [remote 85.26.233.229:32712]   File "/usr/lib/python3.6/site-packages/jinja2/_compat.py", line 37, in reraise
[Mon Apr 23 15:53:56.612234 2018] [wsgi:error] [pid 32654] [remote 85.26.233.229:32712]     raise value.with_traceback(tb)
[Mon Apr 23 15:53:56.612260 2018] [wsgi:error] [pid 32654] [remote 85.26.233.229:32712]   File "/srv/http/virtlabs.tk/5koleso.tk/templates/work/confirm.html", line 1, in top-level template code
[Mon Apr 23 15:53:56.612288 2018] [wsgi:error] [pid 32654] [remote 85.26.233.229:32712]     {% extends "index.html" %}
[Mon Apr 23 15:53:56.612318 2018] [wsgi:error] [pid 32654] [remote 85.26.233.229:32712]   File "/srv/http/virtlabs.tk/5koleso.tk/templates/index.html", line 53, in top-level template code
[Mon Apr 23 15:53:56.612332 2018] [wsgi:error] [pid 32654] [remote 85.26.233.229:32712]     {% block body %}
[Mon Apr 23 15:53:56.612358 2018] [wsgi:error] [pid 32654] [remote 85.26.233.229:32712]   File "/srv/http/virtlabs.tk/5koleso.tk/templates/work/confirm.html", line 4, in block "body"
[Mon Apr 23 15:53:56.612372 2018] [wsgi:error] [pid 32654] [remote 85.26.233.229:32712]     <p id="timer">{{ time // 60 }}:{{ (time % 60).format('02.0f') }}</p>
[Mon Apr 23 15:53:56.612436 2018] [wsgi:error] [pid 32654] [remote 85.26.233.229:32712] jinja2.exceptions.UndefinedError: 'float object' has no attribute 'format'
[Mon Apr 23 15:53:56.612493 2018] [wsgi:error] [pid 32654] [remote 85.26.233.229:32712] 
[Mon Apr 23 15:53:56.612507 2018] [wsgi:error] [pid 32654] [remote 85.26.233.229:32712] During handling of the above exception, another exception occurred:
[Mon Apr 23 15:53:56.612517 2018] [wsgi:error] [pid 32654] [remote 85.26.233.229:32712] 
[Mon Apr 23 15:53:56.612544 2018] [wsgi:error] [pid 32654] [remote 85.26.233.229:32712] Traceback (most recent call last):
[Mon Apr 23 15:53:56.612667 2018] [wsgi:error] [pid 32654] [remote 85.26.233.229:32712]   File "/usr/lib/python3.6/logging/handlers.py", line 1010, in emit
[Mon Apr 23 15:53:56.612682 2018] [wsgi:error] [pid 32654] [remote 85.26.233.229:32712]     smtp = smtplib.SMTP(self.mailhost, port, timeout=self.timeout)
[Mon Apr 23 15:53:56.612709 2018] [wsgi:error] [pid 32654] [remote 85.26.233.229:32712]   File "/usr/lib/python3.6/smtplib.py", line 251, in __init__
[Mon Apr 23 15:53:56.612722 2018] [wsgi:error] [pid 32654] [remote 85.26.233.229:32712]     (code, msg) = self.connect(host, port)
[Mon Apr 23 15:53:56.612748 2018] [wsgi:error] [pid 32654] [remote 85.26.233.229:32712]   File "/usr/lib/python3.6/smtplib.py", line 336, in connect
[Mon Apr 23 15:53:56.612761 2018] [wsgi:error] [pid 32654] [remote 85.26.233.229:32712]     self.sock = self._get_socket(host, port, self.timeout)
[Mon Apr 23 15:53:56.612788 2018] [wsgi:error] [pid 32654] [remote 85.26.233.229:32712]   File "/usr/lib/python3.6/smtplib.py", line 307, in _get_socket
[Mon Apr 23 15:53:56.612801 2018] [wsgi:error] [pid 32654] [remote 85.26.233.229:32712]     self.source_address)
[Mon Apr 23 15:53:56.612826 2018] [wsgi:error] [pid 32654] [remote 85.26.233.229:32712]   File "/usr/lib/python3.6/socket.py", line 704, in create_connection
[Mon Apr 23 15:53:56.612840 2018] [wsgi:error] [pid 32654] [remote 85.26.233.229:32712]     for res in getaddrinfo(host, port, 0, SOCK_STREAM):
[Mon Apr 23 15:53:56.612865 2018] [wsgi:error] [pid 32654] [remote 85.26.233.229:32712]   File "/usr/lib/python3.6/socket.py", line 745, in getaddrinfo
[Mon Apr 23 15:53:56.612879 2018] [wsgi:error] [pid 32654] [remote 85.26.233.229:32712]     for res in _socket.getaddrinfo(host, port, family, type, proto, flags):
[Mon Apr 23 15:53:56.612922 2018] [wsgi:error] [pid 32654] [remote 85.26.233.229:32712] socket.gaierror: [Errno -2] Name or service not known
[Mon Apr 23 15:53:56.612973 2018] [wsgi:error] [pid 32654] [remote 85.26.233.229:32712] Call stack:
[Mon Apr 23 15:53:56.613400 2018] [wsgi:error] [pid 32654] [remote 85.26.233.229:32712]   File "/usr/lib/python3.6/site-packages/flask/app.py", line 1997, in __call__
[Mon Apr 23 15:53:56.613425 2018] [wsgi:error] [pid 32654] [remote 85.26.233.229:32712]     return self.wsgi_app(environ, start_response)
[Mon Apr 23 15:53:56.613453 2018] [wsgi:error] [pid 32654] [remote 85.26.233.229:32712]   File "/usr/lib/python3.6/site-packages/flask/app.py", line 1985, in wsgi_app
[Mon Apr 23 15:53:56.613468 2018] [wsgi:error] [pid 32654] [remote 85.26.233.229:32712]     response = self.handle_exception(e)
[Mon Apr 23 15:53:56.613494 2018] [wsgi:error] [pid 32654] [remote 85.26.233.229:32712]   File "/usr/lib/python3.6/site-packages/flask/app.py", line 1544, in handle_exception
[Mon Apr 23 15:53:56.613573 2018] [wsgi:error] [pid 32654] [remote 85.26.233.229:32712]     self.log_exception((exc_type, exc_value, tb))
[Mon Apr 23 15:53:56.613603 2018] [wsgi:error] [pid 32654] [remote 85.26.233.229:32712]   File "/usr/lib/python3.6/site-packages/flask/app.py", line 1560, in log_exception
[Mon Apr 23 15:53:56.613616 2018] [wsgi:error] [pid 32654] [remote 85.26.233.229:32712]     ), exc_info=exc_info)
[Mon Apr 23 15:53:56.613672 2018] [wsgi:error] [pid 32654] [remote 85.26.233.229:32712] Message: 'Exception on /work/confirm [GET]'
[Mon Apr 23 15:53:56.613687 2018] [wsgi:error] [pid 32654] [remote 85.26.233.229:32712] Arguments: ()
[Mon Apr 23 15:56:13.014312 2018] [wsgi:error] [pid 32660] (2)No such file or directory: [client 176.59.110.90:27179] mod_wsgi (pid=32660): Unable to connect to WSGI daemon process 'api' on '/run/httpd/wsgi.32180.28.1.sock' as user with uid=1002.
[Mon Apr 23 15:56:37.906698 2018] [wsgi:error] [pid 32731] [remote 85.26.233.229:2577] [2018-04-23 15:56:37,901] ERROR in app: Exception on /work/confirm [GET]
[Mon Apr 23 15:56:37.906873 2018] [wsgi:error] [pid 32731] [remote 85.26.233.229:2577] Traceback (most recent call last):
[Mon Apr 23 15:56:37.906888 2018] [wsgi:error] [pid 32731] [remote 85.26.233.229:2577]   File "/usr/lib/python3.6/site-packages/flask/app.py", line 1982, in wsgi_app
[Mon Apr 23 15:56:37.906899 2018] [wsgi:error] [pid 32731] [remote 85.26.233.229:2577]     response = self.full_dispatch_request()
[Mon Apr 23 15:56:37.906909 2018] [wsgi:error] [pid 32731] [remote 85.26.233.229:2577]   File "/usr/lib/python3.6/site-packages/flask/app.py", line 1614, in full_dispatch_request
[Mon Apr 23 15:56:37.906919 2018] [wsgi:error] [pid 32731] [remote 85.26.233.229:2577]     rv = self.handle_user_exception(e)
[Mon Apr 23 15:56:37.906928 2018] [wsgi:error] [pid 32731] [remote 85.26.233.229:2577]   File "/usr/lib/python3.6/site-packages/flask/app.py", line 1517, in handle_user_exception
[Mon Apr 23 15:56:37.906938 2018] [wsgi:error] [pid 32731] [remote 85.26.233.229:2577]     reraise(exc_type, exc_value, tb)
[Mon Apr 23 15:56:37.906947 2018] [wsgi:error] [pid 32731] [remote 85.26.233.229:2577]   File "/usr/lib/python3.6/site-packages/flask/_compat.py", line 33, in reraise
[Mon Apr 23 15:56:37.906956 2018] [wsgi:error] [pid 32731] [remote 85.26.233.229:2577]     raise value
[Mon Apr 23 15:56:37.906965 2018] [wsgi:error] [pid 32731] [remote 85.26.233.229:2577]   File "/usr/lib/python3.6/site-packages/flask/app.py", line 1612, in full_dispatch_request
[Mon Apr 23 15:56:37.906975 2018] [wsgi:error] [pid 32731] [remote 85.26.233.229:2577]     rv = self.dispatch_request()
[Mon Apr 23 15:56:37.906984 2018] [wsgi:error] [pid 32731] [remote 85.26.233.229:2577]   File "/usr/lib/python3.6/site-packages/flask/app.py", line 1598, in dispatch_request
[Mon Apr 23 15:56:37.906994 2018] [wsgi:error] [pid 32731] [remote 85.26.233.229:2577]     return self.view_functions[rule.endpoint](**req.view_args)
[Mon Apr 23 15:56:37.907003 2018] [wsgi:error] [pid 32731] [remote 85.26.233.229:2577]   File "/srv/http/virtlabs.tk/5koleso.tk/worker.py", line 124, in confirm
[Mon Apr 23 15:56:37.907012 2018] [wsgi:error] [pid 32731] [remote 85.26.233.229:2577]     'float': (timer[request.cookies.get('id')] - time.time() % 60).format('02.0f')
[Mon Apr 23 15:56:37.907031 2018] [wsgi:error] [pid 32731] [remote 85.26.233.229:2577] AttributeError: 'float' object has no attribute 'format'
[Mon Apr 23 15:56:37.907090 2018] [wsgi:error] [pid 32731] [remote 85.26.233.229:2577] 
[Mon Apr 23 15:56:37.994545 2018] [wsgi:error] [pid 32731] [remote 85.26.233.229:2577] --- Logging error ---
[Mon Apr 23 15:56:38.000111 2018] [wsgi:error] [pid 32731] [remote 85.26.233.229:2577] Traceback (most recent call last):
[Mon Apr 23 15:56:38.000365 2018] [wsgi:error] [pid 32731] [remote 85.26.233.229:2577]   File "/usr/lib/python3.6/site-packages/flask/app.py", line 1982, in wsgi_app
[Mon Apr 23 15:56:38.000384 2018] [wsgi:error] [pid 32731] [remote 85.26.233.229:2577]     response = self.full_dispatch_request()
[Mon Apr 23 15:56:38.000518 2018] [wsgi:error] [pid 32731] [remote 85.26.233.229:2577]   File "/usr/lib/python3.6/site-packages/flask/app.py", line 1614, in full_dispatch_request
[Mon Apr 23 15:56:38.000535 2018] [wsgi:error] [pid 32731] [remote 85.26.233.229:2577]     rv = self.handle_user_exception(e)
[Mon Apr 23 15:56:38.000564 2018] [wsgi:error] [pid 32731] [remote 85.26.233.229:2577]   File "/usr/lib/python3.6/site-packages/flask/app.py", line 1517, in handle_user_exception
[Mon Apr 23 15:56:38.000577 2018] [wsgi:error] [pid 32731] [remote 85.26.233.229:2577]     reraise(exc_type, exc_value, tb)
[Mon Apr 23 15:56:38.000726 2018] [wsgi:error] [pid 32731] [remote 85.26.233.229:2577]   File "/usr/lib/python3.6/site-packages/flask/_compat.py", line 33, in reraise
[Mon Apr 23 15:56:38.000745 2018] [wsgi:error] [pid 32731] [remote 85.26.233.229:2577]     raise value
[Mon Apr 23 15:56:38.000774 2018] [wsgi:error] [pid 32731] [remote 85.26.233.229:2577]   File "/usr/lib/python3.6/site-packages/flask/app.py", line 1612, in full_dispatch_request
[Mon Apr 23 15:56:38.000788 2018] [wsgi:error] [pid 32731] [remote 85.26.233.229:2577]     rv = self.dispatch_request()
[Mon Apr 23 15:56:38.000816 2018] [wsgi:error] [pid 32731] [remote 85.26.233.229:2577]   File "/usr/lib/python3.6/site-packages/flask/app.py", line 1598, in dispatch_request
[Mon Apr 23 15:56:38.000830 2018] [wsgi:error] [pid 32731] [remote 85.26.233.229:2577]     return self.view_functions[rule.endpoint](**req.view_args)
[Mon Apr 23 15:56:38.000858 2018] [wsgi:error] [pid 32731] [remote 85.26.233.229:2577]   File "/srv/http/virtlabs.tk/5koleso.tk/worker.py", line 124, in confirm
[Mon Apr 23 15:56:38.000871 2018] [wsgi:error] [pid 32731] [remote 85.26.233.229:2577]     'float': (timer[request.cookies.get('id')] - time.time() % 60).format('02.0f')
[Mon Apr 23 15:56:38.000940 2018] [wsgi:error] [pid 32731] [remote 85.26.233.229:2577] AttributeError: 'float' object has no attribute 'format'
[Mon Apr 23 15:56:38.000999 2018] [wsgi:error] [pid 32731] [remote 85.26.233.229:2577] 
[Mon Apr 23 15:56:38.001014 2018] [wsgi:error] [pid 32731] [remote 85.26.233.229:2577] During handling of the above exception, another exception occurred:
[Mon Apr 23 15:56:38.001024 2018] [wsgi:error] [pid 32731] [remote 85.26.233.229:2577] 
[Mon Apr 23 15:56:38.001051 2018] [wsgi:error] [pid 32731] [remote 85.26.233.229:2577] Traceback (most recent call last):
[Mon Apr 23 15:56:38.001169 2018] [wsgi:error] [pid 32731] [remote 85.26.233.229:2577]   File "/usr/lib/python3.6/logging/handlers.py", line 1010, in emit
[Mon Apr 23 15:56:38.001184 2018] [wsgi:error] [pid 32731] [remote 85.26.233.229:2577]     smtp = smtplib.SMTP(self.mailhost, port, timeout=self.timeout)
[Mon Apr 23 15:56:38.001212 2018] [wsgi:error] [pid 32731] [remote 85.26.233.229:2577]   File "/usr/lib/python3.6/smtplib.py", line 251, in __init__
[Mon Apr 23 15:56:38.001225 2018] [wsgi:error] [pid 32731] [remote 85.26.233.229:2577]     (code, msg) = self.connect(host, port)
[Mon Apr 23 15:56:38.001251 2018] [wsgi:error] [pid 32731] [remote 85.26.233.229:2577]   File "/usr/lib/python3.6/smtplib.py", line 336, in connect
[Mon Apr 23 15:56:38.001264 2018] [wsgi:error] [pid 32731] [remote 85.26.233.229:2577]     self.sock = self._get_socket(host, port, self.timeout)
[Mon Apr 23 15:56:38.001290 2018] [wsgi:error] [pid 32731] [remote 85.26.233.229:2577]   File "/usr/lib/python3.6/smtplib.py", line 307, in _get_socket
[Mon Apr 23 15:56:38.001303 2018] [wsgi:error] [pid 32731] [remote 85.26.233.229:2577]     self.source_address)
[Mon Apr 23 15:56:38.001329 2018] [wsgi:error] [pid 32731] [remote 85.26.233.229:2577]   File "/usr/lib/python3.6/socket.py", line 704, in create_connection
[Mon Apr 23 15:56:38.001342 2018] [wsgi:error] [pid 32731] [remote 85.26.233.229:2577]     for res in getaddrinfo(host, port, 0, SOCK_STREAM):
[Mon Apr 23 15:56:38.001368 2018] [wsgi:error] [pid 32731] [remote 85.26.233.229:2577]   File "/usr/lib/python3.6/socket.py", line 745, in getaddrinfo
[Mon Apr 23 15:56:38.001381 2018] [wsgi:error] [pid 32731] [remote 85.26.233.229:2577]     for res in _socket.getaddrinfo(host, port, family, type, proto, flags):
[Mon Apr 23 15:56:38.001480 2018] [wsgi:error] [pid 32731] [remote 85.26.233.229:2577] socket.gaierror: [Errno -2] Name or service not known
[Mon Apr 23 15:56:38.001530 2018] [wsgi:error] [pid 32731] [remote 85.26.233.229:2577] Call stack:
[Mon Apr 23 15:56:38.001976 2018] [wsgi:error] [pid 32731] [remote 85.26.233.229:2577]   File "/usr/lib/python3.6/site-packages/flask/app.py", line 1997, in __call__
[Mon Apr 23 15:56:38.002001 2018] [wsgi:error] [pid 32731] [remote 85.26.233.229:2577]     return self.wsgi_app(environ, start_response)
[Mon Apr 23 15:56:38.002030 2018] [wsgi:error] [pid 32731] [remote 85.26.233.229:2577]   File "/usr/lib/python3.6/site-packages/flask/app.py", line 1985, in wsgi_app
[Mon Apr 23 15:56:38.002044 2018] [wsgi:error] [pid 32731] [remote 85.26.233.229:2577]     response = self.handle_exception(e)
[Mon Apr 23 15:56:38.002070 2018] [wsgi:error] [pid 32731] [remote 85.26.233.229:2577]   File "/usr/lib/python3.6/site-packages/flask/app.py", line 1544, in handle_exception
[Mon Apr 23 15:56:38.002083 2018] [wsgi:error] [pid 32731] [remote 85.26.233.229:2577]     self.log_exception((exc_type, exc_value, tb))
[Mon Apr 23 15:56:38.002108 2018] [wsgi:error] [pid 32731] [remote 85.26.233.229:2577]   File "/usr/lib/python3.6/site-packages/flask/app.py", line 1560, in log_exception
[Mon Apr 23 15:56:38.002121 2018] [wsgi:error] [pid 32731] [remote 85.26.233.229:2577]     ), exc_info=exc_info)
[Mon Apr 23 15:56:38.002175 2018] [wsgi:error] [pid 32731] [remote 85.26.233.229:2577] Message: 'Exception on /work/confirm [GET]'
[Mon Apr 23 15:56:38.002190 2018] [wsgi:error] [pid 32731] [remote 85.26.233.229:2577] Arguments: ()
[Mon Apr 23 16:02:49.060964 2018] [wsgi:error] [pid 429] (2)No such file or directory: [client 85.26.233.229:25922] mod_wsgi (pid=429): Unable to connect to WSGI daemon process 'api' on '/run/httpd/wsgi.32180.31.1.sock' as user with uid=1002., referer: http://5koleso.tk/work/confirm?id=118&phone=5060&address_from=%D1%83%D0%BB.%20%20%D0%B4.%20%20%D0%BA.%20%20%D0%BF.&address_to=&comment=&time=
[Mon Apr 23 16:10:02.161984 2018] [wsgi:error] [pid 518] (2)No such file or directory: [client 85.26.233.229:14305] mod_wsgi (pid=518): Unable to connect to WSGI daemon process 'api' on '/run/httpd/wsgi.32180.32.1.sock' as user with uid=1002., referer: http://5koleso.tk/work/confirm?id=118&phone=5060&address_from=%D1%83%D0%BB.%20%20%D0%B4.%20%20%D0%BA.%20%20%D0%BF.&address_to=&comment=&time=
[Mon Apr 23 16:10:08.098665 2018] [wsgi:error] [pid 611] [remote 85.26.233.229:62396] mod_wsgi (pid=611): Target WSGI script '/srv/http/virtlabs.tk/5koleso.tk/api.wsgi' cannot be loaded as Python module.
[Mon Apr 23 16:10:08.098893 2018] [wsgi:error] [pid 611] [remote 85.26.233.229:62396] mod_wsgi (pid=611): Exception occurred processing WSGI script '/srv/http/virtlabs.tk/5koleso.tk/api.wsgi'.
[Mon Apr 23 16:10:08.100357 2018] [wsgi:error] [pid 611] [remote 85.26.233.229:62396] Traceback (most recent call last):
[Mon Apr 23 16:10:08.100513 2018] [wsgi:error] [pid 611] [remote 85.26.233.229:62396]   File "/srv/http/virtlabs.tk/5koleso.tk/api.wsgi", line 1, in <module>
[Mon Apr 23 16:10:08.100647 2018] [wsgi:error] [pid 611] [remote 85.26.233.229:62396]     from api import app as application
[Mon Apr 23 16:10:08.100680 2018] [wsgi:error] [pid 611] [remote 85.26.233.229:62396]   File "/srv/http/virtlabs.tk/5koleso.tk/api.py", line 54, in <module>
[Mon Apr 23 16:10:08.100696 2018] [wsgi:error] [pid 611] [remote 85.26.233.229:62396]     from worker import *
[Mon Apr 23 16:10:08.100723 2018] [wsgi:error] [pid 611] [remote 85.26.233.229:62396]   File "/srv/http/virtlabs.tk/5koleso.tk/worker.py", line 3, in <module>
[Mon Apr 23 16:10:08.100737 2018] [wsgi:error] [pid 611] [remote 85.26.233.229:62396]     from math import abs
[Mon Apr 23 16:10:08.100807 2018] [wsgi:error] [pid 611] [remote 85.26.233.229:62396] ImportError: cannot import name 'abs'
[Mon Apr 23 16:10:08.105842 2018] [wsgi:error] [pid 611] [remote 85.26.233.229:34088] mod_wsgi (pid=611): Target WSGI script '/srv/http/virtlabs.tk/5koleso.tk/api.wsgi' cannot be loaded as Python module.
[Mon Apr 23 16:10:08.106096 2018] [wsgi:error] [pid 611] [remote 85.26.233.229:34088] mod_wsgi (pid=611): Exception occurred processing WSGI script '/srv/http/virtlabs.tk/5koleso.tk/api.wsgi'.
[Mon Apr 23 16:10:08.106477 2018] [wsgi:error] [pid 611] [remote 85.26.233.229:34088] Traceback (most recent call last):
[Mon Apr 23 16:10:08.106589 2018] [wsgi:error] [pid 611] [remote 85.26.233.229:34088]   File "/srv/http/virtlabs.tk/5koleso.tk/api.wsgi", line 1, in <module>
[Mon Apr 23 16:10:08.106606 2018] [wsgi:error] [pid 611] [remote 85.26.233.229:34088]     from api import app as application
[Mon Apr 23 16:10:08.106636 2018] [wsgi:error] [pid 611] [remote 85.26.233.229:34088]   File "/srv/http/virtlabs.tk/5koleso.tk/api.py", line 54, in <module>
[Mon Apr 23 16:10:08.106651 2018] [wsgi:error] [pid 611] [remote 85.26.233.229:34088]     from worker import *
[Mon Apr 23 16:10:08.106677 2018] [wsgi:error] [pid 611] [remote 85.26.233.229:34088]   File "/srv/http/virtlabs.tk/5koleso.tk/worker.py", line 3, in <module>
[Mon Apr 23 16:10:08.106691 2018] [wsgi:error] [pid 611] [remote 85.26.233.229:34088]     from math import abs
[Mon Apr 23 16:10:08.106745 2018] [wsgi:error] [pid 611] [remote 85.26.233.229:34088] ImportError: cannot import name 'abs'
[Mon Apr 23 16:10:08.622267 2018] [wsgi:error] [pid 611] [remote 85.26.233.229:36660] mod_wsgi (pid=611): Target WSGI script '/srv/http/virtlabs.tk/5koleso.tk/api.wsgi' cannot be loaded as Python module.
[Mon Apr 23 16:10:08.622449 2018] [wsgi:error] [pid 611] [remote 85.26.233.229:36660] mod_wsgi (pid=611): Exception occurred processing WSGI script '/srv/http/virtlabs.tk/5koleso.tk/api.wsgi'.
[Mon Apr 23 16:10:08.622804 2018] [wsgi:error] [pid 611] [remote 85.26.233.229:36660] Traceback (most recent call last):
[Mon Apr 23 16:10:08.622910 2018] [wsgi:error] [pid 611] [remote 85.26.233.229:36660]   File "/srv/http/virtlabs.tk/5koleso.tk/api.wsgi", line 1, in <module>
[Mon Apr 23 16:10:08.622927 2018] [wsgi:error] [pid 611] [remote 85.26.233.229:36660]     from api import app as application
[Mon Apr 23 16:10:08.622957 2018] [wsgi:error] [pid 611] [remote 85.26.233.229:36660]   File "/srv/http/virtlabs.tk/5koleso.tk/api.py", line 54, in <module>
[Mon Apr 23 16:10:08.622971 2018] [wsgi:error] [pid 611] [remote 85.26.233.229:36660]     from worker import *
[Mon Apr 23 16:10:08.622997 2018] [wsgi:error] [pid 611] [remote 85.26.233.229:36660]   File "/srv/http/virtlabs.tk/5koleso.tk/worker.py", line 3, in <module>
[Mon Apr 23 16:10:08.623010 2018] [wsgi:error] [pid 611] [remote 85.26.233.229:36660]     from math import abs
[Mon Apr 23 16:10:08.623061 2018] [wsgi:error] [pid 611] [remote 85.26.233.229:36660] ImportError: cannot import name 'abs'
[Mon Apr 23 16:10:09.848167 2018] [wsgi:error] [pid 611] [remote 85.26.233.229:63350] mod_wsgi (pid=611): Target WSGI script '/srv/http/virtlabs.tk/5koleso.tk/api.wsgi' cannot be loaded as Python module.
[Mon Apr 23 16:10:09.848357 2018] [wsgi:error] [pid 611] [remote 85.26.233.229:63350] mod_wsgi (pid=611): Exception occurred processing WSGI script '/srv/http/virtlabs.tk/5koleso.tk/api.wsgi'.
[Mon Apr 23 16:10:09.848701 2018] [wsgi:error] [pid 611] [remote 85.26.233.229:63350] Traceback (most recent call last):
[Mon Apr 23 16:10:09.848802 2018] [wsgi:error] [pid 611] [remote 85.26.233.229:63350]   File "/srv/http/virtlabs.tk/5koleso.tk/api.wsgi", line 1, in <module>
[Mon Apr 23 16:10:09.848820 2018] [wsgi:error] [pid 611] [remote 85.26.233.229:63350]     from api import app as application
[Mon Apr 23 16:10:09.848847 2018] [wsgi:error] [pid 611] [remote 85.26.233.229:63350]   File "/srv/http/virtlabs.tk/5koleso.tk/api.py", line 54, in <module>
[Mon Apr 23 16:10:09.848862 2018] [wsgi:error] [pid 611] [remote 85.26.233.229:63350]     from worker import *
[Mon Apr 23 16:10:09.848887 2018] [wsgi:error] [pid 611] [remote 85.26.233.229:63350]   File "/srv/http/virtlabs.tk/5koleso.tk/worker.py", line 3, in <module>
[Mon Apr 23 16:10:09.848979 2018] [wsgi:error] [pid 611] [remote 85.26.233.229:63350]     from math import abs
[Mon Apr 23 16:10:09.849037 2018] [wsgi:error] [pid 611] [remote 85.26.233.229:63350] ImportError: cannot import name 'abs'
[Mon Apr 23 16:10:10.206326 2018] [wsgi:error] [pid 611] [remote 85.26.233.229:11823] mod_wsgi (pid=611): Target WSGI script '/srv/http/virtlabs.tk/5koleso.tk/api.wsgi' cannot be loaded as Python module.
[Mon Apr 23 16:10:10.206524 2018] [wsgi:error] [pid 611] [remote 85.26.233.229:11823] mod_wsgi (pid=611): Exception occurred processing WSGI script '/srv/http/virtlabs.tk/5koleso.tk/api.wsgi'.
[Mon Apr 23 16:10:10.206881 2018] [wsgi:error] [pid 611] [remote 85.26.233.229:11823] Traceback (most recent call last):
[Mon Apr 23 16:10:10.206984 2018] [wsgi:error] [pid 611] [remote 85.26.233.229:11823]   File "/srv/http/virtlabs.tk/5koleso.tk/api.wsgi", line 1, in <module>
[Mon Apr 23 16:10:10.207000 2018] [wsgi:error] [pid 611] [remote 85.26.233.229:11823]     from api import app as application
[Mon Apr 23 16:10:10.207028 2018] [wsgi:error] [pid 611] [remote 85.26.233.229:11823]   File "/srv/http/virtlabs.tk/5koleso.tk/api.py", line 54, in <module>
[Mon Apr 23 16:10:10.207042 2018] [wsgi:error] [pid 611] [remote 85.26.233.229:11823]     from worker import *
[Mon Apr 23 16:10:10.207068 2018] [wsgi:error] [pid 611] [remote 85.26.233.229:11823]   File "/srv/http/virtlabs.tk/5koleso.tk/worker.py", line 3, in <module>
[Mon Apr 23 16:10:10.207081 2018] [wsgi:error] [pid 611] [remote 85.26.233.229:11823]     from math import abs
[Mon Apr 23 16:10:10.207132 2018] [wsgi:error] [pid 611] [remote 85.26.233.229:11823] ImportError: cannot import name 'abs'
[Mon Apr 23 16:11:06.542541 2018] [wsgi:error] [pid 611] [remote 85.26.233.229:54312] mod_wsgi (pid=611): Target WSGI script '/srv/http/virtlabs.tk/5koleso.tk/api.wsgi' cannot be loaded as Python module.
[Mon Apr 23 16:11:06.542774 2018] [wsgi:error] [pid 611] [remote 85.26.233.229:54312] mod_wsgi (pid=611): Exception occurred processing WSGI script '/srv/http/virtlabs.tk/5koleso.tk/api.wsgi'.
[Mon Apr 23 16:11:06.543135 2018] [wsgi:error] [pid 611] [remote 85.26.233.229:54312] Traceback (most recent call last):
[Mon Apr 23 16:11:06.543239 2018] [wsgi:error] [pid 611] [remote 85.26.233.229:54312]   File "/srv/http/virtlabs.tk/5koleso.tk/api.wsgi", line 1, in <module>
[Mon Apr 23 16:11:06.543257 2018] [wsgi:error] [pid 611] [remote 85.26.233.229:54312]     from api import app as application
[Mon Apr 23 16:11:06.543286 2018] [wsgi:error] [pid 611] [remote 85.26.233.229:54312]   File "/srv/http/virtlabs.tk/5koleso.tk/api.py", line 54, in <module>
[Mon Apr 23 16:11:06.543300 2018] [wsgi:error] [pid 611] [remote 85.26.233.229:54312]     from worker import *
[Mon Apr 23 16:11:06.543325 2018] [wsgi:error] [pid 611] [remote 85.26.233.229:54312]   File "/srv/http/virtlabs.tk/5koleso.tk/worker.py", line 3, in <module>
[Mon Apr 23 16:11:06.543339 2018] [wsgi:error] [pid 611] [remote 85.26.233.229:54312]     from math import abs
[Mon Apr 23 16:11:06.543391 2018] [wsgi:error] [pid 611] [remote 85.26.233.229:54312] ImportError: cannot import name 'abs'
[Mon Apr 23 16:11:06.569247 2018] [wsgi:error] [pid 611] [remote 85.26.233.229:57316] mod_wsgi (pid=611): Target WSGI script '/srv/http/virtlabs.tk/5koleso.tk/api.wsgi' cannot be loaded as Python module.
[Mon Apr 23 16:11:06.569416 2018] [wsgi:error] [pid 611] [remote 85.26.233.229:57316] mod_wsgi (pid=611): Exception occurred processing WSGI script '/srv/http/virtlabs.tk/5koleso.tk/api.wsgi'.
[Mon Apr 23 16:11:06.569762 2018] [wsgi:error] [pid 611] [remote 85.26.233.229:57316] Traceback (most recent call last):
[Mon Apr 23 16:11:06.569863 2018] [wsgi:error] [pid 611] [remote 85.26.233.229:57316]   File "/srv/http/virtlabs.tk/5koleso.tk/api.wsgi", line 1, in <module>
[Mon Apr 23 16:11:06.569880 2018] [wsgi:error] [pid 611] [remote 85.26.233.229:57316]     from api import app as application
[Mon Apr 23 16:11:06.569908 2018] [wsgi:error] [pid 611] [remote 85.26.233.229:57316]   File "/srv/http/virtlabs.tk/5koleso.tk/api.py", line 54, in <module>
[Mon Apr 23 16:11:06.570032 2018] [wsgi:error] [pid 611] [remote 85.26.233.229:57316]     from worker import *
[Mon Apr 23 16:11:06.570064 2018] [wsgi:error] [pid 611] [remote 85.26.233.229:57316]   File "/srv/http/virtlabs.tk/5koleso.tk/worker.py", line 3, in <module>
[Mon Apr 23 16:11:06.570078 2018] [wsgi:error] [pid 611] [remote 85.26.233.229:57316]     from math import abs
[Mon Apr 23 16:11:06.570134 2018] [wsgi:error] [pid 611] [remote 85.26.233.229:57316] ImportError: cannot import name 'abs'
[Mon Apr 23 16:15:23.061750 2018] [wsgi:error] [pid 677] (2)No such file or directory: [client 85.26.233.229:15281] mod_wsgi (pid=677): Unable to connect to WSGI daemon process 'api' on '/run/httpd/wsgi.32180.34.1.sock' as user with uid=1002., referer: http://5koleso.tk/work/confirm?id=118&phone=5060&address_from=%D1%83%D0%BB.%20%20%D0%B4.%20%20%D0%BA.%20%20%D0%BF.&address_to=&comment=&time=
[Mon Apr 23 16:22:25.993683 2018] [wsgi:error] [pid 797] (2)No such file or directory: [client 85.26.233.229:29990] mod_wsgi (pid=797): Unable to connect to WSGI daemon process 'api' on '/run/httpd/wsgi.32180.35.1.sock' as user with uid=1002., referer: http://5koleso.tk/work/confirm?id=118&phone=5060&address_from=%D1%83%D0%BB.%20%20%D0%B4.%20%20%D0%BA.%20%20%D0%BF.&address_to=&comment=&time=
