[Fri Dec 22 14:10:48.738812 2017] [wsgi:error] [pid 9198] [remote 85.26.235.239:37106] mod_wsgi (pid=9198): Target WSGI script '/srv/http/virtlabs.tk/forsaje.tk/api.wsgi' cannot be loaded as Python module.
[Fri Dec 22 14:10:48.739167 2017] [wsgi:error] [pid 9198] [remote 85.26.235.239:37106] mod_wsgi (pid=9198): Exception occurred processing WSGI script '/srv/http/virtlabs.tk/forsaje.tk/api.wsgi'.
[Fri Dec 22 14:10:48.740468 2017] [wsgi:error] [pid 9198] [remote 85.26.235.239:37106] Traceback (most recent call last):
[Fri Dec 22 14:10:48.740615 2017] [wsgi:error] [pid 9198] [remote 85.26.235.239:37106]   File "/srv/http/virtlabs.tk/forsaje.tk/api.wsgi", line 1, in <module>
[Fri Dec 22 14:10:48.740633 2017] [wsgi:error] [pid 9198] [remote 85.26.235.239:37106]     from api import app as application
[Fri Dec 22 14:10:48.740662 2017] [wsgi:error] [pid 9198] [remote 85.26.235.239:37106]   File "/srv/http/virtlabs.tk/forsaje.tk/api.py", line 4, in <module>
[Fri Dec 22 14:10:48.740677 2017] [wsgi:error] [pid 9198] [remote 85.26.235.239:37106]     from flask import Flask, render_template, redirect, send_file, request, response, session
[Fri Dec 22 14:10:48.740740 2017] [wsgi:error] [pid 9198] [remote 85.26.235.239:37106] ImportError: cannot import name 'response'
[Fri Dec 22 14:16:08.585372 2017] [wsgi:error] [pid 9275] [remote 85.26.235.239:36058] mod_wsgi (pid=9275): Target WSGI script '/srv/http/virtlabs.tk/forsaje.tk/api.wsgi' cannot be loaded as Python module.
[Fri Dec 22 14:16:08.585649 2017] [wsgi:error] [pid 9275] [remote 85.26.235.239:36058] mod_wsgi (pid=9275): Exception occurred processing WSGI script '/srv/http/virtlabs.tk/forsaje.tk/api.wsgi'.
[Fri Dec 22 14:16:08.586930 2017] [wsgi:error] [pid 9275] [remote 85.26.235.239:36058] Traceback (most recent call last):
[Fri Dec 22 14:16:08.587073 2017] [wsgi:error] [pid 9275] [remote 85.26.235.239:36058]   File "/srv/http/virtlabs.tk/forsaje.tk/api.wsgi", line 1, in <module>
[Fri Dec 22 14:16:08.587093 2017] [wsgi:error] [pid 9275] [remote 85.26.235.239:36058]     from api import app as application
[Fri Dec 22 14:16:08.587121 2017] [wsgi:error] [pid 9275] [remote 85.26.235.239:36058]   File "/srv/http/virtlabs.tk/forsaje.tk/api.py", line 4, in <module>
[Fri Dec 22 14:16:08.587136 2017] [wsgi:error] [pid 9275] [remote 85.26.235.239:36058]     from flask import Flask, render_template, redirect, send_file, request, response, session
[Fri Dec 22 14:16:08.587202 2017] [wsgi:error] [pid 9275] [remote 85.26.235.239:36058] ImportError: cannot import name 'response'
[Fri Dec 22 14:16:19.183065 2017] [wsgi:error] [pid 9275] [remote 85.26.235.239:53054] mod_wsgi (pid=9275): Target WSGI script '/srv/http/virtlabs.tk/forsaje.tk/api.wsgi' cannot be loaded as Python module.
[Fri Dec 22 14:16:19.184284 2017] [wsgi:error] [pid 9275] [remote 85.26.235.239:53054] mod_wsgi (pid=9275): Exception occurred processing WSGI script '/srv/http/virtlabs.tk/forsaje.tk/api.wsgi'.
[Fri Dec 22 14:16:19.184778 2017] [wsgi:error] [pid 9275] [remote 85.26.235.239:53054] Traceback (most recent call last):
[Fri Dec 22 14:16:19.184899 2017] [wsgi:error] [pid 9275] [remote 85.26.235.239:53054]   File "/srv/http/virtlabs.tk/forsaje.tk/api.wsgi", line 1, in <module>
[Fri Dec 22 14:16:19.184916 2017] [wsgi:error] [pid 9275] [remote 85.26.235.239:53054]     from api import app as application
[Fri Dec 22 14:16:19.184945 2017] [wsgi:error] [pid 9275] [remote 85.26.235.239:53054]   File "/srv/http/virtlabs.tk/forsaje.tk/api.py", line 4, in <module>
[Fri Dec 22 14:16:19.184972 2017] [wsgi:error] [pid 9275] [remote 85.26.235.239:53054]     from flask import Flask, render_template, redirect, send_file, request, response, session
[Fri Dec 22 14:16:19.185029 2017] [wsgi:error] [pid 9275] [remote 85.26.235.239:53054] ImportError: cannot import name 'response'
[Fri Dec 22 14:17:49.999917 2017] [wsgi:error] [pid 9313] [remote 85.26.235.239:21293] [2017-12-22 14:17:49,964] ERROR in app: Exception on /work/check_worker [POST]
[Fri Dec 22 14:17:50.000064 2017] [wsgi:error] [pid 9313] [remote 85.26.235.239:21293] Traceback (most recent call last):
[Fri Dec 22 14:17:50.000163 2017] [wsgi:error] [pid 9313] [remote 85.26.235.239:21293]   File "/usr/lib/python3.6/site-packages/flask/app.py", line 1982, in wsgi_app
[Fri Dec 22 14:17:50.000177 2017] [wsgi:error] [pid 9313] [remote 85.26.235.239:21293]     response = self.full_dispatch_request()
[Fri Dec 22 14:17:50.000186 2017] [wsgi:error] [pid 9313] [remote 85.26.235.239:21293]   File "/usr/lib/python3.6/site-packages/flask/app.py", line 1614, in full_dispatch_request
[Fri Dec 22 14:17:50.000196 2017] [wsgi:error] [pid 9313] [remote 85.26.235.239:21293]     rv = self.handle_user_exception(e)
[Fri Dec 22 14:17:50.000205 2017] [wsgi:error] [pid 9313] [remote 85.26.235.239:21293]   File "/usr/lib/python3.6/site-packages/flask/app.py", line 1517, in handle_user_exception
[Fri Dec 22 14:17:50.000214 2017] [wsgi:error] [pid 9313] [remote 85.26.235.239:21293]     reraise(exc_type, exc_value, tb)
[Fri Dec 22 14:17:50.000222 2017] [wsgi:error] [pid 9313] [remote 85.26.235.239:21293]   File "/usr/lib/python3.6/site-packages/flask/_compat.py", line 33, in reraise
[Fri Dec 22 14:17:50.000231 2017] [wsgi:error] [pid 9313] [remote 85.26.235.239:21293]     raise value
[Fri Dec 22 14:17:50.000240 2017] [wsgi:error] [pid 9313] [remote 85.26.235.239:21293]   File "/usr/lib/python3.6/site-packages/flask/app.py", line 1612, in full_dispatch_request
[Fri Dec 22 14:17:50.000249 2017] [wsgi:error] [pid 9313] [remote 85.26.235.239:21293]     rv = self.dispatch_request()
[Fri Dec 22 14:17:50.000257 2017] [wsgi:error] [pid 9313] [remote 85.26.235.239:21293]   File "/usr/lib/python3.6/site-packages/flask/app.py", line 1598, in dispatch_request
[Fri Dec 22 14:17:50.000267 2017] [wsgi:error] [pid 9313] [remote 85.26.235.239:21293]     return self.view_functions[rule.endpoint](**req.view_args)
[Fri Dec 22 14:17:50.000275 2017] [wsgi:error] [pid 9313] [remote 85.26.235.239:21293]   File "/srv/http/virtlabs.tk/forsaje.tk/api.py", line 139, in check_worker
[Fri Dec 22 14:17:50.000284 2017] [wsgi:error] [pid 9313] [remote 85.26.235.239:21293]     resp.set_cookie('id', user.id)
[Fri Dec 22 14:17:50.000293 2017] [wsgi:error] [pid 9313] [remote 85.26.235.239:21293]   File "/usr/lib/python3.6/site-packages/werkzeug/wrappers.py", line 1064, in set_cookie
[Fri Dec 22 14:17:50.000302 2017] [wsgi:error] [pid 9313] [remote 85.26.235.239:21293]     charset=self.charset))
[Fri Dec 22 14:17:50.000310 2017] [wsgi:error] [pid 9313] [remote 85.26.235.239:21293]   File "/usr/lib/python3.6/site-packages/werkzeug/http.py", line 978, in dump_cookie
[Fri Dec 22 14:17:50.000319 2017] [wsgi:error] [pid 9313] [remote 85.26.235.239:21293]     value = to_bytes(value, charset)
[Fri Dec 22 14:17:50.000328 2017] [wsgi:error] [pid 9313] [remote 85.26.235.239:21293]   File "/usr/lib/python3.6/site-packages/werkzeug/_compat.py", line 190, in to_bytes
[Fri Dec 22 14:17:50.000337 2017] [wsgi:error] [pid 9313] [remote 85.26.235.239:21293]     raise TypeError('Expected bytes')
[Fri Dec 22 14:17:50.000351 2017] [wsgi:error] [pid 9313] [remote 85.26.235.239:21293] TypeError: Expected bytes
[Fri Dec 22 14:17:50.000413 2017] [wsgi:error] [pid 9313] [remote 85.26.235.239:21293] 
[Fri Dec 22 14:36:31.652656 2017] [wsgi:error] [pid 9486] [remote 85.26.235.239:25142] mod_wsgi (pid=9486): Target WSGI script '/srv/http/virtlabs.tk/forsaje.tk/api.wsgi' cannot be loaded as Python module.
[Fri Dec 22 14:36:31.652914 2017] [wsgi:error] [pid 9486] [remote 85.26.235.239:25142] mod_wsgi (pid=9486): Exception occurred processing WSGI script '/srv/http/virtlabs.tk/forsaje.tk/api.wsgi'.
[Fri Dec 22 14:36:31.654196 2017] [wsgi:error] [pid 9486] [remote 85.26.235.239:25142] Traceback (most recent call last):
[Fri Dec 22 14:36:31.654462 2017] [wsgi:error] [pid 9486] [remote 85.26.235.239:25142]   File "/srv/http/virtlabs.tk/forsaje.tk/api.wsgi", line 1, in <module>
[Fri Dec 22 14:36:31.654488 2017] [wsgi:error] [pid 9486] [remote 85.26.235.239:25142]     from api import app as application
[Fri Dec 22 14:36:31.654518 2017] [wsgi:error] [pid 9486] [remote 85.26.235.239:25142]   File "/srv/http/virtlabs.tk/forsaje.tk/api.py", line 4, in <module>
[Fri Dec 22 14:36:31.654619 2017] [wsgi:error] [pid 9486] [remote 85.26.235.239:25142]     from flask import (
[Fri Dec 22 14:36:31.654700 2017] [wsgi:error] [pid 9486] [remote 85.26.235.239:25142] ImportError: cannot import name 'secret_key'
[Fri Dec 22 14:36:34.450105 2017] [wsgi:error] [pid 9486] [remote 85.26.235.239:17717] mod_wsgi (pid=9486): Target WSGI script '/srv/http/virtlabs.tk/forsaje.tk/api.wsgi' cannot be loaded as Python module.
[Fri Dec 22 14:36:34.450324 2017] [wsgi:error] [pid 9486] [remote 85.26.235.239:17717] mod_wsgi (pid=9486): Exception occurred processing WSGI script '/srv/http/virtlabs.tk/forsaje.tk/api.wsgi'.
[Fri Dec 22 14:36:34.450647 2017] [wsgi:error] [pid 9486] [remote 85.26.235.239:17717] Traceback (most recent call last):
[Fri Dec 22 14:36:34.450751 2017] [wsgi:error] [pid 9486] [remote 85.26.235.239:17717]   File "/srv/http/virtlabs.tk/forsaje.tk/api.wsgi", line 1, in <module>
[Fri Dec 22 14:36:34.450768 2017] [wsgi:error] [pid 9486] [remote 85.26.235.239:17717]     from api import app as application
[Fri Dec 22 14:36:34.450797 2017] [wsgi:error] [pid 9486] [remote 85.26.235.239:17717]   File "/srv/http/virtlabs.tk/forsaje.tk/api.py", line 4, in <module>
[Fri Dec 22 14:36:34.450811 2017] [wsgi:error] [pid 9486] [remote 85.26.235.239:17717]     from flask import (
[Fri Dec 22 14:36:34.450878 2017] [wsgi:error] [pid 9486] [remote 85.26.235.239:17717] ImportError: cannot import name 'secret_key'
[Fri Dec 22 14:36:34.525329 2017] [wsgi:error] [pid 9486] [remote 85.26.235.239:31941] mod_wsgi (pid=9486): Target WSGI script '/srv/http/virtlabs.tk/forsaje.tk/api.wsgi' cannot be loaded as Python module.
[Fri Dec 22 14:36:34.525492 2017] [wsgi:error] [pid 9486] [remote 85.26.235.239:31941] mod_wsgi (pid=9486): Exception occurred processing WSGI script '/srv/http/virtlabs.tk/forsaje.tk/api.wsgi'.
[Fri Dec 22 14:36:34.525783 2017] [wsgi:error] [pid 9486] [remote 85.26.235.239:31941] Traceback (most recent call last):
[Fri Dec 22 14:36:34.525871 2017] [wsgi:error] [pid 9486] [remote 85.26.235.239:31941]   File "/srv/http/virtlabs.tk/forsaje.tk/api.wsgi", line 1, in <module>
[Fri Dec 22 14:36:34.525888 2017] [wsgi:error] [pid 9486] [remote 85.26.235.239:31941]     from api import app as application
[Fri Dec 22 14:36:34.525916 2017] [wsgi:error] [pid 9486] [remote 85.26.235.239:31941]   File "/srv/http/virtlabs.tk/forsaje.tk/api.py", line 4, in <module>
[Fri Dec 22 14:36:34.525930 2017] [wsgi:error] [pid 9486] [remote 85.26.235.239:31941]     from flask import (
[Fri Dec 22 14:36:34.525981 2017] [wsgi:error] [pid 9486] [remote 85.26.235.239:31941] ImportError: cannot import name 'secret_key'
[Fri Dec 22 14:37:16.974579 2017] [wsgi:error] [pid 9486] [remote 85.26.235.239:21449] mod_wsgi (pid=9486): Target WSGI script '/srv/http/virtlabs.tk/forsaje.tk/api.wsgi' cannot be loaded as Python module.
[Fri Dec 22 14:37:16.974809 2017] [wsgi:error] [pid 9486] [remote 85.26.235.239:21449] mod_wsgi (pid=9486): Exception occurred processing WSGI script '/srv/http/virtlabs.tk/forsaje.tk/api.wsgi'.
[Fri Dec 22 14:37:16.975121 2017] [wsgi:error] [pid 9486] [remote 85.26.235.239:21449] Traceback (most recent call last):
[Fri Dec 22 14:37:16.975209 2017] [wsgi:error] [pid 9486] [remote 85.26.235.239:21449]   File "/srv/http/virtlabs.tk/forsaje.tk/api.wsgi", line 1, in <module>
[Fri Dec 22 14:37:16.975225 2017] [wsgi:error] [pid 9486] [remote 85.26.235.239:21449]     from api import app as application
[Fri Dec 22 14:37:16.975253 2017] [wsgi:error] [pid 9486] [remote 85.26.235.239:21449]   File "/srv/http/virtlabs.tk/forsaje.tk/api.py", line 4, in <module>
[Fri Dec 22 14:37:16.975267 2017] [wsgi:error] [pid 9486] [remote 85.26.235.239:21449]     from flask import (
[Fri Dec 22 14:37:16.975319 2017] [wsgi:error] [pid 9486] [remote 85.26.235.239:21449] ImportError: cannot import name 'secret_key'
[Fri Dec 22 14:38:12.952755 2017] [wsgi:error] [pid 9543] [remote 85.26.235.239:44878] [2017-12-22 14:38:12,948] ERROR in app: Exception on /work/ [GET]
[Fri Dec 22 14:38:12.952911 2017] [wsgi:error] [pid 9543] [remote 85.26.235.239:44878] Traceback (most recent call last):
[Fri Dec 22 14:38:12.953001 2017] [wsgi:error] [pid 9543] [remote 85.26.235.239:44878]   File "/usr/lib/python3.6/site-packages/flask/app.py", line 1982, in wsgi_app
[Fri Dec 22 14:38:12.953015 2017] [wsgi:error] [pid 9543] [remote 85.26.235.239:44878]     response = self.full_dispatch_request()
[Fri Dec 22 14:38:12.953025 2017] [wsgi:error] [pid 9543] [remote 85.26.235.239:44878]   File "/usr/lib/python3.6/site-packages/flask/app.py", line 1614, in full_dispatch_request
[Fri Dec 22 14:38:12.953034 2017] [wsgi:error] [pid 9543] [remote 85.26.235.239:44878]     rv = self.handle_user_exception(e)
[Fri Dec 22 14:38:12.953043 2017] [wsgi:error] [pid 9543] [remote 85.26.235.239:44878]   File "/usr/lib/python3.6/site-packages/flask/app.py", line 1517, in handle_user_exception
[Fri Dec 22 14:38:12.953052 2017] [wsgi:error] [pid 9543] [remote 85.26.235.239:44878]     reraise(exc_type, exc_value, tb)
[Fri Dec 22 14:38:12.953061 2017] [wsgi:error] [pid 9543] [remote 85.26.235.239:44878]   File "/usr/lib/python3.6/site-packages/flask/_compat.py", line 33, in reraise
[Fri Dec 22 14:38:12.953071 2017] [wsgi:error] [pid 9543] [remote 85.26.235.239:44878]     raise value
[Fri Dec 22 14:38:12.953079 2017] [wsgi:error] [pid 9543] [remote 85.26.235.239:44878]   File "/usr/lib/python3.6/site-packages/flask/app.py", line 1612, in full_dispatch_request
[Fri Dec 22 14:38:12.953089 2017] [wsgi:error] [pid 9543] [remote 85.26.235.239:44878]     rv = self.dispatch_request()
[Fri Dec 22 14:38:12.953098 2017] [wsgi:error] [pid 9543] [remote 85.26.235.239:44878]   File "/usr/lib/python3.6/site-packages/flask/app.py", line 1598, in dispatch_request
[Fri Dec 22 14:38:12.953107 2017] [wsgi:error] [pid 9543] [remote 85.26.235.239:44878]     return self.view_functions[rule.endpoint](**req.view_args)
[Fri Dec 22 14:38:12.953116 2017] [wsgi:error] [pid 9543] [remote 85.26.235.239:44878]   File "/srv/http/virtlabs.tk/forsaje.tk/api.py", line 134, in auth_check
[Fri Dec 22 14:38:12.953125 2017] [wsgi:error] [pid 9543] [remote 85.26.235.239:44878]     if id:
[Fri Dec 22 14:38:12.953141 2017] [wsgi:error] [pid 9543] [remote 85.26.235.239:44878] UnboundLocalError: local variable 'id' referenced before assignment
[Fri Dec 22 14:38:12.953204 2017] [wsgi:error] [pid 9543] [remote 85.26.235.239:44878] 
[Fri Dec 22 14:38:13.187445 2017] [wsgi:error] [pid 9543] [remote 85.26.235.239:62053] [2017-12-22 14:38:13,186] ERROR in app: Exception on /work/ [GET]
[Fri Dec 22 14:38:13.187575 2017] [wsgi:error] [pid 9543] [remote 85.26.235.239:62053] Traceback (most recent call last):
[Fri Dec 22 14:38:13.187602 2017] [wsgi:error] [pid 9543] [remote 85.26.235.239:62053]   File "/usr/lib/python3.6/site-packages/flask/app.py", line 1982, in wsgi_app
[Fri Dec 22 14:38:13.187615 2017] [wsgi:error] [pid 9543] [remote 85.26.235.239:62053]     response = self.full_dispatch_request()
[Fri Dec 22 14:38:13.187625 2017] [wsgi:error] [pid 9543] [remote 85.26.235.239:62053]   File "/usr/lib/python3.6/site-packages/flask/app.py", line 1614, in full_dispatch_request
[Fri Dec 22 14:38:13.187635 2017] [wsgi:error] [pid 9543] [remote 85.26.235.239:62053]     rv = self.handle_user_exception(e)
[Fri Dec 22 14:38:13.187874 2017] [wsgi:error] [pid 9543] [remote 85.26.235.239:62053]   File "/usr/lib/python3.6/site-packages/flask/app.py", line 1517, in handle_user_exception
[Fri Dec 22 14:38:13.187894 2017] [wsgi:error] [pid 9543] [remote 85.26.235.239:62053]     reraise(exc_type, exc_value, tb)
[Fri Dec 22 14:38:13.187904 2017] [wsgi:error] [pid 9543] [remote 85.26.235.239:62053]   File "/usr/lib/python3.6/site-packages/flask/_compat.py", line 33, in reraise
[Fri Dec 22 14:38:13.187914 2017] [wsgi:error] [pid 9543] [remote 85.26.235.239:62053]     raise value
[Fri Dec 22 14:38:13.187923 2017] [wsgi:error] [pid 9543] [remote 85.26.235.239:62053]   File "/usr/lib/python3.6/site-packages/flask/app.py", line 1612, in full_dispatch_request
[Fri Dec 22 14:38:13.187933 2017] [wsgi:error] [pid 9543] [remote 85.26.235.239:62053]     rv = self.dispatch_request()
[Fri Dec 22 14:38:13.188015 2017] [wsgi:error] [pid 9543] [remote 85.26.235.239:62053]   File "/usr/lib/python3.6/site-packages/flask/app.py", line 1598, in dispatch_request
[Fri Dec 22 14:38:13.188028 2017] [wsgi:error] [pid 9543] [remote 85.26.235.239:62053]     return self.view_functions[rule.endpoint](**req.view_args)
[Fri Dec 22 14:38:13.188037 2017] [wsgi:error] [pid 9543] [remote 85.26.235.239:62053]   File "/srv/http/virtlabs.tk/forsaje.tk/api.py", line 134, in auth_check
[Fri Dec 22 14:38:13.188047 2017] [wsgi:error] [pid 9543] [remote 85.26.235.239:62053]     if id:
[Fri Dec 22 14:38:13.188068 2017] [wsgi:error] [pid 9543] [remote 85.26.235.239:62053] UnboundLocalError: local variable 'id' referenced before assignment
[Fri Dec 22 14:38:13.188184 2017] [wsgi:error] [pid 9543] [remote 85.26.235.239:62053] 
[Fri Dec 22 14:38:14.686023 2017] [wsgi:error] [pid 9543] [remote 85.26.235.239:43331] [2017-12-22 14:38:14,685] ERROR in app: Exception on /work/ [GET]
[Fri Dec 22 14:38:14.686121 2017] [wsgi:error] [pid 9543] [remote 85.26.235.239:43331] Traceback (most recent call last):
[Fri Dec 22 14:38:14.686134 2017] [wsgi:error] [pid 9543] [remote 85.26.235.239:43331]   File "/usr/lib/python3.6/site-packages/flask/app.py", line 1982, in wsgi_app
[Fri Dec 22 14:38:14.686144 2017] [wsgi:error] [pid 9543] [remote 85.26.235.239:43331]     response = self.full_dispatch_request()
[Fri Dec 22 14:38:14.686154 2017] [wsgi:error] [pid 9543] [remote 85.26.235.239:43331]   File "/usr/lib/python3.6/site-packages/flask/app.py", line 1614, in full_dispatch_request
[Fri Dec 22 14:38:14.686163 2017] [wsgi:error] [pid 9543] [remote 85.26.235.239:43331]     rv = self.handle_user_exception(e)
[Fri Dec 22 14:38:14.686172 2017] [wsgi:error] [pid 9543] [remote 85.26.235.239:43331]   File "/usr/lib/python3.6/site-packages/flask/app.py", line 1517, in handle_user_exception
[Fri Dec 22 14:38:14.686182 2017] [wsgi:error] [pid 9543] [remote 85.26.235.239:43331]     reraise(exc_type, exc_value, tb)
[Fri Dec 22 14:38:14.686191 2017] [wsgi:error] [pid 9543] [remote 85.26.235.239:43331]   File "/usr/lib/python3.6/site-packages/flask/_compat.py", line 33, in reraise
[Fri Dec 22 14:38:14.686200 2017] [wsgi:error] [pid 9543] [remote 85.26.235.239:43331]     raise value
[Fri Dec 22 14:38:14.686208 2017] [wsgi:error] [pid 9543] [remote 85.26.235.239:43331]   File "/usr/lib/python3.6/site-packages/flask/app.py", line 1612, in full_dispatch_request
[Fri Dec 22 14:38:14.686218 2017] [wsgi:error] [pid 9543] [remote 85.26.235.239:43331]     rv = self.dispatch_request()
[Fri Dec 22 14:38:14.686226 2017] [wsgi:error] [pid 9543] [remote 85.26.235.239:43331]   File "/usr/lib/python3.6/site-packages/flask/app.py", line 1598, in dispatch_request
[Fri Dec 22 14:38:14.686236 2017] [wsgi:error] [pid 9543] [remote 85.26.235.239:43331]     return self.view_functions[rule.endpoint](**req.view_args)
[Fri Dec 22 14:38:14.686245 2017] [wsgi:error] [pid 9543] [remote 85.26.235.239:43331]   File "/srv/http/virtlabs.tk/forsaje.tk/api.py", line 134, in auth_check
[Fri Dec 22 14:38:14.686253 2017] [wsgi:error] [pid 9543] [remote 85.26.235.239:43331]     if id:
[Fri Dec 22 14:38:14.686267 2017] [wsgi:error] [pid 9543] [remote 85.26.235.239:43331] UnboundLocalError: local variable 'id' referenced before assignment
[Fri Dec 22 14:38:14.686313 2017] [wsgi:error] [pid 9543] [remote 85.26.235.239:43331] 
[Fri Dec 22 14:38:14.738259 2017] [wsgi:error] [pid 9543] [remote 85.26.235.239:31376] [2017-12-22 14:38:14,736] ERROR in app: Exception on /work/ [GET]
[Fri Dec 22 14:38:14.738335 2017] [wsgi:error] [pid 9543] [remote 85.26.235.239:31376] Traceback (most recent call last):
[Fri Dec 22 14:38:14.738348 2017] [wsgi:error] [pid 9543] [remote 85.26.235.239:31376]   File "/usr/lib/python3.6/site-packages/flask/app.py", line 1982, in wsgi_app
[Fri Dec 22 14:38:14.738359 2017] [wsgi:error] [pid 9543] [remote 85.26.235.239:31376]     response = self.full_dispatch_request()
[Fri Dec 22 14:38:14.738369 2017] [wsgi:error] [pid 9543] [remote 85.26.235.239:31376]   File "/usr/lib/python3.6/site-packages/flask/app.py", line 1614, in full_dispatch_request
[Fri Dec 22 14:38:14.738456 2017] [wsgi:error] [pid 9543] [remote 85.26.235.239:31376]     rv = self.handle_user_exception(e)
[Fri Dec 22 14:38:14.738468 2017] [wsgi:error] [pid 9543] [remote 85.26.235.239:31376]   File "/usr/lib/python3.6/site-packages/flask/app.py", line 1517, in handle_user_exception
[Fri Dec 22 14:38:14.738478 2017] [wsgi:error] [pid 9543] [remote 85.26.235.239:31376]     reraise(exc_type, exc_value, tb)
[Fri Dec 22 14:38:14.738486 2017] [wsgi:error] [pid 9543] [remote 85.26.235.239:31376]   File "/usr/lib/python3.6/site-packages/flask/_compat.py", line 33, in reraise
[Fri Dec 22 14:38:14.738496 2017] [wsgi:error] [pid 9543] [remote 85.26.235.239:31376]     raise value
[Fri Dec 22 14:38:14.738504 2017] [wsgi:error] [pid 9543] [remote 85.26.235.239:31376]   File "/usr/lib/python3.6/site-packages/flask/app.py", line 1612, in full_dispatch_request
[Fri Dec 22 14:38:14.738514 2017] [wsgi:error] [pid 9543] [remote 85.26.235.239:31376]     rv = self.dispatch_request()
[Fri Dec 22 14:38:14.738522 2017] [wsgi:error] [pid 9543] [remote 85.26.235.239:31376]   File "/usr/lib/python3.6/site-packages/flask/app.py", line 1598, in dispatch_request
[Fri Dec 22 14:38:14.738532 2017] [wsgi:error] [pid 9543] [remote 85.26.235.239:31376]     return self.view_functions[rule.endpoint](**req.view_args)
[Fri Dec 22 14:38:14.738541 2017] [wsgi:error] [pid 9543] [remote 85.26.235.239:31376]   File "/srv/http/virtlabs.tk/forsaje.tk/api.py", line 134, in auth_check
[Fri Dec 22 14:38:14.738550 2017] [wsgi:error] [pid 9543] [remote 85.26.235.239:31376]     if id:
[Fri Dec 22 14:38:14.738564 2017] [wsgi:error] [pid 9543] [remote 85.26.235.239:31376] UnboundLocalError: local variable 'id' referenced before assignment
[Fri Dec 22 14:38:14.738612 2017] [wsgi:error] [pid 9543] [remote 85.26.235.239:31376] 
[Fri Dec 22 14:38:27.595342 2017] [wsgi:error] [pid 9543] [remote 85.26.235.239:56503] [2017-12-22 14:38:27,594] ERROR in app: Exception on /work/ [GET]
[Fri Dec 22 14:38:27.595457 2017] [wsgi:error] [pid 9543] [remote 85.26.235.239:56503] Traceback (most recent call last):
[Fri Dec 22 14:38:27.595471 2017] [wsgi:error] [pid 9543] [remote 85.26.235.239:56503]   File "/usr/lib/python3.6/site-packages/flask/app.py", line 1982, in wsgi_app
[Fri Dec 22 14:38:27.595482 2017] [wsgi:error] [pid 9543] [remote 85.26.235.239:56503]     response = self.full_dispatch_request()
[Fri Dec 22 14:38:27.595491 2017] [wsgi:error] [pid 9543] [remote 85.26.235.239:56503]   File "/usr/lib/python3.6/site-packages/flask/app.py", line 1614, in full_dispatch_request
[Fri Dec 22 14:38:27.595501 2017] [wsgi:error] [pid 9543] [remote 85.26.235.239:56503]     rv = self.handle_user_exception(e)
[Fri Dec 22 14:38:27.595510 2017] [wsgi:error] [pid 9543] [remote 85.26.235.239:56503]   File "/usr/lib/python3.6/site-packages/flask/app.py", line 1517, in handle_user_exception
[Fri Dec 22 14:38:27.595520 2017] [wsgi:error] [pid 9543] [remote 85.26.235.239:56503]     reraise(exc_type, exc_value, tb)
[Fri Dec 22 14:38:27.595528 2017] [wsgi:error] [pid 9543] [remote 85.26.235.239:56503]   File "/usr/lib/python3.6/site-packages/flask/_compat.py", line 33, in reraise
[Fri Dec 22 14:38:27.595538 2017] [wsgi:error] [pid 9543] [remote 85.26.235.239:56503]     raise value
[Fri Dec 22 14:38:27.595546 2017] [wsgi:error] [pid 9543] [remote 85.26.235.239:56503]   File "/usr/lib/python3.6/site-packages/flask/app.py", line 1612, in full_dispatch_request
[Fri Dec 22 14:38:27.595556 2017] [wsgi:error] [pid 9543] [remote 85.26.235.239:56503]     rv = self.dispatch_request()
[Fri Dec 22 14:38:27.595564 2017] [wsgi:error] [pid 9543] [remote 85.26.235.239:56503]   File "/usr/lib/python3.6/site-packages/flask/app.py", line 1598, in dispatch_request
[Fri Dec 22 14:38:27.595574 2017] [wsgi:error] [pid 9543] [remote 85.26.235.239:56503]     return self.view_functions[rule.endpoint](**req.view_args)
[Fri Dec 22 14:38:27.595583 2017] [wsgi:error] [pid 9543] [remote 85.26.235.239:56503]   File "/srv/http/virtlabs.tk/forsaje.tk/api.py", line 134, in auth_check
[Fri Dec 22 14:38:27.595668 2017] [wsgi:error] [pid 9543] [remote 85.26.235.239:56503]     if id:
[Fri Dec 22 14:38:27.595685 2017] [wsgi:error] [pid 9543] [remote 85.26.235.239:56503] UnboundLocalError: local variable 'id' referenced before assignment
[Fri Dec 22 14:38:27.595737 2017] [wsgi:error] [pid 9543] [remote 85.26.235.239:56503] 
[Fri Dec 22 14:38:29.348712 2017] [wsgi:error] [pid 9543] [remote 85.26.235.239:42692] [2017-12-22 14:38:29,347] ERROR in app: Exception on /work/ [GET]
[Fri Dec 22 14:38:29.350016 2017] [wsgi:error] [pid 9543] [remote 85.26.235.239:42692] Traceback (most recent call last):
[Fri Dec 22 14:38:29.350048 2017] [wsgi:error] [pid 9543] [remote 85.26.235.239:42692]   File "/usr/lib/python3.6/site-packages/flask/app.py", line 1982, in wsgi_app
[Fri Dec 22 14:38:29.350059 2017] [wsgi:error] [pid 9543] [remote 85.26.235.239:42692]     response = self.full_dispatch_request()
[Fri Dec 22 14:38:29.350068 2017] [wsgi:error] [pid 9543] [remote 85.26.235.239:42692]   File "/usr/lib/python3.6/site-packages/flask/app.py", line 1614, in full_dispatch_request
[Fri Dec 22 14:38:29.350078 2017] [wsgi:error] [pid 9543] [remote 85.26.235.239:42692]     rv = self.handle_user_exception(e)
[Fri Dec 22 14:38:29.350086 2017] [wsgi:error] [pid 9543] [remote 85.26.235.239:42692]   File "/usr/lib/python3.6/site-packages/flask/app.py", line 1517, in handle_user_exception
[Fri Dec 22 14:38:29.350095 2017] [wsgi:error] [pid 9543] [remote 85.26.235.239:42692]     reraise(exc_type, exc_value, tb)
[Fri Dec 22 14:38:29.350104 2017] [wsgi:error] [pid 9543] [remote 85.26.235.239:42692]   File "/usr/lib/python3.6/site-packages/flask/_compat.py", line 33, in reraise
[Fri Dec 22 14:38:29.350113 2017] [wsgi:error] [pid 9543] [remote 85.26.235.239:42692]     raise value
[Fri Dec 22 14:38:29.350122 2017] [wsgi:error] [pid 9543] [remote 85.26.235.239:42692]   File "/usr/lib/python3.6/site-packages/flask/app.py", line 1612, in full_dispatch_request
[Fri Dec 22 14:38:29.350131 2017] [wsgi:error] [pid 9543] [remote 85.26.235.239:42692]     rv = self.dispatch_request()
[Fri Dec 22 14:38:29.350140 2017] [wsgi:error] [pid 9543] [remote 85.26.235.239:42692]   File "/usr/lib/python3.6/site-packages/flask/app.py", line 1598, in dispatch_request
[Fri Dec 22 14:38:29.350149 2017] [wsgi:error] [pid 9543] [remote 85.26.235.239:42692]     return self.view_functions[rule.endpoint](**req.view_args)
[Fri Dec 22 14:38:29.350158 2017] [wsgi:error] [pid 9543] [remote 85.26.235.239:42692]   File "/srv/http/virtlabs.tk/forsaje.tk/api.py", line 134, in auth_check
[Fri Dec 22 14:38:29.350167 2017] [wsgi:error] [pid 9543] [remote 85.26.235.239:42692]     if id:
[Fri Dec 22 14:38:29.350191 2017] [wsgi:error] [pid 9543] [remote 85.26.235.239:42692] UnboundLocalError: local variable 'id' referenced before assignment
[Fri Dec 22 14:38:29.350325 2017] [wsgi:error] [pid 9543] [remote 85.26.235.239:42692] 
[Fri Dec 22 14:38:29.447948 2017] [wsgi:error] [pid 9543] [remote 85.26.235.239:49656] [2017-12-22 14:38:29,446] ERROR in app: Exception on /work/ [GET]
[Fri Dec 22 14:38:29.448025 2017] [wsgi:error] [pid 9543] [remote 85.26.235.239:49656] Traceback (most recent call last):
[Fri Dec 22 14:38:29.448038 2017] [wsgi:error] [pid 9543] [remote 85.26.235.239:49656]   File "/usr/lib/python3.6/site-packages/flask/app.py", line 1982, in wsgi_app
[Fri Dec 22 14:38:29.448048 2017] [wsgi:error] [pid 9543] [remote 85.26.235.239:49656]     response = self.full_dispatch_request()
[Fri Dec 22 14:38:29.448057 2017] [wsgi:error] [pid 9543] [remote 85.26.235.239:49656]   File "/usr/lib/python3.6/site-packages/flask/app.py", line 1614, in full_dispatch_request
[Fri Dec 22 14:38:29.448066 2017] [wsgi:error] [pid 9543] [remote 85.26.235.239:49656]     rv = self.handle_user_exception(e)
[Fri Dec 22 14:38:29.448075 2017] [wsgi:error] [pid 9543] [remote 85.26.235.239:49656]   File "/usr/lib/python3.6/site-packages/flask/app.py", line 1517, in handle_user_exception
[Fri Dec 22 14:38:29.448085 2017] [wsgi:error] [pid 9543] [remote 85.26.235.239:49656]     reraise(exc_type, exc_value, tb)
[Fri Dec 22 14:38:29.448180 2017] [wsgi:error] [pid 9543] [remote 85.26.235.239:49656]   File "/usr/lib/python3.6/site-packages/flask/_compat.py", line 33, in reraise
[Fri Dec 22 14:38:29.448192 2017] [wsgi:error] [pid 9543] [remote 85.26.235.239:49656]     raise value
[Fri Dec 22 14:38:29.448201 2017] [wsgi:error] [pid 9543] [remote 85.26.235.239:49656]   File "/usr/lib/python3.6/site-packages/flask/app.py", line 1612, in full_dispatch_request
[Fri Dec 22 14:38:29.448210 2017] [wsgi:error] [pid 9543] [remote 85.26.235.239:49656]     rv = self.dispatch_request()
[Fri Dec 22 14:38:29.448219 2017] [wsgi:error] [pid 9543] [remote 85.26.235.239:49656]   File "/usr/lib/python3.6/site-packages/flask/app.py", line 1598, in dispatch_request
[Fri Dec 22 14:38:29.448229 2017] [wsgi:error] [pid 9543] [remote 85.26.235.239:49656]     return self.view_functions[rule.endpoint](**req.view_args)
[Fri Dec 22 14:38:29.448238 2017] [wsgi:error] [pid 9543] [remote 85.26.235.239:49656]   File "/srv/http/virtlabs.tk/forsaje.tk/api.py", line 134, in auth_check
[Fri Dec 22 14:38:29.448247 2017] [wsgi:error] [pid 9543] [remote 85.26.235.239:49656]     if id:
[Fri Dec 22 14:38:29.448261 2017] [wsgi:error] [pid 9543] [remote 85.26.235.239:49656] UnboundLocalError: local variable 'id' referenced before assignment
[Fri Dec 22 14:38:29.448326 2017] [wsgi:error] [pid 9543] [remote 85.26.235.239:49656] 
[Fri Dec 22 14:38:34.771592 2017] [wsgi:error] [pid 9543] [remote 85.26.235.239:30005] [2017-12-22 14:38:34,770] ERROR in app: Exception on /work/ [GET]
[Fri Dec 22 14:38:34.771719 2017] [wsgi:error] [pid 9543] [remote 85.26.235.239:30005] Traceback (most recent call last):
[Fri Dec 22 14:38:34.771733 2017] [wsgi:error] [pid 9543] [remote 85.26.235.239:30005]   File "/usr/lib/python3.6/site-packages/flask/app.py", line 1982, in wsgi_app
[Fri Dec 22 14:38:34.771743 2017] [wsgi:error] [pid 9543] [remote 85.26.235.239:30005]     response = self.full_dispatch_request()
[Fri Dec 22 14:38:34.771753 2017] [wsgi:error] [pid 9543] [remote 85.26.235.239:30005]   File "/usr/lib/python3.6/site-packages/flask/app.py", line 1614, in full_dispatch_request
[Fri Dec 22 14:38:34.771763 2017] [wsgi:error] [pid 9543] [remote 85.26.235.239:30005]     rv = self.handle_user_exception(e)
[Fri Dec 22 14:38:34.771772 2017] [wsgi:error] [pid 9543] [remote 85.26.235.239:30005]   File "/usr/lib/python3.6/site-packages/flask/app.py", line 1517, in handle_user_exception
[Fri Dec 22 14:38:34.771782 2017] [wsgi:error] [pid 9543] [remote 85.26.235.239:30005]     reraise(exc_type, exc_value, tb)
[Fri Dec 22 14:38:34.771791 2017] [wsgi:error] [pid 9543] [remote 85.26.235.239:30005]   File "/usr/lib/python3.6/site-packages/flask/_compat.py", line 33, in reraise
[Fri Dec 22 14:38:34.771800 2017] [wsgi:error] [pid 9543] [remote 85.26.235.239:30005]     raise value
[Fri Dec 22 14:38:34.771809 2017] [wsgi:error] [pid 9543] [remote 85.26.235.239:30005]   File "/usr/lib/python3.6/site-packages/flask/app.py", line 1612, in full_dispatch_request
[Fri Dec 22 14:38:34.771818 2017] [wsgi:error] [pid 9543] [remote 85.26.235.239:30005]     rv = self.dispatch_request()
[Fri Dec 22 14:38:34.771827 2017] [wsgi:error] [pid 9543] [remote 85.26.235.239:30005]   File "/usr/lib/python3.6/site-packages/flask/app.py", line 1598, in dispatch_request
[Fri Dec 22 14:38:34.771836 2017] [wsgi:error] [pid 9543] [remote 85.26.235.239:30005]     return self.view_functions[rule.endpoint](**req.view_args)
[Fri Dec 22 14:38:34.771846 2017] [wsgi:error] [pid 9543] [remote 85.26.235.239:30005]   File "/srv/http/virtlabs.tk/forsaje.tk/api.py", line 134, in auth_check
[Fri Dec 22 14:38:34.771855 2017] [wsgi:error] [pid 9543] [remote 85.26.235.239:30005]     if id:
[Fri Dec 22 14:38:34.771869 2017] [wsgi:error] [pid 9543] [remote 85.26.235.239:30005] UnboundLocalError: local variable 'id' referenced before assignment
[Fri Dec 22 14:38:34.771922 2017] [wsgi:error] [pid 9543] [remote 85.26.235.239:30005] 
[Fri Dec 22 14:38:34.841789 2017] [wsgi:error] [pid 9543] [remote 85.26.235.239:33414] [2017-12-22 14:38:34,840] ERROR in app: Exception on /work/ [GET]
[Fri Dec 22 14:38:34.841952 2017] [wsgi:error] [pid 9543] [remote 85.26.235.239:33414] Traceback (most recent call last):
[Fri Dec 22 14:38:34.841967 2017] [wsgi:error] [pid 9543] [remote 85.26.235.239:33414]   File "/usr/lib/python3.6/site-packages/flask/app.py", line 1982, in wsgi_app
[Fri Dec 22 14:38:34.841978 2017] [wsgi:error] [pid 9543] [remote 85.26.235.239:33414]     response = self.full_dispatch_request()
[Fri Dec 22 14:38:34.841987 2017] [wsgi:error] [pid 9543] [remote 85.26.235.239:33414]   File "/usr/lib/python3.6/site-packages/flask/app.py", line 1614, in full_dispatch_request
[Fri Dec 22 14:38:34.841996 2017] [wsgi:error] [pid 9543] [remote 85.26.235.239:33414]     rv = self.handle_user_exception(e)
[Fri Dec 22 14:38:34.842005 2017] [wsgi:error] [pid 9543] [remote 85.26.235.239:33414]   File "/usr/lib/python3.6/site-packages/flask/app.py", line 1517, in handle_user_exception
[Fri Dec 22 14:38:34.842014 2017] [wsgi:error] [pid 9543] [remote 85.26.235.239:33414]     reraise(exc_type, exc_value, tb)
[Fri Dec 22 14:38:34.842023 2017] [wsgi:error] [pid 9543] [remote 85.26.235.239:33414]   File "/usr/lib/python3.6/site-packages/flask/_compat.py", line 33, in reraise
[Fri Dec 22 14:38:34.842032 2017] [wsgi:error] [pid 9543] [remote 85.26.235.239:33414]     raise value
[Fri Dec 22 14:38:34.842041 2017] [wsgi:error] [pid 9543] [remote 85.26.235.239:33414]   File "/usr/lib/python3.6/site-packages/flask/app.py", line 1612, in full_dispatch_request
[Fri Dec 22 14:38:34.842050 2017] [wsgi:error] [pid 9543] [remote 85.26.235.239:33414]     rv = self.dispatch_request()
[Fri Dec 22 14:38:34.842059 2017] [wsgi:error] [pid 9543] [remote 85.26.235.239:33414]   File "/usr/lib/python3.6/site-packages/flask/app.py", line 1598, in dispatch_request
[Fri Dec 22 14:38:34.842068 2017] [wsgi:error] [pid 9543] [remote 85.26.235.239:33414]     return self.view_functions[rule.endpoint](**req.view_args)
[Fri Dec 22 14:38:34.842077 2017] [wsgi:error] [pid 9543] [remote 85.26.235.239:33414]   File "/srv/http/virtlabs.tk/forsaje.tk/api.py", line 134, in auth_check
[Fri Dec 22 14:38:34.842086 2017] [wsgi:error] [pid 9543] [remote 85.26.235.239:33414]     if id:
[Fri Dec 22 14:38:34.842100 2017] [wsgi:error] [pid 9543] [remote 85.26.235.239:33414] UnboundLocalError: local variable 'id' referenced before assignment
[Fri Dec 22 14:38:34.842149 2017] [wsgi:error] [pid 9543] [remote 85.26.235.239:33414] 
[Fri Dec 22 15:00:39.072358 2017] [wsgi:error] [pid 9758] [remote 85.26.235.239:55108] mod_wsgi (pid=9758): Target WSGI script '/srv/http/virtlabs.tk/forsaje.tk/api.wsgi' cannot be loaded as Python module.
[Fri Dec 22 15:00:39.072596 2017] [wsgi:error] [pid 9758] [remote 85.26.235.239:55108] mod_wsgi (pid=9758): Exception occurred processing WSGI script '/srv/http/virtlabs.tk/forsaje.tk/api.wsgi'.
[Fri Dec 22 15:00:39.073905 2017] [wsgi:error] [pid 9758] [remote 85.26.235.239:55108] Traceback (most recent call last):
[Fri Dec 22 15:00:39.074053 2017] [wsgi:error] [pid 9758] [remote 85.26.235.239:55108]   File "/srv/http/virtlabs.tk/forsaje.tk/api.wsgi", line 1, in <module>
[Fri Dec 22 15:00:39.074072 2017] [wsgi:error] [pid 9758] [remote 85.26.235.239:55108]     from api import app as application
[Fri Dec 22 15:00:39.074100 2017] [wsgi:error] [pid 9758] [remote 85.26.235.239:55108]   File "/srv/http/virtlabs.tk/forsaje.tk/api.py", line 17, in <module>
[Fri Dec 22 15:00:39.074114 2017] [wsgi:error] [pid 9758] [remote 85.26.235.239:55108]     from session_interface import MySessionInterface
[Fri Dec 22 15:00:39.074175 2017] [wsgi:error] [pid 9758] [remote 85.26.235.239:55108]   File "/srv/http/virtlabs.tk/forsaje.tk/session_interface.py", line 4
[Fri Dec 22 15:00:39.074326 2017] [wsgi:error] [pid 9758] [remote 85.26.235.239:55108]     def __init__:
[Fri Dec 22 15:00:39.074411 2017] [wsgi:error] [pid 9758] [remote 85.26.235.239:55108]                 ^
[Fri Dec 22 15:00:39.074446 2017] [wsgi:error] [pid 9758] [remote 85.26.235.239:55108] SyntaxError: invalid syntax
[Fri Dec 22 15:01:38.384787 2017] [wsgi:error] [pid 9802] [remote 85.26.235.239:27476] mod_wsgi (pid=9802): Target WSGI script '/srv/http/virtlabs.tk/forsaje.tk/api.wsgi' cannot be loaded as Python module.
[Fri Dec 22 15:01:38.385057 2017] [wsgi:error] [pid 9802] [remote 85.26.235.239:27476] mod_wsgi (pid=9802): Exception occurred processing WSGI script '/srv/http/virtlabs.tk/forsaje.tk/api.wsgi'.
[Fri Dec 22 15:01:38.386353 2017] [wsgi:error] [pid 9802] [remote 85.26.235.239:27476] Traceback (most recent call last):
[Fri Dec 22 15:01:38.386497 2017] [wsgi:error] [pid 9802] [remote 85.26.235.239:27476]   File "/srv/http/virtlabs.tk/forsaje.tk/api.wsgi", line 1, in <module>
[Fri Dec 22 15:01:38.386516 2017] [wsgi:error] [pid 9802] [remote 85.26.235.239:27476]     from api import app as application
[Fri Dec 22 15:01:38.386545 2017] [wsgi:error] [pid 9802] [remote 85.26.235.239:27476]   File "/srv/http/virtlabs.tk/forsaje.tk/api.py", line 20, in <module>
[Fri Dec 22 15:01:38.386558 2017] [wsgi:error] [pid 9802] [remote 85.26.235.239:27476]     app.session.permanent = True
[Fri Dec 22 15:01:38.386622 2017] [wsgi:error] [pid 9802] [remote 85.26.235.239:27476] AttributeError: 'Flask' object has no attribute 'session'
[Fri Dec 22 15:01:38.389651 2017] [wsgi:error] [pid 9802] [remote 85.26.235.239:60198] mod_wsgi (pid=9802): Target WSGI script '/srv/http/virtlabs.tk/forsaje.tk/api.wsgi' cannot be loaded as Python module.
[Fri Dec 22 15:01:38.389839 2017] [wsgi:error] [pid 9802] [remote 85.26.235.239:60198] mod_wsgi (pid=9802): Exception occurred processing WSGI script '/srv/http/virtlabs.tk/forsaje.tk/api.wsgi'.
[Fri Dec 22 15:01:38.390160 2017] [wsgi:error] [pid 9802] [remote 85.26.235.239:60198] Traceback (most recent call last):
[Fri Dec 22 15:01:38.390265 2017] [wsgi:error] [pid 9802] [remote 85.26.235.239:60198]   File "/srv/http/virtlabs.tk/forsaje.tk/api.wsgi", line 1, in <module>
[Fri Dec 22 15:01:38.390282 2017] [wsgi:error] [pid 9802] [remote 85.26.235.239:60198]     from api import app as application
[Fri Dec 22 15:01:38.390311 2017] [wsgi:error] [pid 9802] [remote 85.26.235.239:60198]   File "/srv/http/virtlabs.tk/forsaje.tk/api.py", line 20, in <module>
[Fri Dec 22 15:01:38.390326 2017] [wsgi:error] [pid 9802] [remote 85.26.235.239:60198]     app.session.permanent = True
[Fri Dec 22 15:01:38.390387 2017] [wsgi:error] [pid 9802] [remote 85.26.235.239:60198] AttributeError: 'Flask' object has no attribute 'session'
[Fri Dec 22 15:01:38.393935 2017] [wsgi:error] [pid 9802] [remote 85.26.235.239:47251] mod_wsgi (pid=9802): Target WSGI script '/srv/http/virtlabs.tk/forsaje.tk/api.wsgi' cannot be loaded as Python module.
[Fri Dec 22 15:01:38.394136 2017] [wsgi:error] [pid 9802] [remote 85.26.235.239:47251] mod_wsgi (pid=9802): Exception occurred processing WSGI script '/srv/http/virtlabs.tk/forsaje.tk/api.wsgi'.
[Fri Dec 22 15:01:38.400125 2017] [wsgi:error] [pid 9802] [remote 85.26.235.239:47251] Traceback (most recent call last):
[Fri Dec 22 15:01:38.400271 2017] [wsgi:error] [pid 9802] [remote 85.26.235.239:47251]   File "/srv/http/virtlabs.tk/forsaje.tk/api.wsgi", line 1, in <module>
[Fri Dec 22 15:01:38.400290 2017] [wsgi:error] [pid 9802] [remote 85.26.235.239:47251]     from api import app as application
[Fri Dec 22 15:01:38.400317 2017] [wsgi:error] [pid 9802] [remote 85.26.235.239:47251]   File "/srv/http/virtlabs.tk/forsaje.tk/api.py", line 20, in <module>
[Fri Dec 22 15:01:38.400331 2017] [wsgi:error] [pid 9802] [remote 85.26.235.239:47251]     app.session.permanent = True
[Fri Dec 22 15:01:38.400387 2017] [wsgi:error] [pid 9802] [remote 85.26.235.239:47251] AttributeError: 'Flask' object has no attribute 'session'
[Fri Dec 22 15:01:38.403227 2017] [wsgi:error] [pid 9802] [remote 85.26.235.239:56972] mod_wsgi (pid=9802): Target WSGI script '/srv/http/virtlabs.tk/forsaje.tk/api.wsgi' cannot be loaded as Python module.
[Fri Dec 22 15:01:38.403418 2017] [wsgi:error] [pid 9802] [remote 85.26.235.239:56972] mod_wsgi (pid=9802): Exception occurred processing WSGI script '/srv/http/virtlabs.tk/forsaje.tk/api.wsgi'.
[Fri Dec 22 15:01:38.403829 2017] [wsgi:error] [pid 9802] [remote 85.26.235.239:56972] Traceback (most recent call last):
[Fri Dec 22 15:01:38.403927 2017] [wsgi:error] [pid 9802] [remote 85.26.235.239:56972]   File "/srv/http/virtlabs.tk/forsaje.tk/api.wsgi", line 1, in <module>
[Fri Dec 22 15:01:38.403945 2017] [wsgi:error] [pid 9802] [remote 85.26.235.239:56972]     from api import app as application
[Fri Dec 22 15:01:38.403972 2017] [wsgi:error] [pid 9802] [remote 85.26.235.239:56972]   File "/srv/http/virtlabs.tk/forsaje.tk/api.py", line 20, in <module>
[Fri Dec 22 15:01:38.403986 2017] [wsgi:error] [pid 9802] [remote 85.26.235.239:56972]     app.session.permanent = True
[Fri Dec 22 15:01:38.404041 2017] [wsgi:error] [pid 9802] [remote 85.26.235.239:56972] AttributeError: 'Flask' object has no attribute 'session'
[Fri Dec 22 15:01:39.096185 2017] [wsgi:error] [pid 9802] [remote 85.26.235.239:61256] mod_wsgi (pid=9802): Target WSGI script '/srv/http/virtlabs.tk/forsaje.tk/api.wsgi' cannot be loaded as Python module.
[Fri Dec 22 15:01:39.096404 2017] [wsgi:error] [pid 9802] [remote 85.26.235.239:61256] mod_wsgi (pid=9802): Exception occurred processing WSGI script '/srv/http/virtlabs.tk/forsaje.tk/api.wsgi'.
[Fri Dec 22 15:01:39.096723 2017] [wsgi:error] [pid 9802] [remote 85.26.235.239:61256] Traceback (most recent call last):
[Fri Dec 22 15:01:39.096825 2017] [wsgi:error] [pid 9802] [remote 85.26.235.239:61256]   File "/srv/http/virtlabs.tk/forsaje.tk/api.wsgi", line 1, in <module>
[Fri Dec 22 15:01:39.096841 2017] [wsgi:error] [pid 9802] [remote 85.26.235.239:61256]     from api import app as application
[Fri Dec 22 15:01:39.096870 2017] [wsgi:error] [pid 9802] [remote 85.26.235.239:61256]   File "/srv/http/virtlabs.tk/forsaje.tk/api.py", line 20, in <module>
[Fri Dec 22 15:01:39.096885 2017] [wsgi:error] [pid 9802] [remote 85.26.235.239:61256]     app.session.permanent = True
[Fri Dec 22 15:01:39.096937 2017] [wsgi:error] [pid 9802] [remote 85.26.235.239:61256] AttributeError: 'Flask' object has no attribute 'session'
[Fri Dec 22 15:01:39.215361 2017] [wsgi:error] [pid 9802] [remote 85.26.235.239:54180] mod_wsgi (pid=9802): Target WSGI script '/srv/http/virtlabs.tk/forsaje.tk/api.wsgi' cannot be loaded as Python module.
[Fri Dec 22 15:01:39.215537 2017] [wsgi:error] [pid 9802] [remote 85.26.235.239:54180] mod_wsgi (pid=9802): Exception occurred processing WSGI script '/srv/http/virtlabs.tk/forsaje.tk/api.wsgi'.
[Fri Dec 22 15:01:39.215845 2017] [wsgi:error] [pid 9802] [remote 85.26.235.239:54180] Traceback (most recent call last):
[Fri Dec 22 15:01:39.215935 2017] [wsgi:error] [pid 9802] [remote 85.26.235.239:54180]   File "/srv/http/virtlabs.tk/forsaje.tk/api.wsgi", line 1, in <module>
[Fri Dec 22 15:01:39.215952 2017] [wsgi:error] [pid 9802] [remote 85.26.235.239:54180]     from api import app as application
[Fri Dec 22 15:01:39.215980 2017] [wsgi:error] [pid 9802] [remote 85.26.235.239:54180]   File "/srv/http/virtlabs.tk/forsaje.tk/api.py", line 20, in <module>
[Fri Dec 22 15:01:39.215995 2017] [wsgi:error] [pid 9802] [remote 85.26.235.239:54180]     app.session.permanent = True
[Fri Dec 22 15:01:39.216046 2017] [wsgi:error] [pid 9802] [remote 85.26.235.239:54180] AttributeError: 'Flask' object has no attribute 'session'
[Fri Dec 22 15:01:39.361576 2017] [wsgi:error] [pid 9802] [remote 85.26.235.239:18925] mod_wsgi (pid=9802): Target WSGI script '/srv/http/virtlabs.tk/forsaje.tk/api.wsgi' cannot be loaded as Python module.
[Fri Dec 22 15:01:39.361742 2017] [wsgi:error] [pid 9802] [remote 85.26.235.239:18925] mod_wsgi (pid=9802): Exception occurred processing WSGI script '/srv/http/virtlabs.tk/forsaje.tk/api.wsgi'.
[Fri Dec 22 15:01:39.362049 2017] [wsgi:error] [pid 9802] [remote 85.26.235.239:18925] Traceback (most recent call last):
[Fri Dec 22 15:01:39.362139 2017] [wsgi:error] [pid 9802] [remote 85.26.235.239:18925]   File "/srv/http/virtlabs.tk/forsaje.tk/api.wsgi", line 1, in <module>
[Fri Dec 22 15:01:39.362157 2017] [wsgi:error] [pid 9802] [remote 85.26.235.239:18925]     from api import app as application
[Fri Dec 22 15:01:39.362268 2017] [wsgi:error] [pid 9802] [remote 85.26.235.239:18925]   File "/srv/http/virtlabs.tk/forsaje.tk/api.py", line 20, in <module>
[Fri Dec 22 15:01:39.362284 2017] [wsgi:error] [pid 9802] [remote 85.26.235.239:18925]     app.session.permanent = True
[Fri Dec 22 15:01:39.362338 2017] [wsgi:error] [pid 9802] [remote 85.26.235.239:18925] AttributeError: 'Flask' object has no attribute 'session'
[Fri Dec 22 15:01:39.465414 2017] [wsgi:error] [pid 9802] [remote 85.26.235.239:13811] mod_wsgi (pid=9802): Target WSGI script '/srv/http/virtlabs.tk/forsaje.tk/api.wsgi' cannot be loaded as Python module.
[Fri Dec 22 15:01:39.465589 2017] [wsgi:error] [pid 9802] [remote 85.26.235.239:13811] mod_wsgi (pid=9802): Exception occurred processing WSGI script '/srv/http/virtlabs.tk/forsaje.tk/api.wsgi'.
[Fri Dec 22 15:01:39.465896 2017] [wsgi:error] [pid 9802] [remote 85.26.235.239:13811] Traceback (most recent call last):
[Fri Dec 22 15:01:39.465986 2017] [wsgi:error] [pid 9802] [remote 85.26.235.239:13811]   File "/srv/http/virtlabs.tk/forsaje.tk/api.wsgi", line 1, in <module>
[Fri Dec 22 15:01:39.466004 2017] [wsgi:error] [pid 9802] [remote 85.26.235.239:13811]     from api import app as application
[Fri Dec 22 15:01:39.466032 2017] [wsgi:error] [pid 9802] [remote 85.26.235.239:13811]   File "/srv/http/virtlabs.tk/forsaje.tk/api.py", line 20, in <module>
[Fri Dec 22 15:01:39.466045 2017] [wsgi:error] [pid 9802] [remote 85.26.235.239:13811]     app.session.permanent = True
[Fri Dec 22 15:01:39.466096 2017] [wsgi:error] [pid 9802] [remote 85.26.235.239:13811] AttributeError: 'Flask' object has no attribute 'session'
[Fri Dec 22 15:01:39.521583 2017] [wsgi:error] [pid 9802] [remote 85.26.235.239:1226] mod_wsgi (pid=9802): Target WSGI script '/srv/http/virtlabs.tk/forsaje.tk/api.wsgi' cannot be loaded as Python module.
[Fri Dec 22 15:01:39.521748 2017] [wsgi:error] [pid 9802] [remote 85.26.235.239:1226] mod_wsgi (pid=9802): Exception occurred processing WSGI script '/srv/http/virtlabs.tk/forsaje.tk/api.wsgi'.
[Fri Dec 22 15:01:39.522054 2017] [wsgi:error] [pid 9802] [remote 85.26.235.239:1226] Traceback (most recent call last):
[Fri Dec 22 15:01:39.522143 2017] [wsgi:error] [pid 9802] [remote 85.26.235.239:1226]   File "/srv/http/virtlabs.tk/forsaje.tk/api.wsgi", line 1, in <module>
[Fri Dec 22 15:01:39.522160 2017] [wsgi:error] [pid 9802] [remote 85.26.235.239:1226]     from api import app as application
[Fri Dec 22 15:01:39.522188 2017] [wsgi:error] [pid 9802] [remote 85.26.235.239:1226]   File "/srv/http/virtlabs.tk/forsaje.tk/api.py", line 20, in <module>
[Fri Dec 22 15:01:39.522202 2017] [wsgi:error] [pid 9802] [remote 85.26.235.239:1226]     app.session.permanent = True
[Fri Dec 22 15:01:39.522253 2017] [wsgi:error] [pid 9802] [remote 85.26.235.239:1226] AttributeError: 'Flask' object has no attribute 'session'
[Fri Dec 22 15:14:39.331700 2017] [wsgi:error] [pid 9911] [remote 85.26.235.239:24526] mod_wsgi (pid=9911): Target WSGI script '/srv/http/virtlabs.tk/forsaje.tk/api.wsgi' cannot be loaded as Python module.
[Fri Dec 22 15:14:39.331973 2017] [wsgi:error] [pid 9911] [remote 85.26.235.239:24526] mod_wsgi (pid=9911): Exception occurred processing WSGI script '/srv/http/virtlabs.tk/forsaje.tk/api.wsgi'.
[Fri Dec 22 15:14:39.333268 2017] [wsgi:error] [pid 9911] [remote 85.26.235.239:24526] Traceback (most recent call last):
[Fri Dec 22 15:14:39.333415 2017] [wsgi:error] [pid 9911] [remote 85.26.235.239:24526]   File "/srv/http/virtlabs.tk/forsaje.tk/api.wsgi", line 1, in <module>
[Fri Dec 22 15:14:39.333434 2017] [wsgi:error] [pid 9911] [remote 85.26.235.239:24526]     from api import app as application
[Fri Dec 22 15:14:39.333463 2017] [wsgi:error] [pid 9911] [remote 85.26.235.239:24526]   File "/srv/http/virtlabs.tk/forsaje.tk/api.py", line 20, in <module>
[Fri Dec 22 15:14:39.333478 2017] [wsgi:error] [pid 9911] [remote 85.26.235.239:24526]     app.session.permanent = True
[Fri Dec 22 15:14:39.333541 2017] [wsgi:error] [pid 9911] [remote 85.26.235.239:24526] AttributeError: 'Flask' object has no attribute 'session'
[Fri Dec 22 15:25:30.932182 2017] [wsgi:error] [pid 10133] [remote 85.26.235.239:10004] [2017-12-22 15:25:30,918] ERROR in app: Exception on /work/check_worker [POST]
[Fri Dec 22 15:25:30.932344 2017] [wsgi:error] [pid 10133] [remote 85.26.235.239:10004] Traceback (most recent call last):
[Fri Dec 22 15:25:30.932358 2017] [wsgi:error] [pid 10133] [remote 85.26.235.239:10004]   File "/usr/lib/python3.6/site-packages/flask/app.py", line 1982, in wsgi_app
[Fri Dec 22 15:25:30.932369 2017] [wsgi:error] [pid 10133] [remote 85.26.235.239:10004]     response = self.full_dispatch_request()
[Fri Dec 22 15:25:30.932379 2017] [wsgi:error] [pid 10133] [remote 85.26.235.239:10004]   File "/usr/lib/python3.6/site-packages/flask/app.py", line 1614, in full_dispatch_request
[Fri Dec 22 15:25:30.932388 2017] [wsgi:error] [pid 10133] [remote 85.26.235.239:10004]     rv = self.handle_user_exception(e)
[Fri Dec 22 15:25:30.932397 2017] [wsgi:error] [pid 10133] [remote 85.26.235.239:10004]   File "/usr/lib/python3.6/site-packages/flask/app.py", line 1517, in handle_user_exception
[Fri Dec 22 15:25:30.932407 2017] [wsgi:error] [pid 10133] [remote 85.26.235.239:10004]     reraise(exc_type, exc_value, tb)
[Fri Dec 22 15:25:30.932416 2017] [wsgi:error] [pid 10133] [remote 85.26.235.239:10004]   File "/usr/lib/python3.6/site-packages/flask/_compat.py", line 33, in reraise
[Fri Dec 22 15:25:30.932426 2017] [wsgi:error] [pid 10133] [remote 85.26.235.239:10004]     raise value
[Fri Dec 22 15:25:30.932434 2017] [wsgi:error] [pid 10133] [remote 85.26.235.239:10004]   File "/usr/lib/python3.6/site-packages/flask/app.py", line 1612, in full_dispatch_request
[Fri Dec 22 15:25:30.932444 2017] [wsgi:error] [pid 10133] [remote 85.26.235.239:10004]     rv = self.dispatch_request()
[Fri Dec 22 15:25:30.932453 2017] [wsgi:error] [pid 10133] [remote 85.26.235.239:10004]   File "/usr/lib/python3.6/site-packages/flask/app.py", line 1598, in dispatch_request
[Fri Dec 22 15:25:30.932464 2017] [wsgi:error] [pid 10133] [remote 85.26.235.239:10004]     return self.view_functions[rule.endpoint](**req.view_args)
[Fri Dec 22 15:25:30.932474 2017] [wsgi:error] [pid 10133] [remote 85.26.235.239:10004]   File "/srv/http/virtlabs.tk/forsaje.tk/api.py", line 152, in check_worker
[Fri Dec 22 15:25:30.932483 2017] [wsgi:error] [pid 10133] [remote 85.26.235.239:10004]     resp.set_cookie('id', user.id)
[Fri Dec 22 15:25:30.932492 2017] [wsgi:error] [pid 10133] [remote 85.26.235.239:10004]   File "/usr/lib/python3.6/site-packages/werkzeug/wrappers.py", line 1064, in set_cookie
[Fri Dec 22 15:25:30.932502 2017] [wsgi:error] [pid 10133] [remote 85.26.235.239:10004]     charset=self.charset))
[Fri Dec 22 15:25:30.932510 2017] [wsgi:error] [pid 10133] [remote 85.26.235.239:10004]   File "/usr/lib/python3.6/site-packages/werkzeug/http.py", line 978, in dump_cookie
[Fri Dec 22 15:25:30.932520 2017] [wsgi:error] [pid 10133] [remote 85.26.235.239:10004]     value = to_bytes(value, charset)
[Fri Dec 22 15:25:30.932529 2017] [wsgi:error] [pid 10133] [remote 85.26.235.239:10004]   File "/usr/lib/python3.6/site-packages/werkzeug/_compat.py", line 190, in to_bytes
[Fri Dec 22 15:25:30.932538 2017] [wsgi:error] [pid 10133] [remote 85.26.235.239:10004]     raise TypeError('Expected bytes')
[Fri Dec 22 15:25:30.932553 2017] [wsgi:error] [pid 10133] [remote 85.26.235.239:10004] TypeError: Expected bytes
[Fri Dec 22 15:25:30.932608 2017] [wsgi:error] [pid 10133] [remote 85.26.235.239:10004] 
[Fri Dec 22 15:33:23.974256 2017] [wsgi:error] [pid 10204] [remote 85.26.235.239:37987] [2017-12-22 15:33:23,969] ERROR in app: Exception on /work/check_worker [POST]
[Fri Dec 22 15:33:23.974422 2017] [wsgi:error] [pid 10204] [remote 85.26.235.239:37987] Traceback (most recent call last):
[Fri Dec 22 15:33:23.974436 2017] [wsgi:error] [pid 10204] [remote 85.26.235.239:37987]   File "/usr/lib/python3.6/site-packages/flask/app.py", line 1982, in wsgi_app
[Fri Dec 22 15:33:23.974447 2017] [wsgi:error] [pid 10204] [remote 85.26.235.239:37987]     response = self.full_dispatch_request()
[Fri Dec 22 15:33:23.974541 2017] [wsgi:error] [pid 10204] [remote 85.26.235.239:37987]   File "/usr/lib/python3.6/site-packages/flask/app.py", line 1614, in full_dispatch_request
[Fri Dec 22 15:33:23.974554 2017] [wsgi:error] [pid 10204] [remote 85.26.235.239:37987]     rv = self.handle_user_exception(e)
[Fri Dec 22 15:33:23.974564 2017] [wsgi:error] [pid 10204] [remote 85.26.235.239:37987]   File "/usr/lib/python3.6/site-packages/flask/app.py", line 1517, in handle_user_exception
[Fri Dec 22 15:33:23.974573 2017] [wsgi:error] [pid 10204] [remote 85.26.235.239:37987]     reraise(exc_type, exc_value, tb)
[Fri Dec 22 15:33:23.974582 2017] [wsgi:error] [pid 10204] [remote 85.26.235.239:37987]   File "/usr/lib/python3.6/site-packages/flask/_compat.py", line 33, in reraise
[Fri Dec 22 15:33:23.974591 2017] [wsgi:error] [pid 10204] [remote 85.26.235.239:37987]     raise value
[Fri Dec 22 15:33:23.974599 2017] [wsgi:error] [pid 10204] [remote 85.26.235.239:37987]   File "/usr/lib/python3.6/site-packages/flask/app.py", line 1612, in full_dispatch_request
[Fri Dec 22 15:33:23.974609 2017] [wsgi:error] [pid 10204] [remote 85.26.235.239:37987]     rv = self.dispatch_request()
[Fri Dec 22 15:33:23.974617 2017] [wsgi:error] [pid 10204] [remote 85.26.235.239:37987]   File "/usr/lib/python3.6/site-packages/flask/app.py", line 1598, in dispatch_request
[Fri Dec 22 15:33:23.974627 2017] [wsgi:error] [pid 10204] [remote 85.26.235.239:37987]     return self.view_functions[rule.endpoint](**req.view_args)
[Fri Dec 22 15:33:23.974636 2017] [wsgi:error] [pid 10204] [remote 85.26.235.239:37987]   File "/srv/http/virtlabs.tk/forsaje.tk/api.py", line 149, in check_worker
[Fri Dec 22 15:33:23.974645 2017] [wsgi:error] [pid 10204] [remote 85.26.235.239:37987]     s = Session()
[Fri Dec 22 15:33:23.974659 2017] [wsgi:error] [pid 10204] [remote 85.26.235.239:37987] NameError: name 'Session' is not defined
[Fri Dec 22 15:33:23.974729 2017] [wsgi:error] [pid 10204] [remote 85.26.235.239:37987] 
[Fri Dec 22 15:43:45.524142 2017] [wsgi:error] [pid 10204] [remote 85.26.235.239:38764] [2017-12-22 15:43:45,522] ERROR in app: Exception on /work/check_worker [POST]
[Fri Dec 22 15:43:45.524287 2017] [wsgi:error] [pid 10204] [remote 85.26.235.239:38764] Traceback (most recent call last):
[Fri Dec 22 15:43:45.524301 2017] [wsgi:error] [pid 10204] [remote 85.26.235.239:38764]   File "/usr/lib/python3.6/site-packages/flask/app.py", line 1982, in wsgi_app
[Fri Dec 22 15:43:45.524312 2017] [wsgi:error] [pid 10204] [remote 85.26.235.239:38764]     response = self.full_dispatch_request()
[Fri Dec 22 15:43:45.524322 2017] [wsgi:error] [pid 10204] [remote 85.26.235.239:38764]   File "/usr/lib/python3.6/site-packages/flask/app.py", line 1614, in full_dispatch_request
[Fri Dec 22 15:43:45.524331 2017] [wsgi:error] [pid 10204] [remote 85.26.235.239:38764]     rv = self.handle_user_exception(e)
[Fri Dec 22 15:43:45.524340 2017] [wsgi:error] [pid 10204] [remote 85.26.235.239:38764]   File "/usr/lib/python3.6/site-packages/flask/app.py", line 1517, in handle_user_exception
[Fri Dec 22 15:43:45.524349 2017] [wsgi:error] [pid 10204] [remote 85.26.235.239:38764]     reraise(exc_type, exc_value, tb)
[Fri Dec 22 15:43:45.524358 2017] [wsgi:error] [pid 10204] [remote 85.26.235.239:38764]   File "/usr/lib/python3.6/site-packages/flask/_compat.py", line 33, in reraise
[Fri Dec 22 15:43:45.524367 2017] [wsgi:error] [pid 10204] [remote 85.26.235.239:38764]     raise value
[Fri Dec 22 15:43:45.524376 2017] [wsgi:error] [pid 10204] [remote 85.26.235.239:38764]   File "/usr/lib/python3.6/site-packages/flask/app.py", line 1612, in full_dispatch_request
[Fri Dec 22 15:43:45.524385 2017] [wsgi:error] [pid 10204] [remote 85.26.235.239:38764]     rv = self.dispatch_request()
[Fri Dec 22 15:43:45.524393 2017] [wsgi:error] [pid 10204] [remote 85.26.235.239:38764]   File "/usr/lib/python3.6/site-packages/flask/app.py", line 1598, in dispatch_request
[Fri Dec 22 15:43:45.524408 2017] [wsgi:error] [pid 10204] [remote 85.26.235.239:38764]     return self.view_functions[rule.endpoint](**req.view_args)
[Fri Dec 22 15:43:45.524500 2017] [wsgi:error] [pid 10204] [remote 85.26.235.239:38764]   File "/srv/http/virtlabs.tk/forsaje.tk/api.py", line 149, in check_worker
[Fri Dec 22 15:43:45.524512 2017] [wsgi:error] [pid 10204] [remote 85.26.235.239:38764]     s = Session()
[Fri Dec 22 15:43:45.524525 2017] [wsgi:error] [pid 10204] [remote 85.26.235.239:38764] NameError: name 'Session' is not defined
[Fri Dec 22 15:43:45.524585 2017] [wsgi:error] [pid 10204] [remote 85.26.235.239:38764] 
[Fri Dec 22 15:45:11.179272 2017] [wsgi:error] [pid 10301] [remote 85.26.235.239:7296] [2017-12-22 15:45:11,171] ERROR in app: Exception on /work/check_worker [POST]
[Fri Dec 22 15:45:11.179435 2017] [wsgi:error] [pid 10301] [remote 85.26.235.239:7296] Traceback (most recent call last):
[Fri Dec 22 15:45:11.179448 2017] [wsgi:error] [pid 10301] [remote 85.26.235.239:7296]   File "/usr/lib/python3.6/site-packages/flask/app.py", line 1982, in wsgi_app
[Fri Dec 22 15:45:11.179458 2017] [wsgi:error] [pid 10301] [remote 85.26.235.239:7296]     response = self.full_dispatch_request()
[Fri Dec 22 15:45:11.179467 2017] [wsgi:error] [pid 10301] [remote 85.26.235.239:7296]   File "/usr/lib/python3.6/site-packages/flask/app.py", line 1614, in full_dispatch_request
[Fri Dec 22 15:45:11.179477 2017] [wsgi:error] [pid 10301] [remote 85.26.235.239:7296]     rv = self.handle_user_exception(e)
[Fri Dec 22 15:45:11.179486 2017] [wsgi:error] [pid 10301] [remote 85.26.235.239:7296]   File "/usr/lib/python3.6/site-packages/flask/app.py", line 1517, in handle_user_exception
[Fri Dec 22 15:45:11.179495 2017] [wsgi:error] [pid 10301] [remote 85.26.235.239:7296]     reraise(exc_type, exc_value, tb)
[Fri Dec 22 15:45:11.179504 2017] [wsgi:error] [pid 10301] [remote 85.26.235.239:7296]   File "/usr/lib/python3.6/site-packages/flask/_compat.py", line 33, in reraise
[Fri Dec 22 15:45:11.179513 2017] [wsgi:error] [pid 10301] [remote 85.26.235.239:7296]     raise value
[Fri Dec 22 15:45:11.179522 2017] [wsgi:error] [pid 10301] [remote 85.26.235.239:7296]   File "/usr/lib/python3.6/site-packages/flask/app.py", line 1612, in full_dispatch_request
[Fri Dec 22 15:45:11.179531 2017] [wsgi:error] [pid 10301] [remote 85.26.235.239:7296]     rv = self.dispatch_request()
[Fri Dec 22 15:45:11.179540 2017] [wsgi:error] [pid 10301] [remote 85.26.235.239:7296]   File "/usr/lib/python3.6/site-packages/flask/app.py", line 1598, in dispatch_request
[Fri Dec 22 15:45:11.179549 2017] [wsgi:error] [pid 10301] [remote 85.26.235.239:7296]     return self.view_functions[rule.endpoint](**req.view_args)
[Fri Dec 22 15:45:11.179559 2017] [wsgi:error] [pid 10301] [remote 85.26.235.239:7296]   File "/srv/http/virtlabs.tk/forsaje.tk/api.py", line 153, in check_worker
[Fri Dec 22 15:45:11.179568 2017] [wsgi:error] [pid 10301] [remote 85.26.235.239:7296]     resp.set_cookie('id', user.id)
[Fri Dec 22 15:45:11.179577 2017] [wsgi:error] [pid 10301] [remote 85.26.235.239:7296]   File "/usr/lib/python3.6/site-packages/werkzeug/wrappers.py", line 1064, in set_cookie
[Fri Dec 22 15:45:11.179586 2017] [wsgi:error] [pid 10301] [remote 85.26.235.239:7296]     charset=self.charset))
[Fri Dec 22 15:45:11.179595 2017] [wsgi:error] [pid 10301] [remote 85.26.235.239:7296]   File "/usr/lib/python3.6/site-packages/werkzeug/http.py", line 978, in dump_cookie
[Fri Dec 22 15:45:11.179604 2017] [wsgi:error] [pid 10301] [remote 85.26.235.239:7296]     value = to_bytes(value, charset)
[Fri Dec 22 15:45:11.179612 2017] [wsgi:error] [pid 10301] [remote 85.26.235.239:7296]   File "/usr/lib/python3.6/site-packages/werkzeug/_compat.py", line 190, in to_bytes
[Fri Dec 22 15:45:11.179622 2017] [wsgi:error] [pid 10301] [remote 85.26.235.239:7296]     raise TypeError('Expected bytes')
[Fri Dec 22 15:45:11.179636 2017] [wsgi:error] [pid 10301] [remote 85.26.235.239:7296] TypeError: Expected bytes
[Fri Dec 22 15:45:11.179690 2017] [wsgi:error] [pid 10301] [remote 85.26.235.239:7296] 
[Fri Dec 22 15:48:00.922735 2017] [wsgi:error] [pid 10353] [remote 85.26.235.239:58770] [2017-12-22 15:48:00,918] ERROR in app: Exception on /work/check_worker [POST]
[Fri Dec 22 15:48:00.922991 2017] [wsgi:error] [pid 10353] [remote 85.26.235.239:58770] Traceback (most recent call last):
[Fri Dec 22 15:48:00.923005 2017] [wsgi:error] [pid 10353] [remote 85.26.235.239:58770]   File "/usr/lib/python3.6/site-packages/flask/app.py", line 1982, in wsgi_app
[Fri Dec 22 15:48:00.923015 2017] [wsgi:error] [pid 10353] [remote 85.26.235.239:58770]     response = self.full_dispatch_request()
[Fri Dec 22 15:48:00.923024 2017] [wsgi:error] [pid 10353] [remote 85.26.235.239:58770]   File "/usr/lib/python3.6/site-packages/flask/app.py", line 1614, in full_dispatch_request
[Fri Dec 22 15:48:00.923033 2017] [wsgi:error] [pid 10353] [remote 85.26.235.239:58770]     rv = self.handle_user_exception(e)
[Fri Dec 22 15:48:00.923042 2017] [wsgi:error] [pid 10353] [remote 85.26.235.239:58770]   File "/usr/lib/python3.6/site-packages/flask/app.py", line 1517, in handle_user_exception
[Fri Dec 22 15:48:00.923051 2017] [wsgi:error] [pid 10353] [remote 85.26.235.239:58770]     reraise(exc_type, exc_value, tb)
[Fri Dec 22 15:48:00.923059 2017] [wsgi:error] [pid 10353] [remote 85.26.235.239:58770]   File "/usr/lib/python3.6/site-packages/flask/_compat.py", line 33, in reraise
[Fri Dec 22 15:48:00.923068 2017] [wsgi:error] [pid 10353] [remote 85.26.235.239:58770]     raise value
[Fri Dec 22 15:48:00.923076 2017] [wsgi:error] [pid 10353] [remote 85.26.235.239:58770]   File "/usr/lib/python3.6/site-packages/flask/app.py", line 1612, in full_dispatch_request
[Fri Dec 22 15:48:00.923085 2017] [wsgi:error] [pid 10353] [remote 85.26.235.239:58770]     rv = self.dispatch_request()
[Fri Dec 22 15:48:00.923093 2017] [wsgi:error] [pid 10353] [remote 85.26.235.239:58770]   File "/usr/lib/python3.6/site-packages/flask/app.py", line 1598, in dispatch_request
[Fri Dec 22 15:48:00.923108 2017] [wsgi:error] [pid 10353] [remote 85.26.235.239:58770]     return self.view_functions[rule.endpoint](**req.view_args)
[Fri Dec 22 15:48:00.923119 2017] [wsgi:error] [pid 10353] [remote 85.26.235.239:58770]   File "/srv/http/virtlabs.tk/forsaje.tk/api.py", line 153, in check_worker
[Fri Dec 22 15:48:00.923128 2017] [wsgi:error] [pid 10353] [remote 85.26.235.239:58770]     resp.set_cookie('id', b'{}'.format(user.id))
[Fri Dec 22 15:48:00.923144 2017] [wsgi:error] [pid 10353] [remote 85.26.235.239:58770] AttributeError: 'bytes' object has no attribute 'format'
[Fri Dec 22 15:48:00.923209 2017] [wsgi:error] [pid 10353] [remote 85.26.235.239:58770] 
[Fri Dec 22 16:09:47.661824 2017] [wsgi:error] [pid 10488] [remote 85.26.235.239:7964] [2017-12-22 16:09:47,619] ERROR in app: Exception on /work/zarechny [GET]
[Fri Dec 22 16:09:47.661986 2017] [wsgi:error] [pid 10488] [remote 85.26.235.239:7964] Traceback (most recent call last):
[Fri Dec 22 16:09:47.661999 2017] [wsgi:error] [pid 10488] [remote 85.26.235.239:7964]   File "/usr/lib/python3.6/site-packages/flask/app.py", line 1982, in wsgi_app
[Fri Dec 22 16:09:47.662010 2017] [wsgi:error] [pid 10488] [remote 85.26.235.239:7964]     response = self.full_dispatch_request()
[Fri Dec 22 16:09:47.662020 2017] [wsgi:error] [pid 10488] [remote 85.26.235.239:7964]   File "/usr/lib/python3.6/site-packages/flask/app.py", line 1614, in full_dispatch_request
[Fri Dec 22 16:09:47.662030 2017] [wsgi:error] [pid 10488] [remote 85.26.235.239:7964]     rv = self.handle_user_exception(e)
[Fri Dec 22 16:09:47.662039 2017] [wsgi:error] [pid 10488] [remote 85.26.235.239:7964]   File "/usr/lib/python3.6/site-packages/flask/app.py", line 1517, in handle_user_exception
[Fri Dec 22 16:09:47.662048 2017] [wsgi:error] [pid 10488] [remote 85.26.235.239:7964]     reraise(exc_type, exc_value, tb)
[Fri Dec 22 16:09:47.662057 2017] [wsgi:error] [pid 10488] [remote 85.26.235.239:7964]   File "/usr/lib/python3.6/site-packages/flask/_compat.py", line 33, in reraise
[Fri Dec 22 16:09:47.662067 2017] [wsgi:error] [pid 10488] [remote 85.26.235.239:7964]     raise value
[Fri Dec 22 16:09:47.662075 2017] [wsgi:error] [pid 10488] [remote 85.26.235.239:7964]   File "/usr/lib/python3.6/site-packages/flask/app.py", line 1612, in full_dispatch_request
[Fri Dec 22 16:09:47.662191 2017] [wsgi:error] [pid 10488] [remote 85.26.235.239:7964]     rv = self.dispatch_request()
[Fri Dec 22 16:09:47.662202 2017] [wsgi:error] [pid 10488] [remote 85.26.235.239:7964]   File "/usr/lib/python3.6/site-packages/flask/app.py", line 1598, in dispatch_request
[Fri Dec 22 16:09:47.662212 2017] [wsgi:error] [pid 10488] [remote 85.26.235.239:7964]     return self.view_functions[rule.endpoint](**req.view_args)
[Fri Dec 22 16:09:47.662221 2017] [wsgi:error] [pid 10488] [remote 85.26.235.239:7964]   File "/srv/http/virtlabs.tk/forsaje.tk/api.py", line 173, in work_zarechny
[Fri Dec 22 16:09:47.662230 2017] [wsgi:error] [pid 10488] [remote 85.26.235.239:7964]     'position': 1,
[Fri Dec 22 16:09:47.662239 2017] [wsgi:error] [pid 10488] [remote 85.26.235.239:7964]   File "/usr/lib/python3.6/site-packages/flask/templating.py", line 133, in render_template
[Fri Dec 22 16:09:47.662248 2017] [wsgi:error] [pid 10488] [remote 85.26.235.239:7964]     return _render(ctx.app.jinja_env.get_or_select_template(template_name_or_list),
[Fri Dec 22 16:09:47.662257 2017] [wsgi:error] [pid 10488] [remote 85.26.235.239:7964]   File "/usr/lib/python3.6/site-packages/jinja2/environment.py", line 869, in get_or_select_template
[Fri Dec 22 16:09:47.662266 2017] [wsgi:error] [pid 10488] [remote 85.26.235.239:7964]     return self.get_template(template_name_or_list, parent, globals)
[Fri Dec 22 16:09:47.662275 2017] [wsgi:error] [pid 10488] [remote 85.26.235.239:7964]   File "/usr/lib/python3.6/site-packages/jinja2/environment.py", line 830, in get_template
[Fri Dec 22 16:09:47.662284 2017] [wsgi:error] [pid 10488] [remote 85.26.235.239:7964]     return self._load_template(name, self.make_globals(globals))
[Fri Dec 22 16:09:47.662293 2017] [wsgi:error] [pid 10488] [remote 85.26.235.239:7964]   File "/usr/lib/python3.6/site-packages/jinja2/environment.py", line 804, in _load_template
[Fri Dec 22 16:09:47.662303 2017] [wsgi:error] [pid 10488] [remote 85.26.235.239:7964]     template = self.loader.load(self, name, globals)
[Fri Dec 22 16:09:47.662312 2017] [wsgi:error] [pid 10488] [remote 85.26.235.239:7964]   File "/usr/lib/python3.6/site-packages/jinja2/loaders.py", line 113, in load
[Fri Dec 22 16:09:47.662321 2017] [wsgi:error] [pid 10488] [remote 85.26.235.239:7964]     source, filename, uptodate = self.get_source(environment, name)
[Fri Dec 22 16:09:47.662330 2017] [wsgi:error] [pid 10488] [remote 85.26.235.239:7964]   File "/usr/lib/python3.6/site-packages/flask/templating.py", line 57, in get_source
[Fri Dec 22 16:09:47.662339 2017] [wsgi:error] [pid 10488] [remote 85.26.235.239:7964]     return self._get_source_fast(environment, template)
[Fri Dec 22 16:09:47.662347 2017] [wsgi:error] [pid 10488] [remote 85.26.235.239:7964]   File "/usr/lib/python3.6/site-packages/flask/templating.py", line 85, in _get_source_fast
[Fri Dec 22 16:09:47.662357 2017] [wsgi:error] [pid 10488] [remote 85.26.235.239:7964]     raise TemplateNotFound(template)
[Fri Dec 22 16:09:47.662374 2017] [wsgi:error] [pid 10488] [remote 85.26.235.239:7964] jinja2.exceptions.TemplateNotFound: work/zarechny.html
[Fri Dec 22 16:09:47.662441 2017] [wsgi:error] [pid 10488] [remote 85.26.235.239:7964] 
[Fri Dec 22 16:14:47.436769 2017] [wsgi:error] [pid 10651] [remote 85.26.235.239:60471] [2017-12-22 16:14:47,419] ERROR in app: Exception on /work/part [GET]
[Fri Dec 22 16:14:47.436916 2017] [wsgi:error] [pid 10651] [remote 85.26.235.239:60471] Traceback (most recent call last):
[Fri Dec 22 16:14:47.436930 2017] [wsgi:error] [pid 10651] [remote 85.26.235.239:60471]   File "/usr/lib/python3.6/site-packages/flask/app.py", line 1982, in wsgi_app
[Fri Dec 22 16:14:47.436941 2017] [wsgi:error] [pid 10651] [remote 85.26.235.239:60471]     response = self.full_dispatch_request()
[Fri Dec 22 16:14:47.436951 2017] [wsgi:error] [pid 10651] [remote 85.26.235.239:60471]   File "/usr/lib/python3.6/site-packages/flask/app.py", line 1614, in full_dispatch_request
[Fri Dec 22 16:14:47.436960 2017] [wsgi:error] [pid 10651] [remote 85.26.235.239:60471]     rv = self.handle_user_exception(e)
[Fri Dec 22 16:14:47.437167 2017] [wsgi:error] [pid 10651] [remote 85.26.235.239:60471]   File "/usr/lib/python3.6/site-packages/flask/app.py", line 1517, in handle_user_exception
[Fri Dec 22 16:14:47.437185 2017] [wsgi:error] [pid 10651] [remote 85.26.235.239:60471]     reraise(exc_type, exc_value, tb)
[Fri Dec 22 16:14:47.437195 2017] [wsgi:error] [pid 10651] [remote 85.26.235.239:60471]   File "/usr/lib/python3.6/site-packages/flask/_compat.py", line 33, in reraise
[Fri Dec 22 16:14:47.437205 2017] [wsgi:error] [pid 10651] [remote 85.26.235.239:60471]     raise value
[Fri Dec 22 16:14:47.437214 2017] [wsgi:error] [pid 10651] [remote 85.26.235.239:60471]   File "/usr/lib/python3.6/site-packages/flask/app.py", line 1612, in full_dispatch_request
[Fri Dec 22 16:14:47.437223 2017] [wsgi:error] [pid 10651] [remote 85.26.235.239:60471]     rv = self.dispatch_request()
[Fri Dec 22 16:14:47.437232 2017] [wsgi:error] [pid 10651] [remote 85.26.235.239:60471]   File "/usr/lib/python3.6/site-packages/flask/app.py", line 1598, in dispatch_request
[Fri Dec 22 16:14:47.437241 2017] [wsgi:error] [pid 10651] [remote 85.26.235.239:60471]     return self.view_functions[rule.endpoint](**req.view_args)
[Fri Dec 22 16:14:47.437250 2017] [wsgi:error] [pid 10651] [remote 85.26.235.239:60471]   File "/srv/http/virtlabs.tk/forsaje.tk/api.py", line 167, in work_part
[Fri Dec 22 16:14:47.437259 2017] [wsgi:error] [pid 10651] [remote 85.26.235.239:60471]     part = request.get('part')
[Fri Dec 22 16:14:47.437268 2017] [wsgi:error] [pid 10651] [remote 85.26.235.239:60471]   File "/usr/lib/python3.6/site-packages/werkzeug/local.py", line 347, in __getattr__
[Fri Dec 22 16:14:47.437277 2017] [wsgi:error] [pid 10651] [remote 85.26.235.239:60471]     return getattr(self._get_current_object(), name)
[Fri Dec 22 16:14:47.437295 2017] [wsgi:error] [pid 10651] [remote 85.26.235.239:60471] AttributeError: 'Request' object has no attribute 'get'
[Fri Dec 22 16:14:47.437384 2017] [wsgi:error] [pid 10651] [remote 85.26.235.239:60471] 
[Fri Dec 22 16:15:38.808929 2017] [wsgi:error] [pid 10708] [remote 85.26.235.239:29865] [2017-12-22 16:15:38,804] ERROR in app: Exception on /work/part [GET]
[Fri Dec 22 16:15:38.809090 2017] [wsgi:error] [pid 10708] [remote 85.26.235.239:29865] Traceback (most recent call last):
[Fri Dec 22 16:15:38.809104 2017] [wsgi:error] [pid 10708] [remote 85.26.235.239:29865]   File "/usr/lib/python3.6/site-packages/flask/app.py", line 1982, in wsgi_app
[Fri Dec 22 16:15:38.809115 2017] [wsgi:error] [pid 10708] [remote 85.26.235.239:29865]     response = self.full_dispatch_request()
[Fri Dec 22 16:15:38.809125 2017] [wsgi:error] [pid 10708] [remote 85.26.235.239:29865]   File "/usr/lib/python3.6/site-packages/flask/app.py", line 1614, in full_dispatch_request
[Fri Dec 22 16:15:38.809134 2017] [wsgi:error] [pid 10708] [remote 85.26.235.239:29865]     rv = self.handle_user_exception(e)
[Fri Dec 22 16:15:38.809143 2017] [wsgi:error] [pid 10708] [remote 85.26.235.239:29865]   File "/usr/lib/python3.6/site-packages/flask/app.py", line 1517, in handle_user_exception
[Fri Dec 22 16:15:38.809153 2017] [wsgi:error] [pid 10708] [remote 85.26.235.239:29865]     reraise(exc_type, exc_value, tb)
[Fri Dec 22 16:15:38.809161 2017] [wsgi:error] [pid 10708] [remote 85.26.235.239:29865]   File "/usr/lib/python3.6/site-packages/flask/_compat.py", line 33, in reraise
[Fri Dec 22 16:15:38.809171 2017] [wsgi:error] [pid 10708] [remote 85.26.235.239:29865]     raise value
[Fri Dec 22 16:15:38.809179 2017] [wsgi:error] [pid 10708] [remote 85.26.235.239:29865]   File "/usr/lib/python3.6/site-packages/flask/app.py", line 1612, in full_dispatch_request
[Fri Dec 22 16:15:38.809188 2017] [wsgi:error] [pid 10708] [remote 85.26.235.239:29865]     rv = self.dispatch_request()
[Fri Dec 22 16:15:38.809197 2017] [wsgi:error] [pid 10708] [remote 85.26.235.239:29865]   File "/usr/lib/python3.6/site-packages/flask/app.py", line 1598, in dispatch_request
[Fri Dec 22 16:15:38.809207 2017] [wsgi:error] [pid 10708] [remote 85.26.235.239:29865]     return self.view_functions[rule.endpoint](**req.view_args)
[Fri Dec 22 16:15:38.809317 2017] [wsgi:error] [pid 10708] [remote 85.26.235.239:29865]   File "/srv/http/virtlabs.tk/forsaje.tk/api.py", line 174, in work_part
[Fri Dec 22 16:15:38.809329 2017] [wsgi:error] [pid 10708] [remote 85.26.235.239:29865]     'direction': const[part]
[Fri Dec 22 16:15:38.809347 2017] [wsgi:error] [pid 10708] [remote 85.26.235.239:29865] TypeError: list indices must be integers or slices, not str
[Fri Dec 22 16:15:38.809411 2017] [wsgi:error] [pid 10708] [remote 85.26.235.239:29865] 
[Fri Dec 22 16:16:31.816567 2017] [wsgi:error] [pid 10758] [remote 85.26.235.239:27595] [2017-12-22 16:16:31,799] ERROR in app: Exception on /work/part [GET]
[Fri Dec 22 16:16:31.816706 2017] [wsgi:error] [pid 10758] [remote 85.26.235.239:27595] Traceback (most recent call last):
[Fri Dec 22 16:16:31.816720 2017] [wsgi:error] [pid 10758] [remote 85.26.235.239:27595]   File "/usr/lib/python3.6/site-packages/flask/app.py", line 1982, in wsgi_app
[Fri Dec 22 16:16:31.816732 2017] [wsgi:error] [pid 10758] [remote 85.26.235.239:27595]     response = self.full_dispatch_request()
[Fri Dec 22 16:16:31.816742 2017] [wsgi:error] [pid 10758] [remote 85.26.235.239:27595]   File "/usr/lib/python3.6/site-packages/flask/app.py", line 1614, in full_dispatch_request
[Fri Dec 22 16:16:31.816752 2017] [wsgi:error] [pid 10758] [remote 85.26.235.239:27595]     rv = self.handle_user_exception(e)
[Fri Dec 22 16:16:31.816761 2017] [wsgi:error] [pid 10758] [remote 85.26.235.239:27595]   File "/usr/lib/python3.6/site-packages/flask/app.py", line 1517, in handle_user_exception
[Fri Dec 22 16:16:31.816771 2017] [wsgi:error] [pid 10758] [remote 85.26.235.239:27595]     reraise(exc_type, exc_value, tb)
[Fri Dec 22 16:16:31.816780 2017] [wsgi:error] [pid 10758] [remote 85.26.235.239:27595]   File "/usr/lib/python3.6/site-packages/flask/_compat.py", line 33, in reraise
[Fri Dec 22 16:16:31.816790 2017] [wsgi:error] [pid 10758] [remote 85.26.235.239:27595]     raise value
[Fri Dec 22 16:16:31.816798 2017] [wsgi:error] [pid 10758] [remote 85.26.235.239:27595]   File "/usr/lib/python3.6/site-packages/flask/app.py", line 1612, in full_dispatch_request
[Fri Dec 22 16:16:31.816808 2017] [wsgi:error] [pid 10758] [remote 85.26.235.239:27595]     rv = self.dispatch_request()
[Fri Dec 22 16:16:31.816817 2017] [wsgi:error] [pid 10758] [remote 85.26.235.239:27595]   File "/usr/lib/python3.6/site-packages/flask/app.py", line 1598, in dispatch_request
[Fri Dec 22 16:16:31.816827 2017] [wsgi:error] [pid 10758] [remote 85.26.235.239:27595]     return self.view_functions[rule.endpoint](**req.view_args)
[Fri Dec 22 16:16:31.816836 2017] [wsgi:error] [pid 10758] [remote 85.26.235.239:27595]   File "/srv/http/virtlabs.tk/forsaje.tk/api.py", line 176, in work_part
[Fri Dec 22 16:16:31.816846 2017] [wsgi:error] [pid 10758] [remote 85.26.235.239:27595]     return render_template('work/orders.html', **context)
[Fri Dec 22 16:16:31.816856 2017] [wsgi:error] [pid 10758] [remote 85.26.235.239:27595]   File "/usr/lib/python3.6/site-packages/flask/templating.py", line 134, in render_template
[Fri Dec 22 16:16:31.816865 2017] [wsgi:error] [pid 10758] [remote 85.26.235.239:27595]     context, ctx.app)
[Fri Dec 22 16:16:31.816874 2017] [wsgi:error] [pid 10758] [remote 85.26.235.239:27595]   File "/usr/lib/python3.6/site-packages/flask/templating.py", line 116, in _render
[Fri Dec 22 16:16:31.816884 2017] [wsgi:error] [pid 10758] [remote 85.26.235.239:27595]     rv = template.render(context)
[Fri Dec 22 16:16:31.816893 2017] [wsgi:error] [pid 10758] [remote 85.26.235.239:27595]   File "/usr/lib/python3.6/site-packages/jinja2/asyncsupport.py", line 76, in render
[Fri Dec 22 16:16:31.816903 2017] [wsgi:error] [pid 10758] [remote 85.26.235.239:27595]     return original_render(self, *args, **kwargs)
[Fri Dec 22 16:16:31.816912 2017] [wsgi:error] [pid 10758] [remote 85.26.235.239:27595]   File "/usr/lib/python3.6/site-packages/jinja2/environment.py", line 1008, in render
[Fri Dec 22 16:16:31.816922 2017] [wsgi:error] [pid 10758] [remote 85.26.235.239:27595]     return self.environment.handle_exception(exc_info, True)
[Fri Dec 22 16:16:31.817040 2017] [wsgi:error] [pid 10758] [remote 85.26.235.239:27595]   File "/usr/lib/python3.6/site-packages/jinja2/environment.py", line 780, in handle_exception
[Fri Dec 22 16:16:31.817156 2017] [wsgi:error] [pid 10758] [remote 85.26.235.239:27595]     reraise(exc_type, exc_value, tb)
[Fri Dec 22 16:16:31.817173 2017] [wsgi:error] [pid 10758] [remote 85.26.235.239:27595]   File "/usr/lib/python3.6/site-packages/jinja2/_compat.py", line 37, in reraise
[Fri Dec 22 16:16:31.817183 2017] [wsgi:error] [pid 10758] [remote 85.26.235.239:27595]     raise value.with_traceback(tb)
[Fri Dec 22 16:16:31.817192 2017] [wsgi:error] [pid 10758] [remote 85.26.235.239:27595]   File "/srv/http/virtlabs.tk/forsaje.tk/templates/work/orders.html", line 1, in top-level template code
[Fri Dec 22 16:16:31.817202 2017] [wsgi:error] [pid 10758] [remote 85.26.235.239:27595]     {% extends "part.html" %}
[Fri Dec 22 16:16:31.817211 2017] [wsgi:error] [pid 10758] [remote 85.26.235.239:27595]   File "/usr/lib/python3.6/site-packages/flask/templating.py", line 57, in get_source
[Fri Dec 22 16:16:31.817220 2017] [wsgi:error] [pid 10758] [remote 85.26.235.239:27595]     return self._get_source_fast(environment, template)
[Fri Dec 22 16:16:31.817228 2017] [wsgi:error] [pid 10758] [remote 85.26.235.239:27595]   File "/usr/lib/python3.6/site-packages/flask/templating.py", line 85, in _get_source_fast
[Fri Dec 22 16:16:31.817238 2017] [wsgi:error] [pid 10758] [remote 85.26.235.239:27595]     raise TemplateNotFound(template)
[Fri Dec 22 16:16:31.817256 2017] [wsgi:error] [pid 10758] [remote 85.26.235.239:27595] jinja2.exceptions.TemplateNotFound: part.html
[Fri Dec 22 16:16:31.817349 2017] [wsgi:error] [pid 10758] [remote 85.26.235.239:27595] 
[Fri Dec 22 16:18:51.694375 2017] [wsgi:error] [pid 10817] (2)No such file or directory: [client 85.26.235.239:11557] mod_wsgi (pid=10817): Unable to connect to WSGI daemon process 'api_forsaje' on '/run/httpd/wsgi.23089.235.1.sock' as user with uid=1002.
