[Sat Jan 06 16:52:50.695307 2018] [wsgi:error] [pid 924] [remote 94.181.154.87:44949] mod_wsgi (pid=924): Target WSGI script '/srv/http/virtlabs.tk/forsaje.tk/api.wsgi' cannot be loaded as Python module.
[Sat Jan 06 16:52:50.695669 2018] [wsgi:error] [pid 924] [remote 94.181.154.87:44949] mod_wsgi (pid=924): Exception occurred processing WSGI script '/srv/http/virtlabs.tk/forsaje.tk/api.wsgi'.
[Sat Jan 06 16:52:50.800342 2018] [wsgi:error] [pid 924] [remote 94.181.154.87:44949] Traceback (most recent call last):
[Sat Jan 06 16:52:50.800578 2018] [wsgi:error] [pid 924] [remote 94.181.154.87:44949]   File "/usr/lib/python3.6/site-packages/pony/orm/dbapiprovider.py", line 50, in wrap_dbapi_exceptions
[Sat Jan 06 16:52:50.800599 2018] [wsgi:error] [pid 924] [remote 94.181.154.87:44949]     return func(provider, *args, **kwargs)
[Sat Jan 06 16:52:50.800627 2018] [wsgi:error] [pid 924] [remote 94.181.154.87:44949]   File "/usr/lib/python3.6/site-packages/pony/orm/dbapiprovider.py", line 206, in connect
[Sat Jan 06 16:52:50.800641 2018] [wsgi:error] [pid 924] [remote 94.181.154.87:44949]     return provider.pool.connect()
[Sat Jan 06 16:52:50.800668 2018] [wsgi:error] [pid 924] [remote 94.181.154.87:44949]   File "/usr/lib/python3.6/site-packages/pony/orm/dbapiprovider.py", line 322, in connect
[Sat Jan 06 16:52:50.800681 2018] [wsgi:error] [pid 924] [remote 94.181.154.87:44949]     pool._connect()
[Sat Jan 06 16:52:50.800707 2018] [wsgi:error] [pid 924] [remote 94.181.154.87:44949]   File "/usr/lib/python3.6/site-packages/pony/orm/dbproviders/postgres.py", line 145, in _connect
[Sat Jan 06 16:52:50.800721 2018] [wsgi:error] [pid 924] [remote 94.181.154.87:44949]     pool.con = pool.dbapi_module.connect(*pool.args, **pool.kwargs)
[Sat Jan 06 16:52:50.800747 2018] [wsgi:error] [pid 924] [remote 94.181.154.87:44949]   File "/usr/lib/python3.6/site-packages/psycopg2cffi/__init__.py", line 104, in connect
[Sat Jan 06 16:52:50.800760 2018] [wsgi:error] [pid 924] [remote 94.181.154.87:44949]     conn = _connect(dsn, connection_factory=connection_factory, async=async)
[Sat Jan 06 16:52:50.800785 2018] [wsgi:error] [pid 924] [remote 94.181.154.87:44949]   File "/usr/lib/python3.6/site-packages/psycopg2cffi/_impl/connection.py", line 891, in _connect
[Sat Jan 06 16:52:50.800798 2018] [wsgi:error] [pid 924] [remote 94.181.154.87:44949]     return connection_factory(dsn)
[Sat Jan 06 16:52:50.800823 2018] [wsgi:error] [pid 924] [remote 94.181.154.87:44949]   File "/usr/lib/python3.6/site-packages/psycopg2cffi/_impl/connection.py", line 136, in __init__
[Sat Jan 06 16:52:50.800836 2018] [wsgi:error] [pid 924] [remote 94.181.154.87:44949]     self._connect_sync()
[Sat Jan 06 16:52:50.800860 2018] [wsgi:error] [pid 924] [remote 94.181.154.87:44949]   File "/usr/lib/python3.6/site-packages/psycopg2cffi/_impl/connection.py", line 145, in _connect_sync
[Sat Jan 06 16:52:50.800873 2018] [wsgi:error] [pid 924] [remote 94.181.154.87:44949]     raise self._create_exception()
[Sat Jan 06 16:52:50.800949 2018] [wsgi:error] [pid 924] [remote 94.181.154.87:44949] psycopg2cffi._impl.exceptions.OperationalError: could not connect to server: No such file or directory
[Sat Jan 06 16:52:50.800965 2018] [wsgi:error] [pid 924] [remote 94.181.154.87:44949] \tIs the server running locally and accepting
[Sat Jan 06 16:52:50.800975 2018] [wsgi:error] [pid 924] [remote 94.181.154.87:44949] \tconnections on Unix domain socket "/run/postgresql/.s.PGSQL.5432"?
[Sat Jan 06 16:52:50.800984 2018] [wsgi:error] [pid 924] [remote 94.181.154.87:44949] 
[Sat Jan 06 16:52:50.801021 2018] [wsgi:error] [pid 924] [remote 94.181.154.87:44949] 
[Sat Jan 06 16:52:50.801034 2018] [wsgi:error] [pid 924] [remote 94.181.154.87:44949] During handling of the above exception, another exception occurred:
[Sat Jan 06 16:52:50.801044 2018] [wsgi:error] [pid 924] [remote 94.181.154.87:44949] 
[Sat Jan 06 16:52:50.801068 2018] [wsgi:error] [pid 924] [remote 94.181.154.87:44949] Traceback (most recent call last):
[Sat Jan 06 16:52:50.801210 2018] [wsgi:error] [pid 924] [remote 94.181.154.87:44949]   File "/srv/http/virtlabs.tk/forsaje.tk/api.wsgi", line 1, in <module>
[Sat Jan 06 16:52:50.801301 2018] [wsgi:error] [pid 924] [remote 94.181.154.87:44949]     from api import app as application
[Sat Jan 06 16:52:50.801331 2018] [wsgi:error] [pid 924] [remote 94.181.154.87:44949]   File "/srv/http/virtlabs.tk/forsaje.tk/api.py", line 16, in <module>
[Sat Jan 06 16:52:50.801345 2018] [wsgi:error] [pid 924] [remote 94.181.154.87:44949]     from initdb import Worker, Auth, Online, Taxi_order
[Sat Jan 06 16:52:50.801370 2018] [wsgi:error] [pid 924] [remote 94.181.154.87:44949]   File "/srv/http/virtlabs.tk/forsaje.tk/initdb.py", line 35, in <module>
[Sat Jan 06 16:52:50.801382 2018] [wsgi:error] [pid 924] [remote 94.181.154.87:44949]     _PostgresDb.bind(**_config)
[Sat Jan 06 16:52:50.801407 2018] [wsgi:error] [pid 924] [remote 94.181.154.87:44949]   File "<string>", line 2, in bind
[Sat Jan 06 16:52:50.801433 2018] [wsgi:error] [pid 924] [remote 94.181.154.87:44949]   File "/usr/lib/python3.6/site-packages/pony/utils/utils.py", line 58, in cut_traceback
[Sat Jan 06 16:52:50.801446 2018] [wsgi:error] [pid 924] [remote 94.181.154.87:44949]     return func(*args, **kwargs)
[Sat Jan 06 16:52:50.801470 2018] [wsgi:error] [pid 924] [remote 94.181.154.87:44949]   File "/usr/lib/python3.6/site-packages/pony/orm/core.py", line 657, in bind
[Sat Jan 06 16:52:50.801482 2018] [wsgi:error] [pid 924] [remote 94.181.154.87:44949]     self._bind(*args, **kwargs)
[Sat Jan 06 16:52:50.801506 2018] [wsgi:error] [pid 924] [remote 94.181.154.87:44949]   File "/usr/lib/python3.6/site-packages/pony/orm/core.py", line 673, in _bind
[Sat Jan 06 16:52:50.801518 2018] [wsgi:error] [pid 924] [remote 94.181.154.87:44949]     self.provider = provider_cls(*args, **kwargs)
[Sat Jan 06 16:52:50.801543 2018] [wsgi:error] [pid 924] [remote 94.181.154.87:44949]   File "/usr/lib/python3.6/site-packages/pony/orm/dbapiprovider.py", line 114, in __init__
[Sat Jan 06 16:52:50.801555 2018] [wsgi:error] [pid 924] [remote 94.181.154.87:44949]     connection = provider.connect()
[Sat Jan 06 16:52:50.801579 2018] [wsgi:error] [pid 924] [remote 94.181.154.87:44949]   File "<string>", line 2, in connect
[Sat Jan 06 16:52:50.801606 2018] [wsgi:error] [pid 924] [remote 94.181.154.87:44949]   File "/usr/lib/python3.6/site-packages/pony/orm/dbapiprovider.py", line 61, in wrap_dbapi_exceptions
[Sat Jan 06 16:52:50.801619 2018] [wsgi:error] [pid 924] [remote 94.181.154.87:44949]     raise OperationalError(e)
[Sat Jan 06 16:52:50.801663 2018] [wsgi:error] [pid 924] [remote 94.181.154.87:44949] pony.orm.dbapiprovider.OperationalError: could not connect to server: No such file or directory
[Sat Jan 06 16:52:50.801678 2018] [wsgi:error] [pid 924] [remote 94.181.154.87:44949] \tIs the server running locally and accepting
[Sat Jan 06 16:52:50.801687 2018] [wsgi:error] [pid 924] [remote 94.181.154.87:44949] \tconnections on Unix domain socket "/run/postgresql/.s.PGSQL.5432"?
[Sat Jan 06 16:52:50.801697 2018] [wsgi:error] [pid 924] [remote 94.181.154.87:44949] 
[Sat Jan 06 16:55:16.165422 2018] [wsgi:error] [pid 924] [remote 94.181.154.87:44951] mod_wsgi (pid=924): Target WSGI script '/srv/http/virtlabs.tk/forsaje.tk/api.wsgi' cannot be loaded as Python module.
[Sat Jan 06 16:55:16.165657 2018] [wsgi:error] [pid 924] [remote 94.181.154.87:44951] mod_wsgi (pid=924): Exception occurred processing WSGI script '/srv/http/virtlabs.tk/forsaje.tk/api.wsgi'.
[Sat Jan 06 16:55:16.166636 2018] [wsgi:error] [pid 924] [remote 94.181.154.87:44951] Traceback (most recent call last):
[Sat Jan 06 16:55:16.166850 2018] [wsgi:error] [pid 924] [remote 94.181.154.87:44951]   File "/usr/lib/python3.6/site-packages/pony/orm/dbapiprovider.py", line 50, in wrap_dbapi_exceptions
[Sat Jan 06 16:55:16.166869 2018] [wsgi:error] [pid 924] [remote 94.181.154.87:44951]     return func(provider, *args, **kwargs)
[Sat Jan 06 16:55:16.166904 2018] [wsgi:error] [pid 924] [remote 94.181.154.87:44951]   File "/usr/lib/python3.6/site-packages/pony/orm/dbapiprovider.py", line 206, in connect
[Sat Jan 06 16:55:16.166919 2018] [wsgi:error] [pid 924] [remote 94.181.154.87:44951]     return provider.pool.connect()
[Sat Jan 06 16:55:16.167031 2018] [wsgi:error] [pid 924] [remote 94.181.154.87:44951]   File "/usr/lib/python3.6/site-packages/pony/orm/dbapiprovider.py", line 322, in connect
[Sat Jan 06 16:55:16.167046 2018] [wsgi:error] [pid 924] [remote 94.181.154.87:44951]     pool._connect()
[Sat Jan 06 16:55:16.167072 2018] [wsgi:error] [pid 924] [remote 94.181.154.87:44951]   File "/usr/lib/python3.6/site-packages/pony/orm/dbproviders/postgres.py", line 145, in _connect
[Sat Jan 06 16:55:16.167086 2018] [wsgi:error] [pid 924] [remote 94.181.154.87:44951]     pool.con = pool.dbapi_module.connect(*pool.args, **pool.kwargs)
[Sat Jan 06 16:55:16.167111 2018] [wsgi:error] [pid 924] [remote 94.181.154.87:44951]   File "/usr/lib/python3.6/site-packages/psycopg2cffi/__init__.py", line 104, in connect
[Sat Jan 06 16:55:16.167124 2018] [wsgi:error] [pid 924] [remote 94.181.154.87:44951]     conn = _connect(dsn, connection_factory=connection_factory, async=async)
[Sat Jan 06 16:55:16.167149 2018] [wsgi:error] [pid 924] [remote 94.181.154.87:44951]   File "/usr/lib/python3.6/site-packages/psycopg2cffi/_impl/connection.py", line 891, in _connect
[Sat Jan 06 16:55:16.167162 2018] [wsgi:error] [pid 924] [remote 94.181.154.87:44951]     return connection_factory(dsn)
[Sat Jan 06 16:55:16.167186 2018] [wsgi:error] [pid 924] [remote 94.181.154.87:44951]   File "/usr/lib/python3.6/site-packages/psycopg2cffi/_impl/connection.py", line 136, in __init__
[Sat Jan 06 16:55:16.167199 2018] [wsgi:error] [pid 924] [remote 94.181.154.87:44951]     self._connect_sync()
[Sat Jan 06 16:55:16.167223 2018] [wsgi:error] [pid 924] [remote 94.181.154.87:44951]   File "/usr/lib/python3.6/site-packages/psycopg2cffi/_impl/connection.py", line 145, in _connect_sync
[Sat Jan 06 16:55:16.167236 2018] [wsgi:error] [pid 924] [remote 94.181.154.87:44951]     raise self._create_exception()
[Sat Jan 06 16:55:16.167297 2018] [wsgi:error] [pid 924] [remote 94.181.154.87:44951] psycopg2cffi._impl.exceptions.OperationalError: could not connect to server: No such file or directory
[Sat Jan 06 16:55:16.167312 2018] [wsgi:error] [pid 924] [remote 94.181.154.87:44951] \tIs the server running locally and accepting
[Sat Jan 06 16:55:16.167322 2018] [wsgi:error] [pid 924] [remote 94.181.154.87:44951] \tconnections on Unix domain socket "/run/postgresql/.s.PGSQL.5432"?
[Sat Jan 06 16:55:16.167331 2018] [wsgi:error] [pid 924] [remote 94.181.154.87:44951] 
[Sat Jan 06 16:55:16.167360 2018] [wsgi:error] [pid 924] [remote 94.181.154.87:44951] 
[Sat Jan 06 16:55:16.167372 2018] [wsgi:error] [pid 924] [remote 94.181.154.87:44951] During handling of the above exception, another exception occurred:
[Sat Jan 06 16:55:16.167381 2018] [wsgi:error] [pid 924] [remote 94.181.154.87:44951] 
[Sat Jan 06 16:55:16.167405 2018] [wsgi:error] [pid 924] [remote 94.181.154.87:44951] Traceback (most recent call last):
[Sat Jan 06 16:55:16.167546 2018] [wsgi:error] [pid 924] [remote 94.181.154.87:44951]   File "/srv/http/virtlabs.tk/forsaje.tk/api.wsgi", line 1, in <module>
[Sat Jan 06 16:55:16.167560 2018] [wsgi:error] [pid 924] [remote 94.181.154.87:44951]     from api import app as application
[Sat Jan 06 16:55:16.167585 2018] [wsgi:error] [pid 924] [remote 94.181.154.87:44951]   File "/srv/http/virtlabs.tk/forsaje.tk/api.py", line 16, in <module>
[Sat Jan 06 16:55:16.167598 2018] [wsgi:error] [pid 924] [remote 94.181.154.87:44951]     from initdb import Worker, Auth, Online, Taxi_order
[Sat Jan 06 16:55:16.167622 2018] [wsgi:error] [pid 924] [remote 94.181.154.87:44951]   File "/srv/http/virtlabs.tk/forsaje.tk/initdb.py", line 35, in <module>
[Sat Jan 06 16:55:16.167634 2018] [wsgi:error] [pid 924] [remote 94.181.154.87:44951]     _PostgresDb.bind(**_config)
[Sat Jan 06 16:55:16.167658 2018] [wsgi:error] [pid 924] [remote 94.181.154.87:44951]   File "<string>", line 2, in bind
[Sat Jan 06 16:55:16.167685 2018] [wsgi:error] [pid 924] [remote 94.181.154.87:44951]   File "/usr/lib/python3.6/site-packages/pony/utils/utils.py", line 58, in cut_traceback
[Sat Jan 06 16:55:16.167721 2018] [wsgi:error] [pid 924] [remote 94.181.154.87:44951]     return func(*args, **kwargs)
[Sat Jan 06 16:55:16.167749 2018] [wsgi:error] [pid 924] [remote 94.181.154.87:44951]   File "/usr/lib/python3.6/site-packages/pony/orm/core.py", line 657, in bind
[Sat Jan 06 16:55:16.167762 2018] [wsgi:error] [pid 924] [remote 94.181.154.87:44951]     self._bind(*args, **kwargs)
[Sat Jan 06 16:55:16.167787 2018] [wsgi:error] [pid 924] [remote 94.181.154.87:44951]   File "/usr/lib/python3.6/site-packages/pony/orm/core.py", line 673, in _bind
[Sat Jan 06 16:55:16.167799 2018] [wsgi:error] [pid 924] [remote 94.181.154.87:44951]     self.provider = provider_cls(*args, **kwargs)
[Sat Jan 06 16:55:16.167823 2018] [wsgi:error] [pid 924] [remote 94.181.154.87:44951]   File "/usr/lib/python3.6/site-packages/pony/orm/dbapiprovider.py", line 114, in __init__
[Sat Jan 06 16:55:16.167836 2018] [wsgi:error] [pid 924] [remote 94.181.154.87:44951]     connection = provider.connect()
[Sat Jan 06 16:55:16.167859 2018] [wsgi:error] [pid 924] [remote 94.181.154.87:44951]   File "<string>", line 2, in connect
[Sat Jan 06 16:55:16.167886 2018] [wsgi:error] [pid 924] [remote 94.181.154.87:44951]   File "/usr/lib/python3.6/site-packages/pony/orm/dbapiprovider.py", line 61, in wrap_dbapi_exceptions
[Sat Jan 06 16:55:16.167898 2018] [wsgi:error] [pid 924] [remote 94.181.154.87:44951]     raise OperationalError(e)
[Sat Jan 06 16:55:16.167941 2018] [wsgi:error] [pid 924] [remote 94.181.154.87:44951] pony.orm.dbapiprovider.OperationalError: could not connect to server: No such file or directory
[Sat Jan 06 16:55:16.167956 2018] [wsgi:error] [pid 924] [remote 94.181.154.87:44951] \tIs the server running locally and accepting
[Sat Jan 06 16:55:16.167965 2018] [wsgi:error] [pid 924] [remote 94.181.154.87:44951] \tconnections on Unix domain socket "/run/postgresql/.s.PGSQL.5432"?
[Sat Jan 06 16:55:16.167975 2018] [wsgi:error] [pid 924] [remote 94.181.154.87:44951] 
[Sat Jan 06 16:55:16.508854 2018] [wsgi:error] [pid 924] [remote 94.181.154.87:44953] mod_wsgi (pid=924): Target WSGI script '/srv/http/virtlabs.tk/forsaje.tk/api.wsgi' cannot be loaded as Python module.
[Sat Jan 06 16:55:16.509037 2018] [wsgi:error] [pid 924] [remote 94.181.154.87:44953] mod_wsgi (pid=924): Exception occurred processing WSGI script '/srv/http/virtlabs.tk/forsaje.tk/api.wsgi'.
[Sat Jan 06 16:55:16.509974 2018] [wsgi:error] [pid 924] [remote 94.181.154.87:44953] Traceback (most recent call last):
[Sat Jan 06 16:55:16.510170 2018] [wsgi:error] [pid 924] [remote 94.181.154.87:44953]   File "/usr/lib/python3.6/site-packages/pony/orm/dbapiprovider.py", line 50, in wrap_dbapi_exceptions
[Sat Jan 06 16:55:16.510190 2018] [wsgi:error] [pid 924] [remote 94.181.154.87:44953]     return func(provider, *args, **kwargs)
[Sat Jan 06 16:55:16.510219 2018] [wsgi:error] [pid 924] [remote 94.181.154.87:44953]   File "/usr/lib/python3.6/site-packages/pony/orm/dbapiprovider.py", line 206, in connect
[Sat Jan 06 16:55:16.510233 2018] [wsgi:error] [pid 924] [remote 94.181.154.87:44953]     return provider.pool.connect()
[Sat Jan 06 16:55:16.510259 2018] [wsgi:error] [pid 924] [remote 94.181.154.87:44953]   File "/usr/lib/python3.6/site-packages/pony/orm/dbapiprovider.py", line 322, in connect
[Sat Jan 06 16:55:16.510273 2018] [wsgi:error] [pid 924] [remote 94.181.154.87:44953]     pool._connect()
[Sat Jan 06 16:55:16.510299 2018] [wsgi:error] [pid 924] [remote 94.181.154.87:44953]   File "/usr/lib/python3.6/site-packages/pony/orm/dbproviders/postgres.py", line 145, in _connect
[Sat Jan 06 16:55:16.510312 2018] [wsgi:error] [pid 924] [remote 94.181.154.87:44953]     pool.con = pool.dbapi_module.connect(*pool.args, **pool.kwargs)
[Sat Jan 06 16:55:16.510337 2018] [wsgi:error] [pid 924] [remote 94.181.154.87:44953]   File "/usr/lib/python3.6/site-packages/psycopg2cffi/__init__.py", line 104, in connect
[Sat Jan 06 16:55:16.510350 2018] [wsgi:error] [pid 924] [remote 94.181.154.87:44953]     conn = _connect(dsn, connection_factory=connection_factory, async=async)
[Sat Jan 06 16:55:16.510450 2018] [wsgi:error] [pid 924] [remote 94.181.154.87:44953]   File "/usr/lib/python3.6/site-packages/psycopg2cffi/_impl/connection.py", line 891, in _connect
[Sat Jan 06 16:55:16.510465 2018] [wsgi:error] [pid 924] [remote 94.181.154.87:44953]     return connection_factory(dsn)
[Sat Jan 06 16:55:16.510490 2018] [wsgi:error] [pid 924] [remote 94.181.154.87:44953]   File "/usr/lib/python3.6/site-packages/psycopg2cffi/_impl/connection.py", line 136, in __init__
[Sat Jan 06 16:55:16.510503 2018] [wsgi:error] [pid 924] [remote 94.181.154.87:44953]     self._connect_sync()
[Sat Jan 06 16:55:16.510527 2018] [wsgi:error] [pid 924] [remote 94.181.154.87:44953]   File "/usr/lib/python3.6/site-packages/psycopg2cffi/_impl/connection.py", line 145, in _connect_sync
[Sat Jan 06 16:55:16.510541 2018] [wsgi:error] [pid 924] [remote 94.181.154.87:44953]     raise self._create_exception()
[Sat Jan 06 16:55:16.510601 2018] [wsgi:error] [pid 924] [remote 94.181.154.87:44953] psycopg2cffi._impl.exceptions.OperationalError: could not connect to server: No such file or directory
[Sat Jan 06 16:55:16.510615 2018] [wsgi:error] [pid 924] [remote 94.181.154.87:44953] \tIs the server running locally and accepting
[Sat Jan 06 16:55:16.510625 2018] [wsgi:error] [pid 924] [remote 94.181.154.87:44953] \tconnections on Unix domain socket "/run/postgresql/.s.PGSQL.5432"?
[Sat Jan 06 16:55:16.510635 2018] [wsgi:error] [pid 924] [remote 94.181.154.87:44953] 
[Sat Jan 06 16:55:16.510664 2018] [wsgi:error] [pid 924] [remote 94.181.154.87:44953] 
[Sat Jan 06 16:55:16.510677 2018] [wsgi:error] [pid 924] [remote 94.181.154.87:44953] During handling of the above exception, another exception occurred:
[Sat Jan 06 16:55:16.510686 2018] [wsgi:error] [pid 924] [remote 94.181.154.87:44953] 
[Sat Jan 06 16:55:16.510710 2018] [wsgi:error] [pid 924] [remote 94.181.154.87:44953] Traceback (most recent call last):
[Sat Jan 06 16:55:16.510850 2018] [wsgi:error] [pid 924] [remote 94.181.154.87:44953]   File "/srv/http/virtlabs.tk/forsaje.tk/api.wsgi", line 1, in <module>
[Sat Jan 06 16:55:16.510866 2018] [wsgi:error] [pid 924] [remote 94.181.154.87:44953]     from api import app as application
[Sat Jan 06 16:55:16.510891 2018] [wsgi:error] [pid 924] [remote 94.181.154.87:44953]   File "/srv/http/virtlabs.tk/forsaje.tk/api.py", line 16, in <module>
[Sat Jan 06 16:55:16.510904 2018] [wsgi:error] [pid 924] [remote 94.181.154.87:44953]     from initdb import Worker, Auth, Online, Taxi_order
[Sat Jan 06 16:55:16.510929 2018] [wsgi:error] [pid 924] [remote 94.181.154.87:44953]   File "/srv/http/virtlabs.tk/forsaje.tk/initdb.py", line 35, in <module>
[Sat Jan 06 16:55:16.510941 2018] [wsgi:error] [pid 924] [remote 94.181.154.87:44953]     _PostgresDb.bind(**_config)
[Sat Jan 06 16:55:16.510965 2018] [wsgi:error] [pid 924] [remote 94.181.154.87:44953]   File "<string>", line 2, in bind
[Sat Jan 06 16:55:16.510992 2018] [wsgi:error] [pid 924] [remote 94.181.154.87:44953]   File "/usr/lib/python3.6/site-packages/pony/utils/utils.py", line 58, in cut_traceback
[Sat Jan 06 16:55:16.511004 2018] [wsgi:error] [pid 924] [remote 94.181.154.87:44953]     return func(*args, **kwargs)
[Sat Jan 06 16:55:16.511028 2018] [wsgi:error] [pid 924] [remote 94.181.154.87:44953]   File "/usr/lib/python3.6/site-packages/pony/orm/core.py", line 657, in bind
[Sat Jan 06 16:55:16.511040 2018] [wsgi:error] [pid 924] [remote 94.181.154.87:44953]     self._bind(*args, **kwargs)
[Sat Jan 06 16:55:16.511064 2018] [wsgi:error] [pid 924] [remote 94.181.154.87:44953]   File "/usr/lib/python3.6/site-packages/pony/orm/core.py", line 673, in _bind
[Sat Jan 06 16:55:16.511077 2018] [wsgi:error] [pid 924] [remote 94.181.154.87:44953]     self.provider = provider_cls(*args, **kwargs)
[Sat Jan 06 16:55:16.511101 2018] [wsgi:error] [pid 924] [remote 94.181.154.87:44953]   File "/usr/lib/python3.6/site-packages/pony/orm/dbapiprovider.py", line 114, in __init__
[Sat Jan 06 16:55:16.511113 2018] [wsgi:error] [pid 924] [remote 94.181.154.87:44953]     connection = provider.connect()
[Sat Jan 06 16:55:16.511137 2018] [wsgi:error] [pid 924] [remote 94.181.154.87:44953]   File "<string>", line 2, in connect
[Sat Jan 06 16:55:16.511190 2018] [wsgi:error] [pid 924] [remote 94.181.154.87:44953]   File "/usr/lib/python3.6/site-packages/pony/orm/dbapiprovider.py", line 61, in wrap_dbapi_exceptions
[Sat Jan 06 16:55:16.511204 2018] [wsgi:error] [pid 924] [remote 94.181.154.87:44953]     raise OperationalError(e)
[Sat Jan 06 16:55:16.511248 2018] [wsgi:error] [pid 924] [remote 94.181.154.87:44953] pony.orm.dbapiprovider.OperationalError: could not connect to server: No such file or directory
[Sat Jan 06 16:55:16.511263 2018] [wsgi:error] [pid 924] [remote 94.181.154.87:44953] \tIs the server running locally and accepting
[Sat Jan 06 16:55:16.511272 2018] [wsgi:error] [pid 924] [remote 94.181.154.87:44953] \tconnections on Unix domain socket "/run/postgresql/.s.PGSQL.5432"?
[Sat Jan 06 16:55:16.511281 2018] [wsgi:error] [pid 924] [remote 94.181.154.87:44953] 
[Sat Jan 06 17:50:35.993984 2018] [wsgi:error] [pid 924] [remote 94.181.154.87:45492] [2018-01-06 17:50:35,949] ERROR in app: Exception on /wait [GET]
[Sat Jan 06 17:50:35.994135 2018] [wsgi:error] [pid 924] [remote 94.181.154.87:45492] Traceback (most recent call last):
[Sat Jan 06 17:50:35.994149 2018] [wsgi:error] [pid 924] [remote 94.181.154.87:45492]   File "/usr/lib/python3.6/site-packages/flask/app.py", line 1982, in wsgi_app
[Sat Jan 06 17:50:35.994160 2018] [wsgi:error] [pid 924] [remote 94.181.154.87:45492]     response = self.full_dispatch_request()
[Sat Jan 06 17:50:35.994169 2018] [wsgi:error] [pid 924] [remote 94.181.154.87:45492]   File "/usr/lib/python3.6/site-packages/flask/app.py", line 1614, in full_dispatch_request
[Sat Jan 06 17:50:35.994179 2018] [wsgi:error] [pid 924] [remote 94.181.154.87:45492]     rv = self.handle_user_exception(e)
[Sat Jan 06 17:50:35.994187 2018] [wsgi:error] [pid 924] [remote 94.181.154.87:45492]   File "/usr/lib/python3.6/site-packages/flask/app.py", line 1517, in handle_user_exception
[Sat Jan 06 17:50:35.994196 2018] [wsgi:error] [pid 924] [remote 94.181.154.87:45492]     reraise(exc_type, exc_value, tb)
[Sat Jan 06 17:50:35.994205 2018] [wsgi:error] [pid 924] [remote 94.181.154.87:45492]   File "/usr/lib/python3.6/site-packages/flask/_compat.py", line 33, in reraise
[Sat Jan 06 17:50:35.994214 2018] [wsgi:error] [pid 924] [remote 94.181.154.87:45492]     raise value
[Sat Jan 06 17:50:35.994222 2018] [wsgi:error] [pid 924] [remote 94.181.154.87:45492]   File "/usr/lib/python3.6/site-packages/flask/app.py", line 1612, in full_dispatch_request
[Sat Jan 06 17:50:35.994232 2018] [wsgi:error] [pid 924] [remote 94.181.154.87:45492]     rv = self.dispatch_request()
[Sat Jan 06 17:50:35.994240 2018] [wsgi:error] [pid 924] [remote 94.181.154.87:45492]   File "/usr/lib/python3.6/site-packages/flask/app.py", line 1598, in dispatch_request
[Sat Jan 06 17:50:35.994249 2018] [wsgi:error] [pid 924] [remote 94.181.154.87:45492]     return self.view_functions[rule.endpoint](**req.view_args)
[Sat Jan 06 17:50:35.994258 2018] [wsgi:error] [pid 924] [remote 94.181.154.87:45492]   File "/srv/http/virtlabs.tk/forsaje.tk/api.py", line 64, in wait
[Sat Jan 06 17:50:35.994268 2018] [wsgi:error] [pid 924] [remote 94.181.154.87:45492]     order = Taxi_order.get(phone=request.args.get('phone'))
[Sat Jan 06 17:50:35.994276 2018] [wsgi:error] [pid 924] [remote 94.181.154.87:45492]   File "<string>", line 2, in get
[Sat Jan 06 17:50:35.994285 2018] [wsgi:error] [pid 924] [remote 94.181.154.87:45492]   File "/usr/lib/python3.6/site-packages/pony/utils/utils.py", line 58, in cut_traceback
[Sat Jan 06 17:50:35.994294 2018] [wsgi:error] [pid 924] [remote 94.181.154.87:45492]     return func(*args, **kwargs)
[Sat Jan 06 17:50:35.994303 2018] [wsgi:error] [pid 924] [remote 94.181.154.87:45492]   File "/usr/lib/python3.6/site-packages/pony/orm/core.py", line 3702, in get
[Sat Jan 06 17:50:35.994312 2018] [wsgi:error] [pid 924] [remote 94.181.154.87:45492]     try: return entity._find_one_(kwargs)  # can throw MultipleObjectsFoundError
[Sat Jan 06 17:50:35.994321 2018] [wsgi:error] [pid 924] [remote 94.181.154.87:45492]   File "/usr/lib/python3.6/site-packages/pony/orm/core.py", line 3801, in _find_one_
[Sat Jan 06 17:50:35.994401 2018] [wsgi:error] [pid 924] [remote 94.181.154.87:45492]     if obj is None: obj = entity._find_in_db_(avdict, unique, for_update, nowait)
[Sat Jan 06 17:50:35.994413 2018] [wsgi:error] [pid 924] [remote 94.181.154.87:45492]   File "/usr/lib/python3.6/site-packages/pony/orm/core.py", line 3861, in _find_in_db_
[Sat Jan 06 17:50:35.994423 2018] [wsgi:error] [pid 924] [remote 94.181.154.87:45492]     objects = entity._fetch_objects(cursor, attr_offsets, 1, for_update, avdict)
[Sat Jan 06 17:50:35.994433 2018] [wsgi:error] [pid 924] [remote 94.181.154.87:45492]   File "/usr/lib/python3.6/site-packages/pony/orm/core.py", line 3980, in _fetch_objects
[Sat Jan 06 17:50:35.994442 2018] [wsgi:error] [pid 924] [remote 94.181.154.87:45492]     'Multiple objects were found. Use %s.select(...) to retrieve them' % entity.__name__)
[Sat Jan 06 17:50:35.994452 2018] [wsgi:error] [pid 924] [remote 94.181.154.87:45492]   File "/usr/lib/python3.6/site-packages/pony/utils/utils.py", line 98, in throw
[Sat Jan 06 17:50:35.994461 2018] [wsgi:error] [pid 924] [remote 94.181.154.87:45492]     raise exc
[Sat Jan 06 17:50:35.994476 2018] [wsgi:error] [pid 924] [remote 94.181.154.87:45492] pony.orm.core.MultipleObjectsFoundError: Multiple objects were found. Use Taxi_order.select(...) to retrieve them
[Sat Jan 06 17:50:35.994536 2018] [wsgi:error] [pid 924] [remote 94.181.154.87:45492] 
